2023-09-08 07:48:13 [scrapy] DEBUG: Redirecting (302) to <GET https://www.google.com/sorry/index?continue=https://www.google.com/search%3Fq%3D%2Bmacbook%26hl%3Den%26gl%3DDK%26start%3D0&hl=en&q=EgRdpA0SGO6W6qcGIjCRK46V1gvEMLEYQCuF2M7rWhUV9STT69TuN98xY6DBMzjPbffMSWQuvDsQwYD2amwyAXJaAUM> from <GET https://www.google.com/search?q=+macbook&hl=en&gl=DK&start=0>
2023-09-08 07:48:14 [scrapy] DEBUG: Retrying <GET https://www.google.com/sorry/index?continue=https://www.google.com/search%3Fq%3D%2Bmacbook%26hl%3Den%26gl%3DDK%26start%3D0&hl=en&q=EgRdpA0SGO6W6qcGIjCRK46V1gvEMLEYQCuF2M7rWhUV9STT69TuN98xY6DBMzjPbffMSWQuvDsQwYD2amwyAXJaAUM> (failed 1 times): 429 Unknown Status
2023-09-08 07:48:16 [scrapy] DEBUG: Retrying <GET https://www.google.com/sorry/index?continue=https://www.google.com/search%3Fq%3D%2Bmacbook%26hl%3Den%26gl%3DDK%26start%3D0&hl=en&q=EgRdpA0SGO6W6qcGIjCRK46V1gvEMLEYQCuF2M7rWhUV9STT69TuN98xY6DBMzjPbffMSWQuvDsQwYD2amwyAXJaAUM> (failed 2 times): 429 Unknown Status
2023-09-08 07:48:17 [scrapy] ERROR: Gave up retrying <GET https://www.google.com/sorry/index?continue=https://www.google.com/search%3Fq%3D%2Bmacbook%26hl%3Den%26gl%3DDK%26start%3D0&hl=en&q=EgRdpA0SGO6W6qcGIjCRK46V1gvEMLEYQCuF2M7rWhUV9STT69TuN98xY6DBMzjPbffMSWQuvDsQwYD2amwyAXJaAUM> (failed 3 times): 429 Unknown Status
2023-09-08 07:48:17 [scrapy] DEBUG: Crawled (429) <GET https://www.google.com/sorry/index?continue=https://www.google.com/search%3Fq%3D%2Bmacbook%26hl%3Den%26gl%3DDK%26start%3D0&hl=en&q=EgRdpA0SGO6W6qcGIjCRK46V1gvEMLEYQCuF2M7rWhUV9STT69TuN98xY6DBMzjPbffMSWQuvDsQwYD2amwyAXJaAUM> (referer: None)
2023-09-08 07:48:17 [scrapy] INFO: Ignoring response <429 https://www.google.com/sorry/index?continue=https://www.google.com/search%3Fq%3D%2Bmacbook%26hl%3Den%26gl%3DDK%26start%3D0&hl=en&q=EgRdpA0SGO6W6qcGIjCRK46V1gvEMLEYQCuF2M7rWhUV9STT69TuN98xY6DBMzjPbffMSWQuvDsQwYD2amwyAXJaAUM>: HTTP status code is not handled or not allowed
2023-09-08 07:48:20 [scrapy] DEBUG: Crawled (200) <GET https://www.google.com/search?q=+ps5&hl=en&gl=DK&start=0> (referer: None)
2023-09-08 07:48:20 [scrapy] DEBUG: Crawled (200) <GET https://www.google.com/search?q=+iphone+13&hl=en&gl=DK&start=0> (referer: None)
2023-09-08 07:48:20 [scrapy] ERROR: Error processing {'country': 'DK',
 'keyword': ' ps5',
 'position': 1,
 'price': '3.879,00\xa0kr.',
 'product_url': 'https://www.elgiganten.dk/product/gaming/spillekonsol-tilbehor/playstation/playstation-spillekonsol/playstation-5-digital-edition-2022/533977',
 'title': 'PlayStation 5 Digital Edition (2022)',
 'url': 'elgiganten.dk',
 'user_id': 'admin'}
Traceback (most recent call last):
  File "C:\Users\Muhammad Umer\AppData\Local\Programs\Python\Python311\Lib\site-packages\twisted\internet\defer.py", line 1065, in adapt
    extracted = result.result()
                ^^^^^^^^^^^^^^^
  File "C:\Users\Muhammad Umer\AppData\Local\Programs\Python\Python311\Lib\site-packages\asgiref\sync.py", line 448, in __call__
    ret = await asyncio.wait_for(future, timeout=None)
          ^^^^^^^^^^^^^^^^^^^^^^^^^^^^^^^^^^^^^^^^^^^^
  File "C:\Users\Muhammad Umer\AppData\Local\Programs\Python\Python311\Lib\asyncio\tasks.py", line 442, in wait_for
    return await fut
           ^^^^^^^^^
  File "C:\Users\Muhammad Umer\AppData\Local\Programs\Python\Python311\Lib\concurrent\futures\thread.py", line 58, in run
    result = self.fn(*self.args, **self.kwargs)
             ^^^^^^^^^^^^^^^^^^^^^^^^^^^^^^^^^^
  File "C:\Users\Muhammad Umer\AppData\Local\Programs\Python\Python311\Lib\site-packages\asgiref\sync.py", line 490, in thread_handler
    return func(*args, **kwargs)
           ^^^^^^^^^^^^^^^^^^^^^
  File "D:\Outputs\Django Outputs\scraper\pipelines.py", line 33, in process_item
    location = Location.objects.get(country_code=item['country']).first()
               ^^^^^^^^^^^^^^^^^^^^^^^^^^^^^^^^^^^^^^^^^^^^^^^^^^
  File "C:\Users\Muhammad Umer\AppData\Local\Programs\Python\Python311\Lib\site-packages\django\db\models\manager.py", line 85, in manager_method
    return getattr(self.get_queryset(), name)(*args, **kwargs)
           ^^^^^^^^^^^^^^^^^^^^^^^^^^^^^^^^^^^^^^^^^^^^^^^^^^^
  File "C:\Users\Muhammad Umer\AppData\Local\Programs\Python\Python311\Lib\site-packages\django\db\models\query.py", line 653, in get
    raise self.model.MultipleObjectsReturned(
search.models.Location.MultipleObjectsReturned: get() returned more than one Location -- it returned 2!
2023-09-08 07:48:20 [scrapy] ERROR: Error processing {'country': 'DK',
 'keyword': ' ps5',
 'position': 2,
 'price': '3.690,00\xa0kr.',
 'product_url': 'https://www.proshop.dk/Spillekonsol/Sony-5-Digital-Edition-Nordic/3033825?utm_source=google&utm_medium=cpc&utm_campaign=searchengine',
 'title': 'Sony 5 - Digital Edition (Nordic)',
 'url': 'proshop.dk',
 'user_id': 'admin'}
Traceback (most recent call last):
  File "C:\Users\Muhammad Umer\AppData\Local\Programs\Python\Python311\Lib\site-packages\twisted\internet\defer.py", line 1065, in adapt
    extracted = result.result()
                ^^^^^^^^^^^^^^^
  File "C:\Users\Muhammad Umer\AppData\Local\Programs\Python\Python311\Lib\site-packages\asgiref\sync.py", line 448, in __call__
    ret = await asyncio.wait_for(future, timeout=None)
          ^^^^^^^^^^^^^^^^^^^^^^^^^^^^^^^^^^^^^^^^^^^^
  File "C:\Users\Muhammad Umer\AppData\Local\Programs\Python\Python311\Lib\asyncio\tasks.py", line 442, in wait_for
    return await fut
           ^^^^^^^^^
  File "C:\Users\Muhammad Umer\AppData\Local\Programs\Python\Python311\Lib\concurrent\futures\thread.py", line 58, in run
    result = self.fn(*self.args, **self.kwargs)
             ^^^^^^^^^^^^^^^^^^^^^^^^^^^^^^^^^^
  File "C:\Users\Muhammad Umer\AppData\Local\Programs\Python\Python311\Lib\site-packages\asgiref\sync.py", line 490, in thread_handler
    return func(*args, **kwargs)
           ^^^^^^^^^^^^^^^^^^^^^
  File "D:\Outputs\Django Outputs\scraper\pipelines.py", line 33, in process_item
    location = Location.objects.get(country_code=item['country']).first()
               ^^^^^^^^^^^^^^^^^^^^^^^^^^^^^^^^^^^^^^^^^^^^^^^^^^
  File "C:\Users\Muhammad Umer\AppData\Local\Programs\Python\Python311\Lib\site-packages\django\db\models\manager.py", line 85, in manager_method
    return getattr(self.get_queryset(), name)(*args, **kwargs)
           ^^^^^^^^^^^^^^^^^^^^^^^^^^^^^^^^^^^^^^^^^^^^^^^^^^^
  File "C:\Users\Muhammad Umer\AppData\Local\Programs\Python\Python311\Lib\site-packages\django\db\models\query.py", line 653, in get
    raise self.model.MultipleObjectsReturned(
search.models.Location.MultipleObjectsReturned: get() returned more than one Location -- it returned 2!
2023-09-08 07:48:20 [scrapy] ERROR: Error processing {'country': 'DK',
 'keyword': ' ps5',
 'position': 3,
 'price': '2.999,00\xa0kr.',
 'product_url': 'https://www.telia.dk/shop/playstation/sony-playstation-5-23-bundle-med-abonnement/#/white/0-gb',
 'title': 'Sony PlayStation 5 med abonnement. Min.pris: 5.302,00kr. 6 mdr. '
          'binding',
 'url': 'telia.dk',
 'user_id': 'admin'}
Traceback (most recent call last):
  File "C:\Users\Muhammad Umer\AppData\Local\Programs\Python\Python311\Lib\site-packages\twisted\internet\defer.py", line 1065, in adapt
    extracted = result.result()
                ^^^^^^^^^^^^^^^
  File "C:\Users\Muhammad Umer\AppData\Local\Programs\Python\Python311\Lib\site-packages\asgiref\sync.py", line 448, in __call__
    ret = await asyncio.wait_for(future, timeout=None)
          ^^^^^^^^^^^^^^^^^^^^^^^^^^^^^^^^^^^^^^^^^^^^
  File "C:\Users\Muhammad Umer\AppData\Local\Programs\Python\Python311\Lib\asyncio\tasks.py", line 442, in wait_for
    return await fut
           ^^^^^^^^^
  File "C:\Users\Muhammad Umer\AppData\Local\Programs\Python\Python311\Lib\concurrent\futures\thread.py", line 58, in run
    result = self.fn(*self.args, **self.kwargs)
             ^^^^^^^^^^^^^^^^^^^^^^^^^^^^^^^^^^
  File "C:\Users\Muhammad Umer\AppData\Local\Programs\Python\Python311\Lib\site-packages\asgiref\sync.py", line 490, in thread_handler
    return func(*args, **kwargs)
           ^^^^^^^^^^^^^^^^^^^^^
  File "D:\Outputs\Django Outputs\scraper\pipelines.py", line 33, in process_item
    location = Location.objects.get(country_code=item['country']).first()
               ^^^^^^^^^^^^^^^^^^^^^^^^^^^^^^^^^^^^^^^^^^^^^^^^^^
  File "C:\Users\Muhammad Umer\AppData\Local\Programs\Python\Python311\Lib\site-packages\django\db\models\manager.py", line 85, in manager_method
    return getattr(self.get_queryset(), name)(*args, **kwargs)
           ^^^^^^^^^^^^^^^^^^^^^^^^^^^^^^^^^^^^^^^^^^^^^^^^^^^
  File "C:\Users\Muhammad Umer\AppData\Local\Programs\Python\Python311\Lib\site-packages\django\db\models\query.py", line 653, in get
    raise self.model.MultipleObjectsReturned(
search.models.Location.MultipleObjectsReturned: get() returned more than one Location -- it returned 2!
2023-09-08 07:48:20 [scrapy] ERROR: Error processing {'country': 'DK',
 'keyword': ' ps5',
 'position': 4,
 'price': '3.777,00\xa0kr.',
 'product_url': 'https://www.power.dk/gaming-og-underholdning/playstation/playstation-konsoller/playstation-5-digital-edition/p-1840112/',
 'title': 'PLAYSTATION 5 DIGITAL EDITION',
 'url': 'power.dk',
 'user_id': 'admin'}
Traceback (most recent call last):
  File "C:\Users\Muhammad Umer\AppData\Local\Programs\Python\Python311\Lib\site-packages\twisted\internet\defer.py", line 1065, in adapt
    extracted = result.result()
                ^^^^^^^^^^^^^^^
  File "C:\Users\Muhammad Umer\AppData\Local\Programs\Python\Python311\Lib\site-packages\asgiref\sync.py", line 448, in __call__
    ret = await asyncio.wait_for(future, timeout=None)
          ^^^^^^^^^^^^^^^^^^^^^^^^^^^^^^^^^^^^^^^^^^^^
  File "C:\Users\Muhammad Umer\AppData\Local\Programs\Python\Python311\Lib\asyncio\tasks.py", line 442, in wait_for
    return await fut
           ^^^^^^^^^
  File "C:\Users\Muhammad Umer\AppData\Local\Programs\Python\Python311\Lib\concurrent\futures\thread.py", line 58, in run
    result = self.fn(*self.args, **self.kwargs)
             ^^^^^^^^^^^^^^^^^^^^^^^^^^^^^^^^^^
  File "C:\Users\Muhammad Umer\AppData\Local\Programs\Python\Python311\Lib\site-packages\asgiref\sync.py", line 490, in thread_handler
    return func(*args, **kwargs)
           ^^^^^^^^^^^^^^^^^^^^^
  File "D:\Outputs\Django Outputs\scraper\pipelines.py", line 33, in process_item
    location = Location.objects.get(country_code=item['country']).first()
               ^^^^^^^^^^^^^^^^^^^^^^^^^^^^^^^^^^^^^^^^^^^^^^^^^^
  File "C:\Users\Muhammad Umer\AppData\Local\Programs\Python\Python311\Lib\site-packages\django\db\models\manager.py", line 85, in manager_method
    return getattr(self.get_queryset(), name)(*args, **kwargs)
           ^^^^^^^^^^^^^^^^^^^^^^^^^^^^^^^^^^^^^^^^^^^^^^^^^^^
  File "C:\Users\Muhammad Umer\AppData\Local\Programs\Python\Python311\Lib\site-packages\django\db\models\query.py", line 653, in get
    raise self.model.MultipleObjectsReturned(
search.models.Location.MultipleObjectsReturned: get() returned more than one Location -- it returned 2!
2023-09-08 07:48:20 [scrapy] ERROR: Error processing {'country': 'DK',
 'keyword': ' ps5',
 'position': 5,
 'price': '4.359,00\xa0kr.',
 'product_url': 'https://www.elgiganten.dk/product/gaming/spillekonsol-tilbehor/playstation/playstation-spillekonsol/playstation-5-2022/533978',
 'title': 'PlayStation 5 (2022)',
 'url': 'elgiganten.dk',
 'user_id': 'admin'}
Traceback (most recent call last):
  File "C:\Users\Muhammad Umer\AppData\Local\Programs\Python\Python311\Lib\site-packages\twisted\internet\defer.py", line 1065, in adapt
    extracted = result.result()
                ^^^^^^^^^^^^^^^
  File "C:\Users\Muhammad Umer\AppData\Local\Programs\Python\Python311\Lib\site-packages\asgiref\sync.py", line 448, in __call__
    ret = await asyncio.wait_for(future, timeout=None)
          ^^^^^^^^^^^^^^^^^^^^^^^^^^^^^^^^^^^^^^^^^^^^
  File "C:\Users\Muhammad Umer\AppData\Local\Programs\Python\Python311\Lib\asyncio\tasks.py", line 442, in wait_for
    return await fut
           ^^^^^^^^^
  File "C:\Users\Muhammad Umer\AppData\Local\Programs\Python\Python311\Lib\concurrent\futures\thread.py", line 58, in run
    result = self.fn(*self.args, **self.kwargs)
             ^^^^^^^^^^^^^^^^^^^^^^^^^^^^^^^^^^
  File "C:\Users\Muhammad Umer\AppData\Local\Programs\Python\Python311\Lib\site-packages\asgiref\sync.py", line 490, in thread_handler
    return func(*args, **kwargs)
           ^^^^^^^^^^^^^^^^^^^^^
  File "D:\Outputs\Django Outputs\scraper\pipelines.py", line 33, in process_item
    location = Location.objects.get(country_code=item['country']).first()
               ^^^^^^^^^^^^^^^^^^^^^^^^^^^^^^^^^^^^^^^^^^^^^^^^^^
  File "C:\Users\Muhammad Umer\AppData\Local\Programs\Python\Python311\Lib\site-packages\django\db\models\manager.py", line 85, in manager_method
    return getattr(self.get_queryset(), name)(*args, **kwargs)
           ^^^^^^^^^^^^^^^^^^^^^^^^^^^^^^^^^^^^^^^^^^^^^^^^^^^
  File "C:\Users\Muhammad Umer\AppData\Local\Programs\Python\Python311\Lib\site-packages\django\db\models\query.py", line 653, in get
    raise self.model.MultipleObjectsReturned(
search.models.Location.MultipleObjectsReturned: get() returned more than one Location -- it returned 2!
2023-09-08 07:48:20 [scrapy] ERROR: Error processing {'country': 'DK',
 'keyword': ' ps5',
 'position': 6,
 'price': '5.190,00\xa0kr.',
 'product_url': 'https://www.proshop.dk/Spillekonsol/Sony-PlayStation-5-Marvels-Spider-Man-2-Limited-Edition-Bundle/3189056?utm_source=google&utm_medium=cpc&utm_campaign=searchengine',
 'title': "Sony PlayStation 5 Marvel's Spider-Man 2 Limited Edition Bundle",
 'url': 'proshop.dk',
 'user_id': 'admin'}
Traceback (most recent call last):
  File "C:\Users\Muhammad Umer\AppData\Local\Programs\Python\Python311\Lib\site-packages\twisted\internet\defer.py", line 1065, in adapt
    extracted = result.result()
                ^^^^^^^^^^^^^^^
  File "C:\Users\Muhammad Umer\AppData\Local\Programs\Python\Python311\Lib\site-packages\asgiref\sync.py", line 448, in __call__
    ret = await asyncio.wait_for(future, timeout=None)
          ^^^^^^^^^^^^^^^^^^^^^^^^^^^^^^^^^^^^^^^^^^^^
  File "C:\Users\Muhammad Umer\AppData\Local\Programs\Python\Python311\Lib\asyncio\tasks.py", line 442, in wait_for
    return await fut
           ^^^^^^^^^
  File "C:\Users\Muhammad Umer\AppData\Local\Programs\Python\Python311\Lib\concurrent\futures\thread.py", line 58, in run
    result = self.fn(*self.args, **self.kwargs)
             ^^^^^^^^^^^^^^^^^^^^^^^^^^^^^^^^^^
  File "C:\Users\Muhammad Umer\AppData\Local\Programs\Python\Python311\Lib\site-packages\asgiref\sync.py", line 490, in thread_handler
    return func(*args, **kwargs)
           ^^^^^^^^^^^^^^^^^^^^^
  File "D:\Outputs\Django Outputs\scraper\pipelines.py", line 33, in process_item
    location = Location.objects.get(country_code=item['country']).first()
               ^^^^^^^^^^^^^^^^^^^^^^^^^^^^^^^^^^^^^^^^^^^^^^^^^^
  File "C:\Users\Muhammad Umer\AppData\Local\Programs\Python\Python311\Lib\site-packages\django\db\models\manager.py", line 85, in manager_method
    return getattr(self.get_queryset(), name)(*args, **kwargs)
           ^^^^^^^^^^^^^^^^^^^^^^^^^^^^^^^^^^^^^^^^^^^^^^^^^^^
  File "C:\Users\Muhammad Umer\AppData\Local\Programs\Python\Python311\Lib\site-packages\django\db\models\query.py", line 653, in get
    raise self.model.MultipleObjectsReturned(
search.models.Location.MultipleObjectsReturned: get() returned more than one Location -- it returned 2!
2023-09-08 07:48:20 [scrapy] ERROR: Error processing {'country': 'DK',
 'keyword': ' ps5',
 'position': 7,
 'price': '4.991,00\xa0kr.',
 'product_url': 'https://www.elgiganten.dk/product/gaming/spillekonsol-tilbehor/playstation/playstation-spillekonsol/playstation-5-2x-dualsense-controller-pakke/581993',
 'title': 'PlayStation 5 + 2x DualSense controller-pakke',
 'url': 'elgiganten.dk',
 'user_id': 'admin'}
Traceback (most recent call last):
  File "C:\Users\Muhammad Umer\AppData\Local\Programs\Python\Python311\Lib\site-packages\twisted\internet\defer.py", line 1065, in adapt
    extracted = result.result()
                ^^^^^^^^^^^^^^^
  File "C:\Users\Muhammad Umer\AppData\Local\Programs\Python\Python311\Lib\site-packages\asgiref\sync.py", line 448, in __call__
    ret = await asyncio.wait_for(future, timeout=None)
          ^^^^^^^^^^^^^^^^^^^^^^^^^^^^^^^^^^^^^^^^^^^^
  File "C:\Users\Muhammad Umer\AppData\Local\Programs\Python\Python311\Lib\asyncio\tasks.py", line 442, in wait_for
    return await fut
           ^^^^^^^^^
  File "C:\Users\Muhammad Umer\AppData\Local\Programs\Python\Python311\Lib\concurrent\futures\thread.py", line 58, in run
    result = self.fn(*self.args, **self.kwargs)
             ^^^^^^^^^^^^^^^^^^^^^^^^^^^^^^^^^^
  File "C:\Users\Muhammad Umer\AppData\Local\Programs\Python\Python311\Lib\site-packages\asgiref\sync.py", line 490, in thread_handler
    return func(*args, **kwargs)
           ^^^^^^^^^^^^^^^^^^^^^
  File "D:\Outputs\Django Outputs\scraper\pipelines.py", line 33, in process_item
    location = Location.objects.get(country_code=item['country']).first()
               ^^^^^^^^^^^^^^^^^^^^^^^^^^^^^^^^^^^^^^^^^^^^^^^^^^
  File "C:\Users\Muhammad Umer\AppData\Local\Programs\Python\Python311\Lib\site-packages\django\db\models\manager.py", line 85, in manager_method
    return getattr(self.get_queryset(), name)(*args, **kwargs)
           ^^^^^^^^^^^^^^^^^^^^^^^^^^^^^^^^^^^^^^^^^^^^^^^^^^^
  File "C:\Users\Muhammad Umer\AppData\Local\Programs\Python\Python311\Lib\site-packages\django\db\models\query.py", line 653, in get
    raise self.model.MultipleObjectsReturned(
search.models.Location.MultipleObjectsReturned: get() returned more than one Location -- it returned 2!
2023-09-08 07:48:20 [scrapy] ERROR: Error processing {'country': 'DK',
 'keyword': ' ps5',
 'position': 8,
 'price': '4.359,00\xa0kr.',
 'product_url': 'https://www.power.dk/gaming-og-underholdning/playstation/playstation-konsoller/playstation-5/p-1840111/',
 'title': 'PLAYSTATION 5',
 'url': 'power.dk',
 'user_id': 'admin'}
Traceback (most recent call last):
  File "C:\Users\Muhammad Umer\AppData\Local\Programs\Python\Python311\Lib\site-packages\twisted\internet\defer.py", line 1065, in adapt
    extracted = result.result()
                ^^^^^^^^^^^^^^^
  File "C:\Users\Muhammad Umer\AppData\Local\Programs\Python\Python311\Lib\site-packages\asgiref\sync.py", line 448, in __call__
    ret = await asyncio.wait_for(future, timeout=None)
          ^^^^^^^^^^^^^^^^^^^^^^^^^^^^^^^^^^^^^^^^^^^^
  File "C:\Users\Muhammad Umer\AppData\Local\Programs\Python\Python311\Lib\asyncio\tasks.py", line 442, in wait_for
    return await fut
           ^^^^^^^^^
  File "C:\Users\Muhammad Umer\AppData\Local\Programs\Python\Python311\Lib\concurrent\futures\thread.py", line 58, in run
    result = self.fn(*self.args, **self.kwargs)
             ^^^^^^^^^^^^^^^^^^^^^^^^^^^^^^^^^^
  File "C:\Users\Muhammad Umer\AppData\Local\Programs\Python\Python311\Lib\site-packages\asgiref\sync.py", line 490, in thread_handler
    return func(*args, **kwargs)
           ^^^^^^^^^^^^^^^^^^^^^
  File "D:\Outputs\Django Outputs\scraper\pipelines.py", line 33, in process_item
    location = Location.objects.get(country_code=item['country']).first()
               ^^^^^^^^^^^^^^^^^^^^^^^^^^^^^^^^^^^^^^^^^^^^^^^^^^
  File "C:\Users\Muhammad Umer\AppData\Local\Programs\Python\Python311\Lib\site-packages\django\db\models\manager.py", line 85, in manager_method
    return getattr(self.get_queryset(), name)(*args, **kwargs)
           ^^^^^^^^^^^^^^^^^^^^^^^^^^^^^^^^^^^^^^^^^^^^^^^^^^^
  File "C:\Users\Muhammad Umer\AppData\Local\Programs\Python\Python311\Lib\site-packages\django\db\models\query.py", line 653, in get
    raise self.model.MultipleObjectsReturned(
search.models.Location.MultipleObjectsReturned: get() returned more than one Location -- it returned 2!
2023-09-08 07:48:20 [scrapy] ERROR: Error processing {'country': 'DK',
 'keyword': ' ps5',
 'position': 9,
 'price': '5.190,00\xa0kr.',
 'product_url': 'https://www.power.dk/gaming-og-underholdning/playstation/playstation-konsoller/playstation-5-konsol-marvels-spider-man-2-limited-edition-bundle/p-2525860/',
 'title': "PLAYSTATION 5 KONSOL - MARVEL'S SPIDER-MAN 2 LIMITED EDITION BUNDLE",
 'url': 'power.dk',
 'user_id': 'admin'}
Traceback (most recent call last):
  File "C:\Users\Muhammad Umer\AppData\Local\Programs\Python\Python311\Lib\site-packages\twisted\internet\defer.py", line 1065, in adapt
    extracted = result.result()
                ^^^^^^^^^^^^^^^
  File "C:\Users\Muhammad Umer\AppData\Local\Programs\Python\Python311\Lib\site-packages\asgiref\sync.py", line 448, in __call__
    ret = await asyncio.wait_for(future, timeout=None)
          ^^^^^^^^^^^^^^^^^^^^^^^^^^^^^^^^^^^^^^^^^^^^
  File "C:\Users\Muhammad Umer\AppData\Local\Programs\Python\Python311\Lib\asyncio\tasks.py", line 442, in wait_for
    return await fut
           ^^^^^^^^^
  File "C:\Users\Muhammad Umer\AppData\Local\Programs\Python\Python311\Lib\concurrent\futures\thread.py", line 58, in run
    result = self.fn(*self.args, **self.kwargs)
             ^^^^^^^^^^^^^^^^^^^^^^^^^^^^^^^^^^
  File "C:\Users\Muhammad Umer\AppData\Local\Programs\Python\Python311\Lib\site-packages\asgiref\sync.py", line 490, in thread_handler
    return func(*args, **kwargs)
           ^^^^^^^^^^^^^^^^^^^^^
  File "D:\Outputs\Django Outputs\scraper\pipelines.py", line 33, in process_item
    location = Location.objects.get(country_code=item['country']).first()
               ^^^^^^^^^^^^^^^^^^^^^^^^^^^^^^^^^^^^^^^^^^^^^^^^^^
  File "C:\Users\Muhammad Umer\AppData\Local\Programs\Python\Python311\Lib\site-packages\django\db\models\manager.py", line 85, in manager_method
    return getattr(self.get_queryset(), name)(*args, **kwargs)
           ^^^^^^^^^^^^^^^^^^^^^^^^^^^^^^^^^^^^^^^^^^^^^^^^^^^
  File "C:\Users\Muhammad Umer\AppData\Local\Programs\Python\Python311\Lib\site-packages\django\db\models\query.py", line 653, in get
    raise self.model.MultipleObjectsReturned(
search.models.Location.MultipleObjectsReturned: get() returned more than one Location -- it returned 2!
2023-09-08 07:48:20 [scrapy] ERROR: Error processing {'country': 'DK',
 'keyword': ' ps5',
 'position': 10,
 'price': '4.348,00\xa0kr.',
 'product_url': 'https://www.proshop.dk/Spillekonsol/Sony-PlayStation-5-Nordic/2831713?utm_source=google&utm_medium=cpc&utm_campaign=searchengine',
 'title': 'Sony PlayStation 5 (Nordic)',
 'url': 'proshop.dk',
 'user_id': 'admin'}
Traceback (most recent call last):
  File "C:\Users\Muhammad Umer\AppData\Local\Programs\Python\Python311\Lib\site-packages\twisted\internet\defer.py", line 1065, in adapt
    extracted = result.result()
                ^^^^^^^^^^^^^^^
  File "C:\Users\Muhammad Umer\AppData\Local\Programs\Python\Python311\Lib\site-packages\asgiref\sync.py", line 448, in __call__
    ret = await asyncio.wait_for(future, timeout=None)
          ^^^^^^^^^^^^^^^^^^^^^^^^^^^^^^^^^^^^^^^^^^^^
  File "C:\Users\Muhammad Umer\AppData\Local\Programs\Python\Python311\Lib\asyncio\tasks.py", line 442, in wait_for
    return await fut
           ^^^^^^^^^
  File "C:\Users\Muhammad Umer\AppData\Local\Programs\Python\Python311\Lib\concurrent\futures\thread.py", line 58, in run
    result = self.fn(*self.args, **self.kwargs)
             ^^^^^^^^^^^^^^^^^^^^^^^^^^^^^^^^^^
  File "C:\Users\Muhammad Umer\AppData\Local\Programs\Python\Python311\Lib\site-packages\asgiref\sync.py", line 490, in thread_handler
    return func(*args, **kwargs)
           ^^^^^^^^^^^^^^^^^^^^^
  File "D:\Outputs\Django Outputs\scraper\pipelines.py", line 33, in process_item
    location = Location.objects.get(country_code=item['country']).first()
               ^^^^^^^^^^^^^^^^^^^^^^^^^^^^^^^^^^^^^^^^^^^^^^^^^^
  File "C:\Users\Muhammad Umer\AppData\Local\Programs\Python\Python311\Lib\site-packages\django\db\models\manager.py", line 85, in manager_method
    return getattr(self.get_queryset(), name)(*args, **kwargs)
           ^^^^^^^^^^^^^^^^^^^^^^^^^^^^^^^^^^^^^^^^^^^^^^^^^^^
  File "C:\Users\Muhammad Umer\AppData\Local\Programs\Python\Python311\Lib\site-packages\django\db\models\query.py", line 653, in get
    raise self.model.MultipleObjectsReturned(
search.models.Location.MultipleObjectsReturned: get() returned more than one Location -- it returned 2!
2023-09-08 07:48:20 [scrapy] ERROR: Error processing {'country': 'DK',
 'keyword': ' ps5',
 'position': 11,
 'price': None,
 'product_url': None,
 'title': None,
 'url': '',
 'user_id': 'admin'}
Traceback (most recent call last):
  File "C:\Users\Muhammad Umer\AppData\Local\Programs\Python\Python311\Lib\site-packages\twisted\internet\defer.py", line 1065, in adapt
    extracted = result.result()
                ^^^^^^^^^^^^^^^
  File "C:\Users\Muhammad Umer\AppData\Local\Programs\Python\Python311\Lib\site-packages\asgiref\sync.py", line 448, in __call__
    ret = await asyncio.wait_for(future, timeout=None)
          ^^^^^^^^^^^^^^^^^^^^^^^^^^^^^^^^^^^^^^^^^^^^
  File "C:\Users\Muhammad Umer\AppData\Local\Programs\Python\Python311\Lib\asyncio\tasks.py", line 442, in wait_for
    return await fut
           ^^^^^^^^^
  File "C:\Users\Muhammad Umer\AppData\Local\Programs\Python\Python311\Lib\concurrent\futures\thread.py", line 58, in run
    result = self.fn(*self.args, **self.kwargs)
             ^^^^^^^^^^^^^^^^^^^^^^^^^^^^^^^^^^
  File "C:\Users\Muhammad Umer\AppData\Local\Programs\Python\Python311\Lib\site-packages\asgiref\sync.py", line 490, in thread_handler
    return func(*args, **kwargs)
           ^^^^^^^^^^^^^^^^^^^^^
  File "D:\Outputs\Django Outputs\scraper\pipelines.py", line 33, in process_item
    location = Location.objects.get(country_code=item['country']).first()
               ^^^^^^^^^^^^^^^^^^^^^^^^^^^^^^^^^^^^^^^^^^^^^^^^^^
  File "C:\Users\Muhammad Umer\AppData\Local\Programs\Python\Python311\Lib\site-packages\django\db\models\manager.py", line 85, in manager_method
    return getattr(self.get_queryset(), name)(*args, **kwargs)
           ^^^^^^^^^^^^^^^^^^^^^^^^^^^^^^^^^^^^^^^^^^^^^^^^^^^
  File "C:\Users\Muhammad Umer\AppData\Local\Programs\Python\Python311\Lib\site-packages\django\db\models\query.py", line 653, in get
    raise self.model.MultipleObjectsReturned(
search.models.Location.MultipleObjectsReturned: get() returned more than one Location -- it returned 2!
2023-09-08 07:48:20 [scrapy] ERROR: Error processing {'country': 'DK',
 'keyword': ' iphone 13',
 'position': 1,
 'price': '5.666,00\xa0kr.',
 'product_url': 'https://www.power.dk/mobil-og-foto/mobiltelefoner/apple-iphone-13-128-gb-midnat/p-1204127/',
 'title': 'APPLE IPHONE 13 128 GB MIDNAT',
 'url': 'power.dk',
 'user_id': 'admin'}
Traceback (most recent call last):
  File "C:\Users\Muhammad Umer\AppData\Local\Programs\Python\Python311\Lib\site-packages\twisted\internet\defer.py", line 1065, in adapt
    extracted = result.result()
                ^^^^^^^^^^^^^^^
  File "C:\Users\Muhammad Umer\AppData\Local\Programs\Python\Python311\Lib\site-packages\asgiref\sync.py", line 448, in __call__
    ret = await asyncio.wait_for(future, timeout=None)
          ^^^^^^^^^^^^^^^^^^^^^^^^^^^^^^^^^^^^^^^^^^^^
  File "C:\Users\Muhammad Umer\AppData\Local\Programs\Python\Python311\Lib\asyncio\tasks.py", line 442, in wait_for
    return await fut
           ^^^^^^^^^
  File "C:\Users\Muhammad Umer\AppData\Local\Programs\Python\Python311\Lib\concurrent\futures\thread.py", line 58, in run
    result = self.fn(*self.args, **self.kwargs)
             ^^^^^^^^^^^^^^^^^^^^^^^^^^^^^^^^^^
  File "C:\Users\Muhammad Umer\AppData\Local\Programs\Python\Python311\Lib\site-packages\asgiref\sync.py", line 490, in thread_handler
    return func(*args, **kwargs)
           ^^^^^^^^^^^^^^^^^^^^^
  File "D:\Outputs\Django Outputs\scraper\pipelines.py", line 33, in process_item
    location = Location.objects.get(country_code=item['country']).first()
               ^^^^^^^^^^^^^^^^^^^^^^^^^^^^^^^^^^^^^^^^^^^^^^^^^^
  File "C:\Users\Muhammad Umer\AppData\Local\Programs\Python\Python311\Lib\site-packages\django\db\models\manager.py", line 85, in manager_method
    return getattr(self.get_queryset(), name)(*args, **kwargs)
           ^^^^^^^^^^^^^^^^^^^^^^^^^^^^^^^^^^^^^^^^^^^^^^^^^^^
  File "C:\Users\Muhammad Umer\AppData\Local\Programs\Python\Python311\Lib\site-packages\django\db\models\query.py", line 653, in get
    raise self.model.MultipleObjectsReturned(
search.models.Location.MultipleObjectsReturned: get() returned more than one Location -- it returned 2!
2023-09-08 07:48:20 [scrapy] ERROR: Error processing {'country': 'DK',
 'keyword': ' iphone 13',
 'position': 2,
 'price': '5.666,00\xa0kr.',
 'product_url': 'https://www.elgiganten.dk/product/mobil-tablet-smartwatch/mobiltelefon/iphone-13-5g-smartphone-128gb-midnight/361879',
 'title': 'iPhone 13 – 5G smartphone 128GB Midnight',
 'url': 'elgiganten.dk',
 'user_id': 'admin'}
Traceback (most recent call last):
  File "C:\Users\Muhammad Umer\AppData\Local\Programs\Python\Python311\Lib\site-packages\twisted\internet\defer.py", line 1065, in adapt
    extracted = result.result()
                ^^^^^^^^^^^^^^^
  File "C:\Users\Muhammad Umer\AppData\Local\Programs\Python\Python311\Lib\site-packages\asgiref\sync.py", line 448, in __call__
    ret = await asyncio.wait_for(future, timeout=None)
          ^^^^^^^^^^^^^^^^^^^^^^^^^^^^^^^^^^^^^^^^^^^^
  File "C:\Users\Muhammad Umer\AppData\Local\Programs\Python\Python311\Lib\asyncio\tasks.py", line 442, in wait_for
    return await fut
           ^^^^^^^^^
  File "C:\Users\Muhammad Umer\AppData\Local\Programs\Python\Python311\Lib\concurrent\futures\thread.py", line 58, in run
    result = self.fn(*self.args, **self.kwargs)
             ^^^^^^^^^^^^^^^^^^^^^^^^^^^^^^^^^^
  File "C:\Users\Muhammad Umer\AppData\Local\Programs\Python\Python311\Lib\site-packages\asgiref\sync.py", line 490, in thread_handler
    return func(*args, **kwargs)
           ^^^^^^^^^^^^^^^^^^^^^
  File "D:\Outputs\Django Outputs\scraper\pipelines.py", line 33, in process_item
    location = Location.objects.get(country_code=item['country']).first()
               ^^^^^^^^^^^^^^^^^^^^^^^^^^^^^^^^^^^^^^^^^^^^^^^^^^
  File "C:\Users\Muhammad Umer\AppData\Local\Programs\Python\Python311\Lib\site-packages\django\db\models\manager.py", line 85, in manager_method
    return getattr(self.get_queryset(), name)(*args, **kwargs)
           ^^^^^^^^^^^^^^^^^^^^^^^^^^^^^^^^^^^^^^^^^^^^^^^^^^^
  File "C:\Users\Muhammad Umer\AppData\Local\Programs\Python\Python311\Lib\site-packages\django\db\models\query.py", line 653, in get
    raise self.model.MultipleObjectsReturned(
search.models.Location.MultipleObjectsReturned: get() returned more than one Location -- it returned 2!
2023-09-08 07:48:20 [scrapy] ERROR: Error processing {'country': 'DK',
 'keyword': ' iphone 13',
 'position': 3,
 'price': '4.306,99\xa0kr.',
 'product_url': 'https://www.refurbed.dk/p/iphone-13/?co=dk&utm_cluster=gradeC&utm_content=iphone-13&utm_group=iphone-13',
 'title': 'iPhone 13',
 'url': 'refurbed.dk',
 'user_id': 'admin'}
Traceback (most recent call last):
  File "C:\Users\Muhammad Umer\AppData\Local\Programs\Python\Python311\Lib\site-packages\twisted\internet\defer.py", line 1065, in adapt
    extracted = result.result()
                ^^^^^^^^^^^^^^^
  File "C:\Users\Muhammad Umer\AppData\Local\Programs\Python\Python311\Lib\site-packages\asgiref\sync.py", line 448, in __call__
    ret = await asyncio.wait_for(future, timeout=None)
          ^^^^^^^^^^^^^^^^^^^^^^^^^^^^^^^^^^^^^^^^^^^^
  File "C:\Users\Muhammad Umer\AppData\Local\Programs\Python\Python311\Lib\asyncio\tasks.py", line 442, in wait_for
    return await fut
           ^^^^^^^^^
  File "C:\Users\Muhammad Umer\AppData\Local\Programs\Python\Python311\Lib\concurrent\futures\thread.py", line 58, in run
    result = self.fn(*self.args, **self.kwargs)
             ^^^^^^^^^^^^^^^^^^^^^^^^^^^^^^^^^^
  File "C:\Users\Muhammad Umer\AppData\Local\Programs\Python\Python311\Lib\site-packages\asgiref\sync.py", line 490, in thread_handler
    return func(*args, **kwargs)
           ^^^^^^^^^^^^^^^^^^^^^
  File "D:\Outputs\Django Outputs\scraper\pipelines.py", line 33, in process_item
    location = Location.objects.get(country_code=item['country']).first()
               ^^^^^^^^^^^^^^^^^^^^^^^^^^^^^^^^^^^^^^^^^^^^^^^^^^
  File "C:\Users\Muhammad Umer\AppData\Local\Programs\Python\Python311\Lib\site-packages\django\db\models\manager.py", line 85, in manager_method
    return getattr(self.get_queryset(), name)(*args, **kwargs)
           ^^^^^^^^^^^^^^^^^^^^^^^^^^^^^^^^^^^^^^^^^^^^^^^^^^^
  File "C:\Users\Muhammad Umer\AppData\Local\Programs\Python\Python311\Lib\site-packages\django\db\models\query.py", line 653, in get
    raise self.model.MultipleObjectsReturned(
search.models.Location.MultipleObjectsReturned: get() returned more than one Location -- it returned 2!
2023-09-08 07:48:20 [scrapy] ERROR: Error processing {'country': 'DK',
 'keyword': ' iphone 13',
 'position': 4,
 'price': '4.899,00\xa0kr.',
 'product_url': 'https://www.telia.dk/shop/apple/apple-iphone-13/#/pink/128-gb/1',
 'title': 'Apple iPhone 13 128GB Pink. Min.pris: 6.702,00kr. 6 mdr. binding',
 'url': 'telia.dk',
 'user_id': 'admin'}
Traceback (most recent call last):
  File "C:\Users\Muhammad Umer\AppData\Local\Programs\Python\Python311\Lib\site-packages\twisted\internet\defer.py", line 1065, in adapt
    extracted = result.result()
                ^^^^^^^^^^^^^^^
  File "C:\Users\Muhammad Umer\AppData\Local\Programs\Python\Python311\Lib\site-packages\asgiref\sync.py", line 448, in __call__
    ret = await asyncio.wait_for(future, timeout=None)
          ^^^^^^^^^^^^^^^^^^^^^^^^^^^^^^^^^^^^^^^^^^^^
  File "C:\Users\Muhammad Umer\AppData\Local\Programs\Python\Python311\Lib\asyncio\tasks.py", line 442, in wait_for
    return await fut
           ^^^^^^^^^
  File "C:\Users\Muhammad Umer\AppData\Local\Programs\Python\Python311\Lib\concurrent\futures\thread.py", line 58, in run
    result = self.fn(*self.args, **self.kwargs)
             ^^^^^^^^^^^^^^^^^^^^^^^^^^^^^^^^^^
  File "C:\Users\Muhammad Umer\AppData\Local\Programs\Python\Python311\Lib\site-packages\asgiref\sync.py", line 490, in thread_handler
    return func(*args, **kwargs)
           ^^^^^^^^^^^^^^^^^^^^^
  File "D:\Outputs\Django Outputs\scraper\pipelines.py", line 33, in process_item
    location = Location.objects.get(country_code=item['country']).first()
               ^^^^^^^^^^^^^^^^^^^^^^^^^^^^^^^^^^^^^^^^^^^^^^^^^^
  File "C:\Users\Muhammad Umer\AppData\Local\Programs\Python\Python311\Lib\site-packages\django\db\models\manager.py", line 85, in manager_method
    return getattr(self.get_queryset(), name)(*args, **kwargs)
           ^^^^^^^^^^^^^^^^^^^^^^^^^^^^^^^^^^^^^^^^^^^^^^^^^^^
  File "C:\Users\Muhammad Umer\AppData\Local\Programs\Python\Python311\Lib\site-packages\django\db\models\query.py", line 653, in get
    raise self.model.MultipleObjectsReturned(
search.models.Location.MultipleObjectsReturned: get() returned more than one Location -- it returned 2!
2023-09-08 07:48:20 [scrapy] ERROR: Error processing {'country': 'DK',
 'keyword': ' iphone 13',
 'position': 5,
 'price': '4.759,00\xa0kr.',
 'product_url': 'https://swappie.com/dk/iphone/iphone-13/iphone-13-128gb-bla-4/',
 'title': 'iPhone 13 128GB Blå Apple',
 'url': 'swappie.com',
 'user_id': 'admin'}
Traceback (most recent call last):
  File "C:\Users\Muhammad Umer\AppData\Local\Programs\Python\Python311\Lib\site-packages\twisted\internet\defer.py", line 1065, in adapt
    extracted = result.result()
                ^^^^^^^^^^^^^^^
  File "C:\Users\Muhammad Umer\AppData\Local\Programs\Python\Python311\Lib\site-packages\asgiref\sync.py", line 448, in __call__
    ret = await asyncio.wait_for(future, timeout=None)
          ^^^^^^^^^^^^^^^^^^^^^^^^^^^^^^^^^^^^^^^^^^^^
  File "C:\Users\Muhammad Umer\AppData\Local\Programs\Python\Python311\Lib\asyncio\tasks.py", line 442, in wait_for
    return await fut
           ^^^^^^^^^
  File "C:\Users\Muhammad Umer\AppData\Local\Programs\Python\Python311\Lib\concurrent\futures\thread.py", line 58, in run
    result = self.fn(*self.args, **self.kwargs)
             ^^^^^^^^^^^^^^^^^^^^^^^^^^^^^^^^^^
  File "C:\Users\Muhammad Umer\AppData\Local\Programs\Python\Python311\Lib\site-packages\asgiref\sync.py", line 490, in thread_handler
    return func(*args, **kwargs)
           ^^^^^^^^^^^^^^^^^^^^^
  File "D:\Outputs\Django Outputs\scraper\pipelines.py", line 33, in process_item
    location = Location.objects.get(country_code=item['country']).first()
               ^^^^^^^^^^^^^^^^^^^^^^^^^^^^^^^^^^^^^^^^^^^^^^^^^^
  File "C:\Users\Muhammad Umer\AppData\Local\Programs\Python\Python311\Lib\site-packages\django\db\models\manager.py", line 85, in manager_method
    return getattr(self.get_queryset(), name)(*args, **kwargs)
           ^^^^^^^^^^^^^^^^^^^^^^^^^^^^^^^^^^^^^^^^^^^^^^^^^^^
  File "C:\Users\Muhammad Umer\AppData\Local\Programs\Python\Python311\Lib\site-packages\django\db\models\query.py", line 653, in get
    raise self.model.MultipleObjectsReturned(
search.models.Location.MultipleObjectsReturned: get() returned more than one Location -- it returned 2!
2023-09-08 07:48:20 [scrapy] ERROR: Error processing {'country': 'DK',
 'keyword': ' iphone 13',
 'position': 6,
 'price': '4.795,00\xa0kr.',
 'product_url': 'https://tech24.dk/products/brugt-iphone-13-128gb-som-ny-gron?variant=46819275571528&currency=DKK',
 'title': 'Brugt iPhone 13, 128GB - Som Ny - Blå - tech24.dk Nej tak',
 'url': 'tech24.dk',
 'user_id': 'admin'}
Traceback (most recent call last):
  File "C:\Users\Muhammad Umer\AppData\Local\Programs\Python\Python311\Lib\site-packages\twisted\internet\defer.py", line 1065, in adapt
    extracted = result.result()
                ^^^^^^^^^^^^^^^
  File "C:\Users\Muhammad Umer\AppData\Local\Programs\Python\Python311\Lib\site-packages\asgiref\sync.py", line 448, in __call__
    ret = await asyncio.wait_for(future, timeout=None)
          ^^^^^^^^^^^^^^^^^^^^^^^^^^^^^^^^^^^^^^^^^^^^
  File "C:\Users\Muhammad Umer\AppData\Local\Programs\Python\Python311\Lib\asyncio\tasks.py", line 442, in wait_for
    return await fut
           ^^^^^^^^^
  File "C:\Users\Muhammad Umer\AppData\Local\Programs\Python\Python311\Lib\concurrent\futures\thread.py", line 58, in run
    result = self.fn(*self.args, **self.kwargs)
             ^^^^^^^^^^^^^^^^^^^^^^^^^^^^^^^^^^
  File "C:\Users\Muhammad Umer\AppData\Local\Programs\Python\Python311\Lib\site-packages\asgiref\sync.py", line 490, in thread_handler
    return func(*args, **kwargs)
           ^^^^^^^^^^^^^^^^^^^^^
  File "D:\Outputs\Django Outputs\scraper\pipelines.py", line 33, in process_item
    location = Location.objects.get(country_code=item['country']).first()
               ^^^^^^^^^^^^^^^^^^^^^^^^^^^^^^^^^^^^^^^^^^^^^^^^^^
  File "C:\Users\Muhammad Umer\AppData\Local\Programs\Python\Python311\Lib\site-packages\django\db\models\manager.py", line 85, in manager_method
    return getattr(self.get_queryset(), name)(*args, **kwargs)
           ^^^^^^^^^^^^^^^^^^^^^^^^^^^^^^^^^^^^^^^^^^^^^^^^^^^
  File "C:\Users\Muhammad Umer\AppData\Local\Programs\Python\Python311\Lib\site-packages\django\db\models\query.py", line 653, in get
    raise self.model.MultipleObjectsReturned(
search.models.Location.MultipleObjectsReturned: get() returned more than one Location -- it returned 2!
2023-09-08 07:48:20 [scrapy] ERROR: Error processing {'country': 'DK',
 'keyword': ' iphone 13',
 'position': 7,
 'price': '6.999,00\xa0kr.',
 'product_url': 'https://www.power.dk/mobil-og-foto/mobiltelefoner/apple-iphone-13-512-gb-stjerneskaer/p-1204138/',
 'title': 'APPLE IPHONE 13 512 GB STJERNESKÆR',
 'url': 'power.dk',
 'user_id': 'admin'}
Traceback (most recent call last):
  File "C:\Users\Muhammad Umer\AppData\Local\Programs\Python\Python311\Lib\site-packages\twisted\internet\defer.py", line 1065, in adapt
    extracted = result.result()
                ^^^^^^^^^^^^^^^
  File "C:\Users\Muhammad Umer\AppData\Local\Programs\Python\Python311\Lib\site-packages\asgiref\sync.py", line 448, in __call__
    ret = await asyncio.wait_for(future, timeout=None)
          ^^^^^^^^^^^^^^^^^^^^^^^^^^^^^^^^^^^^^^^^^^^^
  File "C:\Users\Muhammad Umer\AppData\Local\Programs\Python\Python311\Lib\asyncio\tasks.py", line 442, in wait_for
    return await fut
           ^^^^^^^^^
  File "C:\Users\Muhammad Umer\AppData\Local\Programs\Python\Python311\Lib\concurrent\futures\thread.py", line 58, in run
    result = self.fn(*self.args, **self.kwargs)
             ^^^^^^^^^^^^^^^^^^^^^^^^^^^^^^^^^^
  File "C:\Users\Muhammad Umer\AppData\Local\Programs\Python\Python311\Lib\site-packages\asgiref\sync.py", line 490, in thread_handler
    return func(*args, **kwargs)
           ^^^^^^^^^^^^^^^^^^^^^
  File "D:\Outputs\Django Outputs\scraper\pipelines.py", line 33, in process_item
    location = Location.objects.get(country_code=item['country']).first()
               ^^^^^^^^^^^^^^^^^^^^^^^^^^^^^^^^^^^^^^^^^^^^^^^^^^
  File "C:\Users\Muhammad Umer\AppData\Local\Programs\Python\Python311\Lib\site-packages\django\db\models\manager.py", line 85, in manager_method
    return getattr(self.get_queryset(), name)(*args, **kwargs)
           ^^^^^^^^^^^^^^^^^^^^^^^^^^^^^^^^^^^^^^^^^^^^^^^^^^^
  File "C:\Users\Muhammad Umer\AppData\Local\Programs\Python\Python311\Lib\site-packages\django\db\models\query.py", line 653, in get
    raise self.model.MultipleObjectsReturned(
search.models.Location.MultipleObjectsReturned: get() returned more than one Location -- it returned 2!
2023-09-08 07:48:20 [scrapy] ERROR: Error processing {'country': 'DK',
 'keyword': ' iphone 13',
 'position': 8,
 'price': '2.989,99\xa0kr.',
 'product_url': 'https://www.refurbed.dk/p/iphone-12/?co=dk&utm_cluster=gradeA&utm_content=iphone-12&utm_group=iphone-12',
 'title': 'iPhone 12',
 'url': 'refurbed.dk',
 'user_id': 'admin'}
Traceback (most recent call last):
  File "C:\Users\Muhammad Umer\AppData\Local\Programs\Python\Python311\Lib\site-packages\twisted\internet\defer.py", line 1065, in adapt
    extracted = result.result()
                ^^^^^^^^^^^^^^^
  File "C:\Users\Muhammad Umer\AppData\Local\Programs\Python\Python311\Lib\site-packages\asgiref\sync.py", line 448, in __call__
    ret = await asyncio.wait_for(future, timeout=None)
          ^^^^^^^^^^^^^^^^^^^^^^^^^^^^^^^^^^^^^^^^^^^^
  File "C:\Users\Muhammad Umer\AppData\Local\Programs\Python\Python311\Lib\asyncio\tasks.py", line 442, in wait_for
    return await fut
           ^^^^^^^^^
  File "C:\Users\Muhammad Umer\AppData\Local\Programs\Python\Python311\Lib\concurrent\futures\thread.py", line 58, in run
    result = self.fn(*self.args, **self.kwargs)
             ^^^^^^^^^^^^^^^^^^^^^^^^^^^^^^^^^^
  File "C:\Users\Muhammad Umer\AppData\Local\Programs\Python\Python311\Lib\site-packages\asgiref\sync.py", line 490, in thread_handler
    return func(*args, **kwargs)
           ^^^^^^^^^^^^^^^^^^^^^
  File "D:\Outputs\Django Outputs\scraper\pipelines.py", line 33, in process_item
    location = Location.objects.get(country_code=item['country']).first()
               ^^^^^^^^^^^^^^^^^^^^^^^^^^^^^^^^^^^^^^^^^^^^^^^^^^
  File "C:\Users\Muhammad Umer\AppData\Local\Programs\Python\Python311\Lib\site-packages\django\db\models\manager.py", line 85, in manager_method
    return getattr(self.get_queryset(), name)(*args, **kwargs)
           ^^^^^^^^^^^^^^^^^^^^^^^^^^^^^^^^^^^^^^^^^^^^^^^^^^^
  File "C:\Users\Muhammad Umer\AppData\Local\Programs\Python\Python311\Lib\site-packages\django\db\models\query.py", line 653, in get
    raise self.model.MultipleObjectsReturned(
search.models.Location.MultipleObjectsReturned: get() returned more than one Location -- it returned 2!
2023-09-08 07:48:20 [scrapy] ERROR: Error processing {'country': 'DK',
 'keyword': ' iphone 13',
 'position': 9,
 'price': '5.049,00\xa0kr.',
 'product_url': 'https://greenmind.dk/telefoner/iphones/iphone-13/iphone-13/apple-iphone-13-256-gb-starlight-used-good-24954',
 'title': 'Apple iPhone 13 256 GB Starlight Used - Good',
 'url': 'greenmind.dk',
 'user_id': 'admin'}
Traceback (most recent call last):
  File "C:\Users\Muhammad Umer\AppData\Local\Programs\Python\Python311\Lib\site-packages\twisted\internet\defer.py", line 1065, in adapt
    extracted = result.result()
                ^^^^^^^^^^^^^^^
  File "C:\Users\Muhammad Umer\AppData\Local\Programs\Python\Python311\Lib\site-packages\asgiref\sync.py", line 448, in __call__
    ret = await asyncio.wait_for(future, timeout=None)
          ^^^^^^^^^^^^^^^^^^^^^^^^^^^^^^^^^^^^^^^^^^^^
  File "C:\Users\Muhammad Umer\AppData\Local\Programs\Python\Python311\Lib\asyncio\tasks.py", line 442, in wait_for
    return await fut
           ^^^^^^^^^
  File "C:\Users\Muhammad Umer\AppData\Local\Programs\Python\Python311\Lib\concurrent\futures\thread.py", line 58, in run
    result = self.fn(*self.args, **self.kwargs)
             ^^^^^^^^^^^^^^^^^^^^^^^^^^^^^^^^^^
  File "C:\Users\Muhammad Umer\AppData\Local\Programs\Python\Python311\Lib\site-packages\asgiref\sync.py", line 490, in thread_handler
    return func(*args, **kwargs)
           ^^^^^^^^^^^^^^^^^^^^^
  File "D:\Outputs\Django Outputs\scraper\pipelines.py", line 33, in process_item
    location = Location.objects.get(country_code=item['country']).first()
               ^^^^^^^^^^^^^^^^^^^^^^^^^^^^^^^^^^^^^^^^^^^^^^^^^^
  File "C:\Users\Muhammad Umer\AppData\Local\Programs\Python\Python311\Lib\site-packages\django\db\models\manager.py", line 85, in manager_method
    return getattr(self.get_queryset(), name)(*args, **kwargs)
           ^^^^^^^^^^^^^^^^^^^^^^^^^^^^^^^^^^^^^^^^^^^^^^^^^^^
  File "C:\Users\Muhammad Umer\AppData\Local\Programs\Python\Python311\Lib\site-packages\django\db\models\query.py", line 653, in get
    raise self.model.MultipleObjectsReturned(
search.models.Location.MultipleObjectsReturned: get() returned more than one Location -- it returned 2!
2023-09-08 07:48:20 [scrapy] ERROR: Error processing {'country': 'DK',
 'keyword': ' iphone 13',
 'position': 10,
 'price': '5.666,00\xa0kr.',
 'product_url': 'https://www.elgiganten.dk/product/mobil-tablet-smartwatch/mobiltelefon/iphone-13-5g-smartphone-128gb-starlight/361914',
 'title': 'iPhone 13 – 5G smartphone 128GB Starlight',
 'url': 'elgiganten.dk',
 'user_id': 'admin'}
Traceback (most recent call last):
  File "C:\Users\Muhammad Umer\AppData\Local\Programs\Python\Python311\Lib\site-packages\twisted\internet\defer.py", line 1065, in adapt
    extracted = result.result()
                ^^^^^^^^^^^^^^^
  File "C:\Users\Muhammad Umer\AppData\Local\Programs\Python\Python311\Lib\site-packages\asgiref\sync.py", line 448, in __call__
    ret = await asyncio.wait_for(future, timeout=None)
          ^^^^^^^^^^^^^^^^^^^^^^^^^^^^^^^^^^^^^^^^^^^^
  File "C:\Users\Muhammad Umer\AppData\Local\Programs\Python\Python311\Lib\asyncio\tasks.py", line 442, in wait_for
    return await fut
           ^^^^^^^^^
  File "C:\Users\Muhammad Umer\AppData\Local\Programs\Python\Python311\Lib\concurrent\futures\thread.py", line 58, in run
    result = self.fn(*self.args, **self.kwargs)
             ^^^^^^^^^^^^^^^^^^^^^^^^^^^^^^^^^^
  File "C:\Users\Muhammad Umer\AppData\Local\Programs\Python\Python311\Lib\site-packages\asgiref\sync.py", line 490, in thread_handler
    return func(*args, **kwargs)
           ^^^^^^^^^^^^^^^^^^^^^
  File "D:\Outputs\Django Outputs\scraper\pipelines.py", line 33, in process_item
    location = Location.objects.get(country_code=item['country']).first()
               ^^^^^^^^^^^^^^^^^^^^^^^^^^^^^^^^^^^^^^^^^^^^^^^^^^
  File "C:\Users\Muhammad Umer\AppData\Local\Programs\Python\Python311\Lib\site-packages\django\db\models\manager.py", line 85, in manager_method
    return getattr(self.get_queryset(), name)(*args, **kwargs)
           ^^^^^^^^^^^^^^^^^^^^^^^^^^^^^^^^^^^^^^^^^^^^^^^^^^^
  File "C:\Users\Muhammad Umer\AppData\Local\Programs\Python\Python311\Lib\site-packages\django\db\models\query.py", line 653, in get
    raise self.model.MultipleObjectsReturned(
search.models.Location.MultipleObjectsReturned: get() returned more than one Location -- it returned 2!
2023-09-08 07:48:20 [scrapy] ERROR: Error processing {'country': 'DK',
 'keyword': ' iphone 13',
 'position': 11,
 'price': '4.306,99\xa0kr.',
 'product_url': 'https://www.refurbed.dk/p/iphone-13/14156c/?co=dk&utm_cluster=gradeC&utm_content=iphone-13-14156c&utm_group=iphone-13',
 'title': 'iPhone 13 | 128 GB | Dual-SIM | pink',
 'url': 'refurbed.dk',
 'user_id': 'admin'}
Traceback (most recent call last):
  File "C:\Users\Muhammad Umer\AppData\Local\Programs\Python\Python311\Lib\site-packages\twisted\internet\defer.py", line 1065, in adapt
    extracted = result.result()
                ^^^^^^^^^^^^^^^
  File "C:\Users\Muhammad Umer\AppData\Local\Programs\Python\Python311\Lib\site-packages\asgiref\sync.py", line 448, in __call__
    ret = await asyncio.wait_for(future, timeout=None)
          ^^^^^^^^^^^^^^^^^^^^^^^^^^^^^^^^^^^^^^^^^^^^
  File "C:\Users\Muhammad Umer\AppData\Local\Programs\Python\Python311\Lib\asyncio\tasks.py", line 442, in wait_for
    return await fut
           ^^^^^^^^^
  File "C:\Users\Muhammad Umer\AppData\Local\Programs\Python\Python311\Lib\concurrent\futures\thread.py", line 58, in run
    result = self.fn(*self.args, **self.kwargs)
             ^^^^^^^^^^^^^^^^^^^^^^^^^^^^^^^^^^
  File "C:\Users\Muhammad Umer\AppData\Local\Programs\Python\Python311\Lib\site-packages\asgiref\sync.py", line 490, in thread_handler
    return func(*args, **kwargs)
           ^^^^^^^^^^^^^^^^^^^^^
  File "D:\Outputs\Django Outputs\scraper\pipelines.py", line 33, in process_item
    location = Location.objects.get(country_code=item['country']).first()
               ^^^^^^^^^^^^^^^^^^^^^^^^^^^^^^^^^^^^^^^^^^^^^^^^^^
  File "C:\Users\Muhammad Umer\AppData\Local\Programs\Python\Python311\Lib\site-packages\django\db\models\manager.py", line 85, in manager_method
    return getattr(self.get_queryset(), name)(*args, **kwargs)
           ^^^^^^^^^^^^^^^^^^^^^^^^^^^^^^^^^^^^^^^^^^^^^^^^^^^
  File "C:\Users\Muhammad Umer\AppData\Local\Programs\Python\Python311\Lib\site-packages\django\db\models\query.py", line 653, in get
    raise self.model.MultipleObjectsReturned(
search.models.Location.MultipleObjectsReturned: get() returned more than one Location -- it returned 2!
2023-09-08 07:48:20 [scrapy] ERROR: Error processing {'country': 'DK',
 'keyword': ' iphone 13',
 'position': 12,
 'price': '5.666,00\xa0kr.',
 'product_url': 'https://www.elgiganten.dk/product/mobil-tablet-smartwatch/mobiltelefon/iphone-13-5g-smartphone-128gb-gron/431372',
 'title': 'iPhone 13 – 5G smartphone 128GB Grøn',
 'url': 'elgiganten.dk',
 'user_id': 'admin'}
Traceback (most recent call last):
  File "C:\Users\Muhammad Umer\AppData\Local\Programs\Python\Python311\Lib\site-packages\twisted\internet\defer.py", line 1065, in adapt
    extracted = result.result()
                ^^^^^^^^^^^^^^^
  File "C:\Users\Muhammad Umer\AppData\Local\Programs\Python\Python311\Lib\site-packages\asgiref\sync.py", line 448, in __call__
    ret = await asyncio.wait_for(future, timeout=None)
          ^^^^^^^^^^^^^^^^^^^^^^^^^^^^^^^^^^^^^^^^^^^^
  File "C:\Users\Muhammad Umer\AppData\Local\Programs\Python\Python311\Lib\asyncio\tasks.py", line 442, in wait_for
    return await fut
           ^^^^^^^^^
  File "C:\Users\Muhammad Umer\AppData\Local\Programs\Python\Python311\Lib\concurrent\futures\thread.py", line 58, in run
    result = self.fn(*self.args, **self.kwargs)
             ^^^^^^^^^^^^^^^^^^^^^^^^^^^^^^^^^^
  File "C:\Users\Muhammad Umer\AppData\Local\Programs\Python\Python311\Lib\site-packages\asgiref\sync.py", line 490, in thread_handler
    return func(*args, **kwargs)
           ^^^^^^^^^^^^^^^^^^^^^
  File "D:\Outputs\Django Outputs\scraper\pipelines.py", line 33, in process_item
    location = Location.objects.get(country_code=item['country']).first()
               ^^^^^^^^^^^^^^^^^^^^^^^^^^^^^^^^^^^^^^^^^^^^^^^^^^
  File "C:\Users\Muhammad Umer\AppData\Local\Programs\Python\Python311\Lib\site-packages\django\db\models\manager.py", line 85, in manager_method
    return getattr(self.get_queryset(), name)(*args, **kwargs)
           ^^^^^^^^^^^^^^^^^^^^^^^^^^^^^^^^^^^^^^^^^^^^^^^^^^^
  File "C:\Users\Muhammad Umer\AppData\Local\Programs\Python\Python311\Lib\site-packages\django\db\models\query.py", line 653, in get
    raise self.model.MultipleObjectsReturned(
search.models.Location.MultipleObjectsReturned: get() returned more than one Location -- it returned 2!
2023-09-08 07:48:20 [scrapy] ERROR: Error processing {'country': 'DK',
 'keyword': ' iphone 13',
 'position': 13,
 'price': '4.680,99\xa0kr.',
 'product_url': 'https://www.refurbed.dk/p/iphone-13/14159/?co=dk&utm_cluster=gradeA&utm_content=iphone-13-14159&utm_group=iphone-13',
 'title': 'Som Ny: iPhone 13 | 128 GB | Dual-SIM | blå',
 'url': 'refurbed.dk',
 'user_id': 'admin'}
Traceback (most recent call last):
  File "C:\Users\Muhammad Umer\AppData\Local\Programs\Python\Python311\Lib\site-packages\twisted\internet\defer.py", line 1065, in adapt
    extracted = result.result()
                ^^^^^^^^^^^^^^^
  File "C:\Users\Muhammad Umer\AppData\Local\Programs\Python\Python311\Lib\site-packages\asgiref\sync.py", line 448, in __call__
    ret = await asyncio.wait_for(future, timeout=None)
          ^^^^^^^^^^^^^^^^^^^^^^^^^^^^^^^^^^^^^^^^^^^^
  File "C:\Users\Muhammad Umer\AppData\Local\Programs\Python\Python311\Lib\asyncio\tasks.py", line 442, in wait_for
    return await fut
           ^^^^^^^^^
  File "C:\Users\Muhammad Umer\AppData\Local\Programs\Python\Python311\Lib\concurrent\futures\thread.py", line 58, in run
    result = self.fn(*self.args, **self.kwargs)
             ^^^^^^^^^^^^^^^^^^^^^^^^^^^^^^^^^^
  File "C:\Users\Muhammad Umer\AppData\Local\Programs\Python\Python311\Lib\site-packages\asgiref\sync.py", line 490, in thread_handler
    return func(*args, **kwargs)
           ^^^^^^^^^^^^^^^^^^^^^
  File "D:\Outputs\Django Outputs\scraper\pipelines.py", line 33, in process_item
    location = Location.objects.get(country_code=item['country']).first()
               ^^^^^^^^^^^^^^^^^^^^^^^^^^^^^^^^^^^^^^^^^^^^^^^^^^
  File "C:\Users\Muhammad Umer\AppData\Local\Programs\Python\Python311\Lib\site-packages\django\db\models\manager.py", line 85, in manager_method
    return getattr(self.get_queryset(), name)(*args, **kwargs)
           ^^^^^^^^^^^^^^^^^^^^^^^^^^^^^^^^^^^^^^^^^^^^^^^^^^^
  File "C:\Users\Muhammad Umer\AppData\Local\Programs\Python\Python311\Lib\site-packages\django\db\models\query.py", line 653, in get
    raise self.model.MultipleObjectsReturned(
search.models.Location.MultipleObjectsReturned: get() returned more than one Location -- it returned 2!
2023-09-08 07:48:20 [scrapy] ERROR: Error processing {'country': 'DK',
 'keyword': ' iphone 13',
 'position': 14,
 'price': '5.666,00\xa0kr.',
 'product_url': 'https://www.power.dk/mobil-og-foto/mobiltelefoner/apple-iphone-13-128-gb-groen/p-1335029/',
 'title': 'APPLE IPHONE 13 128 GB GRØN',
 'url': 'power.dk',
 'user_id': 'admin'}
Traceback (most recent call last):
  File "C:\Users\Muhammad Umer\AppData\Local\Programs\Python\Python311\Lib\site-packages\twisted\internet\defer.py", line 1065, in adapt
    extracted = result.result()
                ^^^^^^^^^^^^^^^
  File "C:\Users\Muhammad Umer\AppData\Local\Programs\Python\Python311\Lib\site-packages\asgiref\sync.py", line 448, in __call__
    ret = await asyncio.wait_for(future, timeout=None)
          ^^^^^^^^^^^^^^^^^^^^^^^^^^^^^^^^^^^^^^^^^^^^
  File "C:\Users\Muhammad Umer\AppData\Local\Programs\Python\Python311\Lib\asyncio\tasks.py", line 442, in wait_for
    return await fut
           ^^^^^^^^^
  File "C:\Users\Muhammad Umer\AppData\Local\Programs\Python\Python311\Lib\concurrent\futures\thread.py", line 58, in run
    result = self.fn(*self.args, **self.kwargs)
             ^^^^^^^^^^^^^^^^^^^^^^^^^^^^^^^^^^
  File "C:\Users\Muhammad Umer\AppData\Local\Programs\Python\Python311\Lib\site-packages\asgiref\sync.py", line 490, in thread_handler
    return func(*args, **kwargs)
           ^^^^^^^^^^^^^^^^^^^^^
  File "D:\Outputs\Django Outputs\scraper\pipelines.py", line 33, in process_item
    location = Location.objects.get(country_code=item['country']).first()
               ^^^^^^^^^^^^^^^^^^^^^^^^^^^^^^^^^^^^^^^^^^^^^^^^^^
  File "C:\Users\Muhammad Umer\AppData\Local\Programs\Python\Python311\Lib\site-packages\django\db\models\manager.py", line 85, in manager_method
    return getattr(self.get_queryset(), name)(*args, **kwargs)
           ^^^^^^^^^^^^^^^^^^^^^^^^^^^^^^^^^^^^^^^^^^^^^^^^^^^
  File "C:\Users\Muhammad Umer\AppData\Local\Programs\Python\Python311\Lib\site-packages\django\db\models\query.py", line 653, in get
    raise self.model.MultipleObjectsReturned(
search.models.Location.MultipleObjectsReturned: get() returned more than one Location -- it returned 2!
2023-09-08 07:48:20 [scrapy] ERROR: Error processing {'country': 'DK',
 'keyword': ' iphone 13',
 'position': 15,
 'price': '3.995,00\xa0kr.',
 'product_url': 'https://www.phonetrade.dk/kob/iphone-13/stjerneskaer-128gb-brugbar-599',
 'title': 'iPhone 13, 128GB, Stjerneskær',
 'url': 'phonetrade.dk',
 'user_id': 'admin'}
Traceback (most recent call last):
  File "C:\Users\Muhammad Umer\AppData\Local\Programs\Python\Python311\Lib\site-packages\twisted\internet\defer.py", line 1065, in adapt
    extracted = result.result()
                ^^^^^^^^^^^^^^^
  File "C:\Users\Muhammad Umer\AppData\Local\Programs\Python\Python311\Lib\site-packages\asgiref\sync.py", line 448, in __call__
    ret = await asyncio.wait_for(future, timeout=None)
          ^^^^^^^^^^^^^^^^^^^^^^^^^^^^^^^^^^^^^^^^^^^^
  File "C:\Users\Muhammad Umer\AppData\Local\Programs\Python\Python311\Lib\asyncio\tasks.py", line 442, in wait_for
    return await fut
           ^^^^^^^^^
  File "C:\Users\Muhammad Umer\AppData\Local\Programs\Python\Python311\Lib\concurrent\futures\thread.py", line 58, in run
    result = self.fn(*self.args, **self.kwargs)
             ^^^^^^^^^^^^^^^^^^^^^^^^^^^^^^^^^^
  File "C:\Users\Muhammad Umer\AppData\Local\Programs\Python\Python311\Lib\site-packages\asgiref\sync.py", line 490, in thread_handler
    return func(*args, **kwargs)
           ^^^^^^^^^^^^^^^^^^^^^
  File "D:\Outputs\Django Outputs\scraper\pipelines.py", line 33, in process_item
    location = Location.objects.get(country_code=item['country']).first()
               ^^^^^^^^^^^^^^^^^^^^^^^^^^^^^^^^^^^^^^^^^^^^^^^^^^
  File "C:\Users\Muhammad Umer\AppData\Local\Programs\Python\Python311\Lib\site-packages\django\db\models\manager.py", line 85, in manager_method
    return getattr(self.get_queryset(), name)(*args, **kwargs)
           ^^^^^^^^^^^^^^^^^^^^^^^^^^^^^^^^^^^^^^^^^^^^^^^^^^^
  File "C:\Users\Muhammad Umer\AppData\Local\Programs\Python\Python311\Lib\site-packages\django\db\models\query.py", line 653, in get
    raise self.model.MultipleObjectsReturned(
search.models.Location.MultipleObjectsReturned: get() returned more than one Location -- it returned 2!
2023-09-08 07:48:20 [scrapy] ERROR: Error processing {'country': 'DK',
 'keyword': ' iphone 13',
 'position': 16,
 'price': '4.295,00\xa0kr.',
 'product_url': 'https://tech24.dk/products/brugt-iphone-13-128gb-som-ny-pink?variant=46819277734216&currency=DKK',
 'title': 'Brugt iPhone 13, 128GB - God stand - Pink - tech24.dk Nej tak',
 'url': 'tech24.dk',
 'user_id': 'admin'}
Traceback (most recent call last):
  File "C:\Users\Muhammad Umer\AppData\Local\Programs\Python\Python311\Lib\site-packages\twisted\internet\defer.py", line 1065, in adapt
    extracted = result.result()
                ^^^^^^^^^^^^^^^
  File "C:\Users\Muhammad Umer\AppData\Local\Programs\Python\Python311\Lib\site-packages\asgiref\sync.py", line 448, in __call__
    ret = await asyncio.wait_for(future, timeout=None)
          ^^^^^^^^^^^^^^^^^^^^^^^^^^^^^^^^^^^^^^^^^^^^
  File "C:\Users\Muhammad Umer\AppData\Local\Programs\Python\Python311\Lib\asyncio\tasks.py", line 442, in wait_for
    return await fut
           ^^^^^^^^^
  File "C:\Users\Muhammad Umer\AppData\Local\Programs\Python\Python311\Lib\concurrent\futures\thread.py", line 58, in run
    result = self.fn(*self.args, **self.kwargs)
             ^^^^^^^^^^^^^^^^^^^^^^^^^^^^^^^^^^
  File "C:\Users\Muhammad Umer\AppData\Local\Programs\Python\Python311\Lib\site-packages\asgiref\sync.py", line 490, in thread_handler
    return func(*args, **kwargs)
           ^^^^^^^^^^^^^^^^^^^^^
  File "D:\Outputs\Django Outputs\scraper\pipelines.py", line 33, in process_item
    location = Location.objects.get(country_code=item['country']).first()
               ^^^^^^^^^^^^^^^^^^^^^^^^^^^^^^^^^^^^^^^^^^^^^^^^^^
  File "C:\Users\Muhammad Umer\AppData\Local\Programs\Python\Python311\Lib\site-packages\django\db\models\manager.py", line 85, in manager_method
    return getattr(self.get_queryset(), name)(*args, **kwargs)
           ^^^^^^^^^^^^^^^^^^^^^^^^^^^^^^^^^^^^^^^^^^^^^^^^^^^
  File "C:\Users\Muhammad Umer\AppData\Local\Programs\Python\Python311\Lib\site-packages\django\db\models\query.py", line 653, in get
    raise self.model.MultipleObjectsReturned(
search.models.Location.MultipleObjectsReturned: get() returned more than one Location -- it returned 2!
2023-09-08 07:48:20 [scrapy] ERROR: Error processing {'country': 'DK',
 'keyword': ' iphone 13',
 'position': 17,
 'price': '4.899,00\xa0kr.',
 'product_url': 'https://www.telia.dk/shop/apple/apple-iphone-13/#/green/128-gb/1',
 'title': 'Apple iPhone 13 128GB Green. Min.pris: 6.702,00kr. 6 mdr. binding',
 'url': 'telia.dk',
 'user_id': 'admin'}
Traceback (most recent call last):
  File "C:\Users\Muhammad Umer\AppData\Local\Programs\Python\Python311\Lib\site-packages\twisted\internet\defer.py", line 1065, in adapt
    extracted = result.result()
                ^^^^^^^^^^^^^^^
  File "C:\Users\Muhammad Umer\AppData\Local\Programs\Python\Python311\Lib\site-packages\asgiref\sync.py", line 448, in __call__
    ret = await asyncio.wait_for(future, timeout=None)
          ^^^^^^^^^^^^^^^^^^^^^^^^^^^^^^^^^^^^^^^^^^^^
  File "C:\Users\Muhammad Umer\AppData\Local\Programs\Python\Python311\Lib\asyncio\tasks.py", line 442, in wait_for
    return await fut
           ^^^^^^^^^
  File "C:\Users\Muhammad Umer\AppData\Local\Programs\Python\Python311\Lib\concurrent\futures\thread.py", line 58, in run
    result = self.fn(*self.args, **self.kwargs)
             ^^^^^^^^^^^^^^^^^^^^^^^^^^^^^^^^^^
  File "C:\Users\Muhammad Umer\AppData\Local\Programs\Python\Python311\Lib\site-packages\asgiref\sync.py", line 490, in thread_handler
    return func(*args, **kwargs)
           ^^^^^^^^^^^^^^^^^^^^^
  File "D:\Outputs\Django Outputs\scraper\pipelines.py", line 33, in process_item
    location = Location.objects.get(country_code=item['country']).first()
               ^^^^^^^^^^^^^^^^^^^^^^^^^^^^^^^^^^^^^^^^^^^^^^^^^^
  File "C:\Users\Muhammad Umer\AppData\Local\Programs\Python\Python311\Lib\site-packages\django\db\models\manager.py", line 85, in manager_method
    return getattr(self.get_queryset(), name)(*args, **kwargs)
           ^^^^^^^^^^^^^^^^^^^^^^^^^^^^^^^^^^^^^^^^^^^^^^^^^^^
  File "C:\Users\Muhammad Umer\AppData\Local\Programs\Python\Python311\Lib\site-packages\django\db\models\query.py", line 653, in get
    raise self.model.MultipleObjectsReturned(
search.models.Location.MultipleObjectsReturned: get() returned more than one Location -- it returned 2!
2023-09-08 07:48:20 [scrapy] ERROR: Error processing {'country': 'DK',
 'keyword': ' iphone 13',
 'position': 18,
 'price': '5.666,00\xa0kr.',
 'product_url': 'https://www.elgiganten.dk/product/mobil-tablet-smartwatch/mobiltelefon/iphone-13-5g-smartphone-128gb-pink/361941',
 'title': 'iPhone 13 – 5G smartphone 128GB Pink',
 'url': 'elgiganten.dk',
 'user_id': 'admin'}
Traceback (most recent call last):
  File "C:\Users\Muhammad Umer\AppData\Local\Programs\Python\Python311\Lib\site-packages\twisted\internet\defer.py", line 1065, in adapt
    extracted = result.result()
                ^^^^^^^^^^^^^^^
  File "C:\Users\Muhammad Umer\AppData\Local\Programs\Python\Python311\Lib\site-packages\asgiref\sync.py", line 448, in __call__
    ret = await asyncio.wait_for(future, timeout=None)
          ^^^^^^^^^^^^^^^^^^^^^^^^^^^^^^^^^^^^^^^^^^^^
  File "C:\Users\Muhammad Umer\AppData\Local\Programs\Python\Python311\Lib\asyncio\tasks.py", line 442, in wait_for
    return await fut
           ^^^^^^^^^
  File "C:\Users\Muhammad Umer\AppData\Local\Programs\Python\Python311\Lib\concurrent\futures\thread.py", line 58, in run
    result = self.fn(*self.args, **self.kwargs)
             ^^^^^^^^^^^^^^^^^^^^^^^^^^^^^^^^^^
  File "C:\Users\Muhammad Umer\AppData\Local\Programs\Python\Python311\Lib\site-packages\asgiref\sync.py", line 490, in thread_handler
    return func(*args, **kwargs)
           ^^^^^^^^^^^^^^^^^^^^^
  File "D:\Outputs\Django Outputs\scraper\pipelines.py", line 33, in process_item
    location = Location.objects.get(country_code=item['country']).first()
               ^^^^^^^^^^^^^^^^^^^^^^^^^^^^^^^^^^^^^^^^^^^^^^^^^^
  File "C:\Users\Muhammad Umer\AppData\Local\Programs\Python\Python311\Lib\site-packages\django\db\models\manager.py", line 85, in manager_method
    return getattr(self.get_queryset(), name)(*args, **kwargs)
           ^^^^^^^^^^^^^^^^^^^^^^^^^^^^^^^^^^^^^^^^^^^^^^^^^^^
  File "C:\Users\Muhammad Umer\AppData\Local\Programs\Python\Python311\Lib\site-packages\django\db\models\query.py", line 653, in get
    raise self.model.MultipleObjectsReturned(
search.models.Location.MultipleObjectsReturned: get() returned more than one Location -- it returned 2!
2023-09-08 07:48:20 [scrapy] ERROR: Error processing {'country': 'DK',
 'keyword': ' iphone 13',
 'position': 19,
 'price': '5.740,00\xa0kr.',
 'product_url': 'https://www.3.dk/shop/mobiler/apple/iphone-13?variant=4_16840_16843',
 'title': 'iPhone 13 128 GB GB Midnight - Fri tale 30 GBmindstepris fra 6700 '
          'kr. (inkl. abonnement). 3Family & 3LikeHome',
 'url': '3.dk',
 'user_id': 'admin'}
Traceback (most recent call last):
  File "C:\Users\Muhammad Umer\AppData\Local\Programs\Python\Python311\Lib\site-packages\twisted\internet\defer.py", line 1065, in adapt
    extracted = result.result()
                ^^^^^^^^^^^^^^^
  File "C:\Users\Muhammad Umer\AppData\Local\Programs\Python\Python311\Lib\site-packages\asgiref\sync.py", line 448, in __call__
    ret = await asyncio.wait_for(future, timeout=None)
          ^^^^^^^^^^^^^^^^^^^^^^^^^^^^^^^^^^^^^^^^^^^^
  File "C:\Users\Muhammad Umer\AppData\Local\Programs\Python\Python311\Lib\asyncio\tasks.py", line 442, in wait_for
    return await fut
           ^^^^^^^^^
  File "C:\Users\Muhammad Umer\AppData\Local\Programs\Python\Python311\Lib\concurrent\futures\thread.py", line 58, in run
    result = self.fn(*self.args, **self.kwargs)
             ^^^^^^^^^^^^^^^^^^^^^^^^^^^^^^^^^^
  File "C:\Users\Muhammad Umer\AppData\Local\Programs\Python\Python311\Lib\site-packages\asgiref\sync.py", line 490, in thread_handler
    return func(*args, **kwargs)
           ^^^^^^^^^^^^^^^^^^^^^
  File "D:\Outputs\Django Outputs\scraper\pipelines.py", line 33, in process_item
    location = Location.objects.get(country_code=item['country']).first()
               ^^^^^^^^^^^^^^^^^^^^^^^^^^^^^^^^^^^^^^^^^^^^^^^^^^
  File "C:\Users\Muhammad Umer\AppData\Local\Programs\Python\Python311\Lib\site-packages\django\db\models\manager.py", line 85, in manager_method
    return getattr(self.get_queryset(), name)(*args, **kwargs)
           ^^^^^^^^^^^^^^^^^^^^^^^^^^^^^^^^^^^^^^^^^^^^^^^^^^^
  File "C:\Users\Muhammad Umer\AppData\Local\Programs\Python\Python311\Lib\site-packages\django\db\models\query.py", line 653, in get
    raise self.model.MultipleObjectsReturned(
search.models.Location.MultipleObjectsReturned: get() returned more than one Location -- it returned 2!
2023-09-08 07:48:20 [scrapy] ERROR: Error processing {'country': 'DK',
 'keyword': ' iphone 13',
 'position': 20,
 'price': '5.666,00\xa0kr.',
 'product_url': 'https://www.power.dk/mobil-og-foto/mobiltelefoner/apple-iphone-13-128-gb-lyseroed/p-1204129/',
 'title': 'APPLE IPHONE 13 128 GB LYSERØD',
 'url': 'power.dk',
 'user_id': 'admin'}
Traceback (most recent call last):
  File "C:\Users\Muhammad Umer\AppData\Local\Programs\Python\Python311\Lib\site-packages\twisted\internet\defer.py", line 1065, in adapt
    extracted = result.result()
                ^^^^^^^^^^^^^^^
  File "C:\Users\Muhammad Umer\AppData\Local\Programs\Python\Python311\Lib\site-packages\asgiref\sync.py", line 448, in __call__
    ret = await asyncio.wait_for(future, timeout=None)
          ^^^^^^^^^^^^^^^^^^^^^^^^^^^^^^^^^^^^^^^^^^^^
  File "C:\Users\Muhammad Umer\AppData\Local\Programs\Python\Python311\Lib\asyncio\tasks.py", line 442, in wait_for
    return await fut
           ^^^^^^^^^
  File "C:\Users\Muhammad Umer\AppData\Local\Programs\Python\Python311\Lib\concurrent\futures\thread.py", line 58, in run
    result = self.fn(*self.args, **self.kwargs)
             ^^^^^^^^^^^^^^^^^^^^^^^^^^^^^^^^^^
  File "C:\Users\Muhammad Umer\AppData\Local\Programs\Python\Python311\Lib\site-packages\asgiref\sync.py", line 490, in thread_handler
    return func(*args, **kwargs)
           ^^^^^^^^^^^^^^^^^^^^^
  File "D:\Outputs\Django Outputs\scraper\pipelines.py", line 33, in process_item
    location = Location.objects.get(country_code=item['country']).first()
               ^^^^^^^^^^^^^^^^^^^^^^^^^^^^^^^^^^^^^^^^^^^^^^^^^^
  File "C:\Users\Muhammad Umer\AppData\Local\Programs\Python\Python311\Lib\site-packages\django\db\models\manager.py", line 85, in manager_method
    return getattr(self.get_queryset(), name)(*args, **kwargs)
           ^^^^^^^^^^^^^^^^^^^^^^^^^^^^^^^^^^^^^^^^^^^^^^^^^^^
  File "C:\Users\Muhammad Umer\AppData\Local\Programs\Python\Python311\Lib\site-packages\django\db\models\query.py", line 653, in get
    raise self.model.MultipleObjectsReturned(
search.models.Location.MultipleObjectsReturned: get() returned more than one Location -- it returned 2!
2023-09-08 07:48:20 [scrapy] ERROR: Error processing {'country': 'DK',
 'keyword': ' iphone 13',
 'position': 21,
 'price': '4.799,00\xa0kr.',
 'product_url': 'https://www.telenor.dk/shop/mobil/apple/apple-iphone-13--128gb-midnight/?cycleCount=none',
 'title': 'Apple iPhone 13 - 128 GB - Midnight med abonnementsaftale. '
          'Mindstepris 6613.00 Kr.',
 'url': 'telenor.dk',
 'user_id': 'admin'}
Traceback (most recent call last):
  File "C:\Users\Muhammad Umer\AppData\Local\Programs\Python\Python311\Lib\site-packages\twisted\internet\defer.py", line 1065, in adapt
    extracted = result.result()
                ^^^^^^^^^^^^^^^
  File "C:\Users\Muhammad Umer\AppData\Local\Programs\Python\Python311\Lib\site-packages\asgiref\sync.py", line 448, in __call__
    ret = await asyncio.wait_for(future, timeout=None)
          ^^^^^^^^^^^^^^^^^^^^^^^^^^^^^^^^^^^^^^^^^^^^
  File "C:\Users\Muhammad Umer\AppData\Local\Programs\Python\Python311\Lib\asyncio\tasks.py", line 442, in wait_for
    return await fut
           ^^^^^^^^^
  File "C:\Users\Muhammad Umer\AppData\Local\Programs\Python\Python311\Lib\concurrent\futures\thread.py", line 58, in run
    result = self.fn(*self.args, **self.kwargs)
             ^^^^^^^^^^^^^^^^^^^^^^^^^^^^^^^^^^
  File "C:\Users\Muhammad Umer\AppData\Local\Programs\Python\Python311\Lib\site-packages\asgiref\sync.py", line 490, in thread_handler
    return func(*args, **kwargs)
           ^^^^^^^^^^^^^^^^^^^^^
  File "D:\Outputs\Django Outputs\scraper\pipelines.py", line 33, in process_item
    location = Location.objects.get(country_code=item['country']).first()
               ^^^^^^^^^^^^^^^^^^^^^^^^^^^^^^^^^^^^^^^^^^^^^^^^^^
  File "C:\Users\Muhammad Umer\AppData\Local\Programs\Python\Python311\Lib\site-packages\django\db\models\manager.py", line 85, in manager_method
    return getattr(self.get_queryset(), name)(*args, **kwargs)
           ^^^^^^^^^^^^^^^^^^^^^^^^^^^^^^^^^^^^^^^^^^^^^^^^^^^
  File "C:\Users\Muhammad Umer\AppData\Local\Programs\Python\Python311\Lib\site-packages\django\db\models\query.py", line 653, in get
    raise self.model.MultipleObjectsReturned(
search.models.Location.MultipleObjectsReturned: get() returned more than one Location -- it returned 2!
2023-09-08 07:48:20 [scrapy] ERROR: Error processing {'country': 'DK',
 'keyword': ' iphone 13',
 'position': 22,
 'price': '4.795,00\xa0kr.',
 'product_url': 'https://tech24.dk/products/brugt-iphone-13-128gb-som-ny-bla?variant=46811915092296&currency=DKK',
 'title': 'Brugt iPhone 13, 128GB - Som Ny - Blå - tech24.dk Nej tak',
 'url': 'tech24.dk',
 'user_id': 'admin'}
Traceback (most recent call last):
  File "C:\Users\Muhammad Umer\AppData\Local\Programs\Python\Python311\Lib\site-packages\twisted\internet\defer.py", line 1065, in adapt
    extracted = result.result()
                ^^^^^^^^^^^^^^^
  File "C:\Users\Muhammad Umer\AppData\Local\Programs\Python\Python311\Lib\site-packages\asgiref\sync.py", line 448, in __call__
    ret = await asyncio.wait_for(future, timeout=None)
          ^^^^^^^^^^^^^^^^^^^^^^^^^^^^^^^^^^^^^^^^^^^^
  File "C:\Users\Muhammad Umer\AppData\Local\Programs\Python\Python311\Lib\asyncio\tasks.py", line 442, in wait_for
    return await fut
           ^^^^^^^^^
  File "C:\Users\Muhammad Umer\AppData\Local\Programs\Python\Python311\Lib\concurrent\futures\thread.py", line 58, in run
    result = self.fn(*self.args, **self.kwargs)
             ^^^^^^^^^^^^^^^^^^^^^^^^^^^^^^^^^^
  File "C:\Users\Muhammad Umer\AppData\Local\Programs\Python\Python311\Lib\site-packages\asgiref\sync.py", line 490, in thread_handler
    return func(*args, **kwargs)
           ^^^^^^^^^^^^^^^^^^^^^
  File "D:\Outputs\Django Outputs\scraper\pipelines.py", line 33, in process_item
    location = Location.objects.get(country_code=item['country']).first()
               ^^^^^^^^^^^^^^^^^^^^^^^^^^^^^^^^^^^^^^^^^^^^^^^^^^
  File "C:\Users\Muhammad Umer\AppData\Local\Programs\Python\Python311\Lib\site-packages\django\db\models\manager.py", line 85, in manager_method
    return getattr(self.get_queryset(), name)(*args, **kwargs)
           ^^^^^^^^^^^^^^^^^^^^^^^^^^^^^^^^^^^^^^^^^^^^^^^^^^^
  File "C:\Users\Muhammad Umer\AppData\Local\Programs\Python\Python311\Lib\site-packages\django\db\models\query.py", line 653, in get
    raise self.model.MultipleObjectsReturned(
search.models.Location.MultipleObjectsReturned: get() returned more than one Location -- it returned 2!
2023-09-08 07:48:20 [scrapy] ERROR: Error processing {'country': 'DK',
 'keyword': ' iphone 13',
 'position': 23,
 'price': '4.784,99\xa0kr.',
 'product_url': 'https://www.refurbed.dk/p/iphone-13/14162/?co=dk&utm_cluster=gradeA&utm_content=iphone-13-14162&utm_group=iphone-13',
 'title': 'Som Ny: iPhone 13 | 128 GB | Dual-SIM | sort',
 'url': 'refurbed.dk',
 'user_id': 'admin'}
Traceback (most recent call last):
  File "C:\Users\Muhammad Umer\AppData\Local\Programs\Python\Python311\Lib\site-packages\twisted\internet\defer.py", line 1065, in adapt
    extracted = result.result()
                ^^^^^^^^^^^^^^^
  File "C:\Users\Muhammad Umer\AppData\Local\Programs\Python\Python311\Lib\site-packages\asgiref\sync.py", line 448, in __call__
    ret = await asyncio.wait_for(future, timeout=None)
          ^^^^^^^^^^^^^^^^^^^^^^^^^^^^^^^^^^^^^^^^^^^^
  File "C:\Users\Muhammad Umer\AppData\Local\Programs\Python\Python311\Lib\asyncio\tasks.py", line 442, in wait_for
    return await fut
           ^^^^^^^^^
  File "C:\Users\Muhammad Umer\AppData\Local\Programs\Python\Python311\Lib\concurrent\futures\thread.py", line 58, in run
    result = self.fn(*self.args, **self.kwargs)
             ^^^^^^^^^^^^^^^^^^^^^^^^^^^^^^^^^^
  File "C:\Users\Muhammad Umer\AppData\Local\Programs\Python\Python311\Lib\site-packages\asgiref\sync.py", line 490, in thread_handler
    return func(*args, **kwargs)
           ^^^^^^^^^^^^^^^^^^^^^
  File "D:\Outputs\Django Outputs\scraper\pipelines.py", line 33, in process_item
    location = Location.objects.get(country_code=item['country']).first()
               ^^^^^^^^^^^^^^^^^^^^^^^^^^^^^^^^^^^^^^^^^^^^^^^^^^
  File "C:\Users\Muhammad Umer\AppData\Local\Programs\Python\Python311\Lib\site-packages\django\db\models\manager.py", line 85, in manager_method
    return getattr(self.get_queryset(), name)(*args, **kwargs)
           ^^^^^^^^^^^^^^^^^^^^^^^^^^^^^^^^^^^^^^^^^^^^^^^^^^^
  File "C:\Users\Muhammad Umer\AppData\Local\Programs\Python\Python311\Lib\site-packages\django\db\models\query.py", line 653, in get
    raise self.model.MultipleObjectsReturned(
search.models.Location.MultipleObjectsReturned: get() returned more than one Location -- it returned 2!
2023-09-08 07:48:20 [scrapy] ERROR: Error processing {'country': 'DK',
 'keyword': ' iphone 13',
 'position': 24,
 'price': '6.199,00\xa0kr.',
 'product_url': 'https://www.proshop.dk/Mobil/Apple-iPhone-13-5G-128GB-Midnight/2998486?utm_source=google&utm_medium=cpc&utm_campaign=searchengine',
 'title': 'Apple iPhone 13 5G 128GB - Midnight',
 'url': 'proshop.dk',
 'user_id': 'admin'}
Traceback (most recent call last):
  File "C:\Users\Muhammad Umer\AppData\Local\Programs\Python\Python311\Lib\site-packages\twisted\internet\defer.py", line 1065, in adapt
    extracted = result.result()
                ^^^^^^^^^^^^^^^
  File "C:\Users\Muhammad Umer\AppData\Local\Programs\Python\Python311\Lib\site-packages\asgiref\sync.py", line 448, in __call__
    ret = await asyncio.wait_for(future, timeout=None)
          ^^^^^^^^^^^^^^^^^^^^^^^^^^^^^^^^^^^^^^^^^^^^
  File "C:\Users\Muhammad Umer\AppData\Local\Programs\Python\Python311\Lib\asyncio\tasks.py", line 442, in wait_for
    return await fut
           ^^^^^^^^^
  File "C:\Users\Muhammad Umer\AppData\Local\Programs\Python\Python311\Lib\concurrent\futures\thread.py", line 58, in run
    result = self.fn(*self.args, **self.kwargs)
             ^^^^^^^^^^^^^^^^^^^^^^^^^^^^^^^^^^
  File "C:\Users\Muhammad Umer\AppData\Local\Programs\Python\Python311\Lib\site-packages\asgiref\sync.py", line 490, in thread_handler
    return func(*args, **kwargs)
           ^^^^^^^^^^^^^^^^^^^^^
  File "D:\Outputs\Django Outputs\scraper\pipelines.py", line 33, in process_item
    location = Location.objects.get(country_code=item['country']).first()
               ^^^^^^^^^^^^^^^^^^^^^^^^^^^^^^^^^^^^^^^^^^^^^^^^^^
  File "C:\Users\Muhammad Umer\AppData\Local\Programs\Python\Python311\Lib\site-packages\django\db\models\manager.py", line 85, in manager_method
    return getattr(self.get_queryset(), name)(*args, **kwargs)
           ^^^^^^^^^^^^^^^^^^^^^^^^^^^^^^^^^^^^^^^^^^^^^^^^^^^
  File "C:\Users\Muhammad Umer\AppData\Local\Programs\Python\Python311\Lib\site-packages\django\db\models\query.py", line 653, in get
    raise self.model.MultipleObjectsReturned(
search.models.Location.MultipleObjectsReturned: get() returned more than one Location -- it returned 2!
2023-09-08 07:48:20 [scrapy] ERROR: Error processing {'country': 'DK',
 'keyword': ' iphone 13',
 'position': 25,
 'price': '4.499,00\xa0kr.',
 'product_url': 'https://greenmind.dk/telefoner/iphones/iphone-13/iphone-13-mini/apple-iphone-13-mini-128-gb-bla-brugt-som-ny-24827',
 'title': 'Apple iPhone 13 Mini 128 GB Blå Brugt - Som ny',
 'url': 'greenmind.dk',
 'user_id': 'admin'}
Traceback (most recent call last):
  File "C:\Users\Muhammad Umer\AppData\Local\Programs\Python\Python311\Lib\site-packages\twisted\internet\defer.py", line 1065, in adapt
    extracted = result.result()
                ^^^^^^^^^^^^^^^
  File "C:\Users\Muhammad Umer\AppData\Local\Programs\Python\Python311\Lib\site-packages\asgiref\sync.py", line 448, in __call__
    ret = await asyncio.wait_for(future, timeout=None)
          ^^^^^^^^^^^^^^^^^^^^^^^^^^^^^^^^^^^^^^^^^^^^
  File "C:\Users\Muhammad Umer\AppData\Local\Programs\Python\Python311\Lib\asyncio\tasks.py", line 442, in wait_for
    return await fut
           ^^^^^^^^^
  File "C:\Users\Muhammad Umer\AppData\Local\Programs\Python\Python311\Lib\concurrent\futures\thread.py", line 58, in run
    result = self.fn(*self.args, **self.kwargs)
             ^^^^^^^^^^^^^^^^^^^^^^^^^^^^^^^^^^
  File "C:\Users\Muhammad Umer\AppData\Local\Programs\Python\Python311\Lib\site-packages\asgiref\sync.py", line 490, in thread_handler
    return func(*args, **kwargs)
           ^^^^^^^^^^^^^^^^^^^^^
  File "D:\Outputs\Django Outputs\scraper\pipelines.py", line 33, in process_item
    location = Location.objects.get(country_code=item['country']).first()
               ^^^^^^^^^^^^^^^^^^^^^^^^^^^^^^^^^^^^^^^^^^^^^^^^^^
  File "C:\Users\Muhammad Umer\AppData\Local\Programs\Python\Python311\Lib\site-packages\django\db\models\manager.py", line 85, in manager_method
    return getattr(self.get_queryset(), name)(*args, **kwargs)
           ^^^^^^^^^^^^^^^^^^^^^^^^^^^^^^^^^^^^^^^^^^^^^^^^^^^
  File "C:\Users\Muhammad Umer\AppData\Local\Programs\Python\Python311\Lib\site-packages\django\db\models\query.py", line 653, in get
    raise self.model.MultipleObjectsReturned(
search.models.Location.MultipleObjectsReturned: get() returned more than one Location -- it returned 2!
2023-09-08 07:48:20 [scrapy] ERROR: Error processing {'country': 'DK',
 'keyword': ' iphone 13',
 'position': 26,
 'price': '5.489,00\xa0kr.',
 'product_url': 'https://www.power.dk/mobil-og-foto/mobiltelefoner/apple-iphone-13-mini-128-gb-midnat/p-1204142/',
 'title': 'APPLE IPHONE 13 MINI 128 GB MIDNAT',
 'url': 'power.dk',
 'user_id': 'admin'}
Traceback (most recent call last):
  File "C:\Users\Muhammad Umer\AppData\Local\Programs\Python\Python311\Lib\site-packages\twisted\internet\defer.py", line 1065, in adapt
    extracted = result.result()
                ^^^^^^^^^^^^^^^
  File "C:\Users\Muhammad Umer\AppData\Local\Programs\Python\Python311\Lib\site-packages\asgiref\sync.py", line 448, in __call__
    ret = await asyncio.wait_for(future, timeout=None)
          ^^^^^^^^^^^^^^^^^^^^^^^^^^^^^^^^^^^^^^^^^^^^
  File "C:\Users\Muhammad Umer\AppData\Local\Programs\Python\Python311\Lib\asyncio\tasks.py", line 442, in wait_for
    return await fut
           ^^^^^^^^^
  File "C:\Users\Muhammad Umer\AppData\Local\Programs\Python\Python311\Lib\concurrent\futures\thread.py", line 58, in run
    result = self.fn(*self.args, **self.kwargs)
             ^^^^^^^^^^^^^^^^^^^^^^^^^^^^^^^^^^
  File "C:\Users\Muhammad Umer\AppData\Local\Programs\Python\Python311\Lib\site-packages\asgiref\sync.py", line 490, in thread_handler
    return func(*args, **kwargs)
           ^^^^^^^^^^^^^^^^^^^^^
  File "D:\Outputs\Django Outputs\scraper\pipelines.py", line 33, in process_item
    location = Location.objects.get(country_code=item['country']).first()
               ^^^^^^^^^^^^^^^^^^^^^^^^^^^^^^^^^^^^^^^^^^^^^^^^^^
  File "C:\Users\Muhammad Umer\AppData\Local\Programs\Python\Python311\Lib\site-packages\django\db\models\manager.py", line 85, in manager_method
    return getattr(self.get_queryset(), name)(*args, **kwargs)
           ^^^^^^^^^^^^^^^^^^^^^^^^^^^^^^^^^^^^^^^^^^^^^^^^^^^
  File "C:\Users\Muhammad Umer\AppData\Local\Programs\Python\Python311\Lib\site-packages\django\db\models\query.py", line 653, in get
    raise self.model.MultipleObjectsReturned(
search.models.Location.MultipleObjectsReturned: get() returned more than one Location -- it returned 2!
2023-09-08 07:48:20 [scrapy] ERROR: Error processing {'country': 'DK',
 'keyword': ' iphone 13',
 'position': 27,
 'price': None,
 'product_url': None,
 'title': None,
 'url': '',
 'user_id': 'admin'}
Traceback (most recent call last):
  File "C:\Users\Muhammad Umer\AppData\Local\Programs\Python\Python311\Lib\site-packages\twisted\internet\defer.py", line 1065, in adapt
    extracted = result.result()
                ^^^^^^^^^^^^^^^
  File "C:\Users\Muhammad Umer\AppData\Local\Programs\Python\Python311\Lib\site-packages\asgiref\sync.py", line 448, in __call__
    ret = await asyncio.wait_for(future, timeout=None)
          ^^^^^^^^^^^^^^^^^^^^^^^^^^^^^^^^^^^^^^^^^^^^
  File "C:\Users\Muhammad Umer\AppData\Local\Programs\Python\Python311\Lib\asyncio\tasks.py", line 442, in wait_for
    return await fut
           ^^^^^^^^^
  File "C:\Users\Muhammad Umer\AppData\Local\Programs\Python\Python311\Lib\concurrent\futures\thread.py", line 58, in run
    result = self.fn(*self.args, **self.kwargs)
             ^^^^^^^^^^^^^^^^^^^^^^^^^^^^^^^^^^
  File "C:\Users\Muhammad Umer\AppData\Local\Programs\Python\Python311\Lib\site-packages\asgiref\sync.py", line 490, in thread_handler
    return func(*args, **kwargs)
           ^^^^^^^^^^^^^^^^^^^^^
  File "D:\Outputs\Django Outputs\scraper\pipelines.py", line 33, in process_item
    location = Location.objects.get(country_code=item['country']).first()
               ^^^^^^^^^^^^^^^^^^^^^^^^^^^^^^^^^^^^^^^^^^^^^^^^^^
  File "C:\Users\Muhammad Umer\AppData\Local\Programs\Python\Python311\Lib\site-packages\django\db\models\manager.py", line 85, in manager_method
    return getattr(self.get_queryset(), name)(*args, **kwargs)
           ^^^^^^^^^^^^^^^^^^^^^^^^^^^^^^^^^^^^^^^^^^^^^^^^^^^
  File "C:\Users\Muhammad Umer\AppData\Local\Programs\Python\Python311\Lib\site-packages\django\db\models\query.py", line 653, in get
    raise self.model.MultipleObjectsReturned(
search.models.Location.MultipleObjectsReturned: get() returned more than one Location -- it returned 2!
2023-09-08 07:48:23 [scrapy] DEBUG: Crawled (200) <GET https://www.google.com/search?q=iphone+14&hl=en&gl=DK&start=0> (referer: None)
2023-09-08 07:48:23 [scrapy] ERROR: Error processing {'country': 'DK',
 'keyword': 'iphone 14',
 'position': 1,
 'price': '6.666,00\xa0kr.',
 'product_url': 'https://www.power.dk/mobil-og-foto/mobiltelefoner/apple-iphone-14-128-gb-midnat/p-1803962/',
 'title': 'APPLE IPHONE 14 128 GB MIDNAT',
 'url': 'power.dk',
 'user_id': 'admin'}
Traceback (most recent call last):
  File "C:\Users\Muhammad Umer\AppData\Local\Programs\Python\Python311\Lib\site-packages\twisted\internet\defer.py", line 1065, in adapt
    extracted = result.result()
                ^^^^^^^^^^^^^^^
  File "C:\Users\Muhammad Umer\AppData\Local\Programs\Python\Python311\Lib\site-packages\asgiref\sync.py", line 448, in __call__
    ret = await asyncio.wait_for(future, timeout=None)
          ^^^^^^^^^^^^^^^^^^^^^^^^^^^^^^^^^^^^^^^^^^^^
  File "C:\Users\Muhammad Umer\AppData\Local\Programs\Python\Python311\Lib\asyncio\tasks.py", line 442, in wait_for
    return await fut
           ^^^^^^^^^
  File "C:\Users\Muhammad Umer\AppData\Local\Programs\Python\Python311\Lib\concurrent\futures\thread.py", line 58, in run
    result = self.fn(*self.args, **self.kwargs)
             ^^^^^^^^^^^^^^^^^^^^^^^^^^^^^^^^^^
  File "C:\Users\Muhammad Umer\AppData\Local\Programs\Python\Python311\Lib\site-packages\asgiref\sync.py", line 490, in thread_handler
    return func(*args, **kwargs)
           ^^^^^^^^^^^^^^^^^^^^^
  File "D:\Outputs\Django Outputs\scraper\pipelines.py", line 33, in process_item
    location = Location.objects.get(country_code=item['country']).first()
               ^^^^^^^^^^^^^^^^^^^^^^^^^^^^^^^^^^^^^^^^^^^^^^^^^^
  File "C:\Users\Muhammad Umer\AppData\Local\Programs\Python\Python311\Lib\site-packages\django\db\models\manager.py", line 85, in manager_method
    return getattr(self.get_queryset(), name)(*args, **kwargs)
           ^^^^^^^^^^^^^^^^^^^^^^^^^^^^^^^^^^^^^^^^^^^^^^^^^^^
  File "C:\Users\Muhammad Umer\AppData\Local\Programs\Python\Python311\Lib\site-packages\django\db\models\query.py", line 653, in get
    raise self.model.MultipleObjectsReturned(
search.models.Location.MultipleObjectsReturned: get() returned more than one Location -- it returned 2!
2023-09-08 07:48:23 [scrapy] ERROR: Error processing {'country': 'DK',
 'keyword': 'iphone 14',
 'position': 2,
 'price': '5.399,00\xa0kr.',
 'product_url': 'https://www.telia.dk/shop/apple/apple-iphone-14/#/midnight/128-gb/1',
 'title': 'Apple iPhone 14 128GB Midnight. Min.pris: 7.202,00kr. 6 mdr. '
          'binding',
 'url': 'telia.dk',
 'user_id': 'admin'}
Traceback (most recent call last):
  File "C:\Users\Muhammad Umer\AppData\Local\Programs\Python\Python311\Lib\site-packages\twisted\internet\defer.py", line 1065, in adapt
    extracted = result.result()
                ^^^^^^^^^^^^^^^
  File "C:\Users\Muhammad Umer\AppData\Local\Programs\Python\Python311\Lib\site-packages\asgiref\sync.py", line 448, in __call__
    ret = await asyncio.wait_for(future, timeout=None)
          ^^^^^^^^^^^^^^^^^^^^^^^^^^^^^^^^^^^^^^^^^^^^
  File "C:\Users\Muhammad Umer\AppData\Local\Programs\Python\Python311\Lib\asyncio\tasks.py", line 442, in wait_for
    return await fut
           ^^^^^^^^^
  File "C:\Users\Muhammad Umer\AppData\Local\Programs\Python\Python311\Lib\concurrent\futures\thread.py", line 58, in run
    result = self.fn(*self.args, **self.kwargs)
             ^^^^^^^^^^^^^^^^^^^^^^^^^^^^^^^^^^
  File "C:\Users\Muhammad Umer\AppData\Local\Programs\Python\Python311\Lib\site-packages\asgiref\sync.py", line 490, in thread_handler
    return func(*args, **kwargs)
           ^^^^^^^^^^^^^^^^^^^^^
  File "D:\Outputs\Django Outputs\scraper\pipelines.py", line 33, in process_item
    location = Location.objects.get(country_code=item['country']).first()
               ^^^^^^^^^^^^^^^^^^^^^^^^^^^^^^^^^^^^^^^^^^^^^^^^^^
  File "C:\Users\Muhammad Umer\AppData\Local\Programs\Python\Python311\Lib\site-packages\django\db\models\manager.py", line 85, in manager_method
    return getattr(self.get_queryset(), name)(*args, **kwargs)
           ^^^^^^^^^^^^^^^^^^^^^^^^^^^^^^^^^^^^^^^^^^^^^^^^^^^
  File "C:\Users\Muhammad Umer\AppData\Local\Programs\Python\Python311\Lib\site-packages\django\db\models\query.py", line 653, in get
    raise self.model.MultipleObjectsReturned(
search.models.Location.MultipleObjectsReturned: get() returned more than one Location -- it returned 2!
2023-09-08 07:48:23 [scrapy] ERROR: Error processing {'country': 'DK',
 'keyword': 'iphone 14',
 'position': 3,
 'price': '7.149,00\xa0kr.',
 'product_url': 'https://www.elgiganten.dk/product/mobil-tablet-smartwatch/mobiltelefon/iphone-14-5g-smartphone-128gb-midnight/522692',
 'title': 'iPhone 14 – 5G smartphone 128GB Midnight',
 'url': 'elgiganten.dk',
 'user_id': 'admin'}
Traceback (most recent call last):
  File "C:\Users\Muhammad Umer\AppData\Local\Programs\Python\Python311\Lib\site-packages\twisted\internet\defer.py", line 1065, in adapt
    extracted = result.result()
                ^^^^^^^^^^^^^^^
  File "C:\Users\Muhammad Umer\AppData\Local\Programs\Python\Python311\Lib\site-packages\asgiref\sync.py", line 448, in __call__
    ret = await asyncio.wait_for(future, timeout=None)
          ^^^^^^^^^^^^^^^^^^^^^^^^^^^^^^^^^^^^^^^^^^^^
  File "C:\Users\Muhammad Umer\AppData\Local\Programs\Python\Python311\Lib\asyncio\tasks.py", line 442, in wait_for
    return await fut
           ^^^^^^^^^
  File "C:\Users\Muhammad Umer\AppData\Local\Programs\Python\Python311\Lib\concurrent\futures\thread.py", line 58, in run
    result = self.fn(*self.args, **self.kwargs)
             ^^^^^^^^^^^^^^^^^^^^^^^^^^^^^^^^^^
  File "C:\Users\Muhammad Umer\AppData\Local\Programs\Python\Python311\Lib\site-packages\asgiref\sync.py", line 490, in thread_handler
    return func(*args, **kwargs)
           ^^^^^^^^^^^^^^^^^^^^^
  File "D:\Outputs\Django Outputs\scraper\pipelines.py", line 33, in process_item
    location = Location.objects.get(country_code=item['country']).first()
               ^^^^^^^^^^^^^^^^^^^^^^^^^^^^^^^^^^^^^^^^^^^^^^^^^^
  File "C:\Users\Muhammad Umer\AppData\Local\Programs\Python\Python311\Lib\site-packages\django\db\models\manager.py", line 85, in manager_method
    return getattr(self.get_queryset(), name)(*args, **kwargs)
           ^^^^^^^^^^^^^^^^^^^^^^^^^^^^^^^^^^^^^^^^^^^^^^^^^^^
  File "C:\Users\Muhammad Umer\AppData\Local\Programs\Python\Python311\Lib\site-packages\django\db\models\query.py", line 653, in get
    raise self.model.MultipleObjectsReturned(
search.models.Location.MultipleObjectsReturned: get() returned more than one Location -- it returned 2!
2023-09-08 07:48:23 [scrapy] ERROR: Error processing {'country': 'DK',
 'keyword': 'iphone 14',
 'position': 4,
 'price': '4.799,00\xa0kr.',
 'product_url': 'https://www.telenor.dk/shop/mobil/apple/iphone-13-128gb-green/?cycleCount=none',
 'title': 'Apple iPhone 13 - 128 GB - Grøn med abonnementsaftale. Mindstepris '
          '6613.00 Kr.',
 'url': 'telenor.dk',
 'user_id': 'admin'}
Traceback (most recent call last):
  File "C:\Users\Muhammad Umer\AppData\Local\Programs\Python\Python311\Lib\site-packages\twisted\internet\defer.py", line 1065, in adapt
    extracted = result.result()
                ^^^^^^^^^^^^^^^
  File "C:\Users\Muhammad Umer\AppData\Local\Programs\Python\Python311\Lib\site-packages\asgiref\sync.py", line 448, in __call__
    ret = await asyncio.wait_for(future, timeout=None)
          ^^^^^^^^^^^^^^^^^^^^^^^^^^^^^^^^^^^^^^^^^^^^
  File "C:\Users\Muhammad Umer\AppData\Local\Programs\Python\Python311\Lib\asyncio\tasks.py", line 442, in wait_for
    return await fut
           ^^^^^^^^^
  File "C:\Users\Muhammad Umer\AppData\Local\Programs\Python\Python311\Lib\concurrent\futures\thread.py", line 58, in run
    result = self.fn(*self.args, **self.kwargs)
             ^^^^^^^^^^^^^^^^^^^^^^^^^^^^^^^^^^
  File "C:\Users\Muhammad Umer\AppData\Local\Programs\Python\Python311\Lib\site-packages\asgiref\sync.py", line 490, in thread_handler
    return func(*args, **kwargs)
           ^^^^^^^^^^^^^^^^^^^^^
  File "D:\Outputs\Django Outputs\scraper\pipelines.py", line 33, in process_item
    location = Location.objects.get(country_code=item['country']).first()
               ^^^^^^^^^^^^^^^^^^^^^^^^^^^^^^^^^^^^^^^^^^^^^^^^^^
  File "C:\Users\Muhammad Umer\AppData\Local\Programs\Python\Python311\Lib\site-packages\django\db\models\manager.py", line 85, in manager_method
    return getattr(self.get_queryset(), name)(*args, **kwargs)
           ^^^^^^^^^^^^^^^^^^^^^^^^^^^^^^^^^^^^^^^^^^^^^^^^^^^
  File "C:\Users\Muhammad Umer\AppData\Local\Programs\Python\Python311\Lib\site-packages\django\db\models\query.py", line 653, in get
    raise self.model.MultipleObjectsReturned(
search.models.Location.MultipleObjectsReturned: get() returned more than one Location -- it returned 2!
2023-09-08 07:48:23 [scrapy] ERROR: Error processing {'country': 'DK',
 'keyword': 'iphone 14',
 'position': 5,
 'price': '5.761,00\xa0kr.',
 'product_url': 'https://yousee.dk/mobil/mobiltelefoner/apple/iphone-14/1468/mobil_80/kontant/',
 'title': 'Apple iPhone 14 128 GB Midnat med abonnementsaftale. Mindstepris '
          '7.075,00 kr.',
 'url': 'yousee.dk',
 'user_id': 'admin'}
Traceback (most recent call last):
  File "C:\Users\Muhammad Umer\AppData\Local\Programs\Python\Python311\Lib\site-packages\twisted\internet\defer.py", line 1065, in adapt
    extracted = result.result()
                ^^^^^^^^^^^^^^^
  File "C:\Users\Muhammad Umer\AppData\Local\Programs\Python\Python311\Lib\site-packages\asgiref\sync.py", line 448, in __call__
    ret = await asyncio.wait_for(future, timeout=None)
          ^^^^^^^^^^^^^^^^^^^^^^^^^^^^^^^^^^^^^^^^^^^^
  File "C:\Users\Muhammad Umer\AppData\Local\Programs\Python\Python311\Lib\asyncio\tasks.py", line 442, in wait_for
    return await fut
           ^^^^^^^^^
  File "C:\Users\Muhammad Umer\AppData\Local\Programs\Python\Python311\Lib\concurrent\futures\thread.py", line 58, in run
    result = self.fn(*self.args, **self.kwargs)
             ^^^^^^^^^^^^^^^^^^^^^^^^^^^^^^^^^^
  File "C:\Users\Muhammad Umer\AppData\Local\Programs\Python\Python311\Lib\site-packages\asgiref\sync.py", line 490, in thread_handler
    return func(*args, **kwargs)
           ^^^^^^^^^^^^^^^^^^^^^
  File "D:\Outputs\Django Outputs\scraper\pipelines.py", line 33, in process_item
    location = Location.objects.get(country_code=item['country']).first()
               ^^^^^^^^^^^^^^^^^^^^^^^^^^^^^^^^^^^^^^^^^^^^^^^^^^
  File "C:\Users\Muhammad Umer\AppData\Local\Programs\Python\Python311\Lib\site-packages\django\db\models\manager.py", line 85, in manager_method
    return getattr(self.get_queryset(), name)(*args, **kwargs)
           ^^^^^^^^^^^^^^^^^^^^^^^^^^^^^^^^^^^^^^^^^^^^^^^^^^^
  File "C:\Users\Muhammad Umer\AppData\Local\Programs\Python\Python311\Lib\site-packages\django\db\models\query.py", line 653, in get
    raise self.model.MultipleObjectsReturned(
search.models.Location.MultipleObjectsReturned: get() returned more than one Location -- it returned 2!
2023-09-08 07:48:23 [scrapy] ERROR: Error processing {'country': 'DK',
 'keyword': 'iphone 14',
 'position': 6,
 'price': '6.777,00\xa0kr.',
 'product_url': 'https://www.proshop.dk/Mobil/Apple-iPhone-14-5G-128GB-Midnight/3104588?utm_source=google&utm_medium=cpc&utm_campaign=searchengine',
 'title': 'Apple iPhone 14 5G 128GB - Midnight',
 'url': 'proshop.dk',
 'user_id': 'admin'}
Traceback (most recent call last):
  File "C:\Users\Muhammad Umer\AppData\Local\Programs\Python\Python311\Lib\site-packages\twisted\internet\defer.py", line 1065, in adapt
    extracted = result.result()
                ^^^^^^^^^^^^^^^
  File "C:\Users\Muhammad Umer\AppData\Local\Programs\Python\Python311\Lib\site-packages\asgiref\sync.py", line 448, in __call__
    ret = await asyncio.wait_for(future, timeout=None)
          ^^^^^^^^^^^^^^^^^^^^^^^^^^^^^^^^^^^^^^^^^^^^
  File "C:\Users\Muhammad Umer\AppData\Local\Programs\Python\Python311\Lib\asyncio\tasks.py", line 442, in wait_for
    return await fut
           ^^^^^^^^^
  File "C:\Users\Muhammad Umer\AppData\Local\Programs\Python\Python311\Lib\concurrent\futures\thread.py", line 58, in run
    result = self.fn(*self.args, **self.kwargs)
             ^^^^^^^^^^^^^^^^^^^^^^^^^^^^^^^^^^
  File "C:\Users\Muhammad Umer\AppData\Local\Programs\Python\Python311\Lib\site-packages\asgiref\sync.py", line 490, in thread_handler
    return func(*args, **kwargs)
           ^^^^^^^^^^^^^^^^^^^^^
  File "D:\Outputs\Django Outputs\scraper\pipelines.py", line 33, in process_item
    location = Location.objects.get(country_code=item['country']).first()
               ^^^^^^^^^^^^^^^^^^^^^^^^^^^^^^^^^^^^^^^^^^^^^^^^^^
  File "C:\Users\Muhammad Umer\AppData\Local\Programs\Python\Python311\Lib\site-packages\django\db\models\manager.py", line 85, in manager_method
    return getattr(self.get_queryset(), name)(*args, **kwargs)
           ^^^^^^^^^^^^^^^^^^^^^^^^^^^^^^^^^^^^^^^^^^^^^^^^^^^
  File "C:\Users\Muhammad Umer\AppData\Local\Programs\Python\Python311\Lib\site-packages\django\db\models\query.py", line 653, in get
    raise self.model.MultipleObjectsReturned(
search.models.Location.MultipleObjectsReturned: get() returned more than one Location -- it returned 2!
2023-09-08 07:48:23 [scrapy] ERROR: Error processing {'country': 'DK',
 'keyword': 'iphone 14',
 'position': 7,
 'price': '5.706,99\xa0kr.',
 'product_url': 'https://www.refurbed.dk/p/iphone-14/?co=dk&utm_cluster=gradeA&utm_content=iphone-14&utm_group=iphone-14',
 'title': 'iPhone 14',
 'url': 'refurbed.dk',
 'user_id': 'admin'}
Traceback (most recent call last):
  File "C:\Users\Muhammad Umer\AppData\Local\Programs\Python\Python311\Lib\site-packages\twisted\internet\defer.py", line 1065, in adapt
    extracted = result.result()
                ^^^^^^^^^^^^^^^
  File "C:\Users\Muhammad Umer\AppData\Local\Programs\Python\Python311\Lib\site-packages\asgiref\sync.py", line 448, in __call__
    ret = await asyncio.wait_for(future, timeout=None)
          ^^^^^^^^^^^^^^^^^^^^^^^^^^^^^^^^^^^^^^^^^^^^
  File "C:\Users\Muhammad Umer\AppData\Local\Programs\Python\Python311\Lib\asyncio\tasks.py", line 442, in wait_for
    return await fut
           ^^^^^^^^^
  File "C:\Users\Muhammad Umer\AppData\Local\Programs\Python\Python311\Lib\concurrent\futures\thread.py", line 58, in run
    result = self.fn(*self.args, **self.kwargs)
             ^^^^^^^^^^^^^^^^^^^^^^^^^^^^^^^^^^
  File "C:\Users\Muhammad Umer\AppData\Local\Programs\Python\Python311\Lib\site-packages\asgiref\sync.py", line 490, in thread_handler
    return func(*args, **kwargs)
           ^^^^^^^^^^^^^^^^^^^^^
  File "D:\Outputs\Django Outputs\scraper\pipelines.py", line 33, in process_item
    location = Location.objects.get(country_code=item['country']).first()
               ^^^^^^^^^^^^^^^^^^^^^^^^^^^^^^^^^^^^^^^^^^^^^^^^^^
  File "C:\Users\Muhammad Umer\AppData\Local\Programs\Python\Python311\Lib\site-packages\django\db\models\manager.py", line 85, in manager_method
    return getattr(self.get_queryset(), name)(*args, **kwargs)
           ^^^^^^^^^^^^^^^^^^^^^^^^^^^^^^^^^^^^^^^^^^^^^^^^^^^
  File "C:\Users\Muhammad Umer\AppData\Local\Programs\Python\Python311\Lib\site-packages\django\db\models\query.py", line 653, in get
    raise self.model.MultipleObjectsReturned(
search.models.Location.MultipleObjectsReturned: get() returned more than one Location -- it returned 2!
2023-09-08 07:48:23 [scrapy] ERROR: Error processing {'country': 'DK',
 'keyword': 'iphone 14',
 'position': 8,
 'price': '4.249,00\xa0kr.',
 'product_url': 'https://greenmind.dk/telefoner/iphones/iphone-12/iphone-12-pro/apple-iphone-12-pro-128-gb-stillehavsbla-brugt-okay-stand-25325',
 'title': 'Apple iPhone 12 Pro 128 GB Stillehavsblå Brugt - Okay stand',
 'url': 'greenmind.dk',
 'user_id': 'admin'}
Traceback (most recent call last):
  File "C:\Users\Muhammad Umer\AppData\Local\Programs\Python\Python311\Lib\site-packages\twisted\internet\defer.py", line 1065, in adapt
    extracted = result.result()
                ^^^^^^^^^^^^^^^
  File "C:\Users\Muhammad Umer\AppData\Local\Programs\Python\Python311\Lib\site-packages\asgiref\sync.py", line 448, in __call__
    ret = await asyncio.wait_for(future, timeout=None)
          ^^^^^^^^^^^^^^^^^^^^^^^^^^^^^^^^^^^^^^^^^^^^
  File "C:\Users\Muhammad Umer\AppData\Local\Programs\Python\Python311\Lib\asyncio\tasks.py", line 442, in wait_for
    return await fut
           ^^^^^^^^^
  File "C:\Users\Muhammad Umer\AppData\Local\Programs\Python\Python311\Lib\concurrent\futures\thread.py", line 58, in run
    result = self.fn(*self.args, **self.kwargs)
             ^^^^^^^^^^^^^^^^^^^^^^^^^^^^^^^^^^
  File "C:\Users\Muhammad Umer\AppData\Local\Programs\Python\Python311\Lib\site-packages\asgiref\sync.py", line 490, in thread_handler
    return func(*args, **kwargs)
           ^^^^^^^^^^^^^^^^^^^^^
  File "D:\Outputs\Django Outputs\scraper\pipelines.py", line 33, in process_item
    location = Location.objects.get(country_code=item['country']).first()
               ^^^^^^^^^^^^^^^^^^^^^^^^^^^^^^^^^^^^^^^^^^^^^^^^^^
  File "C:\Users\Muhammad Umer\AppData\Local\Programs\Python\Python311\Lib\site-packages\django\db\models\manager.py", line 85, in manager_method
    return getattr(self.get_queryset(), name)(*args, **kwargs)
           ^^^^^^^^^^^^^^^^^^^^^^^^^^^^^^^^^^^^^^^^^^^^^^^^^^^
  File "C:\Users\Muhammad Umer\AppData\Local\Programs\Python\Python311\Lib\site-packages\django\db\models\query.py", line 653, in get
    raise self.model.MultipleObjectsReturned(
search.models.Location.MultipleObjectsReturned: get() returned more than one Location -- it returned 2!
2023-09-08 07:48:23 [scrapy] ERROR: Error processing {'country': 'DK',
 'keyword': 'iphone 14',
 'position': 9,
 'price': '5.399,00\xa0kr.',
 'product_url': 'https://www.telia.dk/shop/apple/apple-iphone-14/#/blue/128-gb/1',
 'title': 'Apple iPhone 14 128GB Blue.. Min.pris: 7.202,00kr. 6 mdr. binding',
 'url': 'telia.dk',
 'user_id': 'admin'}
Traceback (most recent call last):
  File "C:\Users\Muhammad Umer\AppData\Local\Programs\Python\Python311\Lib\site-packages\twisted\internet\defer.py", line 1065, in adapt
    extracted = result.result()
                ^^^^^^^^^^^^^^^
  File "C:\Users\Muhammad Umer\AppData\Local\Programs\Python\Python311\Lib\site-packages\asgiref\sync.py", line 448, in __call__
    ret = await asyncio.wait_for(future, timeout=None)
          ^^^^^^^^^^^^^^^^^^^^^^^^^^^^^^^^^^^^^^^^^^^^
  File "C:\Users\Muhammad Umer\AppData\Local\Programs\Python\Python311\Lib\asyncio\tasks.py", line 442, in wait_for
    return await fut
           ^^^^^^^^^
  File "C:\Users\Muhammad Umer\AppData\Local\Programs\Python\Python311\Lib\concurrent\futures\thread.py", line 58, in run
    result = self.fn(*self.args, **self.kwargs)
             ^^^^^^^^^^^^^^^^^^^^^^^^^^^^^^^^^^
  File "C:\Users\Muhammad Umer\AppData\Local\Programs\Python\Python311\Lib\site-packages\asgiref\sync.py", line 490, in thread_handler
    return func(*args, **kwargs)
           ^^^^^^^^^^^^^^^^^^^^^
  File "D:\Outputs\Django Outputs\scraper\pipelines.py", line 33, in process_item
    location = Location.objects.get(country_code=item['country']).first()
               ^^^^^^^^^^^^^^^^^^^^^^^^^^^^^^^^^^^^^^^^^^^^^^^^^^
  File "C:\Users\Muhammad Umer\AppData\Local\Programs\Python\Python311\Lib\site-packages\django\db\models\manager.py", line 85, in manager_method
    return getattr(self.get_queryset(), name)(*args, **kwargs)
           ^^^^^^^^^^^^^^^^^^^^^^^^^^^^^^^^^^^^^^^^^^^^^^^^^^^
  File "C:\Users\Muhammad Umer\AppData\Local\Programs\Python\Python311\Lib\site-packages\django\db\models\query.py", line 653, in get
    raise self.model.MultipleObjectsReturned(
search.models.Location.MultipleObjectsReturned: get() returned more than one Location -- it returned 2!
2023-09-08 07:48:23 [scrapy] ERROR: Error processing {'country': 'DK',
 'keyword': 'iphone 14',
 'position': 10,
 'price': '5.496,00\xa0kr.',
 'product_url': 'https://www.telmore.dk/shop/mobiltelefoner/Apple/iphone-14?cid=_semt_terminal_terminal_Shopping_Shopping_u0617',
 'title': 'Apple iPhone 14 128 GB - Product Red. Mindstepris 7.290,00 kr.',
 'url': 'telmore.dk',
 'user_id': 'admin'}
Traceback (most recent call last):
  File "C:\Users\Muhammad Umer\AppData\Local\Programs\Python\Python311\Lib\site-packages\twisted\internet\defer.py", line 1065, in adapt
    extracted = result.result()
                ^^^^^^^^^^^^^^^
  File "C:\Users\Muhammad Umer\AppData\Local\Programs\Python\Python311\Lib\site-packages\asgiref\sync.py", line 448, in __call__
    ret = await asyncio.wait_for(future, timeout=None)
          ^^^^^^^^^^^^^^^^^^^^^^^^^^^^^^^^^^^^^^^^^^^^
  File "C:\Users\Muhammad Umer\AppData\Local\Programs\Python\Python311\Lib\asyncio\tasks.py", line 442, in wait_for
    return await fut
           ^^^^^^^^^
  File "C:\Users\Muhammad Umer\AppData\Local\Programs\Python\Python311\Lib\concurrent\futures\thread.py", line 58, in run
    result = self.fn(*self.args, **self.kwargs)
             ^^^^^^^^^^^^^^^^^^^^^^^^^^^^^^^^^^
  File "C:\Users\Muhammad Umer\AppData\Local\Programs\Python\Python311\Lib\site-packages\asgiref\sync.py", line 490, in thread_handler
    return func(*args, **kwargs)
           ^^^^^^^^^^^^^^^^^^^^^
  File "D:\Outputs\Django Outputs\scraper\pipelines.py", line 33, in process_item
    location = Location.objects.get(country_code=item['country']).first()
               ^^^^^^^^^^^^^^^^^^^^^^^^^^^^^^^^^^^^^^^^^^^^^^^^^^
  File "C:\Users\Muhammad Umer\AppData\Local\Programs\Python\Python311\Lib\site-packages\django\db\models\manager.py", line 85, in manager_method
    return getattr(self.get_queryset(), name)(*args, **kwargs)
           ^^^^^^^^^^^^^^^^^^^^^^^^^^^^^^^^^^^^^^^^^^^^^^^^^^^
  File "C:\Users\Muhammad Umer\AppData\Local\Programs\Python\Python311\Lib\site-packages\django\db\models\query.py", line 653, in get
    raise self.model.MultipleObjectsReturned(
search.models.Location.MultipleObjectsReturned: get() returned more than one Location -- it returned 2!
2023-09-08 07:48:23 [scrapy] ERROR: Error processing {'country': 'DK',
 'keyword': 'iphone 14',
 'position': 11,
 'price': '4.799,00\xa0kr.',
 'product_url': 'https://www.telenor.dk/shop/mobil/apple/apple-iphone-13--128gb-midnight/?cycleCount=none',
 'title': 'Apple iPhone 13 - 128 GB - Midnight med abonnementsaftale. '
          'Mindstepris 6613.00 Kr.',
 'url': 'telenor.dk',
 'user_id': 'admin'}
Traceback (most recent call last):
  File "C:\Users\Muhammad Umer\AppData\Local\Programs\Python\Python311\Lib\site-packages\twisted\internet\defer.py", line 1065, in adapt
    extracted = result.result()
                ^^^^^^^^^^^^^^^
  File "C:\Users\Muhammad Umer\AppData\Local\Programs\Python\Python311\Lib\site-packages\asgiref\sync.py", line 448, in __call__
    ret = await asyncio.wait_for(future, timeout=None)
          ^^^^^^^^^^^^^^^^^^^^^^^^^^^^^^^^^^^^^^^^^^^^
  File "C:\Users\Muhammad Umer\AppData\Local\Programs\Python\Python311\Lib\asyncio\tasks.py", line 442, in wait_for
    return await fut
           ^^^^^^^^^
  File "C:\Users\Muhammad Umer\AppData\Local\Programs\Python\Python311\Lib\concurrent\futures\thread.py", line 58, in run
    result = self.fn(*self.args, **self.kwargs)
             ^^^^^^^^^^^^^^^^^^^^^^^^^^^^^^^^^^
  File "C:\Users\Muhammad Umer\AppData\Local\Programs\Python\Python311\Lib\site-packages\asgiref\sync.py", line 490, in thread_handler
    return func(*args, **kwargs)
           ^^^^^^^^^^^^^^^^^^^^^
  File "D:\Outputs\Django Outputs\scraper\pipelines.py", line 33, in process_item
    location = Location.objects.get(country_code=item['country']).first()
               ^^^^^^^^^^^^^^^^^^^^^^^^^^^^^^^^^^^^^^^^^^^^^^^^^^
  File "C:\Users\Muhammad Umer\AppData\Local\Programs\Python\Python311\Lib\site-packages\django\db\models\manager.py", line 85, in manager_method
    return getattr(self.get_queryset(), name)(*args, **kwargs)
           ^^^^^^^^^^^^^^^^^^^^^^^^^^^^^^^^^^^^^^^^^^^^^^^^^^^
  File "C:\Users\Muhammad Umer\AppData\Local\Programs\Python\Python311\Lib\site-packages\django\db\models\query.py", line 653, in get
    raise self.model.MultipleObjectsReturned(
search.models.Location.MultipleObjectsReturned: get() returned more than one Location -- it returned 2!
2023-09-08 07:48:23 [scrapy] ERROR: Error processing {'country': 'DK',
 'keyword': 'iphone 14',
 'position': 12,
 'price': '8.599,00\xa0kr.',
 'product_url': 'https://www.foetex.dk/produkter/iphone-14-pro-128gb-space-black/200162701/',
 'title': '"IPHONE 14 PRO 128GB SPACE BLACK"',
 'url': 'foetex.dk',
 'user_id': 'admin'}
Traceback (most recent call last):
  File "C:\Users\Muhammad Umer\AppData\Local\Programs\Python\Python311\Lib\site-packages\twisted\internet\defer.py", line 1065, in adapt
    extracted = result.result()
                ^^^^^^^^^^^^^^^
  File "C:\Users\Muhammad Umer\AppData\Local\Programs\Python\Python311\Lib\site-packages\asgiref\sync.py", line 448, in __call__
    ret = await asyncio.wait_for(future, timeout=None)
          ^^^^^^^^^^^^^^^^^^^^^^^^^^^^^^^^^^^^^^^^^^^^
  File "C:\Users\Muhammad Umer\AppData\Local\Programs\Python\Python311\Lib\asyncio\tasks.py", line 442, in wait_for
    return await fut
           ^^^^^^^^^
  File "C:\Users\Muhammad Umer\AppData\Local\Programs\Python\Python311\Lib\concurrent\futures\thread.py", line 58, in run
    result = self.fn(*self.args, **self.kwargs)
             ^^^^^^^^^^^^^^^^^^^^^^^^^^^^^^^^^^
  File "C:\Users\Muhammad Umer\AppData\Local\Programs\Python\Python311\Lib\site-packages\asgiref\sync.py", line 490, in thread_handler
    return func(*args, **kwargs)
           ^^^^^^^^^^^^^^^^^^^^^
  File "D:\Outputs\Django Outputs\scraper\pipelines.py", line 33, in process_item
    location = Location.objects.get(country_code=item['country']).first()
               ^^^^^^^^^^^^^^^^^^^^^^^^^^^^^^^^^^^^^^^^^^^^^^^^^^
  File "C:\Users\Muhammad Umer\AppData\Local\Programs\Python\Python311\Lib\site-packages\django\db\models\manager.py", line 85, in manager_method
    return getattr(self.get_queryset(), name)(*args, **kwargs)
           ^^^^^^^^^^^^^^^^^^^^^^^^^^^^^^^^^^^^^^^^^^^^^^^^^^^
  File "C:\Users\Muhammad Umer\AppData\Local\Programs\Python\Python311\Lib\site-packages\django\db\models\query.py", line 653, in get
    raise self.model.MultipleObjectsReturned(
search.models.Location.MultipleObjectsReturned: get() returned more than one Location -- it returned 2!
2023-09-08 07:48:23 [scrapy] ERROR: Error processing {'country': 'DK',
 'keyword': 'iphone 14',
 'position': 13,
 'price': '6.666,00\xa0kr.',
 'product_url': 'https://www.power.dk/mobil-og-foto/mobiltelefoner/apple-iphone-14-128-gb-stjerneskaer/p-1803963/',
 'title': 'APPLE IPHONE 14 128 GB STJERNESKÆR',
 'url': 'power.dk',
 'user_id': 'admin'}
Traceback (most recent call last):
  File "C:\Users\Muhammad Umer\AppData\Local\Programs\Python\Python311\Lib\site-packages\twisted\internet\defer.py", line 1065, in adapt
    extracted = result.result()
                ^^^^^^^^^^^^^^^
  File "C:\Users\Muhammad Umer\AppData\Local\Programs\Python\Python311\Lib\site-packages\asgiref\sync.py", line 448, in __call__
    ret = await asyncio.wait_for(future, timeout=None)
          ^^^^^^^^^^^^^^^^^^^^^^^^^^^^^^^^^^^^^^^^^^^^
  File "C:\Users\Muhammad Umer\AppData\Local\Programs\Python\Python311\Lib\asyncio\tasks.py", line 442, in wait_for
    return await fut
           ^^^^^^^^^
  File "C:\Users\Muhammad Umer\AppData\Local\Programs\Python\Python311\Lib\concurrent\futures\thread.py", line 58, in run
    result = self.fn(*self.args, **self.kwargs)
             ^^^^^^^^^^^^^^^^^^^^^^^^^^^^^^^^^^
  File "C:\Users\Muhammad Umer\AppData\Local\Programs\Python\Python311\Lib\site-packages\asgiref\sync.py", line 490, in thread_handler
    return func(*args, **kwargs)
           ^^^^^^^^^^^^^^^^^^^^^
  File "D:\Outputs\Django Outputs\scraper\pipelines.py", line 33, in process_item
    location = Location.objects.get(country_code=item['country']).first()
               ^^^^^^^^^^^^^^^^^^^^^^^^^^^^^^^^^^^^^^^^^^^^^^^^^^
  File "C:\Users\Muhammad Umer\AppData\Local\Programs\Python\Python311\Lib\site-packages\django\db\models\manager.py", line 85, in manager_method
    return getattr(self.get_queryset(), name)(*args, **kwargs)
           ^^^^^^^^^^^^^^^^^^^^^^^^^^^^^^^^^^^^^^^^^^^^^^^^^^^
  File "C:\Users\Muhammad Umer\AppData\Local\Programs\Python\Python311\Lib\site-packages\django\db\models\query.py", line 653, in get
    raise self.model.MultipleObjectsReturned(
search.models.Location.MultipleObjectsReturned: get() returned more than one Location -- it returned 2!
2023-09-08 07:48:23 [scrapy] ERROR: Error processing {'country': 'DK',
 'keyword': 'iphone 14',
 'position': 14,
 'price': '12.275,00\xa0kr.',
 'product_url': 'https://www.boligcenter.dk/elektronik/telefoner-tablets/fastnet-og-ip/telefon-apple-iphone-14-pro-max-715845',
 'title': 'Telefon Apple iPhone 14 Pro Max',
 'url': 'boligcenter.dk',
 'user_id': 'admin'}
Traceback (most recent call last):
  File "C:\Users\Muhammad Umer\AppData\Local\Programs\Python\Python311\Lib\site-packages\twisted\internet\defer.py", line 1065, in adapt
    extracted = result.result()
                ^^^^^^^^^^^^^^^
  File "C:\Users\Muhammad Umer\AppData\Local\Programs\Python\Python311\Lib\site-packages\asgiref\sync.py", line 448, in __call__
    ret = await asyncio.wait_for(future, timeout=None)
          ^^^^^^^^^^^^^^^^^^^^^^^^^^^^^^^^^^^^^^^^^^^^
  File "C:\Users\Muhammad Umer\AppData\Local\Programs\Python\Python311\Lib\asyncio\tasks.py", line 442, in wait_for
    return await fut
           ^^^^^^^^^
  File "C:\Users\Muhammad Umer\AppData\Local\Programs\Python\Python311\Lib\concurrent\futures\thread.py", line 58, in run
    result = self.fn(*self.args, **self.kwargs)
             ^^^^^^^^^^^^^^^^^^^^^^^^^^^^^^^^^^
  File "C:\Users\Muhammad Umer\AppData\Local\Programs\Python\Python311\Lib\site-packages\asgiref\sync.py", line 490, in thread_handler
    return func(*args, **kwargs)
           ^^^^^^^^^^^^^^^^^^^^^
  File "D:\Outputs\Django Outputs\scraper\pipelines.py", line 33, in process_item
    location = Location.objects.get(country_code=item['country']).first()
               ^^^^^^^^^^^^^^^^^^^^^^^^^^^^^^^^^^^^^^^^^^^^^^^^^^
  File "C:\Users\Muhammad Umer\AppData\Local\Programs\Python\Python311\Lib\site-packages\django\db\models\manager.py", line 85, in manager_method
    return getattr(self.get_queryset(), name)(*args, **kwargs)
           ^^^^^^^^^^^^^^^^^^^^^^^^^^^^^^^^^^^^^^^^^^^^^^^^^^^
  File "C:\Users\Muhammad Umer\AppData\Local\Programs\Python\Python311\Lib\site-packages\django\db\models\query.py", line 653, in get
    raise self.model.MultipleObjectsReturned(
search.models.Location.MultipleObjectsReturned: get() returned more than one Location -- it returned 2!
2023-09-08 07:48:23 [scrapy] ERROR: Error processing {'country': 'DK',
 'keyword': 'iphone 14',
 'position': 15,
 'price': '5.579,00\xa0kr.',
 'product_url': 'https://swappie.com/dk/iphone/iphone-14/iphone-14-128gb-bla-18/',
 'title': 'iPhone 14 128GB Blå Apple',
 'url': 'swappie.com',
 'user_id': 'admin'}
Traceback (most recent call last):
  File "C:\Users\Muhammad Umer\AppData\Local\Programs\Python\Python311\Lib\site-packages\twisted\internet\defer.py", line 1065, in adapt
    extracted = result.result()
                ^^^^^^^^^^^^^^^
  File "C:\Users\Muhammad Umer\AppData\Local\Programs\Python\Python311\Lib\site-packages\asgiref\sync.py", line 448, in __call__
    ret = await asyncio.wait_for(future, timeout=None)
          ^^^^^^^^^^^^^^^^^^^^^^^^^^^^^^^^^^^^^^^^^^^^
  File "C:\Users\Muhammad Umer\AppData\Local\Programs\Python\Python311\Lib\asyncio\tasks.py", line 442, in wait_for
    return await fut
           ^^^^^^^^^
  File "C:\Users\Muhammad Umer\AppData\Local\Programs\Python\Python311\Lib\concurrent\futures\thread.py", line 58, in run
    result = self.fn(*self.args, **self.kwargs)
             ^^^^^^^^^^^^^^^^^^^^^^^^^^^^^^^^^^
  File "C:\Users\Muhammad Umer\AppData\Local\Programs\Python\Python311\Lib\site-packages\asgiref\sync.py", line 490, in thread_handler
    return func(*args, **kwargs)
           ^^^^^^^^^^^^^^^^^^^^^
  File "D:\Outputs\Django Outputs\scraper\pipelines.py", line 33, in process_item
    location = Location.objects.get(country_code=item['country']).first()
               ^^^^^^^^^^^^^^^^^^^^^^^^^^^^^^^^^^^^^^^^^^^^^^^^^^
  File "C:\Users\Muhammad Umer\AppData\Local\Programs\Python\Python311\Lib\site-packages\django\db\models\manager.py", line 85, in manager_method
    return getattr(self.get_queryset(), name)(*args, **kwargs)
           ^^^^^^^^^^^^^^^^^^^^^^^^^^^^^^^^^^^^^^^^^^^^^^^^^^^
  File "C:\Users\Muhammad Umer\AppData\Local\Programs\Python\Python311\Lib\site-packages\django\db\models\query.py", line 653, in get
    raise self.model.MultipleObjectsReturned(
search.models.Location.MultipleObjectsReturned: get() returned more than one Location -- it returned 2!
2023-09-08 07:48:23 [scrapy] ERROR: Error processing {'country': 'DK',
 'keyword': 'iphone 14',
 'position': 16,
 'price': '5.496,00\xa0kr.',
 'product_url': 'https://www.telmore.dk/shop/mobiltelefoner/Apple/iphone-14?cid=_semt_terminal_terminal_Shopping_Shopping_u0617',
 'title': 'Apple iPhone 14 128 GB - Purple. Mindstepris 7.290,00 kr.',
 'url': 'telmore.dk',
 'user_id': 'admin'}
Traceback (most recent call last):
  File "C:\Users\Muhammad Umer\AppData\Local\Programs\Python\Python311\Lib\site-packages\twisted\internet\defer.py", line 1065, in adapt
    extracted = result.result()
                ^^^^^^^^^^^^^^^
  File "C:\Users\Muhammad Umer\AppData\Local\Programs\Python\Python311\Lib\site-packages\asgiref\sync.py", line 448, in __call__
    ret = await asyncio.wait_for(future, timeout=None)
          ^^^^^^^^^^^^^^^^^^^^^^^^^^^^^^^^^^^^^^^^^^^^
  File "C:\Users\Muhammad Umer\AppData\Local\Programs\Python\Python311\Lib\asyncio\tasks.py", line 442, in wait_for
    return await fut
           ^^^^^^^^^
  File "C:\Users\Muhammad Umer\AppData\Local\Programs\Python\Python311\Lib\concurrent\futures\thread.py", line 58, in run
    result = self.fn(*self.args, **self.kwargs)
             ^^^^^^^^^^^^^^^^^^^^^^^^^^^^^^^^^^
  File "C:\Users\Muhammad Umer\AppData\Local\Programs\Python\Python311\Lib\site-packages\asgiref\sync.py", line 490, in thread_handler
    return func(*args, **kwargs)
           ^^^^^^^^^^^^^^^^^^^^^
  File "D:\Outputs\Django Outputs\scraper\pipelines.py", line 33, in process_item
    location = Location.objects.get(country_code=item['country']).first()
               ^^^^^^^^^^^^^^^^^^^^^^^^^^^^^^^^^^^^^^^^^^^^^^^^^^
  File "C:\Users\Muhammad Umer\AppData\Local\Programs\Python\Python311\Lib\site-packages\django\db\models\manager.py", line 85, in manager_method
    return getattr(self.get_queryset(), name)(*args, **kwargs)
           ^^^^^^^^^^^^^^^^^^^^^^^^^^^^^^^^^^^^^^^^^^^^^^^^^^^
  File "C:\Users\Muhammad Umer\AppData\Local\Programs\Python\Python311\Lib\site-packages\django\db\models\query.py", line 653, in get
    raise self.model.MultipleObjectsReturned(
search.models.Location.MultipleObjectsReturned: get() returned more than one Location -- it returned 2!
2023-09-08 07:48:23 [scrapy] ERROR: Error processing {'country': 'DK',
 'keyword': 'iphone 14',
 'position': 17,
 'price': '6.839,99\xa0kr.',
 'product_url': 'https://www.refurbed.dk/p/iphone-14-pro/?co=dk&utm_cluster=gradeB&utm_content=iphone-14-pro&utm_group=iphone-14-pro',
 'title': 'iPhone 14 Pro',
 'url': 'refurbed.dk',
 'user_id': 'admin'}
Traceback (most recent call last):
  File "C:\Users\Muhammad Umer\AppData\Local\Programs\Python\Python311\Lib\site-packages\twisted\internet\defer.py", line 1065, in adapt
    extracted = result.result()
                ^^^^^^^^^^^^^^^
  File "C:\Users\Muhammad Umer\AppData\Local\Programs\Python\Python311\Lib\site-packages\asgiref\sync.py", line 448, in __call__
    ret = await asyncio.wait_for(future, timeout=None)
          ^^^^^^^^^^^^^^^^^^^^^^^^^^^^^^^^^^^^^^^^^^^^
  File "C:\Users\Muhammad Umer\AppData\Local\Programs\Python\Python311\Lib\asyncio\tasks.py", line 442, in wait_for
    return await fut
           ^^^^^^^^^
  File "C:\Users\Muhammad Umer\AppData\Local\Programs\Python\Python311\Lib\concurrent\futures\thread.py", line 58, in run
    result = self.fn(*self.args, **self.kwargs)
             ^^^^^^^^^^^^^^^^^^^^^^^^^^^^^^^^^^
  File "C:\Users\Muhammad Umer\AppData\Local\Programs\Python\Python311\Lib\site-packages\asgiref\sync.py", line 490, in thread_handler
    return func(*args, **kwargs)
           ^^^^^^^^^^^^^^^^^^^^^
  File "D:\Outputs\Django Outputs\scraper\pipelines.py", line 33, in process_item
    location = Location.objects.get(country_code=item['country']).first()
               ^^^^^^^^^^^^^^^^^^^^^^^^^^^^^^^^^^^^^^^^^^^^^^^^^^
  File "C:\Users\Muhammad Umer\AppData\Local\Programs\Python\Python311\Lib\site-packages\django\db\models\manager.py", line 85, in manager_method
    return getattr(self.get_queryset(), name)(*args, **kwargs)
           ^^^^^^^^^^^^^^^^^^^^^^^^^^^^^^^^^^^^^^^^^^^^^^^^^^^
  File "C:\Users\Muhammad Umer\AppData\Local\Programs\Python\Python311\Lib\site-packages\django\db\models\query.py", line 653, in get
    raise self.model.MultipleObjectsReturned(
search.models.Location.MultipleObjectsReturned: get() returned more than one Location -- it returned 2!
2023-09-08 07:48:23 [scrapy] ERROR: Error processing {'country': 'DK',
 'keyword': 'iphone 14',
 'position': 18,
 'price': '5.496,00\xa0kr.',
 'product_url': 'https://www.telmore.dk/shop/mobiltelefoner/Apple/iphone-14?cid=_semt_terminal_terminal_Shopping_Shopping_u0617',
 'title': 'Apple iPhone 14 128 GB - Sky Blue. Mindstepris 7.290,00 kr.',
 'url': 'telmore.dk',
 'user_id': 'admin'}
Traceback (most recent call last):
  File "C:\Users\Muhammad Umer\AppData\Local\Programs\Python\Python311\Lib\site-packages\twisted\internet\defer.py", line 1065, in adapt
    extracted = result.result()
                ^^^^^^^^^^^^^^^
  File "C:\Users\Muhammad Umer\AppData\Local\Programs\Python\Python311\Lib\site-packages\asgiref\sync.py", line 448, in __call__
    ret = await asyncio.wait_for(future, timeout=None)
          ^^^^^^^^^^^^^^^^^^^^^^^^^^^^^^^^^^^^^^^^^^^^
  File "C:\Users\Muhammad Umer\AppData\Local\Programs\Python\Python311\Lib\asyncio\tasks.py", line 442, in wait_for
    return await fut
           ^^^^^^^^^
  File "C:\Users\Muhammad Umer\AppData\Local\Programs\Python\Python311\Lib\concurrent\futures\thread.py", line 58, in run
    result = self.fn(*self.args, **self.kwargs)
             ^^^^^^^^^^^^^^^^^^^^^^^^^^^^^^^^^^
  File "C:\Users\Muhammad Umer\AppData\Local\Programs\Python\Python311\Lib\site-packages\asgiref\sync.py", line 490, in thread_handler
    return func(*args, **kwargs)
           ^^^^^^^^^^^^^^^^^^^^^
  File "D:\Outputs\Django Outputs\scraper\pipelines.py", line 33, in process_item
    location = Location.objects.get(country_code=item['country']).first()
               ^^^^^^^^^^^^^^^^^^^^^^^^^^^^^^^^^^^^^^^^^^^^^^^^^^
  File "C:\Users\Muhammad Umer\AppData\Local\Programs\Python\Python311\Lib\site-packages\django\db\models\manager.py", line 85, in manager_method
    return getattr(self.get_queryset(), name)(*args, **kwargs)
           ^^^^^^^^^^^^^^^^^^^^^^^^^^^^^^^^^^^^^^^^^^^^^^^^^^^
  File "C:\Users\Muhammad Umer\AppData\Local\Programs\Python\Python311\Lib\site-packages\django\db\models\query.py", line 653, in get
    raise self.model.MultipleObjectsReturned(
search.models.Location.MultipleObjectsReturned: get() returned more than one Location -- it returned 2!
2023-09-08 07:48:23 [scrapy] ERROR: Error processing {'country': 'DK',
 'keyword': 'iphone 14',
 'position': 19,
 'price': '5.399,00\xa0kr.',
 'product_url': 'https://www.telia.dk/shop/apple/apple-iphone-14/#/purple/128-gb/1',
 'title': 'Apple iPhone 14 128GB Purple. Min.pris: 7.202,00kr. 6 mdr. binding',
 'url': 'telia.dk',
 'user_id': 'admin'}
Traceback (most recent call last):
  File "C:\Users\Muhammad Umer\AppData\Local\Programs\Python\Python311\Lib\site-packages\twisted\internet\defer.py", line 1065, in adapt
    extracted = result.result()
                ^^^^^^^^^^^^^^^
  File "C:\Users\Muhammad Umer\AppData\Local\Programs\Python\Python311\Lib\site-packages\asgiref\sync.py", line 448, in __call__
    ret = await asyncio.wait_for(future, timeout=None)
          ^^^^^^^^^^^^^^^^^^^^^^^^^^^^^^^^^^^^^^^^^^^^
  File "C:\Users\Muhammad Umer\AppData\Local\Programs\Python\Python311\Lib\asyncio\tasks.py", line 442, in wait_for
    return await fut
           ^^^^^^^^^
  File "C:\Users\Muhammad Umer\AppData\Local\Programs\Python\Python311\Lib\concurrent\futures\thread.py", line 58, in run
    result = self.fn(*self.args, **self.kwargs)
             ^^^^^^^^^^^^^^^^^^^^^^^^^^^^^^^^^^
  File "C:\Users\Muhammad Umer\AppData\Local\Programs\Python\Python311\Lib\site-packages\asgiref\sync.py", line 490, in thread_handler
    return func(*args, **kwargs)
           ^^^^^^^^^^^^^^^^^^^^^
  File "D:\Outputs\Django Outputs\scraper\pipelines.py", line 33, in process_item
    location = Location.objects.get(country_code=item['country']).first()
               ^^^^^^^^^^^^^^^^^^^^^^^^^^^^^^^^^^^^^^^^^^^^^^^^^^
  File "C:\Users\Muhammad Umer\AppData\Local\Programs\Python\Python311\Lib\site-packages\django\db\models\manager.py", line 85, in manager_method
    return getattr(self.get_queryset(), name)(*args, **kwargs)
           ^^^^^^^^^^^^^^^^^^^^^^^^^^^^^^^^^^^^^^^^^^^^^^^^^^^
  File "C:\Users\Muhammad Umer\AppData\Local\Programs\Python\Python311\Lib\site-packages\django\db\models\query.py", line 653, in get
    raise self.model.MultipleObjectsReturned(
search.models.Location.MultipleObjectsReturned: get() returned more than one Location -- it returned 2!
2023-09-08 07:48:23 [scrapy] ERROR: Error processing {'country': 'DK',
 'keyword': 'iphone 14',
 'position': 20,
 'price': '8.499,00\xa0kr.',
 'product_url': 'https://www.power.dk/mobil-og-foto/mobiltelefoner/apple-iphone-14-pro-128-gb-space-black/p-1803992/',
 'title': 'APPLE IPHONE 14 PRO 128 GB SPACE BLACK',
 'url': 'power.dk',
 'user_id': 'admin'}
Traceback (most recent call last):
  File "C:\Users\Muhammad Umer\AppData\Local\Programs\Python\Python311\Lib\site-packages\twisted\internet\defer.py", line 1065, in adapt
    extracted = result.result()
                ^^^^^^^^^^^^^^^
  File "C:\Users\Muhammad Umer\AppData\Local\Programs\Python\Python311\Lib\site-packages\asgiref\sync.py", line 448, in __call__
    ret = await asyncio.wait_for(future, timeout=None)
          ^^^^^^^^^^^^^^^^^^^^^^^^^^^^^^^^^^^^^^^^^^^^
  File "C:\Users\Muhammad Umer\AppData\Local\Programs\Python\Python311\Lib\asyncio\tasks.py", line 442, in wait_for
    return await fut
           ^^^^^^^^^
  File "C:\Users\Muhammad Umer\AppData\Local\Programs\Python\Python311\Lib\concurrent\futures\thread.py", line 58, in run
    result = self.fn(*self.args, **self.kwargs)
             ^^^^^^^^^^^^^^^^^^^^^^^^^^^^^^^^^^
  File "C:\Users\Muhammad Umer\AppData\Local\Programs\Python\Python311\Lib\site-packages\asgiref\sync.py", line 490, in thread_handler
    return func(*args, **kwargs)
           ^^^^^^^^^^^^^^^^^^^^^
  File "D:\Outputs\Django Outputs\scraper\pipelines.py", line 33, in process_item
    location = Location.objects.get(country_code=item['country']).first()
               ^^^^^^^^^^^^^^^^^^^^^^^^^^^^^^^^^^^^^^^^^^^^^^^^^^
  File "C:\Users\Muhammad Umer\AppData\Local\Programs\Python\Python311\Lib\site-packages\django\db\models\manager.py", line 85, in manager_method
    return getattr(self.get_queryset(), name)(*args, **kwargs)
           ^^^^^^^^^^^^^^^^^^^^^^^^^^^^^^^^^^^^^^^^^^^^^^^^^^^
  File "C:\Users\Muhammad Umer\AppData\Local\Programs\Python\Python311\Lib\site-packages\django\db\models\query.py", line 653, in get
    raise self.model.MultipleObjectsReturned(
search.models.Location.MultipleObjectsReturned: get() returned more than one Location -- it returned 2!
2023-09-08 07:48:23 [scrapy] ERROR: Error processing {'country': 'DK',
 'keyword': 'iphone 14',
 'position': 21,
 'price': '6.291,00\xa0kr.',
 'product_url': 'https://www.elgiganten.dk/product/outlet/iphone-14-5g-smartphone-128gb-product-red/653032',
 'title': 'iPhone 14 – 5G smartphone 128GB Product Red',
 'url': 'elgiganten.dk',
 'user_id': 'admin'}
Traceback (most recent call last):
  File "C:\Users\Muhammad Umer\AppData\Local\Programs\Python\Python311\Lib\site-packages\twisted\internet\defer.py", line 1065, in adapt
    extracted = result.result()
                ^^^^^^^^^^^^^^^
  File "C:\Users\Muhammad Umer\AppData\Local\Programs\Python\Python311\Lib\site-packages\asgiref\sync.py", line 448, in __call__
    ret = await asyncio.wait_for(future, timeout=None)
          ^^^^^^^^^^^^^^^^^^^^^^^^^^^^^^^^^^^^^^^^^^^^
  File "C:\Users\Muhammad Umer\AppData\Local\Programs\Python\Python311\Lib\asyncio\tasks.py", line 442, in wait_for
    return await fut
           ^^^^^^^^^
  File "C:\Users\Muhammad Umer\AppData\Local\Programs\Python\Python311\Lib\concurrent\futures\thread.py", line 58, in run
    result = self.fn(*self.args, **self.kwargs)
             ^^^^^^^^^^^^^^^^^^^^^^^^^^^^^^^^^^
  File "C:\Users\Muhammad Umer\AppData\Local\Programs\Python\Python311\Lib\site-packages\asgiref\sync.py", line 490, in thread_handler
    return func(*args, **kwargs)
           ^^^^^^^^^^^^^^^^^^^^^
  File "D:\Outputs\Django Outputs\scraper\pipelines.py", line 33, in process_item
    location = Location.objects.get(country_code=item['country']).first()
               ^^^^^^^^^^^^^^^^^^^^^^^^^^^^^^^^^^^^^^^^^^^^^^^^^^
  File "C:\Users\Muhammad Umer\AppData\Local\Programs\Python\Python311\Lib\site-packages\django\db\models\manager.py", line 85, in manager_method
    return getattr(self.get_queryset(), name)(*args, **kwargs)
           ^^^^^^^^^^^^^^^^^^^^^^^^^^^^^^^^^^^^^^^^^^^^^^^^^^^
  File "C:\Users\Muhammad Umer\AppData\Local\Programs\Python\Python311\Lib\site-packages\django\db\models\query.py", line 653, in get
    raise self.model.MultipleObjectsReturned(
search.models.Location.MultipleObjectsReturned: get() returned more than one Location -- it returned 2!
2023-09-08 07:48:23 [scrapy] ERROR: Error processing {'country': 'DK',
 'keyword': 'iphone 14',
 'position': 22,
 'price': '4.895,00\xa0kr.',
 'product_url': 'https://www.phonetrade.dk/kob/iphone-14/blaa-128gb-brugbar-829',
 'title': 'iPhone 14, 128GB, Blå',
 'url': 'phonetrade.dk',
 'user_id': 'admin'}
Traceback (most recent call last):
  File "C:\Users\Muhammad Umer\AppData\Local\Programs\Python\Python311\Lib\site-packages\twisted\internet\defer.py", line 1065, in adapt
    extracted = result.result()
                ^^^^^^^^^^^^^^^
  File "C:\Users\Muhammad Umer\AppData\Local\Programs\Python\Python311\Lib\site-packages\asgiref\sync.py", line 448, in __call__
    ret = await asyncio.wait_for(future, timeout=None)
          ^^^^^^^^^^^^^^^^^^^^^^^^^^^^^^^^^^^^^^^^^^^^
  File "C:\Users\Muhammad Umer\AppData\Local\Programs\Python\Python311\Lib\asyncio\tasks.py", line 442, in wait_for
    return await fut
           ^^^^^^^^^
  File "C:\Users\Muhammad Umer\AppData\Local\Programs\Python\Python311\Lib\concurrent\futures\thread.py", line 58, in run
    result = self.fn(*self.args, **self.kwargs)
             ^^^^^^^^^^^^^^^^^^^^^^^^^^^^^^^^^^
  File "C:\Users\Muhammad Umer\AppData\Local\Programs\Python\Python311\Lib\site-packages\asgiref\sync.py", line 490, in thread_handler
    return func(*args, **kwargs)
           ^^^^^^^^^^^^^^^^^^^^^
  File "D:\Outputs\Django Outputs\scraper\pipelines.py", line 33, in process_item
    location = Location.objects.get(country_code=item['country']).first()
               ^^^^^^^^^^^^^^^^^^^^^^^^^^^^^^^^^^^^^^^^^^^^^^^^^^
  File "C:\Users\Muhammad Umer\AppData\Local\Programs\Python\Python311\Lib\site-packages\django\db\models\manager.py", line 85, in manager_method
    return getattr(self.get_queryset(), name)(*args, **kwargs)
           ^^^^^^^^^^^^^^^^^^^^^^^^^^^^^^^^^^^^^^^^^^^^^^^^^^^
  File "C:\Users\Muhammad Umer\AppData\Local\Programs\Python\Python311\Lib\site-packages\django\db\models\query.py", line 653, in get
    raise self.model.MultipleObjectsReturned(
search.models.Location.MultipleObjectsReturned: get() returned more than one Location -- it returned 2!
2023-09-08 07:48:23 [scrapy] ERROR: Error processing {'country': 'DK',
 'keyword': 'iphone 14',
 'position': 23,
 'price': '5.761,00\xa0kr.',
 'product_url': 'https://yousee.dk/mobil/mobiltelefoner/apple/iphone-14/1611/mobil_80/kontant/',
 'title': 'Apple iPhone 14 128 GB Gul med abonnementsaftale. Mindstepris '
          '7.075,00 kr.',
 'url': 'yousee.dk',
 'user_id': 'admin'}
Traceback (most recent call last):
  File "C:\Users\Muhammad Umer\AppData\Local\Programs\Python\Python311\Lib\site-packages\twisted\internet\defer.py", line 1065, in adapt
    extracted = result.result()
                ^^^^^^^^^^^^^^^
  File "C:\Users\Muhammad Umer\AppData\Local\Programs\Python\Python311\Lib\site-packages\asgiref\sync.py", line 448, in __call__
    ret = await asyncio.wait_for(future, timeout=None)
          ^^^^^^^^^^^^^^^^^^^^^^^^^^^^^^^^^^^^^^^^^^^^
  File "C:\Users\Muhammad Umer\AppData\Local\Programs\Python\Python311\Lib\asyncio\tasks.py", line 442, in wait_for
    return await fut
           ^^^^^^^^^
  File "C:\Users\Muhammad Umer\AppData\Local\Programs\Python\Python311\Lib\concurrent\futures\thread.py", line 58, in run
    result = self.fn(*self.args, **self.kwargs)
             ^^^^^^^^^^^^^^^^^^^^^^^^^^^^^^^^^^
  File "C:\Users\Muhammad Umer\AppData\Local\Programs\Python\Python311\Lib\site-packages\asgiref\sync.py", line 490, in thread_handler
    return func(*args, **kwargs)
           ^^^^^^^^^^^^^^^^^^^^^
  File "D:\Outputs\Django Outputs\scraper\pipelines.py", line 33, in process_item
    location = Location.objects.get(country_code=item['country']).first()
               ^^^^^^^^^^^^^^^^^^^^^^^^^^^^^^^^^^^^^^^^^^^^^^^^^^
  File "C:\Users\Muhammad Umer\AppData\Local\Programs\Python\Python311\Lib\site-packages\django\db\models\manager.py", line 85, in manager_method
    return getattr(self.get_queryset(), name)(*args, **kwargs)
           ^^^^^^^^^^^^^^^^^^^^^^^^^^^^^^^^^^^^^^^^^^^^^^^^^^^
  File "C:\Users\Muhammad Umer\AppData\Local\Programs\Python\Python311\Lib\site-packages\django\db\models\query.py", line 653, in get
    raise self.model.MultipleObjectsReturned(
search.models.Location.MultipleObjectsReturned: get() returned more than one Location -- it returned 2!
2023-09-08 07:48:23 [scrapy] ERROR: Error processing {'country': 'DK',
 'keyword': 'iphone 14',
 'position': 24,
 'price': '6.666,00\xa0kr.',
 'product_url': 'https://www.power.dk/mobil-og-foto/mobiltelefoner/apple-iphone-14-128-gb-blaa/p-1803966/',
 'title': 'APPLE IPHONE 14 128 GB BLÅ',
 'url': 'power.dk',
 'user_id': 'admin'}
Traceback (most recent call last):
  File "C:\Users\Muhammad Umer\AppData\Local\Programs\Python\Python311\Lib\site-packages\twisted\internet\defer.py", line 1065, in adapt
    extracted = result.result()
                ^^^^^^^^^^^^^^^
  File "C:\Users\Muhammad Umer\AppData\Local\Programs\Python\Python311\Lib\site-packages\asgiref\sync.py", line 448, in __call__
    ret = await asyncio.wait_for(future, timeout=None)
          ^^^^^^^^^^^^^^^^^^^^^^^^^^^^^^^^^^^^^^^^^^^^
  File "C:\Users\Muhammad Umer\AppData\Local\Programs\Python\Python311\Lib\asyncio\tasks.py", line 442, in wait_for
    return await fut
           ^^^^^^^^^
  File "C:\Users\Muhammad Umer\AppData\Local\Programs\Python\Python311\Lib\concurrent\futures\thread.py", line 58, in run
    result = self.fn(*self.args, **self.kwargs)
             ^^^^^^^^^^^^^^^^^^^^^^^^^^^^^^^^^^
  File "C:\Users\Muhammad Umer\AppData\Local\Programs\Python\Python311\Lib\site-packages\asgiref\sync.py", line 490, in thread_handler
    return func(*args, **kwargs)
           ^^^^^^^^^^^^^^^^^^^^^
  File "D:\Outputs\Django Outputs\scraper\pipelines.py", line 33, in process_item
    location = Location.objects.get(country_code=item['country']).first()
               ^^^^^^^^^^^^^^^^^^^^^^^^^^^^^^^^^^^^^^^^^^^^^^^^^^
  File "C:\Users\Muhammad Umer\AppData\Local\Programs\Python\Python311\Lib\site-packages\django\db\models\manager.py", line 85, in manager_method
    return getattr(self.get_queryset(), name)(*args, **kwargs)
           ^^^^^^^^^^^^^^^^^^^^^^^^^^^^^^^^^^^^^^^^^^^^^^^^^^^
  File "C:\Users\Muhammad Umer\AppData\Local\Programs\Python\Python311\Lib\site-packages\django\db\models\query.py", line 653, in get
    raise self.model.MultipleObjectsReturned(
search.models.Location.MultipleObjectsReturned: get() returned more than one Location -- it returned 2!
2023-09-08 07:48:23 [scrapy] ERROR: Error processing {'country': 'DK',
 'keyword': 'iphone 14',
 'position': 25,
 'price': None,
 'product_url': None,
 'title': None,
 'url': '',
 'user_id': 'admin'}
Traceback (most recent call last):
  File "C:\Users\Muhammad Umer\AppData\Local\Programs\Python\Python311\Lib\site-packages\twisted\internet\defer.py", line 1065, in adapt
    extracted = result.result()
                ^^^^^^^^^^^^^^^
  File "C:\Users\Muhammad Umer\AppData\Local\Programs\Python\Python311\Lib\site-packages\asgiref\sync.py", line 448, in __call__
    ret = await asyncio.wait_for(future, timeout=None)
          ^^^^^^^^^^^^^^^^^^^^^^^^^^^^^^^^^^^^^^^^^^^^
  File "C:\Users\Muhammad Umer\AppData\Local\Programs\Python\Python311\Lib\asyncio\tasks.py", line 442, in wait_for
    return await fut
           ^^^^^^^^^
  File "C:\Users\Muhammad Umer\AppData\Local\Programs\Python\Python311\Lib\concurrent\futures\thread.py", line 58, in run
    result = self.fn(*self.args, **self.kwargs)
             ^^^^^^^^^^^^^^^^^^^^^^^^^^^^^^^^^^
  File "C:\Users\Muhammad Umer\AppData\Local\Programs\Python\Python311\Lib\site-packages\asgiref\sync.py", line 490, in thread_handler
    return func(*args, **kwargs)
           ^^^^^^^^^^^^^^^^^^^^^
  File "D:\Outputs\Django Outputs\scraper\pipelines.py", line 33, in process_item
    location = Location.objects.get(country_code=item['country']).first()
               ^^^^^^^^^^^^^^^^^^^^^^^^^^^^^^^^^^^^^^^^^^^^^^^^^^
  File "C:\Users\Muhammad Umer\AppData\Local\Programs\Python\Python311\Lib\site-packages\django\db\models\manager.py", line 85, in manager_method
    return getattr(self.get_queryset(), name)(*args, **kwargs)
           ^^^^^^^^^^^^^^^^^^^^^^^^^^^^^^^^^^^^^^^^^^^^^^^^^^^
  File "C:\Users\Muhammad Umer\AppData\Local\Programs\Python\Python311\Lib\site-packages\django\db\models\query.py", line 653, in get
    raise self.model.MultipleObjectsReturned(
search.models.Location.MultipleObjectsReturned: get() returned more than one Location -- it returned 2!
2023-09-08 07:48:25 [scrapy] DEBUG: Crawled (200) <GET https://www.google.com/search?q=+apple&hl=en&gl=DK&start=0> (referer: None)
2023-09-08 07:48:25 [scrapy] INFO: Closing spider (finished)
2023-09-08 07:48:25 [scrapy] INFO: Dumping Scrapy stats:
{'downloader/request_bytes': 4712,
 'downloader/request_count': 8,
 'downloader/request_method_count/GET': 8,
 'downloader/response_bytes': 1031318,
 'downloader/response_count': 8,
 'downloader/response_status_count/200': 4,
 'downloader/response_status_count/302': 1,
 'downloader/response_status_count/429': 3,
 'elapsed_time_seconds': 14.560525,
 'finish_reason': 'finished',
 'finish_time': datetime.datetime(2023, 9, 8, 2, 48, 25, 548356),
 'httpcompression/response_bytes': 3577993,
 'httpcompression/response_count': 4,
 'httperror/response_ignored_count': 1,
 'httperror/response_ignored_status_count/429': 1,
 'log_count/DEBUG': 8,
 'log_count/ERROR': 64,
 'log_count/INFO': 9,
 'response_received_count': 5,
 'retry/count': 2,
 'retry/max_reached': 1,
 'retry/reason_count/429 Unknown Status': 2,
 'scheduler/dequeued': 8,
 'scheduler/dequeued/memory': 8,
 'scheduler/enqueued': 8,
 'scheduler/enqueued/memory': 8,
 'start_time': datetime.datetime(2023, 9, 8, 2, 48, 10, 987831)}
2023-09-08 07:48:25 [scrapy] INFO: Spider closed (finished)
