2023-09-08 08:01:30 [scrapy] DEBUG: Redirecting (302) to <GET https://www.google.com/sorry/index?continue=https://www.google.com/search%3Fq%3D%2Bmacbook%26hl%3Den%26gl%3DDK%26start%3D0&hl=en&q=EgRdpA0SGIud6qcGIjBPF21TF2Bvi--95w9BfEn1wPs7HuabJPY46HNuAgjsyqp-0fpXJZmQSrnc4_R56wEyAXJaAUM> from <GET https://www.google.com/search?q=+macbook&hl=en&gl=DK&start=0>
2023-09-08 08:01:31 [scrapy] DEBUG: Retrying <GET https://www.google.com/sorry/index?continue=https://www.google.com/search%3Fq%3D%2Bmacbook%26hl%3Den%26gl%3DDK%26start%3D0&hl=en&q=EgRdpA0SGIud6qcGIjBPF21TF2Bvi--95w9BfEn1wPs7HuabJPY46HNuAgjsyqp-0fpXJZmQSrnc4_R56wEyAXJaAUM> (failed 1 times): 429 Unknown Status
2023-09-08 08:01:31 [scrapy] DEBUG: Crawled (200) <GET https://www.google.com/search?q=+ps5&hl=en&gl=DK&start=0> (referer: None)
2023-09-08 08:01:31 [scrapy] DEBUG: Crawled (200) <GET https://www.google.com/search?q=iphone+14&hl=en&gl=DK&start=0> (referer: None)
2023-09-08 08:01:31 [scrapy] ERROR: Error processing {'country': 'DK',
 'keyword': ' ps5',
 'position': 1,
 'price': '3.690,00\xa0kr.',
 'product_url': 'https://www.proshop.dk/Spillekonsol/Sony-5-Digital-Edition-Nordic/3033825?utm_source=google&utm_medium=cpc&utm_campaign=searchengine',
 'title': 'Sony 5 - Digital Edition (Nordic)',
 'url': 'proshop.dk',
 'user_id': 'admin'}
Traceback (most recent call last):
  File "D:\Outputs\Django Outputs\scraper\pipelines.py", line 37, in process_item
    res = Result.objects.get(
          ^^^^^^^^^^^^^^^^^^^
  File "C:\Users\Muhammad Umer\AppData\Local\Programs\Python\Python311\Lib\site-packages\django\db\models\manager.py", line 85, in manager_method
    return getattr(self.get_queryset(), name)(*args, **kwargs)
           ^^^^^^^^^^^^^^^^^^^^^^^^^^^^^^^^^^^^^^^^^^^^^^^^^^^
  File "C:\Users\Muhammad Umer\AppData\Local\Programs\Python\Python311\Lib\site-packages\django\db\models\query.py", line 650, in get
    raise self.model.DoesNotExist(
search.models.Result.DoesNotExist: Result matching query does not exist.

During handling of the above exception, another exception occurred:

Traceback (most recent call last):
  File "C:\Users\Muhammad Umer\AppData\Local\Programs\Python\Python311\Lib\site-packages\twisted\internet\defer.py", line 1065, in adapt
    extracted = result.result()
                ^^^^^^^^^^^^^^^
  File "C:\Users\Muhammad Umer\AppData\Local\Programs\Python\Python311\Lib\site-packages\asgiref\sync.py", line 448, in __call__
    ret = await asyncio.wait_for(future, timeout=None)
          ^^^^^^^^^^^^^^^^^^^^^^^^^^^^^^^^^^^^^^^^^^^^
  File "C:\Users\Muhammad Umer\AppData\Local\Programs\Python\Python311\Lib\asyncio\tasks.py", line 442, in wait_for
    return await fut
           ^^^^^^^^^
  File "C:\Users\Muhammad Umer\AppData\Local\Programs\Python\Python311\Lib\concurrent\futures\thread.py", line 58, in run
    result = self.fn(*self.args, **self.kwargs)
             ^^^^^^^^^^^^^^^^^^^^^^^^^^^^^^^^^^
  File "C:\Users\Muhammad Umer\AppData\Local\Programs\Python\Python311\Lib\site-packages\asgiref\sync.py", line 490, in thread_handler
    return func(*args, **kwargs)
           ^^^^^^^^^^^^^^^^^^^^^
  File "D:\Outputs\Django Outputs\scraper\pipelines.py", line 44, in process_item
    Result.objects.create(
  File "C:\Users\Muhammad Umer\AppData\Local\Programs\Python\Python311\Lib\site-packages\django\db\models\manager.py", line 85, in manager_method
    return getattr(self.get_queryset(), name)(*args, **kwargs)
           ^^^^^^^^^^^^^^^^^^^^^^^^^^^^^^^^^^^^^^^^^^^^^^^^^^^
  File "C:\Users\Muhammad Umer\AppData\Local\Programs\Python\Python311\Lib\site-packages\django\db\models\query.py", line 669, in create
    obj = self.model(**kwargs)
          ^^^^^^^^^^^^^^^^^^^^
  File "C:\Users\Muhammad Umer\AppData\Local\Programs\Python\Python311\Lib\site-packages\django\db\models\base.py", line 541, in __init__
    _setattr(self, field.name, rel_obj)
  File "C:\Users\Muhammad Umer\AppData\Local\Programs\Python\Python311\Lib\site-packages\django\db\models\fields\related_descriptors.py", line 237, in __set__
    raise ValueError(
ValueError: Cannot assign "' ps5'": "Result.keyword" must be a "Keyword" instance.
2023-09-08 08:01:31 [scrapy] ERROR: Error processing {'country': 'DK',
 'keyword': ' ps5',
 'position': 2,
 'price': '3.879,00\xa0kr.',
 'product_url': 'https://www.elgiganten.dk/product/gaming/spillekonsol-tilbehor/playstation/playstation-spillekonsol/playstation-5-digital-edition-2022/533977',
 'title': 'PlayStation 5 Digital Edition (2022)',
 'url': 'elgiganten.dk',
 'user_id': 'admin'}
Traceback (most recent call last):
  File "D:\Outputs\Django Outputs\scraper\pipelines.py", line 37, in process_item
    res = Result.objects.get(
          ^^^^^^^^^^^^^^^^^^^
  File "C:\Users\Muhammad Umer\AppData\Local\Programs\Python\Python311\Lib\site-packages\django\db\models\manager.py", line 85, in manager_method
    return getattr(self.get_queryset(), name)(*args, **kwargs)
           ^^^^^^^^^^^^^^^^^^^^^^^^^^^^^^^^^^^^^^^^^^^^^^^^^^^
  File "C:\Users\Muhammad Umer\AppData\Local\Programs\Python\Python311\Lib\site-packages\django\db\models\query.py", line 650, in get
    raise self.model.DoesNotExist(
search.models.Result.DoesNotExist: Result matching query does not exist.

During handling of the above exception, another exception occurred:

Traceback (most recent call last):
  File "C:\Users\Muhammad Umer\AppData\Local\Programs\Python\Python311\Lib\site-packages\twisted\internet\defer.py", line 1065, in adapt
    extracted = result.result()
                ^^^^^^^^^^^^^^^
  File "C:\Users\Muhammad Umer\AppData\Local\Programs\Python\Python311\Lib\site-packages\asgiref\sync.py", line 448, in __call__
    ret = await asyncio.wait_for(future, timeout=None)
          ^^^^^^^^^^^^^^^^^^^^^^^^^^^^^^^^^^^^^^^^^^^^
  File "C:\Users\Muhammad Umer\AppData\Local\Programs\Python\Python311\Lib\asyncio\tasks.py", line 442, in wait_for
    return await fut
           ^^^^^^^^^
  File "C:\Users\Muhammad Umer\AppData\Local\Programs\Python\Python311\Lib\concurrent\futures\thread.py", line 58, in run
    result = self.fn(*self.args, **self.kwargs)
             ^^^^^^^^^^^^^^^^^^^^^^^^^^^^^^^^^^
  File "C:\Users\Muhammad Umer\AppData\Local\Programs\Python\Python311\Lib\site-packages\asgiref\sync.py", line 490, in thread_handler
    return func(*args, **kwargs)
           ^^^^^^^^^^^^^^^^^^^^^
  File "D:\Outputs\Django Outputs\scraper\pipelines.py", line 44, in process_item
    Result.objects.create(
  File "C:\Users\Muhammad Umer\AppData\Local\Programs\Python\Python311\Lib\site-packages\django\db\models\manager.py", line 85, in manager_method
    return getattr(self.get_queryset(), name)(*args, **kwargs)
           ^^^^^^^^^^^^^^^^^^^^^^^^^^^^^^^^^^^^^^^^^^^^^^^^^^^
  File "C:\Users\Muhammad Umer\AppData\Local\Programs\Python\Python311\Lib\site-packages\django\db\models\query.py", line 669, in create
    obj = self.model(**kwargs)
          ^^^^^^^^^^^^^^^^^^^^
  File "C:\Users\Muhammad Umer\AppData\Local\Programs\Python\Python311\Lib\site-packages\django\db\models\base.py", line 541, in __init__
    _setattr(self, field.name, rel_obj)
  File "C:\Users\Muhammad Umer\AppData\Local\Programs\Python\Python311\Lib\site-packages\django\db\models\fields\related_descriptors.py", line 237, in __set__
    raise ValueError(
ValueError: Cannot assign "' ps5'": "Result.keyword" must be a "Keyword" instance.
2023-09-08 08:01:31 [scrapy] ERROR: Error processing {'country': 'DK',
 'keyword': ' ps5',
 'position': 3,
 'price': '2.999,00\xa0kr.',
 'product_url': 'https://www.telia.dk/shop/playstation/sony-playstation-5-23-bundle-med-abonnement/#/white/0-gb',
 'title': 'Sony PlayStation 5 med abonnement. Min.pris: 5.302,00kr. 6 mdr. '
          'binding',
 'url': 'telia.dk',
 'user_id': 'admin'}
Traceback (most recent call last):
  File "D:\Outputs\Django Outputs\scraper\pipelines.py", line 37, in process_item
    res = Result.objects.get(
          ^^^^^^^^^^^^^^^^^^^
  File "C:\Users\Muhammad Umer\AppData\Local\Programs\Python\Python311\Lib\site-packages\django\db\models\manager.py", line 85, in manager_method
    return getattr(self.get_queryset(), name)(*args, **kwargs)
           ^^^^^^^^^^^^^^^^^^^^^^^^^^^^^^^^^^^^^^^^^^^^^^^^^^^
  File "C:\Users\Muhammad Umer\AppData\Local\Programs\Python\Python311\Lib\site-packages\django\db\models\query.py", line 650, in get
    raise self.model.DoesNotExist(
search.models.Result.DoesNotExist: Result matching query does not exist.

During handling of the above exception, another exception occurred:

Traceback (most recent call last):
  File "C:\Users\Muhammad Umer\AppData\Local\Programs\Python\Python311\Lib\site-packages\twisted\internet\defer.py", line 1065, in adapt
    extracted = result.result()
                ^^^^^^^^^^^^^^^
  File "C:\Users\Muhammad Umer\AppData\Local\Programs\Python\Python311\Lib\site-packages\asgiref\sync.py", line 448, in __call__
    ret = await asyncio.wait_for(future, timeout=None)
          ^^^^^^^^^^^^^^^^^^^^^^^^^^^^^^^^^^^^^^^^^^^^
  File "C:\Users\Muhammad Umer\AppData\Local\Programs\Python\Python311\Lib\asyncio\tasks.py", line 442, in wait_for
    return await fut
           ^^^^^^^^^
  File "C:\Users\Muhammad Umer\AppData\Local\Programs\Python\Python311\Lib\concurrent\futures\thread.py", line 58, in run
    result = self.fn(*self.args, **self.kwargs)
             ^^^^^^^^^^^^^^^^^^^^^^^^^^^^^^^^^^
  File "C:\Users\Muhammad Umer\AppData\Local\Programs\Python\Python311\Lib\site-packages\asgiref\sync.py", line 490, in thread_handler
    return func(*args, **kwargs)
           ^^^^^^^^^^^^^^^^^^^^^
  File "D:\Outputs\Django Outputs\scraper\pipelines.py", line 44, in process_item
    Result.objects.create(
  File "C:\Users\Muhammad Umer\AppData\Local\Programs\Python\Python311\Lib\site-packages\django\db\models\manager.py", line 85, in manager_method
    return getattr(self.get_queryset(), name)(*args, **kwargs)
           ^^^^^^^^^^^^^^^^^^^^^^^^^^^^^^^^^^^^^^^^^^^^^^^^^^^
  File "C:\Users\Muhammad Umer\AppData\Local\Programs\Python\Python311\Lib\site-packages\django\db\models\query.py", line 669, in create
    obj = self.model(**kwargs)
          ^^^^^^^^^^^^^^^^^^^^
  File "C:\Users\Muhammad Umer\AppData\Local\Programs\Python\Python311\Lib\site-packages\django\db\models\base.py", line 541, in __init__
    _setattr(self, field.name, rel_obj)
  File "C:\Users\Muhammad Umer\AppData\Local\Programs\Python\Python311\Lib\site-packages\django\db\models\fields\related_descriptors.py", line 237, in __set__
    raise ValueError(
ValueError: Cannot assign "' ps5'": "Result.keyword" must be a "Keyword" instance.
2023-09-08 08:01:31 [scrapy] ERROR: Error processing {'country': 'DK',
 'keyword': ' ps5',
 'position': 4,
 'price': '3.777,00\xa0kr.',
 'product_url': 'https://www.power.dk/gaming-og-underholdning/playstation/playstation-konsoller/playstation-5-digital-edition/p-1840112/',
 'title': 'PLAYSTATION 5 DIGITAL EDITION',
 'url': 'power.dk',
 'user_id': 'admin'}
Traceback (most recent call last):
  File "D:\Outputs\Django Outputs\scraper\pipelines.py", line 37, in process_item
    res = Result.objects.get(
          ^^^^^^^^^^^^^^^^^^^
  File "C:\Users\Muhammad Umer\AppData\Local\Programs\Python\Python311\Lib\site-packages\django\db\models\manager.py", line 85, in manager_method
    return getattr(self.get_queryset(), name)(*args, **kwargs)
           ^^^^^^^^^^^^^^^^^^^^^^^^^^^^^^^^^^^^^^^^^^^^^^^^^^^
  File "C:\Users\Muhammad Umer\AppData\Local\Programs\Python\Python311\Lib\site-packages\django\db\models\query.py", line 650, in get
    raise self.model.DoesNotExist(
search.models.Result.DoesNotExist: Result matching query does not exist.

During handling of the above exception, another exception occurred:

Traceback (most recent call last):
  File "C:\Users\Muhammad Umer\AppData\Local\Programs\Python\Python311\Lib\site-packages\twisted\internet\defer.py", line 1065, in adapt
    extracted = result.result()
                ^^^^^^^^^^^^^^^
  File "C:\Users\Muhammad Umer\AppData\Local\Programs\Python\Python311\Lib\site-packages\asgiref\sync.py", line 448, in __call__
    ret = await asyncio.wait_for(future, timeout=None)
          ^^^^^^^^^^^^^^^^^^^^^^^^^^^^^^^^^^^^^^^^^^^^
  File "C:\Users\Muhammad Umer\AppData\Local\Programs\Python\Python311\Lib\asyncio\tasks.py", line 442, in wait_for
    return await fut
           ^^^^^^^^^
  File "C:\Users\Muhammad Umer\AppData\Local\Programs\Python\Python311\Lib\concurrent\futures\thread.py", line 58, in run
    result = self.fn(*self.args, **self.kwargs)
             ^^^^^^^^^^^^^^^^^^^^^^^^^^^^^^^^^^
  File "C:\Users\Muhammad Umer\AppData\Local\Programs\Python\Python311\Lib\site-packages\asgiref\sync.py", line 490, in thread_handler
    return func(*args, **kwargs)
           ^^^^^^^^^^^^^^^^^^^^^
  File "D:\Outputs\Django Outputs\scraper\pipelines.py", line 44, in process_item
    Result.objects.create(
  File "C:\Users\Muhammad Umer\AppData\Local\Programs\Python\Python311\Lib\site-packages\django\db\models\manager.py", line 85, in manager_method
    return getattr(self.get_queryset(), name)(*args, **kwargs)
           ^^^^^^^^^^^^^^^^^^^^^^^^^^^^^^^^^^^^^^^^^^^^^^^^^^^
  File "C:\Users\Muhammad Umer\AppData\Local\Programs\Python\Python311\Lib\site-packages\django\db\models\query.py", line 669, in create
    obj = self.model(**kwargs)
          ^^^^^^^^^^^^^^^^^^^^
  File "C:\Users\Muhammad Umer\AppData\Local\Programs\Python\Python311\Lib\site-packages\django\db\models\base.py", line 541, in __init__
    _setattr(self, field.name, rel_obj)
  File "C:\Users\Muhammad Umer\AppData\Local\Programs\Python\Python311\Lib\site-packages\django\db\models\fields\related_descriptors.py", line 237, in __set__
    raise ValueError(
ValueError: Cannot assign "' ps5'": "Result.keyword" must be a "Keyword" instance.
2023-09-08 08:01:31 [scrapy] ERROR: Error processing {'country': 'DK',
 'keyword': ' ps5',
 'position': 5,
 'price': '5.190,00\xa0kr.',
 'product_url': 'https://www.proshop.dk/Spillekonsol/Sony-PlayStation-5-Marvels-Spider-Man-2-Limited-Edition-Bundle/3189056?utm_source=google&utm_medium=cpc&utm_campaign=searchengine',
 'title': "Sony PlayStation 5 Marvel's Spider-Man 2 Limited Edition Bundle",
 'url': 'proshop.dk',
 'user_id': 'admin'}
Traceback (most recent call last):
  File "D:\Outputs\Django Outputs\scraper\pipelines.py", line 37, in process_item
    res = Result.objects.get(
          ^^^^^^^^^^^^^^^^^^^
  File "C:\Users\Muhammad Umer\AppData\Local\Programs\Python\Python311\Lib\site-packages\django\db\models\manager.py", line 85, in manager_method
    return getattr(self.get_queryset(), name)(*args, **kwargs)
           ^^^^^^^^^^^^^^^^^^^^^^^^^^^^^^^^^^^^^^^^^^^^^^^^^^^
  File "C:\Users\Muhammad Umer\AppData\Local\Programs\Python\Python311\Lib\site-packages\django\db\models\query.py", line 650, in get
    raise self.model.DoesNotExist(
search.models.Result.DoesNotExist: Result matching query does not exist.

During handling of the above exception, another exception occurred:

Traceback (most recent call last):
  File "C:\Users\Muhammad Umer\AppData\Local\Programs\Python\Python311\Lib\site-packages\twisted\internet\defer.py", line 1065, in adapt
    extracted = result.result()
                ^^^^^^^^^^^^^^^
  File "C:\Users\Muhammad Umer\AppData\Local\Programs\Python\Python311\Lib\site-packages\asgiref\sync.py", line 448, in __call__
    ret = await asyncio.wait_for(future, timeout=None)
          ^^^^^^^^^^^^^^^^^^^^^^^^^^^^^^^^^^^^^^^^^^^^
  File "C:\Users\Muhammad Umer\AppData\Local\Programs\Python\Python311\Lib\asyncio\tasks.py", line 442, in wait_for
    return await fut
           ^^^^^^^^^
  File "C:\Users\Muhammad Umer\AppData\Local\Programs\Python\Python311\Lib\concurrent\futures\thread.py", line 58, in run
    result = self.fn(*self.args, **self.kwargs)
             ^^^^^^^^^^^^^^^^^^^^^^^^^^^^^^^^^^
  File "C:\Users\Muhammad Umer\AppData\Local\Programs\Python\Python311\Lib\site-packages\asgiref\sync.py", line 490, in thread_handler
    return func(*args, **kwargs)
           ^^^^^^^^^^^^^^^^^^^^^
  File "D:\Outputs\Django Outputs\scraper\pipelines.py", line 44, in process_item
    Result.objects.create(
  File "C:\Users\Muhammad Umer\AppData\Local\Programs\Python\Python311\Lib\site-packages\django\db\models\manager.py", line 85, in manager_method
    return getattr(self.get_queryset(), name)(*args, **kwargs)
           ^^^^^^^^^^^^^^^^^^^^^^^^^^^^^^^^^^^^^^^^^^^^^^^^^^^
  File "C:\Users\Muhammad Umer\AppData\Local\Programs\Python\Python311\Lib\site-packages\django\db\models\query.py", line 669, in create
    obj = self.model(**kwargs)
          ^^^^^^^^^^^^^^^^^^^^
  File "C:\Users\Muhammad Umer\AppData\Local\Programs\Python\Python311\Lib\site-packages\django\db\models\base.py", line 541, in __init__
    _setattr(self, field.name, rel_obj)
  File "C:\Users\Muhammad Umer\AppData\Local\Programs\Python\Python311\Lib\site-packages\django\db\models\fields\related_descriptors.py", line 237, in __set__
    raise ValueError(
ValueError: Cannot assign "' ps5'": "Result.keyword" must be a "Keyword" instance.
2023-09-08 08:01:31 [scrapy] ERROR: Error processing {'country': 'DK',
 'keyword': ' ps5',
 'position': 6,
 'price': '5.190,00\xa0kr.',
 'product_url': 'https://www.power.dk/gaming-og-underholdning/playstation/playstation-konsoller/playstation-5-konsol-marvels-spider-man-2-limited-edition-bundle/p-2525860/',
 'title': "PLAYSTATION 5 KONSOL - MARVEL'S SPIDER-MAN 2 LIMITED EDITION BUNDLE",
 'url': 'power.dk',
 'user_id': 'admin'}
Traceback (most recent call last):
  File "D:\Outputs\Django Outputs\scraper\pipelines.py", line 37, in process_item
    res = Result.objects.get(
          ^^^^^^^^^^^^^^^^^^^
  File "C:\Users\Muhammad Umer\AppData\Local\Programs\Python\Python311\Lib\site-packages\django\db\models\manager.py", line 85, in manager_method
    return getattr(self.get_queryset(), name)(*args, **kwargs)
           ^^^^^^^^^^^^^^^^^^^^^^^^^^^^^^^^^^^^^^^^^^^^^^^^^^^
  File "C:\Users\Muhammad Umer\AppData\Local\Programs\Python\Python311\Lib\site-packages\django\db\models\query.py", line 650, in get
    raise self.model.DoesNotExist(
search.models.Result.DoesNotExist: Result matching query does not exist.

During handling of the above exception, another exception occurred:

Traceback (most recent call last):
  File "C:\Users\Muhammad Umer\AppData\Local\Programs\Python\Python311\Lib\site-packages\twisted\internet\defer.py", line 1065, in adapt
    extracted = result.result()
                ^^^^^^^^^^^^^^^
  File "C:\Users\Muhammad Umer\AppData\Local\Programs\Python\Python311\Lib\site-packages\asgiref\sync.py", line 448, in __call__
    ret = await asyncio.wait_for(future, timeout=None)
          ^^^^^^^^^^^^^^^^^^^^^^^^^^^^^^^^^^^^^^^^^^^^
  File "C:\Users\Muhammad Umer\AppData\Local\Programs\Python\Python311\Lib\asyncio\tasks.py", line 442, in wait_for
    return await fut
           ^^^^^^^^^
  File "C:\Users\Muhammad Umer\AppData\Local\Programs\Python\Python311\Lib\concurrent\futures\thread.py", line 58, in run
    result = self.fn(*self.args, **self.kwargs)
             ^^^^^^^^^^^^^^^^^^^^^^^^^^^^^^^^^^
  File "C:\Users\Muhammad Umer\AppData\Local\Programs\Python\Python311\Lib\site-packages\asgiref\sync.py", line 490, in thread_handler
    return func(*args, **kwargs)
           ^^^^^^^^^^^^^^^^^^^^^
  File "D:\Outputs\Django Outputs\scraper\pipelines.py", line 44, in process_item
    Result.objects.create(
  File "C:\Users\Muhammad Umer\AppData\Local\Programs\Python\Python311\Lib\site-packages\django\db\models\manager.py", line 85, in manager_method
    return getattr(self.get_queryset(), name)(*args, **kwargs)
           ^^^^^^^^^^^^^^^^^^^^^^^^^^^^^^^^^^^^^^^^^^^^^^^^^^^
  File "C:\Users\Muhammad Umer\AppData\Local\Programs\Python\Python311\Lib\site-packages\django\db\models\query.py", line 669, in create
    obj = self.model(**kwargs)
          ^^^^^^^^^^^^^^^^^^^^
  File "C:\Users\Muhammad Umer\AppData\Local\Programs\Python\Python311\Lib\site-packages\django\db\models\base.py", line 541, in __init__
    _setattr(self, field.name, rel_obj)
  File "C:\Users\Muhammad Umer\AppData\Local\Programs\Python\Python311\Lib\site-packages\django\db\models\fields\related_descriptors.py", line 237, in __set__
    raise ValueError(
ValueError: Cannot assign "' ps5'": "Result.keyword" must be a "Keyword" instance.
2023-09-08 08:01:31 [scrapy] ERROR: Error processing {'country': 'DK',
 'keyword': ' ps5',
 'position': 7,
 'price': '3.792,00\xa0kr.',
 'product_url': 'https://www.elgiganten.dk/product/outlet/playstation-5-2022/555353',
 'title': 'PlayStation 5 (2022)',
 'url': 'elgiganten.dk',
 'user_id': 'admin'}
Traceback (most recent call last):
  File "D:\Outputs\Django Outputs\scraper\pipelines.py", line 37, in process_item
    res = Result.objects.get(
          ^^^^^^^^^^^^^^^^^^^
  File "C:\Users\Muhammad Umer\AppData\Local\Programs\Python\Python311\Lib\site-packages\django\db\models\manager.py", line 85, in manager_method
    return getattr(self.get_queryset(), name)(*args, **kwargs)
           ^^^^^^^^^^^^^^^^^^^^^^^^^^^^^^^^^^^^^^^^^^^^^^^^^^^
  File "C:\Users\Muhammad Umer\AppData\Local\Programs\Python\Python311\Lib\site-packages\django\db\models\query.py", line 650, in get
    raise self.model.DoesNotExist(
search.models.Result.DoesNotExist: Result matching query does not exist.

During handling of the above exception, another exception occurred:

Traceback (most recent call last):
  File "C:\Users\Muhammad Umer\AppData\Local\Programs\Python\Python311\Lib\site-packages\twisted\internet\defer.py", line 1065, in adapt
    extracted = result.result()
                ^^^^^^^^^^^^^^^
  File "C:\Users\Muhammad Umer\AppData\Local\Programs\Python\Python311\Lib\site-packages\asgiref\sync.py", line 448, in __call__
    ret = await asyncio.wait_for(future, timeout=None)
          ^^^^^^^^^^^^^^^^^^^^^^^^^^^^^^^^^^^^^^^^^^^^
  File "C:\Users\Muhammad Umer\AppData\Local\Programs\Python\Python311\Lib\asyncio\tasks.py", line 442, in wait_for
    return await fut
           ^^^^^^^^^
  File "C:\Users\Muhammad Umer\AppData\Local\Programs\Python\Python311\Lib\concurrent\futures\thread.py", line 58, in run
    result = self.fn(*self.args, **self.kwargs)
             ^^^^^^^^^^^^^^^^^^^^^^^^^^^^^^^^^^
  File "C:\Users\Muhammad Umer\AppData\Local\Programs\Python\Python311\Lib\site-packages\asgiref\sync.py", line 490, in thread_handler
    return func(*args, **kwargs)
           ^^^^^^^^^^^^^^^^^^^^^
  File "D:\Outputs\Django Outputs\scraper\pipelines.py", line 44, in process_item
    Result.objects.create(
  File "C:\Users\Muhammad Umer\AppData\Local\Programs\Python\Python311\Lib\site-packages\django\db\models\manager.py", line 85, in manager_method
    return getattr(self.get_queryset(), name)(*args, **kwargs)
           ^^^^^^^^^^^^^^^^^^^^^^^^^^^^^^^^^^^^^^^^^^^^^^^^^^^
  File "C:\Users\Muhammad Umer\AppData\Local\Programs\Python\Python311\Lib\site-packages\django\db\models\query.py", line 669, in create
    obj = self.model(**kwargs)
          ^^^^^^^^^^^^^^^^^^^^
  File "C:\Users\Muhammad Umer\AppData\Local\Programs\Python\Python311\Lib\site-packages\django\db\models\base.py", line 541, in __init__
    _setattr(self, field.name, rel_obj)
  File "C:\Users\Muhammad Umer\AppData\Local\Programs\Python\Python311\Lib\site-packages\django\db\models\fields\related_descriptors.py", line 237, in __set__
    raise ValueError(
ValueError: Cannot assign "' ps5'": "Result.keyword" must be a "Keyword" instance.
2023-09-08 08:01:31 [scrapy] ERROR: Error processing {'country': 'DK',
 'keyword': ' ps5',
 'position': 8,
 'price': '3.999,00\xa0kr.',
 'product_url': 'https://www.foetex.dk/produkter/ps5-digital-inkl-god-of-war/200169973/',
 'title': '"PS5 Digital inkl. God of War"',
 'url': 'foetex.dk',
 'user_id': 'admin'}
Traceback (most recent call last):
  File "D:\Outputs\Django Outputs\scraper\pipelines.py", line 37, in process_item
    res = Result.objects.get(
          ^^^^^^^^^^^^^^^^^^^
  File "C:\Users\Muhammad Umer\AppData\Local\Programs\Python\Python311\Lib\site-packages\django\db\models\manager.py", line 85, in manager_method
    return getattr(self.get_queryset(), name)(*args, **kwargs)
           ^^^^^^^^^^^^^^^^^^^^^^^^^^^^^^^^^^^^^^^^^^^^^^^^^^^
  File "C:\Users\Muhammad Umer\AppData\Local\Programs\Python\Python311\Lib\site-packages\django\db\models\query.py", line 650, in get
    raise self.model.DoesNotExist(
search.models.Result.DoesNotExist: Result matching query does not exist.

During handling of the above exception, another exception occurred:

Traceback (most recent call last):
  File "C:\Users\Muhammad Umer\AppData\Local\Programs\Python\Python311\Lib\site-packages\twisted\internet\defer.py", line 1065, in adapt
    extracted = result.result()
                ^^^^^^^^^^^^^^^
  File "C:\Users\Muhammad Umer\AppData\Local\Programs\Python\Python311\Lib\site-packages\asgiref\sync.py", line 448, in __call__
    ret = await asyncio.wait_for(future, timeout=None)
          ^^^^^^^^^^^^^^^^^^^^^^^^^^^^^^^^^^^^^^^^^^^^
  File "C:\Users\Muhammad Umer\AppData\Local\Programs\Python\Python311\Lib\asyncio\tasks.py", line 442, in wait_for
    return await fut
           ^^^^^^^^^
  File "C:\Users\Muhammad Umer\AppData\Local\Programs\Python\Python311\Lib\concurrent\futures\thread.py", line 58, in run
    result = self.fn(*self.args, **self.kwargs)
             ^^^^^^^^^^^^^^^^^^^^^^^^^^^^^^^^^^
  File "C:\Users\Muhammad Umer\AppData\Local\Programs\Python\Python311\Lib\site-packages\asgiref\sync.py", line 490, in thread_handler
    return func(*args, **kwargs)
           ^^^^^^^^^^^^^^^^^^^^^
  File "D:\Outputs\Django Outputs\scraper\pipelines.py", line 44, in process_item
    Result.objects.create(
  File "C:\Users\Muhammad Umer\AppData\Local\Programs\Python\Python311\Lib\site-packages\django\db\models\manager.py", line 85, in manager_method
    return getattr(self.get_queryset(), name)(*args, **kwargs)
           ^^^^^^^^^^^^^^^^^^^^^^^^^^^^^^^^^^^^^^^^^^^^^^^^^^^
  File "C:\Users\Muhammad Umer\AppData\Local\Programs\Python\Python311\Lib\site-packages\django\db\models\query.py", line 669, in create
    obj = self.model(**kwargs)
          ^^^^^^^^^^^^^^^^^^^^
  File "C:\Users\Muhammad Umer\AppData\Local\Programs\Python\Python311\Lib\site-packages\django\db\models\base.py", line 541, in __init__
    _setattr(self, field.name, rel_obj)
  File "C:\Users\Muhammad Umer\AppData\Local\Programs\Python\Python311\Lib\site-packages\django\db\models\fields\related_descriptors.py", line 237, in __set__
    raise ValueError(
ValueError: Cannot assign "' ps5'": "Result.keyword" must be a "Keyword" instance.
2023-09-08 08:01:31 [scrapy] ERROR: Error processing {'country': 'DK',
 'keyword': ' ps5',
 'position': 9,
 'price': '4.359,00\xa0kr.',
 'product_url': 'https://www.power.dk/gaming-og-underholdning/playstation/playstation-konsoller/playstation-5/p-1840111/',
 'title': 'PLAYSTATION 5',
 'url': 'power.dk',
 'user_id': 'admin'}
Traceback (most recent call last):
  File "D:\Outputs\Django Outputs\scraper\pipelines.py", line 37, in process_item
    res = Result.objects.get(
          ^^^^^^^^^^^^^^^^^^^
  File "C:\Users\Muhammad Umer\AppData\Local\Programs\Python\Python311\Lib\site-packages\django\db\models\manager.py", line 85, in manager_method
    return getattr(self.get_queryset(), name)(*args, **kwargs)
           ^^^^^^^^^^^^^^^^^^^^^^^^^^^^^^^^^^^^^^^^^^^^^^^^^^^
  File "C:\Users\Muhammad Umer\AppData\Local\Programs\Python\Python311\Lib\site-packages\django\db\models\query.py", line 650, in get
    raise self.model.DoesNotExist(
search.models.Result.DoesNotExist: Result matching query does not exist.

During handling of the above exception, another exception occurred:

Traceback (most recent call last):
  File "C:\Users\Muhammad Umer\AppData\Local\Programs\Python\Python311\Lib\site-packages\twisted\internet\defer.py", line 1065, in adapt
    extracted = result.result()
                ^^^^^^^^^^^^^^^
  File "C:\Users\Muhammad Umer\AppData\Local\Programs\Python\Python311\Lib\site-packages\asgiref\sync.py", line 448, in __call__
    ret = await asyncio.wait_for(future, timeout=None)
          ^^^^^^^^^^^^^^^^^^^^^^^^^^^^^^^^^^^^^^^^^^^^
  File "C:\Users\Muhammad Umer\AppData\Local\Programs\Python\Python311\Lib\asyncio\tasks.py", line 442, in wait_for
    return await fut
           ^^^^^^^^^
  File "C:\Users\Muhammad Umer\AppData\Local\Programs\Python\Python311\Lib\concurrent\futures\thread.py", line 58, in run
    result = self.fn(*self.args, **self.kwargs)
             ^^^^^^^^^^^^^^^^^^^^^^^^^^^^^^^^^^
  File "C:\Users\Muhammad Umer\AppData\Local\Programs\Python\Python311\Lib\site-packages\asgiref\sync.py", line 490, in thread_handler
    return func(*args, **kwargs)
           ^^^^^^^^^^^^^^^^^^^^^
  File "D:\Outputs\Django Outputs\scraper\pipelines.py", line 44, in process_item
    Result.objects.create(
  File "C:\Users\Muhammad Umer\AppData\Local\Programs\Python\Python311\Lib\site-packages\django\db\models\manager.py", line 85, in manager_method
    return getattr(self.get_queryset(), name)(*args, **kwargs)
           ^^^^^^^^^^^^^^^^^^^^^^^^^^^^^^^^^^^^^^^^^^^^^^^^^^^
  File "C:\Users\Muhammad Umer\AppData\Local\Programs\Python\Python311\Lib\site-packages\django\db\models\query.py", line 669, in create
    obj = self.model(**kwargs)
          ^^^^^^^^^^^^^^^^^^^^
  File "C:\Users\Muhammad Umer\AppData\Local\Programs\Python\Python311\Lib\site-packages\django\db\models\base.py", line 541, in __init__
    _setattr(self, field.name, rel_obj)
  File "C:\Users\Muhammad Umer\AppData\Local\Programs\Python\Python311\Lib\site-packages\django\db\models\fields\related_descriptors.py", line 237, in __set__
    raise ValueError(
ValueError: Cannot assign "' ps5'": "Result.keyword" must be a "Keyword" instance.
2023-09-08 08:01:31 [scrapy] ERROR: Error processing {'country': 'DK',
 'keyword': ' ps5',
 'position': 10,
 'price': '3.899,00\xa0kr.',
 'product_url': 'https://www.komplett.dk/product/1161553/gaming/playstation/playstation-5-digital-edition-ps5?channable=0095b76964003131363135353374',
 'title': 'PlayStation 5 Digital Edition / PS5',
 'url': 'komplett.dk',
 'user_id': 'admin'}
Traceback (most recent call last):
  File "D:\Outputs\Django Outputs\scraper\pipelines.py", line 37, in process_item
    res = Result.objects.get(
          ^^^^^^^^^^^^^^^^^^^
  File "C:\Users\Muhammad Umer\AppData\Local\Programs\Python\Python311\Lib\site-packages\django\db\models\manager.py", line 85, in manager_method
    return getattr(self.get_queryset(), name)(*args, **kwargs)
           ^^^^^^^^^^^^^^^^^^^^^^^^^^^^^^^^^^^^^^^^^^^^^^^^^^^
  File "C:\Users\Muhammad Umer\AppData\Local\Programs\Python\Python311\Lib\site-packages\django\db\models\query.py", line 650, in get
    raise self.model.DoesNotExist(
search.models.Result.DoesNotExist: Result matching query does not exist.

During handling of the above exception, another exception occurred:

Traceback (most recent call last):
  File "C:\Users\Muhammad Umer\AppData\Local\Programs\Python\Python311\Lib\site-packages\twisted\internet\defer.py", line 1065, in adapt
    extracted = result.result()
                ^^^^^^^^^^^^^^^
  File "C:\Users\Muhammad Umer\AppData\Local\Programs\Python\Python311\Lib\site-packages\asgiref\sync.py", line 448, in __call__
    ret = await asyncio.wait_for(future, timeout=None)
          ^^^^^^^^^^^^^^^^^^^^^^^^^^^^^^^^^^^^^^^^^^^^
  File "C:\Users\Muhammad Umer\AppData\Local\Programs\Python\Python311\Lib\asyncio\tasks.py", line 442, in wait_for
    return await fut
           ^^^^^^^^^
  File "C:\Users\Muhammad Umer\AppData\Local\Programs\Python\Python311\Lib\concurrent\futures\thread.py", line 58, in run
    result = self.fn(*self.args, **self.kwargs)
             ^^^^^^^^^^^^^^^^^^^^^^^^^^^^^^^^^^
  File "C:\Users\Muhammad Umer\AppData\Local\Programs\Python\Python311\Lib\site-packages\asgiref\sync.py", line 490, in thread_handler
    return func(*args, **kwargs)
           ^^^^^^^^^^^^^^^^^^^^^
  File "D:\Outputs\Django Outputs\scraper\pipelines.py", line 44, in process_item
    Result.objects.create(
  File "C:\Users\Muhammad Umer\AppData\Local\Programs\Python\Python311\Lib\site-packages\django\db\models\manager.py", line 85, in manager_method
    return getattr(self.get_queryset(), name)(*args, **kwargs)
           ^^^^^^^^^^^^^^^^^^^^^^^^^^^^^^^^^^^^^^^^^^^^^^^^^^^
  File "C:\Users\Muhammad Umer\AppData\Local\Programs\Python\Python311\Lib\site-packages\django\db\models\query.py", line 669, in create
    obj = self.model(**kwargs)
          ^^^^^^^^^^^^^^^^^^^^
  File "C:\Users\Muhammad Umer\AppData\Local\Programs\Python\Python311\Lib\site-packages\django\db\models\base.py", line 541, in __init__
    _setattr(self, field.name, rel_obj)
  File "C:\Users\Muhammad Umer\AppData\Local\Programs\Python\Python311\Lib\site-packages\django\db\models\fields\related_descriptors.py", line 237, in __set__
    raise ValueError(
ValueError: Cannot assign "' ps5'": "Result.keyword" must be a "Keyword" instance.
2023-09-08 08:01:31 [scrapy] ERROR: Error processing {'country': 'DK',
 'keyword': ' ps5',
 'position': 11,
 'price': '4.348,00\xa0kr.',
 'product_url': 'https://www.proshop.dk/Spillekonsol/Sony-PlayStation-5-Nordic/2831713?utm_source=google&utm_medium=cpc&utm_campaign=searchengine',
 'title': 'Sony PlayStation 5 (Nordic)',
 'url': 'proshop.dk',
 'user_id': 'admin'}
Traceback (most recent call last):
  File "D:\Outputs\Django Outputs\scraper\pipelines.py", line 37, in process_item
    res = Result.objects.get(
          ^^^^^^^^^^^^^^^^^^^
  File "C:\Users\Muhammad Umer\AppData\Local\Programs\Python\Python311\Lib\site-packages\django\db\models\manager.py", line 85, in manager_method
    return getattr(self.get_queryset(), name)(*args, **kwargs)
           ^^^^^^^^^^^^^^^^^^^^^^^^^^^^^^^^^^^^^^^^^^^^^^^^^^^
  File "C:\Users\Muhammad Umer\AppData\Local\Programs\Python\Python311\Lib\site-packages\django\db\models\query.py", line 650, in get
    raise self.model.DoesNotExist(
search.models.Result.DoesNotExist: Result matching query does not exist.

During handling of the above exception, another exception occurred:

Traceback (most recent call last):
  File "C:\Users\Muhammad Umer\AppData\Local\Programs\Python\Python311\Lib\site-packages\twisted\internet\defer.py", line 1065, in adapt
    extracted = result.result()
                ^^^^^^^^^^^^^^^
  File "C:\Users\Muhammad Umer\AppData\Local\Programs\Python\Python311\Lib\site-packages\asgiref\sync.py", line 448, in __call__
    ret = await asyncio.wait_for(future, timeout=None)
          ^^^^^^^^^^^^^^^^^^^^^^^^^^^^^^^^^^^^^^^^^^^^
  File "C:\Users\Muhammad Umer\AppData\Local\Programs\Python\Python311\Lib\asyncio\tasks.py", line 442, in wait_for
    return await fut
           ^^^^^^^^^
  File "C:\Users\Muhammad Umer\AppData\Local\Programs\Python\Python311\Lib\concurrent\futures\thread.py", line 58, in run
    result = self.fn(*self.args, **self.kwargs)
             ^^^^^^^^^^^^^^^^^^^^^^^^^^^^^^^^^^
  File "C:\Users\Muhammad Umer\AppData\Local\Programs\Python\Python311\Lib\site-packages\asgiref\sync.py", line 490, in thread_handler
    return func(*args, **kwargs)
           ^^^^^^^^^^^^^^^^^^^^^
  File "D:\Outputs\Django Outputs\scraper\pipelines.py", line 44, in process_item
    Result.objects.create(
  File "C:\Users\Muhammad Umer\AppData\Local\Programs\Python\Python311\Lib\site-packages\django\db\models\manager.py", line 85, in manager_method
    return getattr(self.get_queryset(), name)(*args, **kwargs)
           ^^^^^^^^^^^^^^^^^^^^^^^^^^^^^^^^^^^^^^^^^^^^^^^^^^^
  File "C:\Users\Muhammad Umer\AppData\Local\Programs\Python\Python311\Lib\site-packages\django\db\models\query.py", line 669, in create
    obj = self.model(**kwargs)
          ^^^^^^^^^^^^^^^^^^^^
  File "C:\Users\Muhammad Umer\AppData\Local\Programs\Python\Python311\Lib\site-packages\django\db\models\base.py", line 541, in __init__
    _setattr(self, field.name, rel_obj)
  File "C:\Users\Muhammad Umer\AppData\Local\Programs\Python\Python311\Lib\site-packages\django\db\models\fields\related_descriptors.py", line 237, in __set__
    raise ValueError(
ValueError: Cannot assign "' ps5'": "Result.keyword" must be a "Keyword" instance.
2023-09-08 08:01:31 [scrapy] ERROR: Error processing {'country': 'DK',
 'keyword': ' ps5',
 'position': 12,
 'price': '4.991,00\xa0kr.',
 'product_url': 'https://www.elgiganten.dk/product/gaming/spillekonsol-tilbehor/playstation/playstation-spillekonsol/playstation-5-2x-dualsense-controller-pakke/581993',
 'title': 'PlayStation 5 + 2x DualSense controller-pakke',
 'url': 'elgiganten.dk',
 'user_id': 'admin'}
Traceback (most recent call last):
  File "D:\Outputs\Django Outputs\scraper\pipelines.py", line 37, in process_item
    res = Result.objects.get(
          ^^^^^^^^^^^^^^^^^^^
  File "C:\Users\Muhammad Umer\AppData\Local\Programs\Python\Python311\Lib\site-packages\django\db\models\manager.py", line 85, in manager_method
    return getattr(self.get_queryset(), name)(*args, **kwargs)
           ^^^^^^^^^^^^^^^^^^^^^^^^^^^^^^^^^^^^^^^^^^^^^^^^^^^
  File "C:\Users\Muhammad Umer\AppData\Local\Programs\Python\Python311\Lib\site-packages\django\db\models\query.py", line 650, in get
    raise self.model.DoesNotExist(
search.models.Result.DoesNotExist: Result matching query does not exist.

During handling of the above exception, another exception occurred:

Traceback (most recent call last):
  File "C:\Users\Muhammad Umer\AppData\Local\Programs\Python\Python311\Lib\site-packages\twisted\internet\defer.py", line 1065, in adapt
    extracted = result.result()
                ^^^^^^^^^^^^^^^
  File "C:\Users\Muhammad Umer\AppData\Local\Programs\Python\Python311\Lib\site-packages\asgiref\sync.py", line 448, in __call__
    ret = await asyncio.wait_for(future, timeout=None)
          ^^^^^^^^^^^^^^^^^^^^^^^^^^^^^^^^^^^^^^^^^^^^
  File "C:\Users\Muhammad Umer\AppData\Local\Programs\Python\Python311\Lib\asyncio\tasks.py", line 442, in wait_for
    return await fut
           ^^^^^^^^^
  File "C:\Users\Muhammad Umer\AppData\Local\Programs\Python\Python311\Lib\concurrent\futures\thread.py", line 58, in run
    result = self.fn(*self.args, **self.kwargs)
             ^^^^^^^^^^^^^^^^^^^^^^^^^^^^^^^^^^
  File "C:\Users\Muhammad Umer\AppData\Local\Programs\Python\Python311\Lib\site-packages\asgiref\sync.py", line 490, in thread_handler
    return func(*args, **kwargs)
           ^^^^^^^^^^^^^^^^^^^^^
  File "D:\Outputs\Django Outputs\scraper\pipelines.py", line 44, in process_item
    Result.objects.create(
  File "C:\Users\Muhammad Umer\AppData\Local\Programs\Python\Python311\Lib\site-packages\django\db\models\manager.py", line 85, in manager_method
    return getattr(self.get_queryset(), name)(*args, **kwargs)
           ^^^^^^^^^^^^^^^^^^^^^^^^^^^^^^^^^^^^^^^^^^^^^^^^^^^
  File "C:\Users\Muhammad Umer\AppData\Local\Programs\Python\Python311\Lib\site-packages\django\db\models\query.py", line 669, in create
    obj = self.model(**kwargs)
          ^^^^^^^^^^^^^^^^^^^^
  File "C:\Users\Muhammad Umer\AppData\Local\Programs\Python\Python311\Lib\site-packages\django\db\models\base.py", line 541, in __init__
    _setattr(self, field.name, rel_obj)
  File "C:\Users\Muhammad Umer\AppData\Local\Programs\Python\Python311\Lib\site-packages\django\db\models\fields\related_descriptors.py", line 237, in __set__
    raise ValueError(
ValueError: Cannot assign "' ps5'": "Result.keyword" must be a "Keyword" instance.
2023-09-08 08:01:31 [scrapy] ERROR: Error processing {'country': 'DK',
 'keyword': ' ps5',
 'position': 13,
 'price': '4.359,00\xa0kr.',
 'product_url': 'https://www.foetex.dk/produkter/ps5-standard-konsol/200169033/',
 'title': '"PS5 Standard Konsol"',
 'url': 'foetex.dk',
 'user_id': 'admin'}
Traceback (most recent call last):
  File "D:\Outputs\Django Outputs\scraper\pipelines.py", line 37, in process_item
    res = Result.objects.get(
          ^^^^^^^^^^^^^^^^^^^
  File "C:\Users\Muhammad Umer\AppData\Local\Programs\Python\Python311\Lib\site-packages\django\db\models\manager.py", line 85, in manager_method
    return getattr(self.get_queryset(), name)(*args, **kwargs)
           ^^^^^^^^^^^^^^^^^^^^^^^^^^^^^^^^^^^^^^^^^^^^^^^^^^^
  File "C:\Users\Muhammad Umer\AppData\Local\Programs\Python\Python311\Lib\site-packages\django\db\models\query.py", line 650, in get
    raise self.model.DoesNotExist(
search.models.Result.DoesNotExist: Result matching query does not exist.

During handling of the above exception, another exception occurred:

Traceback (most recent call last):
  File "C:\Users\Muhammad Umer\AppData\Local\Programs\Python\Python311\Lib\site-packages\twisted\internet\defer.py", line 1065, in adapt
    extracted = result.result()
                ^^^^^^^^^^^^^^^
  File "C:\Users\Muhammad Umer\AppData\Local\Programs\Python\Python311\Lib\site-packages\asgiref\sync.py", line 448, in __call__
    ret = await asyncio.wait_for(future, timeout=None)
          ^^^^^^^^^^^^^^^^^^^^^^^^^^^^^^^^^^^^^^^^^^^^
  File "C:\Users\Muhammad Umer\AppData\Local\Programs\Python\Python311\Lib\asyncio\tasks.py", line 442, in wait_for
    return await fut
           ^^^^^^^^^
  File "C:\Users\Muhammad Umer\AppData\Local\Programs\Python\Python311\Lib\concurrent\futures\thread.py", line 58, in run
    result = self.fn(*self.args, **self.kwargs)
             ^^^^^^^^^^^^^^^^^^^^^^^^^^^^^^^^^^
  File "C:\Users\Muhammad Umer\AppData\Local\Programs\Python\Python311\Lib\site-packages\asgiref\sync.py", line 490, in thread_handler
    return func(*args, **kwargs)
           ^^^^^^^^^^^^^^^^^^^^^
  File "D:\Outputs\Django Outputs\scraper\pipelines.py", line 44, in process_item
    Result.objects.create(
  File "C:\Users\Muhammad Umer\AppData\Local\Programs\Python\Python311\Lib\site-packages\django\db\models\manager.py", line 85, in manager_method
    return getattr(self.get_queryset(), name)(*args, **kwargs)
           ^^^^^^^^^^^^^^^^^^^^^^^^^^^^^^^^^^^^^^^^^^^^^^^^^^^
  File "C:\Users\Muhammad Umer\AppData\Local\Programs\Python\Python311\Lib\site-packages\django\db\models\query.py", line 669, in create
    obj = self.model(**kwargs)
          ^^^^^^^^^^^^^^^^^^^^
  File "C:\Users\Muhammad Umer\AppData\Local\Programs\Python\Python311\Lib\site-packages\django\db\models\base.py", line 541, in __init__
    _setattr(self, field.name, rel_obj)
  File "C:\Users\Muhammad Umer\AppData\Local\Programs\Python\Python311\Lib\site-packages\django\db\models\fields\related_descriptors.py", line 237, in __set__
    raise ValueError(
ValueError: Cannot assign "' ps5'": "Result.keyword" must be a "Keyword" instance.
2023-09-08 08:01:31 [scrapy] ERROR: Error processing {'country': 'DK',
 'keyword': ' ps5',
 'position': 14,
 'price': '5.199,00\xa0kr.',
 'product_url': 'https://www.elgiganten.dk/product/gaming/spillekonsol-tilbehor/playstation/playstation-spillekonsol/playstation-5-marvel-s-spider-man-2-limited-edition-pakke/645207',
 'title': 'PlayStation 5 + Marvel s Spider-Man 2 Limited Edition pakke',
 'url': 'elgiganten.dk',
 'user_id': 'admin'}
Traceback (most recent call last):
  File "D:\Outputs\Django Outputs\scraper\pipelines.py", line 37, in process_item
    res = Result.objects.get(
          ^^^^^^^^^^^^^^^^^^^
  File "C:\Users\Muhammad Umer\AppData\Local\Programs\Python\Python311\Lib\site-packages\django\db\models\manager.py", line 85, in manager_method
    return getattr(self.get_queryset(), name)(*args, **kwargs)
           ^^^^^^^^^^^^^^^^^^^^^^^^^^^^^^^^^^^^^^^^^^^^^^^^^^^
  File "C:\Users\Muhammad Umer\AppData\Local\Programs\Python\Python311\Lib\site-packages\django\db\models\query.py", line 650, in get
    raise self.model.DoesNotExist(
search.models.Result.DoesNotExist: Result matching query does not exist.

During handling of the above exception, another exception occurred:

Traceback (most recent call last):
  File "C:\Users\Muhammad Umer\AppData\Local\Programs\Python\Python311\Lib\site-packages\twisted\internet\defer.py", line 1065, in adapt
    extracted = result.result()
                ^^^^^^^^^^^^^^^
  File "C:\Users\Muhammad Umer\AppData\Local\Programs\Python\Python311\Lib\site-packages\asgiref\sync.py", line 448, in __call__
    ret = await asyncio.wait_for(future, timeout=None)
          ^^^^^^^^^^^^^^^^^^^^^^^^^^^^^^^^^^^^^^^^^^^^
  File "C:\Users\Muhammad Umer\AppData\Local\Programs\Python\Python311\Lib\asyncio\tasks.py", line 442, in wait_for
    return await fut
           ^^^^^^^^^
  File "C:\Users\Muhammad Umer\AppData\Local\Programs\Python\Python311\Lib\concurrent\futures\thread.py", line 58, in run
    result = self.fn(*self.args, **self.kwargs)
             ^^^^^^^^^^^^^^^^^^^^^^^^^^^^^^^^^^
  File "C:\Users\Muhammad Umer\AppData\Local\Programs\Python\Python311\Lib\site-packages\asgiref\sync.py", line 490, in thread_handler
    return func(*args, **kwargs)
           ^^^^^^^^^^^^^^^^^^^^^
  File "D:\Outputs\Django Outputs\scraper\pipelines.py", line 44, in process_item
    Result.objects.create(
  File "C:\Users\Muhammad Umer\AppData\Local\Programs\Python\Python311\Lib\site-packages\django\db\models\manager.py", line 85, in manager_method
    return getattr(self.get_queryset(), name)(*args, **kwargs)
           ^^^^^^^^^^^^^^^^^^^^^^^^^^^^^^^^^^^^^^^^^^^^^^^^^^^
  File "C:\Users\Muhammad Umer\AppData\Local\Programs\Python\Python311\Lib\site-packages\django\db\models\query.py", line 669, in create
    obj = self.model(**kwargs)
          ^^^^^^^^^^^^^^^^^^^^
  File "C:\Users\Muhammad Umer\AppData\Local\Programs\Python\Python311\Lib\site-packages\django\db\models\base.py", line 541, in __init__
    _setattr(self, field.name, rel_obj)
  File "C:\Users\Muhammad Umer\AppData\Local\Programs\Python\Python311\Lib\site-packages\django\db\models\fields\related_descriptors.py", line 237, in __set__
    raise ValueError(
ValueError: Cannot assign "' ps5'": "Result.keyword" must be a "Keyword" instance.
2023-09-08 08:01:31 [scrapy] ERROR: Error processing {'country': 'DK',
 'keyword': ' ps5',
 'position': 15,
 'price': '4.799,00\xa0kr.',
 'product_url': 'https://www.foetex.dk/produkter/ps5-standard-konsol-inkl-2-x-hvid-dualsense/200183008/',
 'title': '"PS5 Standard Konsol inkl. 2 x hvid Dualsense"',
 'url': 'foetex.dk',
 'user_id': 'admin'}
Traceback (most recent call last):
  File "D:\Outputs\Django Outputs\scraper\pipelines.py", line 37, in process_item
    res = Result.objects.get(
          ^^^^^^^^^^^^^^^^^^^
  File "C:\Users\Muhammad Umer\AppData\Local\Programs\Python\Python311\Lib\site-packages\django\db\models\manager.py", line 85, in manager_method
    return getattr(self.get_queryset(), name)(*args, **kwargs)
           ^^^^^^^^^^^^^^^^^^^^^^^^^^^^^^^^^^^^^^^^^^^^^^^^^^^
  File "C:\Users\Muhammad Umer\AppData\Local\Programs\Python\Python311\Lib\site-packages\django\db\models\query.py", line 650, in get
    raise self.model.DoesNotExist(
search.models.Result.DoesNotExist: Result matching query does not exist.

During handling of the above exception, another exception occurred:

Traceback (most recent call last):
  File "C:\Users\Muhammad Umer\AppData\Local\Programs\Python\Python311\Lib\site-packages\twisted\internet\defer.py", line 1065, in adapt
    extracted = result.result()
                ^^^^^^^^^^^^^^^
  File "C:\Users\Muhammad Umer\AppData\Local\Programs\Python\Python311\Lib\site-packages\asgiref\sync.py", line 448, in __call__
    ret = await asyncio.wait_for(future, timeout=None)
          ^^^^^^^^^^^^^^^^^^^^^^^^^^^^^^^^^^^^^^^^^^^^
  File "C:\Users\Muhammad Umer\AppData\Local\Programs\Python\Python311\Lib\asyncio\tasks.py", line 442, in wait_for
    return await fut
           ^^^^^^^^^
  File "C:\Users\Muhammad Umer\AppData\Local\Programs\Python\Python311\Lib\concurrent\futures\thread.py", line 58, in run
    result = self.fn(*self.args, **self.kwargs)
             ^^^^^^^^^^^^^^^^^^^^^^^^^^^^^^^^^^
  File "C:\Users\Muhammad Umer\AppData\Local\Programs\Python\Python311\Lib\site-packages\asgiref\sync.py", line 490, in thread_handler
    return func(*args, **kwargs)
           ^^^^^^^^^^^^^^^^^^^^^
  File "D:\Outputs\Django Outputs\scraper\pipelines.py", line 44, in process_item
    Result.objects.create(
  File "C:\Users\Muhammad Umer\AppData\Local\Programs\Python\Python311\Lib\site-packages\django\db\models\manager.py", line 85, in manager_method
    return getattr(self.get_queryset(), name)(*args, **kwargs)
           ^^^^^^^^^^^^^^^^^^^^^^^^^^^^^^^^^^^^^^^^^^^^^^^^^^^
  File "C:\Users\Muhammad Umer\AppData\Local\Programs\Python\Python311\Lib\site-packages\django\db\models\query.py", line 669, in create
    obj = self.model(**kwargs)
          ^^^^^^^^^^^^^^^^^^^^
  File "C:\Users\Muhammad Umer\AppData\Local\Programs\Python\Python311\Lib\site-packages\django\db\models\base.py", line 541, in __init__
    _setattr(self, field.name, rel_obj)
  File "C:\Users\Muhammad Umer\AppData\Local\Programs\Python\Python311\Lib\site-packages\django\db\models\fields\related_descriptors.py", line 237, in __set__
    raise ValueError(
ValueError: Cannot assign "' ps5'": "Result.keyword" must be a "Keyword" instance.
2023-09-08 08:01:31 [scrapy] ERROR: Error processing {'country': 'DK',
 'keyword': ' ps5',
 'position': 16,
 'price': '3.999,00\xa0kr.',
 'product_url': 'https://www.bilka.dk/produkter/ps5-digital-inkl-god-of-war/200169973/',
 'title': 'PS5 Digital inkl. God of War',
 'url': 'bilka.dk',
 'user_id': 'admin'}
Traceback (most recent call last):
  File "D:\Outputs\Django Outputs\scraper\pipelines.py", line 37, in process_item
    res = Result.objects.get(
          ^^^^^^^^^^^^^^^^^^^
  File "C:\Users\Muhammad Umer\AppData\Local\Programs\Python\Python311\Lib\site-packages\django\db\models\manager.py", line 85, in manager_method
    return getattr(self.get_queryset(), name)(*args, **kwargs)
           ^^^^^^^^^^^^^^^^^^^^^^^^^^^^^^^^^^^^^^^^^^^^^^^^^^^
  File "C:\Users\Muhammad Umer\AppData\Local\Programs\Python\Python311\Lib\site-packages\django\db\models\query.py", line 650, in get
    raise self.model.DoesNotExist(
search.models.Result.DoesNotExist: Result matching query does not exist.

During handling of the above exception, another exception occurred:

Traceback (most recent call last):
  File "C:\Users\Muhammad Umer\AppData\Local\Programs\Python\Python311\Lib\site-packages\twisted\internet\defer.py", line 1065, in adapt
    extracted = result.result()
                ^^^^^^^^^^^^^^^
  File "C:\Users\Muhammad Umer\AppData\Local\Programs\Python\Python311\Lib\site-packages\asgiref\sync.py", line 448, in __call__
    ret = await asyncio.wait_for(future, timeout=None)
          ^^^^^^^^^^^^^^^^^^^^^^^^^^^^^^^^^^^^^^^^^^^^
  File "C:\Users\Muhammad Umer\AppData\Local\Programs\Python\Python311\Lib\asyncio\tasks.py", line 442, in wait_for
    return await fut
           ^^^^^^^^^
  File "C:\Users\Muhammad Umer\AppData\Local\Programs\Python\Python311\Lib\concurrent\futures\thread.py", line 58, in run
    result = self.fn(*self.args, **self.kwargs)
             ^^^^^^^^^^^^^^^^^^^^^^^^^^^^^^^^^^
  File "C:\Users\Muhammad Umer\AppData\Local\Programs\Python\Python311\Lib\site-packages\asgiref\sync.py", line 490, in thread_handler
    return func(*args, **kwargs)
           ^^^^^^^^^^^^^^^^^^^^^
  File "D:\Outputs\Django Outputs\scraper\pipelines.py", line 44, in process_item
    Result.objects.create(
  File "C:\Users\Muhammad Umer\AppData\Local\Programs\Python\Python311\Lib\site-packages\django\db\models\manager.py", line 85, in manager_method
    return getattr(self.get_queryset(), name)(*args, **kwargs)
           ^^^^^^^^^^^^^^^^^^^^^^^^^^^^^^^^^^^^^^^^^^^^^^^^^^^
  File "C:\Users\Muhammad Umer\AppData\Local\Programs\Python\Python311\Lib\site-packages\django\db\models\query.py", line 669, in create
    obj = self.model(**kwargs)
          ^^^^^^^^^^^^^^^^^^^^
  File "C:\Users\Muhammad Umer\AppData\Local\Programs\Python\Python311\Lib\site-packages\django\db\models\base.py", line 541, in __init__
    _setattr(self, field.name, rel_obj)
  File "C:\Users\Muhammad Umer\AppData\Local\Programs\Python\Python311\Lib\site-packages\django\db\models\fields\related_descriptors.py", line 237, in __set__
    raise ValueError(
ValueError: Cannot assign "' ps5'": "Result.keyword" must be a "Keyword" instance.
2023-09-08 08:01:31 [scrapy] ERROR: Error processing {'country': 'DK',
 'keyword': ' ps5',
 'position': 17,
 'price': '4.610,00\xa0kr.',
 'product_url': 'https://www.elgiganten.dk/product/outlet/playstation-5-god-of-war-ragnarok-pakke/575375',
 'title': 'PlayStation 5 + God of War Ragnarök pakke',
 'url': 'elgiganten.dk',
 'user_id': 'admin'}
Traceback (most recent call last):
  File "D:\Outputs\Django Outputs\scraper\pipelines.py", line 37, in process_item
    res = Result.objects.get(
          ^^^^^^^^^^^^^^^^^^^
  File "C:\Users\Muhammad Umer\AppData\Local\Programs\Python\Python311\Lib\site-packages\django\db\models\manager.py", line 85, in manager_method
    return getattr(self.get_queryset(), name)(*args, **kwargs)
           ^^^^^^^^^^^^^^^^^^^^^^^^^^^^^^^^^^^^^^^^^^^^^^^^^^^
  File "C:\Users\Muhammad Umer\AppData\Local\Programs\Python\Python311\Lib\site-packages\django\db\models\query.py", line 650, in get
    raise self.model.DoesNotExist(
search.models.Result.DoesNotExist: Result matching query does not exist.

During handling of the above exception, another exception occurred:

Traceback (most recent call last):
  File "C:\Users\Muhammad Umer\AppData\Local\Programs\Python\Python311\Lib\site-packages\twisted\internet\defer.py", line 1065, in adapt
    extracted = result.result()
                ^^^^^^^^^^^^^^^
  File "C:\Users\Muhammad Umer\AppData\Local\Programs\Python\Python311\Lib\site-packages\asgiref\sync.py", line 448, in __call__
    ret = await asyncio.wait_for(future, timeout=None)
          ^^^^^^^^^^^^^^^^^^^^^^^^^^^^^^^^^^^^^^^^^^^^
  File "C:\Users\Muhammad Umer\AppData\Local\Programs\Python\Python311\Lib\asyncio\tasks.py", line 442, in wait_for
    return await fut
           ^^^^^^^^^
  File "C:\Users\Muhammad Umer\AppData\Local\Programs\Python\Python311\Lib\concurrent\futures\thread.py", line 58, in run
    result = self.fn(*self.args, **self.kwargs)
             ^^^^^^^^^^^^^^^^^^^^^^^^^^^^^^^^^^
  File "C:\Users\Muhammad Umer\AppData\Local\Programs\Python\Python311\Lib\site-packages\asgiref\sync.py", line 490, in thread_handler
    return func(*args, **kwargs)
           ^^^^^^^^^^^^^^^^^^^^^
  File "D:\Outputs\Django Outputs\scraper\pipelines.py", line 44, in process_item
    Result.objects.create(
  File "C:\Users\Muhammad Umer\AppData\Local\Programs\Python\Python311\Lib\site-packages\django\db\models\manager.py", line 85, in manager_method
    return getattr(self.get_queryset(), name)(*args, **kwargs)
           ^^^^^^^^^^^^^^^^^^^^^^^^^^^^^^^^^^^^^^^^^^^^^^^^^^^
  File "C:\Users\Muhammad Umer\AppData\Local\Programs\Python\Python311\Lib\site-packages\django\db\models\query.py", line 669, in create
    obj = self.model(**kwargs)
          ^^^^^^^^^^^^^^^^^^^^
  File "C:\Users\Muhammad Umer\AppData\Local\Programs\Python\Python311\Lib\site-packages\django\db\models\base.py", line 541, in __init__
    _setattr(self, field.name, rel_obj)
  File "C:\Users\Muhammad Umer\AppData\Local\Programs\Python\Python311\Lib\site-packages\django\db\models\fields\related_descriptors.py", line 237, in __set__
    raise ValueError(
ValueError: Cannot assign "' ps5'": "Result.keyword" must be a "Keyword" instance.
2023-09-08 08:01:31 [scrapy] ERROR: Error processing {'country': 'DK',
 'keyword': ' ps5',
 'position': 18,
 'price': None,
 'product_url': None,
 'title': None,
 'url': '',
 'user_id': 'admin'}
Traceback (most recent call last):
  File "D:\Outputs\Django Outputs\scraper\pipelines.py", line 37, in process_item
    res = Result.objects.get(
          ^^^^^^^^^^^^^^^^^^^
  File "C:\Users\Muhammad Umer\AppData\Local\Programs\Python\Python311\Lib\site-packages\django\db\models\manager.py", line 85, in manager_method
    return getattr(self.get_queryset(), name)(*args, **kwargs)
           ^^^^^^^^^^^^^^^^^^^^^^^^^^^^^^^^^^^^^^^^^^^^^^^^^^^
  File "C:\Users\Muhammad Umer\AppData\Local\Programs\Python\Python311\Lib\site-packages\django\db\models\query.py", line 650, in get
    raise self.model.DoesNotExist(
search.models.Result.DoesNotExist: Result matching query does not exist.

During handling of the above exception, another exception occurred:

Traceback (most recent call last):
  File "C:\Users\Muhammad Umer\AppData\Local\Programs\Python\Python311\Lib\site-packages\twisted\internet\defer.py", line 1065, in adapt
    extracted = result.result()
                ^^^^^^^^^^^^^^^
  File "C:\Users\Muhammad Umer\AppData\Local\Programs\Python\Python311\Lib\site-packages\asgiref\sync.py", line 448, in __call__
    ret = await asyncio.wait_for(future, timeout=None)
          ^^^^^^^^^^^^^^^^^^^^^^^^^^^^^^^^^^^^^^^^^^^^
  File "C:\Users\Muhammad Umer\AppData\Local\Programs\Python\Python311\Lib\asyncio\tasks.py", line 442, in wait_for
    return await fut
           ^^^^^^^^^
  File "C:\Users\Muhammad Umer\AppData\Local\Programs\Python\Python311\Lib\concurrent\futures\thread.py", line 58, in run
    result = self.fn(*self.args, **self.kwargs)
             ^^^^^^^^^^^^^^^^^^^^^^^^^^^^^^^^^^
  File "C:\Users\Muhammad Umer\AppData\Local\Programs\Python\Python311\Lib\site-packages\asgiref\sync.py", line 490, in thread_handler
    return func(*args, **kwargs)
           ^^^^^^^^^^^^^^^^^^^^^
  File "D:\Outputs\Django Outputs\scraper\pipelines.py", line 44, in process_item
    Result.objects.create(
  File "C:\Users\Muhammad Umer\AppData\Local\Programs\Python\Python311\Lib\site-packages\django\db\models\manager.py", line 85, in manager_method
    return getattr(self.get_queryset(), name)(*args, **kwargs)
           ^^^^^^^^^^^^^^^^^^^^^^^^^^^^^^^^^^^^^^^^^^^^^^^^^^^
  File "C:\Users\Muhammad Umer\AppData\Local\Programs\Python\Python311\Lib\site-packages\django\db\models\query.py", line 669, in create
    obj = self.model(**kwargs)
          ^^^^^^^^^^^^^^^^^^^^
  File "C:\Users\Muhammad Umer\AppData\Local\Programs\Python\Python311\Lib\site-packages\django\db\models\base.py", line 541, in __init__
    _setattr(self, field.name, rel_obj)
  File "C:\Users\Muhammad Umer\AppData\Local\Programs\Python\Python311\Lib\site-packages\django\db\models\fields\related_descriptors.py", line 237, in __set__
    raise ValueError(
ValueError: Cannot assign "' ps5'": "Result.keyword" must be a "Keyword" instance.
2023-09-08 08:01:31 [scrapy] ERROR: Error processing {'country': 'DK',
 'keyword': 'iphone 14',
 'position': 1,
 'price': '6.666,00\xa0kr.',
 'product_url': 'https://www.power.dk/mobil-og-foto/mobiltelefoner/apple-iphone-14-128-gb-midnat/p-1803962/',
 'title': 'APPLE IPHONE 14 128 GB MIDNAT',
 'url': 'power.dk',
 'user_id': 'admin'}
Traceback (most recent call last):
  File "D:\Outputs\Django Outputs\scraper\pipelines.py", line 37, in process_item
    res = Result.objects.get(
          ^^^^^^^^^^^^^^^^^^^
  File "C:\Users\Muhammad Umer\AppData\Local\Programs\Python\Python311\Lib\site-packages\django\db\models\manager.py", line 85, in manager_method
    return getattr(self.get_queryset(), name)(*args, **kwargs)
           ^^^^^^^^^^^^^^^^^^^^^^^^^^^^^^^^^^^^^^^^^^^^^^^^^^^
  File "C:\Users\Muhammad Umer\AppData\Local\Programs\Python\Python311\Lib\site-packages\django\db\models\query.py", line 650, in get
    raise self.model.DoesNotExist(
search.models.Result.DoesNotExist: Result matching query does not exist.

During handling of the above exception, another exception occurred:

Traceback (most recent call last):
  File "C:\Users\Muhammad Umer\AppData\Local\Programs\Python\Python311\Lib\site-packages\twisted\internet\defer.py", line 1065, in adapt
    extracted = result.result()
                ^^^^^^^^^^^^^^^
  File "C:\Users\Muhammad Umer\AppData\Local\Programs\Python\Python311\Lib\site-packages\asgiref\sync.py", line 448, in __call__
    ret = await asyncio.wait_for(future, timeout=None)
          ^^^^^^^^^^^^^^^^^^^^^^^^^^^^^^^^^^^^^^^^^^^^
  File "C:\Users\Muhammad Umer\AppData\Local\Programs\Python\Python311\Lib\asyncio\tasks.py", line 442, in wait_for
    return await fut
           ^^^^^^^^^
  File "C:\Users\Muhammad Umer\AppData\Local\Programs\Python\Python311\Lib\concurrent\futures\thread.py", line 58, in run
    result = self.fn(*self.args, **self.kwargs)
             ^^^^^^^^^^^^^^^^^^^^^^^^^^^^^^^^^^
  File "C:\Users\Muhammad Umer\AppData\Local\Programs\Python\Python311\Lib\site-packages\asgiref\sync.py", line 490, in thread_handler
    return func(*args, **kwargs)
           ^^^^^^^^^^^^^^^^^^^^^
  File "D:\Outputs\Django Outputs\scraper\pipelines.py", line 44, in process_item
    Result.objects.create(
  File "C:\Users\Muhammad Umer\AppData\Local\Programs\Python\Python311\Lib\site-packages\django\db\models\manager.py", line 85, in manager_method
    return getattr(self.get_queryset(), name)(*args, **kwargs)
           ^^^^^^^^^^^^^^^^^^^^^^^^^^^^^^^^^^^^^^^^^^^^^^^^^^^
  File "C:\Users\Muhammad Umer\AppData\Local\Programs\Python\Python311\Lib\site-packages\django\db\models\query.py", line 669, in create
    obj = self.model(**kwargs)
          ^^^^^^^^^^^^^^^^^^^^
  File "C:\Users\Muhammad Umer\AppData\Local\Programs\Python\Python311\Lib\site-packages\django\db\models\base.py", line 541, in __init__
    _setattr(self, field.name, rel_obj)
  File "C:\Users\Muhammad Umer\AppData\Local\Programs\Python\Python311\Lib\site-packages\django\db\models\fields\related_descriptors.py", line 237, in __set__
    raise ValueError(
ValueError: Cannot assign "'iphone 14'": "Result.keyword" must be a "Keyword" instance.
2023-09-08 08:01:31 [scrapy] ERROR: Error processing {'country': 'DK',
 'keyword': 'iphone 14',
 'position': 2,
 'price': '4.799,00\xa0kr.',
 'product_url': 'https://www.telenor.dk/shop/mobil/apple/iphone-13-128gb-green/?cycleCount=none',
 'title': 'Apple iPhone 13 - 128 GB - Grøn med abonnementsaftale. Mindstepris '
          '6613.00 Kr.',
 'url': 'telenor.dk',
 'user_id': 'admin'}
Traceback (most recent call last):
  File "D:\Outputs\Django Outputs\scraper\pipelines.py", line 37, in process_item
    res = Result.objects.get(
          ^^^^^^^^^^^^^^^^^^^
  File "C:\Users\Muhammad Umer\AppData\Local\Programs\Python\Python311\Lib\site-packages\django\db\models\manager.py", line 85, in manager_method
    return getattr(self.get_queryset(), name)(*args, **kwargs)
           ^^^^^^^^^^^^^^^^^^^^^^^^^^^^^^^^^^^^^^^^^^^^^^^^^^^
  File "C:\Users\Muhammad Umer\AppData\Local\Programs\Python\Python311\Lib\site-packages\django\db\models\query.py", line 650, in get
    raise self.model.DoesNotExist(
search.models.Result.DoesNotExist: Result matching query does not exist.

During handling of the above exception, another exception occurred:

Traceback (most recent call last):
  File "C:\Users\Muhammad Umer\AppData\Local\Programs\Python\Python311\Lib\site-packages\twisted\internet\defer.py", line 1065, in adapt
    extracted = result.result()
                ^^^^^^^^^^^^^^^
  File "C:\Users\Muhammad Umer\AppData\Local\Programs\Python\Python311\Lib\site-packages\asgiref\sync.py", line 448, in __call__
    ret = await asyncio.wait_for(future, timeout=None)
          ^^^^^^^^^^^^^^^^^^^^^^^^^^^^^^^^^^^^^^^^^^^^
  File "C:\Users\Muhammad Umer\AppData\Local\Programs\Python\Python311\Lib\asyncio\tasks.py", line 442, in wait_for
    return await fut
           ^^^^^^^^^
  File "C:\Users\Muhammad Umer\AppData\Local\Programs\Python\Python311\Lib\concurrent\futures\thread.py", line 58, in run
    result = self.fn(*self.args, **self.kwargs)
             ^^^^^^^^^^^^^^^^^^^^^^^^^^^^^^^^^^
  File "C:\Users\Muhammad Umer\AppData\Local\Programs\Python\Python311\Lib\site-packages\asgiref\sync.py", line 490, in thread_handler
    return func(*args, **kwargs)
           ^^^^^^^^^^^^^^^^^^^^^
  File "D:\Outputs\Django Outputs\scraper\pipelines.py", line 44, in process_item
    Result.objects.create(
  File "C:\Users\Muhammad Umer\AppData\Local\Programs\Python\Python311\Lib\site-packages\django\db\models\manager.py", line 85, in manager_method
    return getattr(self.get_queryset(), name)(*args, **kwargs)
           ^^^^^^^^^^^^^^^^^^^^^^^^^^^^^^^^^^^^^^^^^^^^^^^^^^^
  File "C:\Users\Muhammad Umer\AppData\Local\Programs\Python\Python311\Lib\site-packages\django\db\models\query.py", line 669, in create
    obj = self.model(**kwargs)
          ^^^^^^^^^^^^^^^^^^^^
  File "C:\Users\Muhammad Umer\AppData\Local\Programs\Python\Python311\Lib\site-packages\django\db\models\base.py", line 541, in __init__
    _setattr(self, field.name, rel_obj)
  File "C:\Users\Muhammad Umer\AppData\Local\Programs\Python\Python311\Lib\site-packages\django\db\models\fields\related_descriptors.py", line 237, in __set__
    raise ValueError(
ValueError: Cannot assign "'iphone 14'": "Result.keyword" must be a "Keyword" instance.
2023-09-08 08:01:31 [scrapy] ERROR: Error processing {'country': 'DK',
 'keyword': 'iphone 14',
 'position': 3,
 'price': '5.579,00\xa0kr.',
 'product_url': 'https://swappie.com/dk/iphone/iphone-14/iphone-14-128gb-bla-18/',
 'title': 'iPhone 14 128GB Blå Apple',
 'url': 'swappie.com',
 'user_id': 'admin'}
Traceback (most recent call last):
  File "D:\Outputs\Django Outputs\scraper\pipelines.py", line 37, in process_item
    res = Result.objects.get(
          ^^^^^^^^^^^^^^^^^^^
  File "C:\Users\Muhammad Umer\AppData\Local\Programs\Python\Python311\Lib\site-packages\django\db\models\manager.py", line 85, in manager_method
    return getattr(self.get_queryset(), name)(*args, **kwargs)
           ^^^^^^^^^^^^^^^^^^^^^^^^^^^^^^^^^^^^^^^^^^^^^^^^^^^
  File "C:\Users\Muhammad Umer\AppData\Local\Programs\Python\Python311\Lib\site-packages\django\db\models\query.py", line 650, in get
    raise self.model.DoesNotExist(
search.models.Result.DoesNotExist: Result matching query does not exist.

During handling of the above exception, another exception occurred:

Traceback (most recent call last):
  File "C:\Users\Muhammad Umer\AppData\Local\Programs\Python\Python311\Lib\site-packages\twisted\internet\defer.py", line 1065, in adapt
    extracted = result.result()
                ^^^^^^^^^^^^^^^
  File "C:\Users\Muhammad Umer\AppData\Local\Programs\Python\Python311\Lib\site-packages\asgiref\sync.py", line 448, in __call__
    ret = await asyncio.wait_for(future, timeout=None)
          ^^^^^^^^^^^^^^^^^^^^^^^^^^^^^^^^^^^^^^^^^^^^
  File "C:\Users\Muhammad Umer\AppData\Local\Programs\Python\Python311\Lib\asyncio\tasks.py", line 442, in wait_for
    return await fut
           ^^^^^^^^^
  File "C:\Users\Muhammad Umer\AppData\Local\Programs\Python\Python311\Lib\concurrent\futures\thread.py", line 58, in run
    result = self.fn(*self.args, **self.kwargs)
             ^^^^^^^^^^^^^^^^^^^^^^^^^^^^^^^^^^
  File "C:\Users\Muhammad Umer\AppData\Local\Programs\Python\Python311\Lib\site-packages\asgiref\sync.py", line 490, in thread_handler
    return func(*args, **kwargs)
           ^^^^^^^^^^^^^^^^^^^^^
  File "D:\Outputs\Django Outputs\scraper\pipelines.py", line 44, in process_item
    Result.objects.create(
  File "C:\Users\Muhammad Umer\AppData\Local\Programs\Python\Python311\Lib\site-packages\django\db\models\manager.py", line 85, in manager_method
    return getattr(self.get_queryset(), name)(*args, **kwargs)
           ^^^^^^^^^^^^^^^^^^^^^^^^^^^^^^^^^^^^^^^^^^^^^^^^^^^
  File "C:\Users\Muhammad Umer\AppData\Local\Programs\Python\Python311\Lib\site-packages\django\db\models\query.py", line 669, in create
    obj = self.model(**kwargs)
          ^^^^^^^^^^^^^^^^^^^^
  File "C:\Users\Muhammad Umer\AppData\Local\Programs\Python\Python311\Lib\site-packages\django\db\models\base.py", line 541, in __init__
    _setattr(self, field.name, rel_obj)
  File "C:\Users\Muhammad Umer\AppData\Local\Programs\Python\Python311\Lib\site-packages\django\db\models\fields\related_descriptors.py", line 237, in __set__
    raise ValueError(
ValueError: Cannot assign "'iphone 14'": "Result.keyword" must be a "Keyword" instance.
2023-09-08 08:01:31 [scrapy] ERROR: Error processing {'country': 'DK',
 'keyword': 'iphone 14',
 'position': 4,
 'price': '5.706,99\xa0kr.',
 'product_url': 'https://www.refurbed.dk/p/iphone-14/?co=dk&utm_cluster=gradeA&utm_content=iphone-14&utm_group=iphone-14',
 'title': 'iPhone 14',
 'url': 'refurbed.dk',
 'user_id': 'admin'}
Traceback (most recent call last):
  File "D:\Outputs\Django Outputs\scraper\pipelines.py", line 37, in process_item
    res = Result.objects.get(
          ^^^^^^^^^^^^^^^^^^^
  File "C:\Users\Muhammad Umer\AppData\Local\Programs\Python\Python311\Lib\site-packages\django\db\models\manager.py", line 85, in manager_method
    return getattr(self.get_queryset(), name)(*args, **kwargs)
           ^^^^^^^^^^^^^^^^^^^^^^^^^^^^^^^^^^^^^^^^^^^^^^^^^^^
  File "C:\Users\Muhammad Umer\AppData\Local\Programs\Python\Python311\Lib\site-packages\django\db\models\query.py", line 650, in get
    raise self.model.DoesNotExist(
search.models.Result.DoesNotExist: Result matching query does not exist.

During handling of the above exception, another exception occurred:

Traceback (most recent call last):
  File "C:\Users\Muhammad Umer\AppData\Local\Programs\Python\Python311\Lib\site-packages\twisted\internet\defer.py", line 1065, in adapt
    extracted = result.result()
                ^^^^^^^^^^^^^^^
  File "C:\Users\Muhammad Umer\AppData\Local\Programs\Python\Python311\Lib\site-packages\asgiref\sync.py", line 448, in __call__
    ret = await asyncio.wait_for(future, timeout=None)
          ^^^^^^^^^^^^^^^^^^^^^^^^^^^^^^^^^^^^^^^^^^^^
  File "C:\Users\Muhammad Umer\AppData\Local\Programs\Python\Python311\Lib\asyncio\tasks.py", line 442, in wait_for
    return await fut
           ^^^^^^^^^
  File "C:\Users\Muhammad Umer\AppData\Local\Programs\Python\Python311\Lib\concurrent\futures\thread.py", line 58, in run
    result = self.fn(*self.args, **self.kwargs)
             ^^^^^^^^^^^^^^^^^^^^^^^^^^^^^^^^^^
  File "C:\Users\Muhammad Umer\AppData\Local\Programs\Python\Python311\Lib\site-packages\asgiref\sync.py", line 490, in thread_handler
    return func(*args, **kwargs)
           ^^^^^^^^^^^^^^^^^^^^^
  File "D:\Outputs\Django Outputs\scraper\pipelines.py", line 44, in process_item
    Result.objects.create(
  File "C:\Users\Muhammad Umer\AppData\Local\Programs\Python\Python311\Lib\site-packages\django\db\models\manager.py", line 85, in manager_method
    return getattr(self.get_queryset(), name)(*args, **kwargs)
           ^^^^^^^^^^^^^^^^^^^^^^^^^^^^^^^^^^^^^^^^^^^^^^^^^^^
  File "C:\Users\Muhammad Umer\AppData\Local\Programs\Python\Python311\Lib\site-packages\django\db\models\query.py", line 669, in create
    obj = self.model(**kwargs)
          ^^^^^^^^^^^^^^^^^^^^
  File "C:\Users\Muhammad Umer\AppData\Local\Programs\Python\Python311\Lib\site-packages\django\db\models\base.py", line 541, in __init__
    _setattr(self, field.name, rel_obj)
  File "C:\Users\Muhammad Umer\AppData\Local\Programs\Python\Python311\Lib\site-packages\django\db\models\fields\related_descriptors.py", line 237, in __set__
    raise ValueError(
ValueError: Cannot assign "'iphone 14'": "Result.keyword" must be a "Keyword" instance.
2023-09-08 08:01:31 [scrapy] ERROR: Error processing {'country': 'DK',
 'keyword': 'iphone 14',
 'position': 5,
 'price': '6.838,99\xa0kr.',
 'product_url': 'https://www.refurbed.dk/p/iphone-14-pro/?co=dk&utm_cluster=gradeB&utm_content=iphone-14-pro&utm_group=iphone-14-pro',
 'title': 'iPhone 14 Pro',
 'url': 'refurbed.dk',
 'user_id': 'admin'}
Traceback (most recent call last):
  File "D:\Outputs\Django Outputs\scraper\pipelines.py", line 37, in process_item
    res = Result.objects.get(
          ^^^^^^^^^^^^^^^^^^^
  File "C:\Users\Muhammad Umer\AppData\Local\Programs\Python\Python311\Lib\site-packages\django\db\models\manager.py", line 85, in manager_method
    return getattr(self.get_queryset(), name)(*args, **kwargs)
           ^^^^^^^^^^^^^^^^^^^^^^^^^^^^^^^^^^^^^^^^^^^^^^^^^^^
  File "C:\Users\Muhammad Umer\AppData\Local\Programs\Python\Python311\Lib\site-packages\django\db\models\query.py", line 650, in get
    raise self.model.DoesNotExist(
search.models.Result.DoesNotExist: Result matching query does not exist.

During handling of the above exception, another exception occurred:

Traceback (most recent call last):
  File "C:\Users\Muhammad Umer\AppData\Local\Programs\Python\Python311\Lib\site-packages\twisted\internet\defer.py", line 1065, in adapt
    extracted = result.result()
                ^^^^^^^^^^^^^^^
  File "C:\Users\Muhammad Umer\AppData\Local\Programs\Python\Python311\Lib\site-packages\asgiref\sync.py", line 448, in __call__
    ret = await asyncio.wait_for(future, timeout=None)
          ^^^^^^^^^^^^^^^^^^^^^^^^^^^^^^^^^^^^^^^^^^^^
  File "C:\Users\Muhammad Umer\AppData\Local\Programs\Python\Python311\Lib\asyncio\tasks.py", line 442, in wait_for
    return await fut
           ^^^^^^^^^
  File "C:\Users\Muhammad Umer\AppData\Local\Programs\Python\Python311\Lib\concurrent\futures\thread.py", line 58, in run
    result = self.fn(*self.args, **self.kwargs)
             ^^^^^^^^^^^^^^^^^^^^^^^^^^^^^^^^^^
  File "C:\Users\Muhammad Umer\AppData\Local\Programs\Python\Python311\Lib\site-packages\asgiref\sync.py", line 490, in thread_handler
    return func(*args, **kwargs)
           ^^^^^^^^^^^^^^^^^^^^^
  File "D:\Outputs\Django Outputs\scraper\pipelines.py", line 44, in process_item
    Result.objects.create(
  File "C:\Users\Muhammad Umer\AppData\Local\Programs\Python\Python311\Lib\site-packages\django\db\models\manager.py", line 85, in manager_method
    return getattr(self.get_queryset(), name)(*args, **kwargs)
           ^^^^^^^^^^^^^^^^^^^^^^^^^^^^^^^^^^^^^^^^^^^^^^^^^^^
  File "C:\Users\Muhammad Umer\AppData\Local\Programs\Python\Python311\Lib\site-packages\django\db\models\query.py", line 669, in create
    obj = self.model(**kwargs)
          ^^^^^^^^^^^^^^^^^^^^
  File "C:\Users\Muhammad Umer\AppData\Local\Programs\Python\Python311\Lib\site-packages\django\db\models\base.py", line 541, in __init__
    _setattr(self, field.name, rel_obj)
  File "C:\Users\Muhammad Umer\AppData\Local\Programs\Python\Python311\Lib\site-packages\django\db\models\fields\related_descriptors.py", line 237, in __set__
    raise ValueError(
ValueError: Cannot assign "'iphone 14'": "Result.keyword" must be a "Keyword" instance.
2023-09-08 08:01:31 [scrapy] ERROR: Error processing {'country': 'DK',
 'keyword': 'iphone 14',
 'position': 6,
 'price': '5.496,00\xa0kr.',
 'product_url': 'https://www.telmore.dk/shop/mobiltelefoner/Apple/iphone-14?cid=_semt_terminal_terminal_Shopping_Shopping_u0617',
 'title': 'Apple iPhone 14 128 GB - Purple. Mindstepris 7.290,00 kr.',
 'url': 'telmore.dk',
 'user_id': 'admin'}
Traceback (most recent call last):
  File "D:\Outputs\Django Outputs\scraper\pipelines.py", line 37, in process_item
    res = Result.objects.get(
          ^^^^^^^^^^^^^^^^^^^
  File "C:\Users\Muhammad Umer\AppData\Local\Programs\Python\Python311\Lib\site-packages\django\db\models\manager.py", line 85, in manager_method
    return getattr(self.get_queryset(), name)(*args, **kwargs)
           ^^^^^^^^^^^^^^^^^^^^^^^^^^^^^^^^^^^^^^^^^^^^^^^^^^^
  File "C:\Users\Muhammad Umer\AppData\Local\Programs\Python\Python311\Lib\site-packages\django\db\models\query.py", line 650, in get
    raise self.model.DoesNotExist(
search.models.Result.DoesNotExist: Result matching query does not exist.

During handling of the above exception, another exception occurred:

Traceback (most recent call last):
  File "C:\Users\Muhammad Umer\AppData\Local\Programs\Python\Python311\Lib\site-packages\twisted\internet\defer.py", line 1065, in adapt
    extracted = result.result()
                ^^^^^^^^^^^^^^^
  File "C:\Users\Muhammad Umer\AppData\Local\Programs\Python\Python311\Lib\site-packages\asgiref\sync.py", line 448, in __call__
    ret = await asyncio.wait_for(future, timeout=None)
          ^^^^^^^^^^^^^^^^^^^^^^^^^^^^^^^^^^^^^^^^^^^^
  File "C:\Users\Muhammad Umer\AppData\Local\Programs\Python\Python311\Lib\asyncio\tasks.py", line 442, in wait_for
    return await fut
           ^^^^^^^^^
  File "C:\Users\Muhammad Umer\AppData\Local\Programs\Python\Python311\Lib\concurrent\futures\thread.py", line 58, in run
    result = self.fn(*self.args, **self.kwargs)
             ^^^^^^^^^^^^^^^^^^^^^^^^^^^^^^^^^^
  File "C:\Users\Muhammad Umer\AppData\Local\Programs\Python\Python311\Lib\site-packages\asgiref\sync.py", line 490, in thread_handler
    return func(*args, **kwargs)
           ^^^^^^^^^^^^^^^^^^^^^
  File "D:\Outputs\Django Outputs\scraper\pipelines.py", line 44, in process_item
    Result.objects.create(
  File "C:\Users\Muhammad Umer\AppData\Local\Programs\Python\Python311\Lib\site-packages\django\db\models\manager.py", line 85, in manager_method
    return getattr(self.get_queryset(), name)(*args, **kwargs)
           ^^^^^^^^^^^^^^^^^^^^^^^^^^^^^^^^^^^^^^^^^^^^^^^^^^^
  File "C:\Users\Muhammad Umer\AppData\Local\Programs\Python\Python311\Lib\site-packages\django\db\models\query.py", line 669, in create
    obj = self.model(**kwargs)
          ^^^^^^^^^^^^^^^^^^^^
  File "C:\Users\Muhammad Umer\AppData\Local\Programs\Python\Python311\Lib\site-packages\django\db\models\base.py", line 541, in __init__
    _setattr(self, field.name, rel_obj)
  File "C:\Users\Muhammad Umer\AppData\Local\Programs\Python\Python311\Lib\site-packages\django\db\models\fields\related_descriptors.py", line 237, in __set__
    raise ValueError(
ValueError: Cannot assign "'iphone 14'": "Result.keyword" must be a "Keyword" instance.
2023-09-08 08:01:31 [scrapy] ERROR: Error processing {'country': 'DK',
 'keyword': 'iphone 14',
 'position': 7,
 'price': '5.399,00\xa0kr.',
 'product_url': 'https://www.telia.dk/shop/apple/apple-iphone-14/#/midnight/128-gb/1',
 'title': 'Apple iPhone 14 128GB Midnight. Min.pris: 7.202,00kr. 6 mdr. '
          'binding',
 'url': 'telia.dk',
 'user_id': 'admin'}
Traceback (most recent call last):
  File "D:\Outputs\Django Outputs\scraper\pipelines.py", line 37, in process_item
    res = Result.objects.get(
          ^^^^^^^^^^^^^^^^^^^
  File "C:\Users\Muhammad Umer\AppData\Local\Programs\Python\Python311\Lib\site-packages\django\db\models\manager.py", line 85, in manager_method
    return getattr(self.get_queryset(), name)(*args, **kwargs)
           ^^^^^^^^^^^^^^^^^^^^^^^^^^^^^^^^^^^^^^^^^^^^^^^^^^^
  File "C:\Users\Muhammad Umer\AppData\Local\Programs\Python\Python311\Lib\site-packages\django\db\models\query.py", line 650, in get
    raise self.model.DoesNotExist(
search.models.Result.DoesNotExist: Result matching query does not exist.

During handling of the above exception, another exception occurred:

Traceback (most recent call last):
  File "C:\Users\Muhammad Umer\AppData\Local\Programs\Python\Python311\Lib\site-packages\twisted\internet\defer.py", line 1065, in adapt
    extracted = result.result()
                ^^^^^^^^^^^^^^^
  File "C:\Users\Muhammad Umer\AppData\Local\Programs\Python\Python311\Lib\site-packages\asgiref\sync.py", line 448, in __call__
    ret = await asyncio.wait_for(future, timeout=None)
          ^^^^^^^^^^^^^^^^^^^^^^^^^^^^^^^^^^^^^^^^^^^^
  File "C:\Users\Muhammad Umer\AppData\Local\Programs\Python\Python311\Lib\asyncio\tasks.py", line 442, in wait_for
    return await fut
           ^^^^^^^^^
  File "C:\Users\Muhammad Umer\AppData\Local\Programs\Python\Python311\Lib\concurrent\futures\thread.py", line 58, in run
    result = self.fn(*self.args, **self.kwargs)
             ^^^^^^^^^^^^^^^^^^^^^^^^^^^^^^^^^^
  File "C:\Users\Muhammad Umer\AppData\Local\Programs\Python\Python311\Lib\site-packages\asgiref\sync.py", line 490, in thread_handler
    return func(*args, **kwargs)
           ^^^^^^^^^^^^^^^^^^^^^
  File "D:\Outputs\Django Outputs\scraper\pipelines.py", line 44, in process_item
    Result.objects.create(
  File "C:\Users\Muhammad Umer\AppData\Local\Programs\Python\Python311\Lib\site-packages\django\db\models\manager.py", line 85, in manager_method
    return getattr(self.get_queryset(), name)(*args, **kwargs)
           ^^^^^^^^^^^^^^^^^^^^^^^^^^^^^^^^^^^^^^^^^^^^^^^^^^^
  File "C:\Users\Muhammad Umer\AppData\Local\Programs\Python\Python311\Lib\site-packages\django\db\models\query.py", line 669, in create
    obj = self.model(**kwargs)
          ^^^^^^^^^^^^^^^^^^^^
  File "C:\Users\Muhammad Umer\AppData\Local\Programs\Python\Python311\Lib\site-packages\django\db\models\base.py", line 541, in __init__
    _setattr(self, field.name, rel_obj)
  File "C:\Users\Muhammad Umer\AppData\Local\Programs\Python\Python311\Lib\site-packages\django\db\models\fields\related_descriptors.py", line 237, in __set__
    raise ValueError(
ValueError: Cannot assign "'iphone 14'": "Result.keyword" must be a "Keyword" instance.
2023-09-08 08:01:31 [scrapy] ERROR: Error processing {'country': 'DK',
 'keyword': 'iphone 14',
 'position': 8,
 'price': '4.799,00\xa0kr.',
 'product_url': 'https://www.telenor.dk/shop/mobil/apple/apple-iphone-13--128gb-midnight/?cycleCount=none',
 'title': 'Apple iPhone 13 - 128 GB - Midnight med abonnementsaftale. '
          'Mindstepris 6613.00 Kr.',
 'url': 'telenor.dk',
 'user_id': 'admin'}
Traceback (most recent call last):
  File "D:\Outputs\Django Outputs\scraper\pipelines.py", line 37, in process_item
    res = Result.objects.get(
          ^^^^^^^^^^^^^^^^^^^
  File "C:\Users\Muhammad Umer\AppData\Local\Programs\Python\Python311\Lib\site-packages\django\db\models\manager.py", line 85, in manager_method
    return getattr(self.get_queryset(), name)(*args, **kwargs)
           ^^^^^^^^^^^^^^^^^^^^^^^^^^^^^^^^^^^^^^^^^^^^^^^^^^^
  File "C:\Users\Muhammad Umer\AppData\Local\Programs\Python\Python311\Lib\site-packages\django\db\models\query.py", line 650, in get
    raise self.model.DoesNotExist(
search.models.Result.DoesNotExist: Result matching query does not exist.

During handling of the above exception, another exception occurred:

Traceback (most recent call last):
  File "C:\Users\Muhammad Umer\AppData\Local\Programs\Python\Python311\Lib\site-packages\twisted\internet\defer.py", line 1065, in adapt
    extracted = result.result()
                ^^^^^^^^^^^^^^^
  File "C:\Users\Muhammad Umer\AppData\Local\Programs\Python\Python311\Lib\site-packages\asgiref\sync.py", line 448, in __call__
    ret = await asyncio.wait_for(future, timeout=None)
          ^^^^^^^^^^^^^^^^^^^^^^^^^^^^^^^^^^^^^^^^^^^^
  File "C:\Users\Muhammad Umer\AppData\Local\Programs\Python\Python311\Lib\asyncio\tasks.py", line 442, in wait_for
    return await fut
           ^^^^^^^^^
  File "C:\Users\Muhammad Umer\AppData\Local\Programs\Python\Python311\Lib\concurrent\futures\thread.py", line 58, in run
    result = self.fn(*self.args, **self.kwargs)
             ^^^^^^^^^^^^^^^^^^^^^^^^^^^^^^^^^^
  File "C:\Users\Muhammad Umer\AppData\Local\Programs\Python\Python311\Lib\site-packages\asgiref\sync.py", line 490, in thread_handler
    return func(*args, **kwargs)
           ^^^^^^^^^^^^^^^^^^^^^
  File "D:\Outputs\Django Outputs\scraper\pipelines.py", line 44, in process_item
    Result.objects.create(
  File "C:\Users\Muhammad Umer\AppData\Local\Programs\Python\Python311\Lib\site-packages\django\db\models\manager.py", line 85, in manager_method
    return getattr(self.get_queryset(), name)(*args, **kwargs)
           ^^^^^^^^^^^^^^^^^^^^^^^^^^^^^^^^^^^^^^^^^^^^^^^^^^^
  File "C:\Users\Muhammad Umer\AppData\Local\Programs\Python\Python311\Lib\site-packages\django\db\models\query.py", line 669, in create
    obj = self.model(**kwargs)
          ^^^^^^^^^^^^^^^^^^^^
  File "C:\Users\Muhammad Umer\AppData\Local\Programs\Python\Python311\Lib\site-packages\django\db\models\base.py", line 541, in __init__
    _setattr(self, field.name, rel_obj)
  File "C:\Users\Muhammad Umer\AppData\Local\Programs\Python\Python311\Lib\site-packages\django\db\models\fields\related_descriptors.py", line 237, in __set__
    raise ValueError(
ValueError: Cannot assign "'iphone 14'": "Result.keyword" must be a "Keyword" instance.
2023-09-08 08:01:31 [scrapy] ERROR: Error processing {'country': 'DK',
 'keyword': 'iphone 14',
 'position': 9,
 'price': '6.777,00\xa0kr.',
 'product_url': 'https://www.proshop.dk/Mobil/Apple-iPhone-14-5G-128GB-Midnight/3104588?utm_source=google&utm_medium=cpc&utm_campaign=searchengine',
 'title': 'Apple iPhone 14 5G 128GB - Midnight',
 'url': 'proshop.dk',
 'user_id': 'admin'}
Traceback (most recent call last):
  File "D:\Outputs\Django Outputs\scraper\pipelines.py", line 37, in process_item
    res = Result.objects.get(
          ^^^^^^^^^^^^^^^^^^^
  File "C:\Users\Muhammad Umer\AppData\Local\Programs\Python\Python311\Lib\site-packages\django\db\models\manager.py", line 85, in manager_method
    return getattr(self.get_queryset(), name)(*args, **kwargs)
           ^^^^^^^^^^^^^^^^^^^^^^^^^^^^^^^^^^^^^^^^^^^^^^^^^^^
  File "C:\Users\Muhammad Umer\AppData\Local\Programs\Python\Python311\Lib\site-packages\django\db\models\query.py", line 650, in get
    raise self.model.DoesNotExist(
search.models.Result.DoesNotExist: Result matching query does not exist.

During handling of the above exception, another exception occurred:

Traceback (most recent call last):
  File "C:\Users\Muhammad Umer\AppData\Local\Programs\Python\Python311\Lib\site-packages\twisted\internet\defer.py", line 1065, in adapt
    extracted = result.result()
                ^^^^^^^^^^^^^^^
  File "C:\Users\Muhammad Umer\AppData\Local\Programs\Python\Python311\Lib\site-packages\asgiref\sync.py", line 448, in __call__
    ret = await asyncio.wait_for(future, timeout=None)
          ^^^^^^^^^^^^^^^^^^^^^^^^^^^^^^^^^^^^^^^^^^^^
  File "C:\Users\Muhammad Umer\AppData\Local\Programs\Python\Python311\Lib\asyncio\tasks.py", line 442, in wait_for
    return await fut
           ^^^^^^^^^
  File "C:\Users\Muhammad Umer\AppData\Local\Programs\Python\Python311\Lib\concurrent\futures\thread.py", line 58, in run
    result = self.fn(*self.args, **self.kwargs)
             ^^^^^^^^^^^^^^^^^^^^^^^^^^^^^^^^^^
  File "C:\Users\Muhammad Umer\AppData\Local\Programs\Python\Python311\Lib\site-packages\asgiref\sync.py", line 490, in thread_handler
    return func(*args, **kwargs)
           ^^^^^^^^^^^^^^^^^^^^^
  File "D:\Outputs\Django Outputs\scraper\pipelines.py", line 44, in process_item
    Result.objects.create(
  File "C:\Users\Muhammad Umer\AppData\Local\Programs\Python\Python311\Lib\site-packages\django\db\models\manager.py", line 85, in manager_method
    return getattr(self.get_queryset(), name)(*args, **kwargs)
           ^^^^^^^^^^^^^^^^^^^^^^^^^^^^^^^^^^^^^^^^^^^^^^^^^^^
  File "C:\Users\Muhammad Umer\AppData\Local\Programs\Python\Python311\Lib\site-packages\django\db\models\query.py", line 669, in create
    obj = self.model(**kwargs)
          ^^^^^^^^^^^^^^^^^^^^
  File "C:\Users\Muhammad Umer\AppData\Local\Programs\Python\Python311\Lib\site-packages\django\db\models\base.py", line 541, in __init__
    _setattr(self, field.name, rel_obj)
  File "C:\Users\Muhammad Umer\AppData\Local\Programs\Python\Python311\Lib\site-packages\django\db\models\fields\related_descriptors.py", line 237, in __set__
    raise ValueError(
ValueError: Cannot assign "'iphone 14'": "Result.keyword" must be a "Keyword" instance.
2023-09-08 08:01:31 [scrapy] ERROR: Error processing {'country': 'DK',
 'keyword': 'iphone 14',
 'position': 10,
 'price': '5.761,00\xa0kr.',
 'product_url': 'https://yousee.dk/mobil/mobiltelefoner/apple/iphone-14/1468/mobil_80/kontant/',
 'title': 'Apple iPhone 14 128 GB Midnat med abonnementsaftale. Mindstepris '
          '7.075,00 kr.',
 'url': 'yousee.dk',
 'user_id': 'admin'}
Traceback (most recent call last):
  File "D:\Outputs\Django Outputs\scraper\pipelines.py", line 37, in process_item
    res = Result.objects.get(
          ^^^^^^^^^^^^^^^^^^^
  File "C:\Users\Muhammad Umer\AppData\Local\Programs\Python\Python311\Lib\site-packages\django\db\models\manager.py", line 85, in manager_method
    return getattr(self.get_queryset(), name)(*args, **kwargs)
           ^^^^^^^^^^^^^^^^^^^^^^^^^^^^^^^^^^^^^^^^^^^^^^^^^^^
  File "C:\Users\Muhammad Umer\AppData\Local\Programs\Python\Python311\Lib\site-packages\django\db\models\query.py", line 650, in get
    raise self.model.DoesNotExist(
search.models.Result.DoesNotExist: Result matching query does not exist.

During handling of the above exception, another exception occurred:

Traceback (most recent call last):
  File "C:\Users\Muhammad Umer\AppData\Local\Programs\Python\Python311\Lib\site-packages\twisted\internet\defer.py", line 1065, in adapt
    extracted = result.result()
                ^^^^^^^^^^^^^^^
  File "C:\Users\Muhammad Umer\AppData\Local\Programs\Python\Python311\Lib\site-packages\asgiref\sync.py", line 448, in __call__
    ret = await asyncio.wait_for(future, timeout=None)
          ^^^^^^^^^^^^^^^^^^^^^^^^^^^^^^^^^^^^^^^^^^^^
  File "C:\Users\Muhammad Umer\AppData\Local\Programs\Python\Python311\Lib\asyncio\tasks.py", line 442, in wait_for
    return await fut
           ^^^^^^^^^
  File "C:\Users\Muhammad Umer\AppData\Local\Programs\Python\Python311\Lib\concurrent\futures\thread.py", line 58, in run
    result = self.fn(*self.args, **self.kwargs)
             ^^^^^^^^^^^^^^^^^^^^^^^^^^^^^^^^^^
  File "C:\Users\Muhammad Umer\AppData\Local\Programs\Python\Python311\Lib\site-packages\asgiref\sync.py", line 490, in thread_handler
    return func(*args, **kwargs)
           ^^^^^^^^^^^^^^^^^^^^^
  File "D:\Outputs\Django Outputs\scraper\pipelines.py", line 44, in process_item
    Result.objects.create(
  File "C:\Users\Muhammad Umer\AppData\Local\Programs\Python\Python311\Lib\site-packages\django\db\models\manager.py", line 85, in manager_method
    return getattr(self.get_queryset(), name)(*args, **kwargs)
           ^^^^^^^^^^^^^^^^^^^^^^^^^^^^^^^^^^^^^^^^^^^^^^^^^^^
  File "C:\Users\Muhammad Umer\AppData\Local\Programs\Python\Python311\Lib\site-packages\django\db\models\query.py", line 669, in create
    obj = self.model(**kwargs)
          ^^^^^^^^^^^^^^^^^^^^
  File "C:\Users\Muhammad Umer\AppData\Local\Programs\Python\Python311\Lib\site-packages\django\db\models\base.py", line 541, in __init__
    _setattr(self, field.name, rel_obj)
  File "C:\Users\Muhammad Umer\AppData\Local\Programs\Python\Python311\Lib\site-packages\django\db\models\fields\related_descriptors.py", line 237, in __set__
    raise ValueError(
ValueError: Cannot assign "'iphone 14'": "Result.keyword" must be a "Keyword" instance.
2023-09-08 08:01:31 [scrapy] ERROR: Error processing {'country': 'DK',
 'keyword': 'iphone 14',
 'position': 11,
 'price': '7.149,00\xa0kr.',
 'product_url': 'https://www.elgiganten.dk/product/mobil-tablet-smartwatch/mobiltelefon/iphone-14-5g-smartphone-128gb-midnight/522692',
 'title': 'iPhone 14 – 5G smartphone 128GB Midnight',
 'url': 'elgiganten.dk',
 'user_id': 'admin'}
Traceback (most recent call last):
  File "D:\Outputs\Django Outputs\scraper\pipelines.py", line 37, in process_item
    res = Result.objects.get(
          ^^^^^^^^^^^^^^^^^^^
  File "C:\Users\Muhammad Umer\AppData\Local\Programs\Python\Python311\Lib\site-packages\django\db\models\manager.py", line 85, in manager_method
    return getattr(self.get_queryset(), name)(*args, **kwargs)
           ^^^^^^^^^^^^^^^^^^^^^^^^^^^^^^^^^^^^^^^^^^^^^^^^^^^
  File "C:\Users\Muhammad Umer\AppData\Local\Programs\Python\Python311\Lib\site-packages\django\db\models\query.py", line 650, in get
    raise self.model.DoesNotExist(
search.models.Result.DoesNotExist: Result matching query does not exist.

During handling of the above exception, another exception occurred:

Traceback (most recent call last):
  File "C:\Users\Muhammad Umer\AppData\Local\Programs\Python\Python311\Lib\site-packages\twisted\internet\defer.py", line 1065, in adapt
    extracted = result.result()
                ^^^^^^^^^^^^^^^
  File "C:\Users\Muhammad Umer\AppData\Local\Programs\Python\Python311\Lib\site-packages\asgiref\sync.py", line 448, in __call__
    ret = await asyncio.wait_for(future, timeout=None)
          ^^^^^^^^^^^^^^^^^^^^^^^^^^^^^^^^^^^^^^^^^^^^
  File "C:\Users\Muhammad Umer\AppData\Local\Programs\Python\Python311\Lib\asyncio\tasks.py", line 442, in wait_for
    return await fut
           ^^^^^^^^^
  File "C:\Users\Muhammad Umer\AppData\Local\Programs\Python\Python311\Lib\concurrent\futures\thread.py", line 58, in run
    result = self.fn(*self.args, **self.kwargs)
             ^^^^^^^^^^^^^^^^^^^^^^^^^^^^^^^^^^
  File "C:\Users\Muhammad Umer\AppData\Local\Programs\Python\Python311\Lib\site-packages\asgiref\sync.py", line 490, in thread_handler
    return func(*args, **kwargs)
           ^^^^^^^^^^^^^^^^^^^^^
  File "D:\Outputs\Django Outputs\scraper\pipelines.py", line 44, in process_item
    Result.objects.create(
  File "C:\Users\Muhammad Umer\AppData\Local\Programs\Python\Python311\Lib\site-packages\django\db\models\manager.py", line 85, in manager_method
    return getattr(self.get_queryset(), name)(*args, **kwargs)
           ^^^^^^^^^^^^^^^^^^^^^^^^^^^^^^^^^^^^^^^^^^^^^^^^^^^
  File "C:\Users\Muhammad Umer\AppData\Local\Programs\Python\Python311\Lib\site-packages\django\db\models\query.py", line 669, in create
    obj = self.model(**kwargs)
          ^^^^^^^^^^^^^^^^^^^^
  File "C:\Users\Muhammad Umer\AppData\Local\Programs\Python\Python311\Lib\site-packages\django\db\models\base.py", line 541, in __init__
    _setattr(self, field.name, rel_obj)
  File "C:\Users\Muhammad Umer\AppData\Local\Programs\Python\Python311\Lib\site-packages\django\db\models\fields\related_descriptors.py", line 237, in __set__
    raise ValueError(
ValueError: Cannot assign "'iphone 14'": "Result.keyword" must be a "Keyword" instance.
2023-09-08 08:01:31 [scrapy] ERROR: Error processing {'country': 'DK',
 'keyword': 'iphone 14',
 'position': 12,
 'price': '5.496,00\xa0kr.',
 'product_url': 'https://www.telmore.dk/shop/mobiltelefoner/Apple/iphone-14?cid=_semt_terminal_terminal_Shopping_Shopping_u0617',
 'title': 'Apple iPhone 14 128 GB - Product Red. Mindstepris 7.290,00 kr.',
 'url': 'telmore.dk',
 'user_id': 'admin'}
Traceback (most recent call last):
  File "D:\Outputs\Django Outputs\scraper\pipelines.py", line 37, in process_item
    res = Result.objects.get(
          ^^^^^^^^^^^^^^^^^^^
  File "C:\Users\Muhammad Umer\AppData\Local\Programs\Python\Python311\Lib\site-packages\django\db\models\manager.py", line 85, in manager_method
    return getattr(self.get_queryset(), name)(*args, **kwargs)
           ^^^^^^^^^^^^^^^^^^^^^^^^^^^^^^^^^^^^^^^^^^^^^^^^^^^
  File "C:\Users\Muhammad Umer\AppData\Local\Programs\Python\Python311\Lib\site-packages\django\db\models\query.py", line 650, in get
    raise self.model.DoesNotExist(
search.models.Result.DoesNotExist: Result matching query does not exist.

During handling of the above exception, another exception occurred:

Traceback (most recent call last):
  File "C:\Users\Muhammad Umer\AppData\Local\Programs\Python\Python311\Lib\site-packages\twisted\internet\defer.py", line 1065, in adapt
    extracted = result.result()
                ^^^^^^^^^^^^^^^
  File "C:\Users\Muhammad Umer\AppData\Local\Programs\Python\Python311\Lib\site-packages\asgiref\sync.py", line 448, in __call__
    ret = await asyncio.wait_for(future, timeout=None)
          ^^^^^^^^^^^^^^^^^^^^^^^^^^^^^^^^^^^^^^^^^^^^
  File "C:\Users\Muhammad Umer\AppData\Local\Programs\Python\Python311\Lib\asyncio\tasks.py", line 442, in wait_for
    return await fut
           ^^^^^^^^^
  File "C:\Users\Muhammad Umer\AppData\Local\Programs\Python\Python311\Lib\concurrent\futures\thread.py", line 58, in run
    result = self.fn(*self.args, **self.kwargs)
             ^^^^^^^^^^^^^^^^^^^^^^^^^^^^^^^^^^
  File "C:\Users\Muhammad Umer\AppData\Local\Programs\Python\Python311\Lib\site-packages\asgiref\sync.py", line 490, in thread_handler
    return func(*args, **kwargs)
           ^^^^^^^^^^^^^^^^^^^^^
  File "D:\Outputs\Django Outputs\scraper\pipelines.py", line 44, in process_item
    Result.objects.create(
  File "C:\Users\Muhammad Umer\AppData\Local\Programs\Python\Python311\Lib\site-packages\django\db\models\manager.py", line 85, in manager_method
    return getattr(self.get_queryset(), name)(*args, **kwargs)
           ^^^^^^^^^^^^^^^^^^^^^^^^^^^^^^^^^^^^^^^^^^^^^^^^^^^
  File "C:\Users\Muhammad Umer\AppData\Local\Programs\Python\Python311\Lib\site-packages\django\db\models\query.py", line 669, in create
    obj = self.model(**kwargs)
          ^^^^^^^^^^^^^^^^^^^^
  File "C:\Users\Muhammad Umer\AppData\Local\Programs\Python\Python311\Lib\site-packages\django\db\models\base.py", line 541, in __init__
    _setattr(self, field.name, rel_obj)
  File "C:\Users\Muhammad Umer\AppData\Local\Programs\Python\Python311\Lib\site-packages\django\db\models\fields\related_descriptors.py", line 237, in __set__
    raise ValueError(
ValueError: Cannot assign "'iphone 14'": "Result.keyword" must be a "Keyword" instance.
2023-09-08 08:01:31 [scrapy] ERROR: Error processing {'country': 'DK',
 'keyword': 'iphone 14',
 'position': 13,
 'price': '6.666,00\xa0kr.',
 'product_url': 'https://www.power.dk/mobil-og-foto/mobiltelefoner/apple-iphone-14-128-gb-stjerneskaer/p-1803963/',
 'title': 'APPLE IPHONE 14 128 GB STJERNESKÆR',
 'url': 'power.dk',
 'user_id': 'admin'}
Traceback (most recent call last):
  File "D:\Outputs\Django Outputs\scraper\pipelines.py", line 37, in process_item
    res = Result.objects.get(
          ^^^^^^^^^^^^^^^^^^^
  File "C:\Users\Muhammad Umer\AppData\Local\Programs\Python\Python311\Lib\site-packages\django\db\models\manager.py", line 85, in manager_method
    return getattr(self.get_queryset(), name)(*args, **kwargs)
           ^^^^^^^^^^^^^^^^^^^^^^^^^^^^^^^^^^^^^^^^^^^^^^^^^^^
  File "C:\Users\Muhammad Umer\AppData\Local\Programs\Python\Python311\Lib\site-packages\django\db\models\query.py", line 650, in get
    raise self.model.DoesNotExist(
search.models.Result.DoesNotExist: Result matching query does not exist.

During handling of the above exception, another exception occurred:

Traceback (most recent call last):
  File "C:\Users\Muhammad Umer\AppData\Local\Programs\Python\Python311\Lib\site-packages\twisted\internet\defer.py", line 1065, in adapt
    extracted = result.result()
                ^^^^^^^^^^^^^^^
  File "C:\Users\Muhammad Umer\AppData\Local\Programs\Python\Python311\Lib\site-packages\asgiref\sync.py", line 448, in __call__
    ret = await asyncio.wait_for(future, timeout=None)
          ^^^^^^^^^^^^^^^^^^^^^^^^^^^^^^^^^^^^^^^^^^^^
  File "C:\Users\Muhammad Umer\AppData\Local\Programs\Python\Python311\Lib\asyncio\tasks.py", line 442, in wait_for
    return await fut
           ^^^^^^^^^
  File "C:\Users\Muhammad Umer\AppData\Local\Programs\Python\Python311\Lib\concurrent\futures\thread.py", line 58, in run
    result = self.fn(*self.args, **self.kwargs)
             ^^^^^^^^^^^^^^^^^^^^^^^^^^^^^^^^^^
  File "C:\Users\Muhammad Umer\AppData\Local\Programs\Python\Python311\Lib\site-packages\asgiref\sync.py", line 490, in thread_handler
    return func(*args, **kwargs)
           ^^^^^^^^^^^^^^^^^^^^^
  File "D:\Outputs\Django Outputs\scraper\pipelines.py", line 44, in process_item
    Result.objects.create(
  File "C:\Users\Muhammad Umer\AppData\Local\Programs\Python\Python311\Lib\site-packages\django\db\models\manager.py", line 85, in manager_method
    return getattr(self.get_queryset(), name)(*args, **kwargs)
           ^^^^^^^^^^^^^^^^^^^^^^^^^^^^^^^^^^^^^^^^^^^^^^^^^^^
  File "C:\Users\Muhammad Umer\AppData\Local\Programs\Python\Python311\Lib\site-packages\django\db\models\query.py", line 669, in create
    obj = self.model(**kwargs)
          ^^^^^^^^^^^^^^^^^^^^
  File "C:\Users\Muhammad Umer\AppData\Local\Programs\Python\Python311\Lib\site-packages\django\db\models\base.py", line 541, in __init__
    _setattr(self, field.name, rel_obj)
  File "C:\Users\Muhammad Umer\AppData\Local\Programs\Python\Python311\Lib\site-packages\django\db\models\fields\related_descriptors.py", line 237, in __set__
    raise ValueError(
ValueError: Cannot assign "'iphone 14'": "Result.keyword" must be a "Keyword" instance.
2023-09-08 08:01:31 [scrapy] ERROR: Error processing {'country': 'DK',
 'keyword': 'iphone 14',
 'position': 14,
 'price': '5.659,00\xa0kr.',
 'product_url': 'https://swappie.com/dk/iphone/iphone-14/iphone-14-128gb-midnat-18/',
 'title': 'iPhone 14 128GB Midnat Apple',
 'url': 'swappie.com',
 'user_id': 'admin'}
Traceback (most recent call last):
  File "D:\Outputs\Django Outputs\scraper\pipelines.py", line 37, in process_item
    res = Result.objects.get(
          ^^^^^^^^^^^^^^^^^^^
  File "C:\Users\Muhammad Umer\AppData\Local\Programs\Python\Python311\Lib\site-packages\django\db\models\manager.py", line 85, in manager_method
    return getattr(self.get_queryset(), name)(*args, **kwargs)
           ^^^^^^^^^^^^^^^^^^^^^^^^^^^^^^^^^^^^^^^^^^^^^^^^^^^
  File "C:\Users\Muhammad Umer\AppData\Local\Programs\Python\Python311\Lib\site-packages\django\db\models\query.py", line 650, in get
    raise self.model.DoesNotExist(
search.models.Result.DoesNotExist: Result matching query does not exist.

During handling of the above exception, another exception occurred:

Traceback (most recent call last):
  File "C:\Users\Muhammad Umer\AppData\Local\Programs\Python\Python311\Lib\site-packages\twisted\internet\defer.py", line 1065, in adapt
    extracted = result.result()
                ^^^^^^^^^^^^^^^
  File "C:\Users\Muhammad Umer\AppData\Local\Programs\Python\Python311\Lib\site-packages\asgiref\sync.py", line 448, in __call__
    ret = await asyncio.wait_for(future, timeout=None)
          ^^^^^^^^^^^^^^^^^^^^^^^^^^^^^^^^^^^^^^^^^^^^
  File "C:\Users\Muhammad Umer\AppData\Local\Programs\Python\Python311\Lib\asyncio\tasks.py", line 442, in wait_for
    return await fut
           ^^^^^^^^^
  File "C:\Users\Muhammad Umer\AppData\Local\Programs\Python\Python311\Lib\concurrent\futures\thread.py", line 58, in run
    result = self.fn(*self.args, **self.kwargs)
             ^^^^^^^^^^^^^^^^^^^^^^^^^^^^^^^^^^
  File "C:\Users\Muhammad Umer\AppData\Local\Programs\Python\Python311\Lib\site-packages\asgiref\sync.py", line 490, in thread_handler
    return func(*args, **kwargs)
           ^^^^^^^^^^^^^^^^^^^^^
  File "D:\Outputs\Django Outputs\scraper\pipelines.py", line 44, in process_item
    Result.objects.create(
  File "C:\Users\Muhammad Umer\AppData\Local\Programs\Python\Python311\Lib\site-packages\django\db\models\manager.py", line 85, in manager_method
    return getattr(self.get_queryset(), name)(*args, **kwargs)
           ^^^^^^^^^^^^^^^^^^^^^^^^^^^^^^^^^^^^^^^^^^^^^^^^^^^
  File "C:\Users\Muhammad Umer\AppData\Local\Programs\Python\Python311\Lib\site-packages\django\db\models\query.py", line 669, in create
    obj = self.model(**kwargs)
          ^^^^^^^^^^^^^^^^^^^^
  File "C:\Users\Muhammad Umer\AppData\Local\Programs\Python\Python311\Lib\site-packages\django\db\models\base.py", line 541, in __init__
    _setattr(self, field.name, rel_obj)
  File "C:\Users\Muhammad Umer\AppData\Local\Programs\Python\Python311\Lib\site-packages\django\db\models\fields\related_descriptors.py", line 237, in __set__
    raise ValueError(
ValueError: Cannot assign "'iphone 14'": "Result.keyword" must be a "Keyword" instance.
2023-09-08 08:01:31 [scrapy] ERROR: Error processing {'country': 'DK',
 'keyword': 'iphone 14',
 'position': 15,
 'price': '5.496,00\xa0kr.',
 'product_url': 'https://www.telmore.dk/shop/mobiltelefoner/Apple/iphone-14?cid=_semt_terminal_terminal_Shopping_Shopping_u0617',
 'title': 'Apple iPhone 14 128 GB - Sky Blue. Mindstepris 7.290,00 kr.',
 'url': 'telmore.dk',
 'user_id': 'admin'}
Traceback (most recent call last):
  File "D:\Outputs\Django Outputs\scraper\pipelines.py", line 37, in process_item
    res = Result.objects.get(
          ^^^^^^^^^^^^^^^^^^^
  File "C:\Users\Muhammad Umer\AppData\Local\Programs\Python\Python311\Lib\site-packages\django\db\models\manager.py", line 85, in manager_method
    return getattr(self.get_queryset(), name)(*args, **kwargs)
           ^^^^^^^^^^^^^^^^^^^^^^^^^^^^^^^^^^^^^^^^^^^^^^^^^^^
  File "C:\Users\Muhammad Umer\AppData\Local\Programs\Python\Python311\Lib\site-packages\django\db\models\query.py", line 650, in get
    raise self.model.DoesNotExist(
search.models.Result.DoesNotExist: Result matching query does not exist.

During handling of the above exception, another exception occurred:

Traceback (most recent call last):
  File "C:\Users\Muhammad Umer\AppData\Local\Programs\Python\Python311\Lib\site-packages\twisted\internet\defer.py", line 1065, in adapt
    extracted = result.result()
                ^^^^^^^^^^^^^^^
  File "C:\Users\Muhammad Umer\AppData\Local\Programs\Python\Python311\Lib\site-packages\asgiref\sync.py", line 448, in __call__
    ret = await asyncio.wait_for(future, timeout=None)
          ^^^^^^^^^^^^^^^^^^^^^^^^^^^^^^^^^^^^^^^^^^^^
  File "C:\Users\Muhammad Umer\AppData\Local\Programs\Python\Python311\Lib\asyncio\tasks.py", line 442, in wait_for
    return await fut
           ^^^^^^^^^
  File "C:\Users\Muhammad Umer\AppData\Local\Programs\Python\Python311\Lib\concurrent\futures\thread.py", line 58, in run
    result = self.fn(*self.args, **self.kwargs)
             ^^^^^^^^^^^^^^^^^^^^^^^^^^^^^^^^^^
  File "C:\Users\Muhammad Umer\AppData\Local\Programs\Python\Python311\Lib\site-packages\asgiref\sync.py", line 490, in thread_handler
    return func(*args, **kwargs)
           ^^^^^^^^^^^^^^^^^^^^^
  File "D:\Outputs\Django Outputs\scraper\pipelines.py", line 44, in process_item
    Result.objects.create(
  File "C:\Users\Muhammad Umer\AppData\Local\Programs\Python\Python311\Lib\site-packages\django\db\models\manager.py", line 85, in manager_method
    return getattr(self.get_queryset(), name)(*args, **kwargs)
           ^^^^^^^^^^^^^^^^^^^^^^^^^^^^^^^^^^^^^^^^^^^^^^^^^^^
  File "C:\Users\Muhammad Umer\AppData\Local\Programs\Python\Python311\Lib\site-packages\django\db\models\query.py", line 669, in create
    obj = self.model(**kwargs)
          ^^^^^^^^^^^^^^^^^^^^
  File "C:\Users\Muhammad Umer\AppData\Local\Programs\Python\Python311\Lib\site-packages\django\db\models\base.py", line 541, in __init__
    _setattr(self, field.name, rel_obj)
  File "C:\Users\Muhammad Umer\AppData\Local\Programs\Python\Python311\Lib\site-packages\django\db\models\fields\related_descriptors.py", line 237, in __set__
    raise ValueError(
ValueError: Cannot assign "'iphone 14'": "Result.keyword" must be a "Keyword" instance.
2023-09-08 08:01:31 [scrapy] ERROR: Error processing {'country': 'DK',
 'keyword': 'iphone 14',
 'position': 16,
 'price': None,
 'product_url': None,
 'title': None,
 'url': '',
 'user_id': 'admin'}
Traceback (most recent call last):
  File "D:\Outputs\Django Outputs\scraper\pipelines.py", line 37, in process_item
    res = Result.objects.get(
          ^^^^^^^^^^^^^^^^^^^
  File "C:\Users\Muhammad Umer\AppData\Local\Programs\Python\Python311\Lib\site-packages\django\db\models\manager.py", line 85, in manager_method
    return getattr(self.get_queryset(), name)(*args, **kwargs)
           ^^^^^^^^^^^^^^^^^^^^^^^^^^^^^^^^^^^^^^^^^^^^^^^^^^^
  File "C:\Users\Muhammad Umer\AppData\Local\Programs\Python\Python311\Lib\site-packages\django\db\models\query.py", line 650, in get
    raise self.model.DoesNotExist(
search.models.Result.DoesNotExist: Result matching query does not exist.

During handling of the above exception, another exception occurred:

Traceback (most recent call last):
  File "C:\Users\Muhammad Umer\AppData\Local\Programs\Python\Python311\Lib\site-packages\twisted\internet\defer.py", line 1065, in adapt
    extracted = result.result()
                ^^^^^^^^^^^^^^^
  File "C:\Users\Muhammad Umer\AppData\Local\Programs\Python\Python311\Lib\site-packages\asgiref\sync.py", line 448, in __call__
    ret = await asyncio.wait_for(future, timeout=None)
          ^^^^^^^^^^^^^^^^^^^^^^^^^^^^^^^^^^^^^^^^^^^^
  File "C:\Users\Muhammad Umer\AppData\Local\Programs\Python\Python311\Lib\asyncio\tasks.py", line 442, in wait_for
    return await fut
           ^^^^^^^^^
  File "C:\Users\Muhammad Umer\AppData\Local\Programs\Python\Python311\Lib\concurrent\futures\thread.py", line 58, in run
    result = self.fn(*self.args, **self.kwargs)
             ^^^^^^^^^^^^^^^^^^^^^^^^^^^^^^^^^^
  File "C:\Users\Muhammad Umer\AppData\Local\Programs\Python\Python311\Lib\site-packages\asgiref\sync.py", line 490, in thread_handler
    return func(*args, **kwargs)
           ^^^^^^^^^^^^^^^^^^^^^
  File "D:\Outputs\Django Outputs\scraper\pipelines.py", line 44, in process_item
    Result.objects.create(
  File "C:\Users\Muhammad Umer\AppData\Local\Programs\Python\Python311\Lib\site-packages\django\db\models\manager.py", line 85, in manager_method
    return getattr(self.get_queryset(), name)(*args, **kwargs)
           ^^^^^^^^^^^^^^^^^^^^^^^^^^^^^^^^^^^^^^^^^^^^^^^^^^^
  File "C:\Users\Muhammad Umer\AppData\Local\Programs\Python\Python311\Lib\site-packages\django\db\models\query.py", line 669, in create
    obj = self.model(**kwargs)
          ^^^^^^^^^^^^^^^^^^^^
  File "C:\Users\Muhammad Umer\AppData\Local\Programs\Python\Python311\Lib\site-packages\django\db\models\base.py", line 541, in __init__
    _setattr(self, field.name, rel_obj)
  File "C:\Users\Muhammad Umer\AppData\Local\Programs\Python\Python311\Lib\site-packages\django\db\models\fields\related_descriptors.py", line 237, in __set__
    raise ValueError(
ValueError: Cannot assign "'iphone 14'": "Result.keyword" must be a "Keyword" instance.
2023-09-08 08:01:32 [scrapy] DEBUG: Retrying <GET https://www.google.com/sorry/index?continue=https://www.google.com/search%3Fq%3D%2Bmacbook%26hl%3Den%26gl%3DDK%26start%3D0&hl=en&q=EgRdpA0SGIud6qcGIjBPF21TF2Bvi--95w9BfEn1wPs7HuabJPY46HNuAgjsyqp-0fpXJZmQSrnc4_R56wEyAXJaAUM> (failed 2 times): 429 Unknown Status
2023-09-08 08:01:32 [scrapy] ERROR: Gave up retrying <GET https://www.google.com/sorry/index?continue=https://www.google.com/search%3Fq%3D%2Bmacbook%26hl%3Den%26gl%3DDK%26start%3D0&hl=en&q=EgRdpA0SGIud6qcGIjBPF21TF2Bvi--95w9BfEn1wPs7HuabJPY46HNuAgjsyqp-0fpXJZmQSrnc4_R56wEyAXJaAUM> (failed 3 times): 429 Unknown Status
2023-09-08 08:01:32 [scrapy] DEBUG: Crawled (429) <GET https://www.google.com/sorry/index?continue=https://www.google.com/search%3Fq%3D%2Bmacbook%26hl%3Den%26gl%3DDK%26start%3D0&hl=en&q=EgRdpA0SGIud6qcGIjBPF21TF2Bvi--95w9BfEn1wPs7HuabJPY46HNuAgjsyqp-0fpXJZmQSrnc4_R56wEyAXJaAUM> (referer: None)
2023-09-08 08:01:32 [scrapy] INFO: Ignoring response <429 https://www.google.com/sorry/index?continue=https://www.google.com/search%3Fq%3D%2Bmacbook%26hl%3Den%26gl%3DDK%26start%3D0&hl=en&q=EgRdpA0SGIud6qcGIjBPF21TF2Bvi--95w9BfEn1wPs7HuabJPY46HNuAgjsyqp-0fpXJZmQSrnc4_R56wEyAXJaAUM>: HTTP status code is not handled or not allowed
2023-09-08 08:01:33 [scrapy] DEBUG: Crawled (200) <GET https://www.google.com/search?q=+apple&hl=en&gl=DK&start=0> (referer: None)
2023-09-08 08:01:50 [scrapy] DEBUG: Redirecting (302) to <GET https://www.google.com/sorry/index?continue=https://www.google.com/search%3Fq%3D%2Biphone%2B13%26hl%3Den%26gl%3DDK%26start%3D0&hl=en&q=EgRdpA0SGJ-d6qcGIjDXMBaHUxGvnMmmd53zWBsNbRn6gLKekUj8NiFL9Ed6lHgSOGwC2ZFtxswSMZziNKoyAXJaAUM> from <GET https://www.google.com/search?q=+iphone+13&hl=en&gl=DK&start=0>
2023-09-08 08:01:51 [scrapy] DEBUG: Retrying <GET https://www.google.com/sorry/index?continue=https://www.google.com/search%3Fq%3D%2Biphone%2B13%26hl%3Den%26gl%3DDK%26start%3D0&hl=en&q=EgRdpA0SGJ-d6qcGIjDXMBaHUxGvnMmmd53zWBsNbRn6gLKekUj8NiFL9Ed6lHgSOGwC2ZFtxswSMZziNKoyAXJaAUM> (failed 1 times): 429 Unknown Status
2023-09-08 08:01:52 [scrapy] DEBUG: Retrying <GET https://www.google.com/sorry/index?continue=https://www.google.com/search%3Fq%3D%2Biphone%2B13%26hl%3Den%26gl%3DDK%26start%3D0&hl=en&q=EgRdpA0SGJ-d6qcGIjDXMBaHUxGvnMmmd53zWBsNbRn6gLKekUj8NiFL9Ed6lHgSOGwC2ZFtxswSMZziNKoyAXJaAUM> (failed 2 times): 429 Unknown Status
2023-09-08 08:01:52 [scrapy] ERROR: Gave up retrying <GET https://www.google.com/sorry/index?continue=https://www.google.com/search%3Fq%3D%2Biphone%2B13%26hl%3Den%26gl%3DDK%26start%3D0&hl=en&q=EgRdpA0SGJ-d6qcGIjDXMBaHUxGvnMmmd53zWBsNbRn6gLKekUj8NiFL9Ed6lHgSOGwC2ZFtxswSMZziNKoyAXJaAUM> (failed 3 times): 429 Unknown Status
2023-09-08 08:01:52 [scrapy] DEBUG: Crawled (429) <GET https://www.google.com/sorry/index?continue=https://www.google.com/search%3Fq%3D%2Biphone%2B13%26hl%3Den%26gl%3DDK%26start%3D0&hl=en&q=EgRdpA0SGJ-d6qcGIjDXMBaHUxGvnMmmd53zWBsNbRn6gLKekUj8NiFL9Ed6lHgSOGwC2ZFtxswSMZziNKoyAXJaAUM> (referer: None)
2023-09-08 08:01:52 [scrapy] INFO: Ignoring response <429 https://www.google.com/sorry/index?continue=https://www.google.com/search%3Fq%3D%2Biphone%2B13%26hl%3Den%26gl%3DDK%26start%3D0&hl=en&q=EgRdpA0SGJ-d6qcGIjDXMBaHUxGvnMmmd53zWBsNbRn6gLKekUj8NiFL9Ed6lHgSOGwC2ZFtxswSMZziNKoyAXJaAUM>: HTTP status code is not handled or not allowed
2023-09-08 08:01:52 [scrapy] INFO: Closing spider (finished)
2023-09-08 08:01:52 [scrapy] INFO: Dumping Scrapy stats:
{'downloader/request_bytes': 7334,
 'downloader/request_count': 11,
 'downloader/request_method_count/GET': 11,
 'downloader/response_bytes': 808768,
 'downloader/response_count': 11,
 'downloader/response_status_count/200': 3,
 'downloader/response_status_count/302': 2,
 'downloader/response_status_count/429': 6,
 'elapsed_time_seconds': 24.467354,
 'finish_reason': 'finished',
 'finish_time': datetime.datetime(2023, 9, 8, 3, 1, 52, 949463),
 'httpcompression/response_bytes': 2605354,
 'httpcompression/response_count': 3,
 'httperror/response_ignored_count': 2,
 'httperror/response_ignored_status_count/429': 2,
 'log_count/DEBUG': 11,
 'log_count/ERROR': 36,
 'log_count/INFO': 10,
 'response_received_count': 5,
 'retry/count': 4,
 'retry/max_reached': 2,
 'retry/reason_count/429 Unknown Status': 4,
 'scheduler/dequeued': 11,
 'scheduler/dequeued/memory': 11,
 'scheduler/enqueued': 11,
 'scheduler/enqueued/memory': 11,
 'start_time': datetime.datetime(2023, 9, 8, 3, 1, 28, 482109)}
2023-09-08 08:01:52 [scrapy] INFO: Spider closed (finished)
