2023-09-23 18:35:46 [scrapy] DEBUG: Crawled (200) <GET https://www.google.com/search?q=iphone+14&hl=en&gl=DK&start=0> (referer: None)
2023-09-23 18:35:46 [scrapy] ERROR: Error processing {'country': 'DK',
 'keyword': 'iphone 14',
 'position': 1,
 'price': '6.299,00\xa0kr.',
 'product_url': 'https://www.foetex.dk/produkter/iphone-14-128gb-midnight/200162606/',
 'title': '"iPhone 14 128GB - Midnight"',
 'url': 'foetex.dk',
 'user_id': 'admin'}
Traceback (most recent call last):
  File "C:\Users\Muhammad Umer\AppData\Local\Programs\Python\Python311\Lib\site-packages\django\db\backends\utils.py", line 89, in _execute
    return self.cursor.execute(sql, params)
           ^^^^^^^^^^^^^^^^^^^^^^^^^^^^^^^^
psycopg2.OperationalError: server closed the connection unexpectedly
	This probably means the server terminated abnormally
	before or while processing the request.
server closed the connection unexpectedly
	This probably means the server terminated abnormally
	before or while processing the request.


The above exception was the direct cause of the following exception:

Traceback (most recent call last):
  File "C:\Users\Muhammad Umer\AppData\Local\Programs\Python\Python311\Lib\site-packages\twisted\internet\defer.py", line 1065, in adapt
    extracted = result.result()
                ^^^^^^^^^^^^^^^
  File "C:\Users\Muhammad Umer\AppData\Local\Programs\Python\Python311\Lib\site-packages\asgiref\sync.py", line 448, in __call__
    ret = await asyncio.wait_for(future, timeout=None)
          ^^^^^^^^^^^^^^^^^^^^^^^^^^^^^^^^^^^^^^^^^^^^
  File "C:\Users\Muhammad Umer\AppData\Local\Programs\Python\Python311\Lib\asyncio\tasks.py", line 442, in wait_for
    return await fut
           ^^^^^^^^^
  File "C:\Users\Muhammad Umer\AppData\Local\Programs\Python\Python311\Lib\concurrent\futures\thread.py", line 58, in run
    result = self.fn(*self.args, **self.kwargs)
             ^^^^^^^^^^^^^^^^^^^^^^^^^^^^^^^^^^
  File "C:\Users\Muhammad Umer\AppData\Local\Programs\Python\Python311\Lib\site-packages\asgiref\sync.py", line 490, in thread_handler
    return func(*args, **kwargs)
           ^^^^^^^^^^^^^^^^^^^^^
  File "D:\Outputs\Django Outputs\scraper\pipelines.py", line 33, in process_item
    location = Location.objects.filter(country_code=item['country']).first()
               ^^^^^^^^^^^^^^^^^^^^^^^^^^^^^^^^^^^^^^^^^^^^^^^^^^^^^^^^^^^^^
  File "C:\Users\Muhammad Umer\AppData\Local\Programs\Python\Python311\Lib\site-packages\django\db\models\query.py", line 1047, in first
    for obj in (self if self.ordered else self.order_by("pk"))[:1]:
  File "C:\Users\Muhammad Umer\AppData\Local\Programs\Python\Python311\Lib\site-packages\django\db\models\query.py", line 394, in __iter__
    self._fetch_all()
  File "C:\Users\Muhammad Umer\AppData\Local\Programs\Python\Python311\Lib\site-packages\django\db\models\query.py", line 1867, in _fetch_all
    self._result_cache = list(self._iterable_class(self))
                         ^^^^^^^^^^^^^^^^^^^^^^^^^^^^^^^^
  File "C:\Users\Muhammad Umer\AppData\Local\Programs\Python\Python311\Lib\site-packages\django\db\models\query.py", line 87, in __iter__
    results = compiler.execute_sql(
              ^^^^^^^^^^^^^^^^^^^^^
  File "C:\Users\Muhammad Umer\AppData\Local\Programs\Python\Python311\Lib\site-packages\django\db\models\sql\compiler.py", line 1398, in execute_sql
    cursor.execute(sql, params)
  File "C:\Users\Muhammad Umer\AppData\Local\Programs\Python\Python311\Lib\site-packages\django\db\backends\utils.py", line 102, in execute
    return super().execute(sql, params)
           ^^^^^^^^^^^^^^^^^^^^^^^^^^^^
  File "C:\Users\Muhammad Umer\AppData\Local\Programs\Python\Python311\Lib\site-packages\django\db\backends\utils.py", line 67, in execute
    return self._execute_with_wrappers(
           ^^^^^^^^^^^^^^^^^^^^^^^^^^^^
  File "C:\Users\Muhammad Umer\AppData\Local\Programs\Python\Python311\Lib\site-packages\django\db\backends\utils.py", line 80, in _execute_with_wrappers
    return executor(sql, params, many, context)
           ^^^^^^^^^^^^^^^^^^^^^^^^^^^^^^^^^^^^
  File "C:\Users\Muhammad Umer\AppData\Local\Programs\Python\Python311\Lib\site-packages\django\db\backends\utils.py", line 84, in _execute
    with self.db.wrap_database_errors:
  File "C:\Users\Muhammad Umer\AppData\Local\Programs\Python\Python311\Lib\site-packages\django\db\utils.py", line 91, in __exit__
    raise dj_exc_value.with_traceback(traceback) from exc_value
  File "C:\Users\Muhammad Umer\AppData\Local\Programs\Python\Python311\Lib\site-packages\django\db\backends\utils.py", line 89, in _execute
    return self.cursor.execute(sql, params)
           ^^^^^^^^^^^^^^^^^^^^^^^^^^^^^^^^
django.db.utils.OperationalError: server closed the connection unexpectedly
	This probably means the server terminated abnormally
	before or while processing the request.
server closed the connection unexpectedly
	This probably means the server terminated abnormally
	before or while processing the request.

2023-09-23 18:35:46 [scrapy] ERROR: Error processing {'country': 'DK',
 'keyword': 'iphone 14',
 'position': 2,
 'price': '7.149,00\xa0kr.',
 'product_url': 'https://www.elgiganten.dk/product/mobil-tablet-smartwatch/mobiltelefon/iphone-14-5g-smartphone-128gb-midnight/522692',
 'title': 'iPhone 14 â€“ 5G smartphone 128GB Midnight',
 'url': 'elgiganten.dk',
 'user_id': 'admin'}
Traceback (most recent call last):
  File "C:\Users\Muhammad Umer\AppData\Local\Programs\Python\Python311\Lib\site-packages\django\db\backends\base\base.py", line 301, in _cursor
    return self._prepare_cursor(self.create_cursor(name))
                                ^^^^^^^^^^^^^^^^^^^^^^^^
  File "C:\Users\Muhammad Umer\AppData\Local\Programs\Python\Python311\Lib\site-packages\django\utils\asyncio.py", line 26, in inner
    return func(*args, **kwargs)
           ^^^^^^^^^^^^^^^^^^^^^
  File "C:\Users\Muhammad Umer\AppData\Local\Programs\Python\Python311\Lib\site-packages\django\db\backends\postgresql\base.py", line 269, in create_cursor
    cursor = self.connection.cursor()
             ^^^^^^^^^^^^^^^^^^^^^^^^
psycopg2.InterfaceError: connection already closed

The above exception was the direct cause of the following exception:

Traceback (most recent call last):
  File "C:\Users\Muhammad Umer\AppData\Local\Programs\Python\Python311\Lib\site-packages\twisted\internet\defer.py", line 1065, in adapt
    extracted = result.result()
                ^^^^^^^^^^^^^^^
  File "C:\Users\Muhammad Umer\AppData\Local\Programs\Python\Python311\Lib\site-packages\asgiref\sync.py", line 448, in __call__
    ret = await asyncio.wait_for(future, timeout=None)
          ^^^^^^^^^^^^^^^^^^^^^^^^^^^^^^^^^^^^^^^^^^^^
  File "C:\Users\Muhammad Umer\AppData\Local\Programs\Python\Python311\Lib\asyncio\tasks.py", line 442, in wait_for
    return await fut
           ^^^^^^^^^
  File "C:\Users\Muhammad Umer\AppData\Local\Programs\Python\Python311\Lib\concurrent\futures\thread.py", line 58, in run
    result = self.fn(*self.args, **self.kwargs)
             ^^^^^^^^^^^^^^^^^^^^^^^^^^^^^^^^^^
  File "C:\Users\Muhammad Umer\AppData\Local\Programs\Python\Python311\Lib\site-packages\asgiref\sync.py", line 490, in thread_handler
    return func(*args, **kwargs)
           ^^^^^^^^^^^^^^^^^^^^^
  File "D:\Outputs\Django Outputs\scraper\pipelines.py", line 33, in process_item
    location = Location.objects.filter(country_code=item['country']).first()
               ^^^^^^^^^^^^^^^^^^^^^^^^^^^^^^^^^^^^^^^^^^^^^^^^^^^^^^^^^^^^^
  File "C:\Users\Muhammad Umer\AppData\Local\Programs\Python\Python311\Lib\site-packages\django\db\models\query.py", line 1047, in first
    for obj in (self if self.ordered else self.order_by("pk"))[:1]:
  File "C:\Users\Muhammad Umer\AppData\Local\Programs\Python\Python311\Lib\site-packages\django\db\models\query.py", line 394, in __iter__
    self._fetch_all()
  File "C:\Users\Muhammad Umer\AppData\Local\Programs\Python\Python311\Lib\site-packages\django\db\models\query.py", line 1867, in _fetch_all
    self._result_cache = list(self._iterable_class(self))
                         ^^^^^^^^^^^^^^^^^^^^^^^^^^^^^^^^
  File "C:\Users\Muhammad Umer\AppData\Local\Programs\Python\Python311\Lib\site-packages\django\db\models\query.py", line 87, in __iter__
    results = compiler.execute_sql(
              ^^^^^^^^^^^^^^^^^^^^^
  File "C:\Users\Muhammad Umer\AppData\Local\Programs\Python\Python311\Lib\site-packages\django\db\models\sql\compiler.py", line 1396, in execute_sql
    cursor = self.connection.cursor()
             ^^^^^^^^^^^^^^^^^^^^^^^^
  File "C:\Users\Muhammad Umer\AppData\Local\Programs\Python\Python311\Lib\site-packages\django\utils\asyncio.py", line 26, in inner
    return func(*args, **kwargs)
           ^^^^^^^^^^^^^^^^^^^^^
  File "C:\Users\Muhammad Umer\AppData\Local\Programs\Python\Python311\Lib\site-packages\django\db\backends\base\base.py", line 323, in cursor
    return self._cursor()
           ^^^^^^^^^^^^^^
  File "C:\Users\Muhammad Umer\AppData\Local\Programs\Python\Python311\Lib\site-packages\django\db\backends\base\base.py", line 300, in _cursor
    with self.wrap_database_errors:
  File "C:\Users\Muhammad Umer\AppData\Local\Programs\Python\Python311\Lib\site-packages\django\db\utils.py", line 91, in __exit__
    raise dj_exc_value.with_traceback(traceback) from exc_value
  File "C:\Users\Muhammad Umer\AppData\Local\Programs\Python\Python311\Lib\site-packages\django\db\backends\base\base.py", line 301, in _cursor
    return self._prepare_cursor(self.create_cursor(name))
                                ^^^^^^^^^^^^^^^^^^^^^^^^
  File "C:\Users\Muhammad Umer\AppData\Local\Programs\Python\Python311\Lib\site-packages\django\utils\asyncio.py", line 26, in inner
    return func(*args, **kwargs)
           ^^^^^^^^^^^^^^^^^^^^^
  File "C:\Users\Muhammad Umer\AppData\Local\Programs\Python\Python311\Lib\site-packages\django\db\backends\postgresql\base.py", line 269, in create_cursor
    cursor = self.connection.cursor()
             ^^^^^^^^^^^^^^^^^^^^^^^^
django.db.utils.InterfaceError: connection already closed
2023-09-23 18:35:46 [scrapy] ERROR: Error processing {'country': 'DK',
 'keyword': 'iphone 14',
 'position': 3,
 'price': '6.666,00\xa0kr.',
 'product_url': 'https://www.power.dk/mobil-og-foto/mobiltelefoner/apple-iphone-14-128-gb-midnat/p-1803962/',
 'title': 'APPLE IPHONE 14 128 GB MIDNAT',
 'url': 'power.dk',
 'user_id': 'admin'}
Traceback (most recent call last):
  File "C:\Users\Muhammad Umer\AppData\Local\Programs\Python\Python311\Lib\site-packages\django\db\backends\base\base.py", line 301, in _cursor
    return self._prepare_cursor(self.create_cursor(name))
                                ^^^^^^^^^^^^^^^^^^^^^^^^
  File "C:\Users\Muhammad Umer\AppData\Local\Programs\Python\Python311\Lib\site-packages\django\utils\asyncio.py", line 26, in inner
    return func(*args, **kwargs)
           ^^^^^^^^^^^^^^^^^^^^^
  File "C:\Users\Muhammad Umer\AppData\Local\Programs\Python\Python311\Lib\site-packages\django\db\backends\postgresql\base.py", line 269, in create_cursor
    cursor = self.connection.cursor()
             ^^^^^^^^^^^^^^^^^^^^^^^^
psycopg2.InterfaceError: connection already closed

The above exception was the direct cause of the following exception:

Traceback (most recent call last):
  File "C:\Users\Muhammad Umer\AppData\Local\Programs\Python\Python311\Lib\site-packages\twisted\internet\defer.py", line 1065, in adapt
    extracted = result.result()
                ^^^^^^^^^^^^^^^
  File "C:\Users\Muhammad Umer\AppData\Local\Programs\Python\Python311\Lib\site-packages\asgiref\sync.py", line 448, in __call__
    ret = await asyncio.wait_for(future, timeout=None)
          ^^^^^^^^^^^^^^^^^^^^^^^^^^^^^^^^^^^^^^^^^^^^
  File "C:\Users\Muhammad Umer\AppData\Local\Programs\Python\Python311\Lib\asyncio\tasks.py", line 442, in wait_for
    return await fut
           ^^^^^^^^^
  File "C:\Users\Muhammad Umer\AppData\Local\Programs\Python\Python311\Lib\concurrent\futures\thread.py", line 58, in run
    result = self.fn(*self.args, **self.kwargs)
             ^^^^^^^^^^^^^^^^^^^^^^^^^^^^^^^^^^
  File "C:\Users\Muhammad Umer\AppData\Local\Programs\Python\Python311\Lib\site-packages\asgiref\sync.py", line 490, in thread_handler
    return func(*args, **kwargs)
           ^^^^^^^^^^^^^^^^^^^^^
  File "D:\Outputs\Django Outputs\scraper\pipelines.py", line 33, in process_item
    location = Location.objects.filter(country_code=item['country']).first()
               ^^^^^^^^^^^^^^^^^^^^^^^^^^^^^^^^^^^^^^^^^^^^^^^^^^^^^^^^^^^^^
  File "C:\Users\Muhammad Umer\AppData\Local\Programs\Python\Python311\Lib\site-packages\django\db\models\query.py", line 1047, in first
    for obj in (self if self.ordered else self.order_by("pk"))[:1]:
  File "C:\Users\Muhammad Umer\AppData\Local\Programs\Python\Python311\Lib\site-packages\django\db\models\query.py", line 394, in __iter__
    self._fetch_all()
  File "C:\Users\Muhammad Umer\AppData\Local\Programs\Python\Python311\Lib\site-packages\django\db\models\query.py", line 1867, in _fetch_all
    self._result_cache = list(self._iterable_class(self))
                         ^^^^^^^^^^^^^^^^^^^^^^^^^^^^^^^^
  File "C:\Users\Muhammad Umer\AppData\Local\Programs\Python\Python311\Lib\site-packages\django\db\models\query.py", line 87, in __iter__
    results = compiler.execute_sql(
              ^^^^^^^^^^^^^^^^^^^^^
  File "C:\Users\Muhammad Umer\AppData\Local\Programs\Python\Python311\Lib\site-packages\django\db\models\sql\compiler.py", line 1396, in execute_sql
    cursor = self.connection.cursor()
             ^^^^^^^^^^^^^^^^^^^^^^^^
  File "C:\Users\Muhammad Umer\AppData\Local\Programs\Python\Python311\Lib\site-packages\django\utils\asyncio.py", line 26, in inner
    return func(*args, **kwargs)
           ^^^^^^^^^^^^^^^^^^^^^
  File "C:\Users\Muhammad Umer\AppData\Local\Programs\Python\Python311\Lib\site-packages\django\db\backends\base\base.py", line 323, in cursor
    return self._cursor()
           ^^^^^^^^^^^^^^
  File "C:\Users\Muhammad Umer\AppData\Local\Programs\Python\Python311\Lib\site-packages\django\db\backends\base\base.py", line 300, in _cursor
    with self.wrap_database_errors:
  File "C:\Users\Muhammad Umer\AppData\Local\Programs\Python\Python311\Lib\site-packages\django\db\utils.py", line 91, in __exit__
    raise dj_exc_value.with_traceback(traceback) from exc_value
  File "C:\Users\Muhammad Umer\AppData\Local\Programs\Python\Python311\Lib\site-packages\django\db\backends\base\base.py", line 301, in _cursor
    return self._prepare_cursor(self.create_cursor(name))
                                ^^^^^^^^^^^^^^^^^^^^^^^^
  File "C:\Users\Muhammad Umer\AppData\Local\Programs\Python\Python311\Lib\site-packages\django\utils\asyncio.py", line 26, in inner
    return func(*args, **kwargs)
           ^^^^^^^^^^^^^^^^^^^^^
  File "C:\Users\Muhammad Umer\AppData\Local\Programs\Python\Python311\Lib\site-packages\django\db\backends\postgresql\base.py", line 269, in create_cursor
    cursor = self.connection.cursor()
             ^^^^^^^^^^^^^^^^^^^^^^^^
django.db.utils.InterfaceError: connection already closed
2023-09-23 18:35:46 [scrapy] ERROR: Error processing {'country': 'DK',
 'keyword': 'iphone 14',
 'position': 4,
 'price': '6.666,00\xa0kr.',
 'product_url': 'https://www.proshop.dk/Mobil/Apple-iPhone-14-5G-128GB-Midnight/3104588?utm_source=google&utm_medium=cpc&utm_campaign=searchengine',
 'title': 'Apple iPhone 14 5G 128GB - Midnight',
 'url': 'proshop.dk',
 'user_id': 'admin'}
Traceback (most recent call last):
  File "C:\Users\Muhammad Umer\AppData\Local\Programs\Python\Python311\Lib\site-packages\django\db\backends\base\base.py", line 301, in _cursor
    return self._prepare_cursor(self.create_cursor(name))
                                ^^^^^^^^^^^^^^^^^^^^^^^^
  File "C:\Users\Muhammad Umer\AppData\Local\Programs\Python\Python311\Lib\site-packages\django\utils\asyncio.py", line 26, in inner
    return func(*args, **kwargs)
           ^^^^^^^^^^^^^^^^^^^^^
  File "C:\Users\Muhammad Umer\AppData\Local\Programs\Python\Python311\Lib\site-packages\django\db\backends\postgresql\base.py", line 269, in create_cursor
    cursor = self.connection.cursor()
             ^^^^^^^^^^^^^^^^^^^^^^^^
psycopg2.InterfaceError: connection already closed

The above exception was the direct cause of the following exception:

Traceback (most recent call last):
  File "C:\Users\Muhammad Umer\AppData\Local\Programs\Python\Python311\Lib\site-packages\twisted\internet\defer.py", line 1065, in adapt
    extracted = result.result()
                ^^^^^^^^^^^^^^^
  File "C:\Users\Muhammad Umer\AppData\Local\Programs\Python\Python311\Lib\site-packages\asgiref\sync.py", line 448, in __call__
    ret = await asyncio.wait_for(future, timeout=None)
          ^^^^^^^^^^^^^^^^^^^^^^^^^^^^^^^^^^^^^^^^^^^^
  File "C:\Users\Muhammad Umer\AppData\Local\Programs\Python\Python311\Lib\asyncio\tasks.py", line 442, in wait_for
    return await fut
           ^^^^^^^^^
  File "C:\Users\Muhammad Umer\AppData\Local\Programs\Python\Python311\Lib\concurrent\futures\thread.py", line 58, in run
    result = self.fn(*self.args, **self.kwargs)
             ^^^^^^^^^^^^^^^^^^^^^^^^^^^^^^^^^^
  File "C:\Users\Muhammad Umer\AppData\Local\Programs\Python\Python311\Lib\site-packages\asgiref\sync.py", line 490, in thread_handler
    return func(*args, **kwargs)
           ^^^^^^^^^^^^^^^^^^^^^
  File "D:\Outputs\Django Outputs\scraper\pipelines.py", line 33, in process_item
    location = Location.objects.filter(country_code=item['country']).first()
               ^^^^^^^^^^^^^^^^^^^^^^^^^^^^^^^^^^^^^^^^^^^^^^^^^^^^^^^^^^^^^
  File "C:\Users\Muhammad Umer\AppData\Local\Programs\Python\Python311\Lib\site-packages\django\db\models\query.py", line 1047, in first
    for obj in (self if self.ordered else self.order_by("pk"))[:1]:
  File "C:\Users\Muhammad Umer\AppData\Local\Programs\Python\Python311\Lib\site-packages\django\db\models\query.py", line 394, in __iter__
    self._fetch_all()
  File "C:\Users\Muhammad Umer\AppData\Local\Programs\Python\Python311\Lib\site-packages\django\db\models\query.py", line 1867, in _fetch_all
    self._result_cache = list(self._iterable_class(self))
                         ^^^^^^^^^^^^^^^^^^^^^^^^^^^^^^^^
  File "C:\Users\Muhammad Umer\AppData\Local\Programs\Python\Python311\Lib\site-packages\django\db\models\query.py", line 87, in __iter__
    results = compiler.execute_sql(
              ^^^^^^^^^^^^^^^^^^^^^
  File "C:\Users\Muhammad Umer\AppData\Local\Programs\Python\Python311\Lib\site-packages\django\db\models\sql\compiler.py", line 1396, in execute_sql
    cursor = self.connection.cursor()
             ^^^^^^^^^^^^^^^^^^^^^^^^
  File "C:\Users\Muhammad Umer\AppData\Local\Programs\Python\Python311\Lib\site-packages\django\utils\asyncio.py", line 26, in inner
    return func(*args, **kwargs)
           ^^^^^^^^^^^^^^^^^^^^^
  File "C:\Users\Muhammad Umer\AppData\Local\Programs\Python\Python311\Lib\site-packages\django\db\backends\base\base.py", line 323, in cursor
    return self._cursor()
           ^^^^^^^^^^^^^^
  File "C:\Users\Muhammad Umer\AppData\Local\Programs\Python\Python311\Lib\site-packages\django\db\backends\base\base.py", line 300, in _cursor
    with self.wrap_database_errors:
  File "C:\Users\Muhammad Umer\AppData\Local\Programs\Python\Python311\Lib\site-packages\django\db\utils.py", line 91, in __exit__
    raise dj_exc_value.with_traceback(traceback) from exc_value
  File "C:\Users\Muhammad Umer\AppData\Local\Programs\Python\Python311\Lib\site-packages\django\db\backends\base\base.py", line 301, in _cursor
    return self._prepare_cursor(self.create_cursor(name))
                                ^^^^^^^^^^^^^^^^^^^^^^^^
  File "C:\Users\Muhammad Umer\AppData\Local\Programs\Python\Python311\Lib\site-packages\django\utils\asyncio.py", line 26, in inner
    return func(*args, **kwargs)
           ^^^^^^^^^^^^^^^^^^^^^
  File "C:\Users\Muhammad Umer\AppData\Local\Programs\Python\Python311\Lib\site-packages\django\db\backends\postgresql\base.py", line 269, in create_cursor
    cursor = self.connection.cursor()
             ^^^^^^^^^^^^^^^^^^^^^^^^
django.db.utils.InterfaceError: connection already closed
2023-09-23 18:35:46 [scrapy] ERROR: Error processing {'country': 'DK',
 'keyword': 'iphone 14',
 'position': 5,
 'price': '5.544,99\xa0kr.',
 'product_url': 'https://www.refurbed.dk/p/iphone-14/?co=dk&utm_cluster=gradeA&utm_content=iphone-14&utm_group=iphone-14',
 'title': '>> iPhone 14 <<',
 'url': 'refurbed.dk',
 'user_id': 'admin'}
Traceback (most recent call last):
  File "C:\Users\Muhammad Umer\AppData\Local\Programs\Python\Python311\Lib\site-packages\django\db\backends\base\base.py", line 301, in _cursor
    return self._prepare_cursor(self.create_cursor(name))
                                ^^^^^^^^^^^^^^^^^^^^^^^^
  File "C:\Users\Muhammad Umer\AppData\Local\Programs\Python\Python311\Lib\site-packages\django\utils\asyncio.py", line 26, in inner
    return func(*args, **kwargs)
           ^^^^^^^^^^^^^^^^^^^^^
  File "C:\Users\Muhammad Umer\AppData\Local\Programs\Python\Python311\Lib\site-packages\django\db\backends\postgresql\base.py", line 269, in create_cursor
    cursor = self.connection.cursor()
             ^^^^^^^^^^^^^^^^^^^^^^^^
psycopg2.InterfaceError: connection already closed

The above exception was the direct cause of the following exception:

Traceback (most recent call last):
  File "C:\Users\Muhammad Umer\AppData\Local\Programs\Python\Python311\Lib\site-packages\twisted\internet\defer.py", line 1065, in adapt
    extracted = result.result()
                ^^^^^^^^^^^^^^^
  File "C:\Users\Muhammad Umer\AppData\Local\Programs\Python\Python311\Lib\site-packages\asgiref\sync.py", line 448, in __call__
    ret = await asyncio.wait_for(future, timeout=None)
          ^^^^^^^^^^^^^^^^^^^^^^^^^^^^^^^^^^^^^^^^^^^^
  File "C:\Users\Muhammad Umer\AppData\Local\Programs\Python\Python311\Lib\asyncio\tasks.py", line 442, in wait_for
    return await fut
           ^^^^^^^^^
  File "C:\Users\Muhammad Umer\AppData\Local\Programs\Python\Python311\Lib\concurrent\futures\thread.py", line 58, in run
    result = self.fn(*self.args, **self.kwargs)
             ^^^^^^^^^^^^^^^^^^^^^^^^^^^^^^^^^^
  File "C:\Users\Muhammad Umer\AppData\Local\Programs\Python\Python311\Lib\site-packages\asgiref\sync.py", line 490, in thread_handler
    return func(*args, **kwargs)
           ^^^^^^^^^^^^^^^^^^^^^
  File "D:\Outputs\Django Outputs\scraper\pipelines.py", line 33, in process_item
    location = Location.objects.filter(country_code=item['country']).first()
               ^^^^^^^^^^^^^^^^^^^^^^^^^^^^^^^^^^^^^^^^^^^^^^^^^^^^^^^^^^^^^
  File "C:\Users\Muhammad Umer\AppData\Local\Programs\Python\Python311\Lib\site-packages\django\db\models\query.py", line 1047, in first
    for obj in (self if self.ordered else self.order_by("pk"))[:1]:
  File "C:\Users\Muhammad Umer\AppData\Local\Programs\Python\Python311\Lib\site-packages\django\db\models\query.py", line 394, in __iter__
    self._fetch_all()
  File "C:\Users\Muhammad Umer\AppData\Local\Programs\Python\Python311\Lib\site-packages\django\db\models\query.py", line 1867, in _fetch_all
    self._result_cache = list(self._iterable_class(self))
                         ^^^^^^^^^^^^^^^^^^^^^^^^^^^^^^^^
  File "C:\Users\Muhammad Umer\AppData\Local\Programs\Python\Python311\Lib\site-packages\django\db\models\query.py", line 87, in __iter__
    results = compiler.execute_sql(
              ^^^^^^^^^^^^^^^^^^^^^
  File "C:\Users\Muhammad Umer\AppData\Local\Programs\Python\Python311\Lib\site-packages\django\db\models\sql\compiler.py", line 1396, in execute_sql
    cursor = self.connection.cursor()
             ^^^^^^^^^^^^^^^^^^^^^^^^
  File "C:\Users\Muhammad Umer\AppData\Local\Programs\Python\Python311\Lib\site-packages\django\utils\asyncio.py", line 26, in inner
    return func(*args, **kwargs)
           ^^^^^^^^^^^^^^^^^^^^^
  File "C:\Users\Muhammad Umer\AppData\Local\Programs\Python\Python311\Lib\site-packages\django\db\backends\base\base.py", line 323, in cursor
    return self._cursor()
           ^^^^^^^^^^^^^^
  File "C:\Users\Muhammad Umer\AppData\Local\Programs\Python\Python311\Lib\site-packages\django\db\backends\base\base.py", line 300, in _cursor
    with self.wrap_database_errors:
  File "C:\Users\Muhammad Umer\AppData\Local\Programs\Python\Python311\Lib\site-packages\django\db\utils.py", line 91, in __exit__
    raise dj_exc_value.with_traceback(traceback) from exc_value
  File "C:\Users\Muhammad Umer\AppData\Local\Programs\Python\Python311\Lib\site-packages\django\db\backends\base\base.py", line 301, in _cursor
    return self._prepare_cursor(self.create_cursor(name))
                                ^^^^^^^^^^^^^^^^^^^^^^^^
  File "C:\Users\Muhammad Umer\AppData\Local\Programs\Python\Python311\Lib\site-packages\django\utils\asyncio.py", line 26, in inner
    return func(*args, **kwargs)
           ^^^^^^^^^^^^^^^^^^^^^
  File "C:\Users\Muhammad Umer\AppData\Local\Programs\Python\Python311\Lib\site-packages\django\db\backends\postgresql\base.py", line 269, in create_cursor
    cursor = self.connection.cursor()
             ^^^^^^^^^^^^^^^^^^^^^^^^
django.db.utils.InterfaceError: connection already closed
2023-09-23 18:35:46 [scrapy] ERROR: Error processing {'country': 'DK',
 'keyword': 'iphone 14',
 'position': 6,
 'price': '5.281,00\xa0kr.',
 'product_url': 'https://yousee.dk/mobil/mobiltelefoner/apple/iphone-14/1468/mobil_80/kontant/',
 'title': 'Apple iPhone 14 128 GB Midnat med abonnementsaftale. Mindstepris '
          '6.595,00 kr.',
 'url': 'yousee.dk',
 'user_id': 'admin'}
Traceback (most recent call last):
  File "C:\Users\Muhammad Umer\AppData\Local\Programs\Python\Python311\Lib\site-packages\django\db\backends\base\base.py", line 301, in _cursor
    return self._prepare_cursor(self.create_cursor(name))
                                ^^^^^^^^^^^^^^^^^^^^^^^^
  File "C:\Users\Muhammad Umer\AppData\Local\Programs\Python\Python311\Lib\site-packages\django\utils\asyncio.py", line 26, in inner
    return func(*args, **kwargs)
           ^^^^^^^^^^^^^^^^^^^^^
  File "C:\Users\Muhammad Umer\AppData\Local\Programs\Python\Python311\Lib\site-packages\django\db\backends\postgresql\base.py", line 269, in create_cursor
    cursor = self.connection.cursor()
             ^^^^^^^^^^^^^^^^^^^^^^^^
psycopg2.InterfaceError: connection already closed

The above exception was the direct cause of the following exception:

Traceback (most recent call last):
  File "C:\Users\Muhammad Umer\AppData\Local\Programs\Python\Python311\Lib\site-packages\twisted\internet\defer.py", line 1065, in adapt
    extracted = result.result()
                ^^^^^^^^^^^^^^^
  File "C:\Users\Muhammad Umer\AppData\Local\Programs\Python\Python311\Lib\site-packages\asgiref\sync.py", line 448, in __call__
    ret = await asyncio.wait_for(future, timeout=None)
          ^^^^^^^^^^^^^^^^^^^^^^^^^^^^^^^^^^^^^^^^^^^^
  File "C:\Users\Muhammad Umer\AppData\Local\Programs\Python\Python311\Lib\asyncio\tasks.py", line 442, in wait_for
    return await fut
           ^^^^^^^^^
  File "C:\Users\Muhammad Umer\AppData\Local\Programs\Python\Python311\Lib\concurrent\futures\thread.py", line 58, in run
    result = self.fn(*self.args, **self.kwargs)
             ^^^^^^^^^^^^^^^^^^^^^^^^^^^^^^^^^^
  File "C:\Users\Muhammad Umer\AppData\Local\Programs\Python\Python311\Lib\site-packages\asgiref\sync.py", line 490, in thread_handler
    return func(*args, **kwargs)
           ^^^^^^^^^^^^^^^^^^^^^
  File "D:\Outputs\Django Outputs\scraper\pipelines.py", line 33, in process_item
    location = Location.objects.filter(country_code=item['country']).first()
               ^^^^^^^^^^^^^^^^^^^^^^^^^^^^^^^^^^^^^^^^^^^^^^^^^^^^^^^^^^^^^
  File "C:\Users\Muhammad Umer\AppData\Local\Programs\Python\Python311\Lib\site-packages\django\db\models\query.py", line 1047, in first
    for obj in (self if self.ordered else self.order_by("pk"))[:1]:
  File "C:\Users\Muhammad Umer\AppData\Local\Programs\Python\Python311\Lib\site-packages\django\db\models\query.py", line 394, in __iter__
    self._fetch_all()
  File "C:\Users\Muhammad Umer\AppData\Local\Programs\Python\Python311\Lib\site-packages\django\db\models\query.py", line 1867, in _fetch_all
    self._result_cache = list(self._iterable_class(self))
                         ^^^^^^^^^^^^^^^^^^^^^^^^^^^^^^^^
  File "C:\Users\Muhammad Umer\AppData\Local\Programs\Python\Python311\Lib\site-packages\django\db\models\query.py", line 87, in __iter__
    results = compiler.execute_sql(
              ^^^^^^^^^^^^^^^^^^^^^
  File "C:\Users\Muhammad Umer\AppData\Local\Programs\Python\Python311\Lib\site-packages\django\db\models\sql\compiler.py", line 1396, in execute_sql
    cursor = self.connection.cursor()
             ^^^^^^^^^^^^^^^^^^^^^^^^
  File "C:\Users\Muhammad Umer\AppData\Local\Programs\Python\Python311\Lib\site-packages\django\utils\asyncio.py", line 26, in inner
    return func(*args, **kwargs)
           ^^^^^^^^^^^^^^^^^^^^^
  File "C:\Users\Muhammad Umer\AppData\Local\Programs\Python\Python311\Lib\site-packages\django\db\backends\base\base.py", line 323, in cursor
    return self._cursor()
           ^^^^^^^^^^^^^^
  File "C:\Users\Muhammad Umer\AppData\Local\Programs\Python\Python311\Lib\site-packages\django\db\backends\base\base.py", line 300, in _cursor
    with self.wrap_database_errors:
  File "C:\Users\Muhammad Umer\AppData\Local\Programs\Python\Python311\Lib\site-packages\django\db\utils.py", line 91, in __exit__
    raise dj_exc_value.with_traceback(traceback) from exc_value
  File "C:\Users\Muhammad Umer\AppData\Local\Programs\Python\Python311\Lib\site-packages\django\db\backends\base\base.py", line 301, in _cursor
    return self._prepare_cursor(self.create_cursor(name))
                                ^^^^^^^^^^^^^^^^^^^^^^^^
  File "C:\Users\Muhammad Umer\AppData\Local\Programs\Python\Python311\Lib\site-packages\django\utils\asyncio.py", line 26, in inner
    return func(*args, **kwargs)
           ^^^^^^^^^^^^^^^^^^^^^
  File "C:\Users\Muhammad Umer\AppData\Local\Programs\Python\Python311\Lib\site-packages\django\db\backends\postgresql\base.py", line 269, in create_cursor
    cursor = self.connection.cursor()
             ^^^^^^^^^^^^^^^^^^^^^^^^
django.db.utils.InterfaceError: connection already closed
2023-09-23 18:35:46 [scrapy] ERROR: Error processing {'country': 'DK',
 'keyword': 'iphone 14',
 'position': 7,
 'price': '4.799,00\xa0kr.',
 'product_url': 'https://www.telenor.dk/shop/mobil/apple/apple-iphone-13--128gb-midnight/?cycleCount=none',
 'title': 'Apple iPhone 13 - 128 GB - Midnight med abonnementsaftale. '
          'Mindstepris 6413.00 Kr.',
 'url': 'telenor.dk',
 'user_id': 'admin'}
Traceback (most recent call last):
  File "C:\Users\Muhammad Umer\AppData\Local\Programs\Python\Python311\Lib\site-packages\django\db\backends\base\base.py", line 301, in _cursor
    return self._prepare_cursor(self.create_cursor(name))
                                ^^^^^^^^^^^^^^^^^^^^^^^^
  File "C:\Users\Muhammad Umer\AppData\Local\Programs\Python\Python311\Lib\site-packages\django\utils\asyncio.py", line 26, in inner
    return func(*args, **kwargs)
           ^^^^^^^^^^^^^^^^^^^^^
  File "C:\Users\Muhammad Umer\AppData\Local\Programs\Python\Python311\Lib\site-packages\django\db\backends\postgresql\base.py", line 269, in create_cursor
    cursor = self.connection.cursor()
             ^^^^^^^^^^^^^^^^^^^^^^^^
psycopg2.InterfaceError: connection already closed

The above exception was the direct cause of the following exception:

Traceback (most recent call last):
  File "C:\Users\Muhammad Umer\AppData\Local\Programs\Python\Python311\Lib\site-packages\twisted\internet\defer.py", line 1065, in adapt
    extracted = result.result()
                ^^^^^^^^^^^^^^^
  File "C:\Users\Muhammad Umer\AppData\Local\Programs\Python\Python311\Lib\site-packages\asgiref\sync.py", line 448, in __call__
    ret = await asyncio.wait_for(future, timeout=None)
          ^^^^^^^^^^^^^^^^^^^^^^^^^^^^^^^^^^^^^^^^^^^^
  File "C:\Users\Muhammad Umer\AppData\Local\Programs\Python\Python311\Lib\asyncio\tasks.py", line 442, in wait_for
    return await fut
           ^^^^^^^^^
  File "C:\Users\Muhammad Umer\AppData\Local\Programs\Python\Python311\Lib\concurrent\futures\thread.py", line 58, in run
    result = self.fn(*self.args, **self.kwargs)
             ^^^^^^^^^^^^^^^^^^^^^^^^^^^^^^^^^^
  File "C:\Users\Muhammad Umer\AppData\Local\Programs\Python\Python311\Lib\site-packages\asgiref\sync.py", line 490, in thread_handler
    return func(*args, **kwargs)
           ^^^^^^^^^^^^^^^^^^^^^
  File "D:\Outputs\Django Outputs\scraper\pipelines.py", line 33, in process_item
    location = Location.objects.filter(country_code=item['country']).first()
               ^^^^^^^^^^^^^^^^^^^^^^^^^^^^^^^^^^^^^^^^^^^^^^^^^^^^^^^^^^^^^
  File "C:\Users\Muhammad Umer\AppData\Local\Programs\Python\Python311\Lib\site-packages\django\db\models\query.py", line 1047, in first
    for obj in (self if self.ordered else self.order_by("pk"))[:1]:
  File "C:\Users\Muhammad Umer\AppData\Local\Programs\Python\Python311\Lib\site-packages\django\db\models\query.py", line 394, in __iter__
    self._fetch_all()
  File "C:\Users\Muhammad Umer\AppData\Local\Programs\Python\Python311\Lib\site-packages\django\db\models\query.py", line 1867, in _fetch_all
    self._result_cache = list(self._iterable_class(self))
                         ^^^^^^^^^^^^^^^^^^^^^^^^^^^^^^^^
  File "C:\Users\Muhammad Umer\AppData\Local\Programs\Python\Python311\Lib\site-packages\django\db\models\query.py", line 87, in __iter__
    results = compiler.execute_sql(
              ^^^^^^^^^^^^^^^^^^^^^
  File "C:\Users\Muhammad Umer\AppData\Local\Programs\Python\Python311\Lib\site-packages\django\db\models\sql\compiler.py", line 1396, in execute_sql
    cursor = self.connection.cursor()
             ^^^^^^^^^^^^^^^^^^^^^^^^
  File "C:\Users\Muhammad Umer\AppData\Local\Programs\Python\Python311\Lib\site-packages\django\utils\asyncio.py", line 26, in inner
    return func(*args, **kwargs)
           ^^^^^^^^^^^^^^^^^^^^^
  File "C:\Users\Muhammad Umer\AppData\Local\Programs\Python\Python311\Lib\site-packages\django\db\backends\base\base.py", line 323, in cursor
    return self._cursor()
           ^^^^^^^^^^^^^^
  File "C:\Users\Muhammad Umer\AppData\Local\Programs\Python\Python311\Lib\site-packages\django\db\backends\base\base.py", line 300, in _cursor
    with self.wrap_database_errors:
  File "C:\Users\Muhammad Umer\AppData\Local\Programs\Python\Python311\Lib\site-packages\django\db\utils.py", line 91, in __exit__
    raise dj_exc_value.with_traceback(traceback) from exc_value
  File "C:\Users\Muhammad Umer\AppData\Local\Programs\Python\Python311\Lib\site-packages\django\db\backends\base\base.py", line 301, in _cursor
    return self._prepare_cursor(self.create_cursor(name))
                                ^^^^^^^^^^^^^^^^^^^^^^^^
  File "C:\Users\Muhammad Umer\AppData\Local\Programs\Python\Python311\Lib\site-packages\django\utils\asyncio.py", line 26, in inner
    return func(*args, **kwargs)
           ^^^^^^^^^^^^^^^^^^^^^
  File "C:\Users\Muhammad Umer\AppData\Local\Programs\Python\Python311\Lib\site-packages\django\db\backends\postgresql\base.py", line 269, in create_cursor
    cursor = self.connection.cursor()
             ^^^^^^^^^^^^^^^^^^^^^^^^
django.db.utils.InterfaceError: connection already closed
2023-09-23 18:35:46 [scrapy] ERROR: Error processing {'country': 'DK',
 'keyword': 'iphone 14',
 'position': 8,
 'price': '5.729,00\xa0kr.',
 'product_url': 'https://swappie.com/dk/iphone/iphone-14/iphone-14-128gb-bla-18/',
 'title': 'iPhone 14 128GB BlÃ¥ Apple',
 'url': 'swappie.com',
 'user_id': 'admin'}
Traceback (most recent call last):
  File "C:\Users\Muhammad Umer\AppData\Local\Programs\Python\Python311\Lib\site-packages\django\db\backends\base\base.py", line 301, in _cursor
    return self._prepare_cursor(self.create_cursor(name))
                                ^^^^^^^^^^^^^^^^^^^^^^^^
  File "C:\Users\Muhammad Umer\AppData\Local\Programs\Python\Python311\Lib\site-packages\django\utils\asyncio.py", line 26, in inner
    return func(*args, **kwargs)
           ^^^^^^^^^^^^^^^^^^^^^
  File "C:\Users\Muhammad Umer\AppData\Local\Programs\Python\Python311\Lib\site-packages\django\db\backends\postgresql\base.py", line 269, in create_cursor
    cursor = self.connection.cursor()
             ^^^^^^^^^^^^^^^^^^^^^^^^
psycopg2.InterfaceError: connection already closed

The above exception was the direct cause of the following exception:

Traceback (most recent call last):
  File "C:\Users\Muhammad Umer\AppData\Local\Programs\Python\Python311\Lib\site-packages\twisted\internet\defer.py", line 1065, in adapt
    extracted = result.result()
                ^^^^^^^^^^^^^^^
  File "C:\Users\Muhammad Umer\AppData\Local\Programs\Python\Python311\Lib\site-packages\asgiref\sync.py", line 448, in __call__
    ret = await asyncio.wait_for(future, timeout=None)
          ^^^^^^^^^^^^^^^^^^^^^^^^^^^^^^^^^^^^^^^^^^^^
  File "C:\Users\Muhammad Umer\AppData\Local\Programs\Python\Python311\Lib\asyncio\tasks.py", line 442, in wait_for
    return await fut
           ^^^^^^^^^
  File "C:\Users\Muhammad Umer\AppData\Local\Programs\Python\Python311\Lib\concurrent\futures\thread.py", line 58, in run
    result = self.fn(*self.args, **self.kwargs)
             ^^^^^^^^^^^^^^^^^^^^^^^^^^^^^^^^^^
  File "C:\Users\Muhammad Umer\AppData\Local\Programs\Python\Python311\Lib\site-packages\asgiref\sync.py", line 490, in thread_handler
    return func(*args, **kwargs)
           ^^^^^^^^^^^^^^^^^^^^^
  File "D:\Outputs\Django Outputs\scraper\pipelines.py", line 33, in process_item
    location = Location.objects.filter(country_code=item['country']).first()
               ^^^^^^^^^^^^^^^^^^^^^^^^^^^^^^^^^^^^^^^^^^^^^^^^^^^^^^^^^^^^^
  File "C:\Users\Muhammad Umer\AppData\Local\Programs\Python\Python311\Lib\site-packages\django\db\models\query.py", line 1047, in first
    for obj in (self if self.ordered else self.order_by("pk"))[:1]:
  File "C:\Users\Muhammad Umer\AppData\Local\Programs\Python\Python311\Lib\site-packages\django\db\models\query.py", line 394, in __iter__
    self._fetch_all()
  File "C:\Users\Muhammad Umer\AppData\Local\Programs\Python\Python311\Lib\site-packages\django\db\models\query.py", line 1867, in _fetch_all
    self._result_cache = list(self._iterable_class(self))
                         ^^^^^^^^^^^^^^^^^^^^^^^^^^^^^^^^
  File "C:\Users\Muhammad Umer\AppData\Local\Programs\Python\Python311\Lib\site-packages\django\db\models\query.py", line 87, in __iter__
    results = compiler.execute_sql(
              ^^^^^^^^^^^^^^^^^^^^^
  File "C:\Users\Muhammad Umer\AppData\Local\Programs\Python\Python311\Lib\site-packages\django\db\models\sql\compiler.py", line 1396, in execute_sql
    cursor = self.connection.cursor()
             ^^^^^^^^^^^^^^^^^^^^^^^^
  File "C:\Users\Muhammad Umer\AppData\Local\Programs\Python\Python311\Lib\site-packages\django\utils\asyncio.py", line 26, in inner
    return func(*args, **kwargs)
           ^^^^^^^^^^^^^^^^^^^^^
  File "C:\Users\Muhammad Umer\AppData\Local\Programs\Python\Python311\Lib\site-packages\django\db\backends\base\base.py", line 323, in cursor
    return self._cursor()
           ^^^^^^^^^^^^^^
  File "C:\Users\Muhammad Umer\AppData\Local\Programs\Python\Python311\Lib\site-packages\django\db\backends\base\base.py", line 300, in _cursor
    with self.wrap_database_errors:
  File "C:\Users\Muhammad Umer\AppData\Local\Programs\Python\Python311\Lib\site-packages\django\db\utils.py", line 91, in __exit__
    raise dj_exc_value.with_traceback(traceback) from exc_value
  File "C:\Users\Muhammad Umer\AppData\Local\Programs\Python\Python311\Lib\site-packages\django\db\backends\base\base.py", line 301, in _cursor
    return self._prepare_cursor(self.create_cursor(name))
                                ^^^^^^^^^^^^^^^^^^^^^^^^
  File "C:\Users\Muhammad Umer\AppData\Local\Programs\Python\Python311\Lib\site-packages\django\utils\asyncio.py", line 26, in inner
    return func(*args, **kwargs)
           ^^^^^^^^^^^^^^^^^^^^^
  File "C:\Users\Muhammad Umer\AppData\Local\Programs\Python\Python311\Lib\site-packages\django\db\backends\postgresql\base.py", line 269, in create_cursor
    cursor = self.connection.cursor()
             ^^^^^^^^^^^^^^^^^^^^^^^^
django.db.utils.InterfaceError: connection already closed
2023-09-23 18:35:46 [scrapy] ERROR: Error processing {'country': 'DK',
 'keyword': 'iphone 14',
 'position': 9,
 'price': '6.299,00\xa0kr.',
 'product_url': 'https://www.foetex.dk/produkter/iphone-14-128gb-purple/200162610/',
 'title': '"iPhone 14 128GB - Purple"',
 'url': 'foetex.dk',
 'user_id': 'admin'}
Traceback (most recent call last):
  File "C:\Users\Muhammad Umer\AppData\Local\Programs\Python\Python311\Lib\site-packages\django\db\backends\base\base.py", line 301, in _cursor
    return self._prepare_cursor(self.create_cursor(name))
                                ^^^^^^^^^^^^^^^^^^^^^^^^
  File "C:\Users\Muhammad Umer\AppData\Local\Programs\Python\Python311\Lib\site-packages\django\utils\asyncio.py", line 26, in inner
    return func(*args, **kwargs)
           ^^^^^^^^^^^^^^^^^^^^^
  File "C:\Users\Muhammad Umer\AppData\Local\Programs\Python\Python311\Lib\site-packages\django\db\backends\postgresql\base.py", line 269, in create_cursor
    cursor = self.connection.cursor()
             ^^^^^^^^^^^^^^^^^^^^^^^^
psycopg2.InterfaceError: connection already closed

The above exception was the direct cause of the following exception:

Traceback (most recent call last):
  File "C:\Users\Muhammad Umer\AppData\Local\Programs\Python\Python311\Lib\site-packages\twisted\internet\defer.py", line 1065, in adapt
    extracted = result.result()
                ^^^^^^^^^^^^^^^
  File "C:\Users\Muhammad Umer\AppData\Local\Programs\Python\Python311\Lib\site-packages\asgiref\sync.py", line 448, in __call__
    ret = await asyncio.wait_for(future, timeout=None)
          ^^^^^^^^^^^^^^^^^^^^^^^^^^^^^^^^^^^^^^^^^^^^
  File "C:\Users\Muhammad Umer\AppData\Local\Programs\Python\Python311\Lib\asyncio\tasks.py", line 442, in wait_for
    return await fut
           ^^^^^^^^^
  File "C:\Users\Muhammad Umer\AppData\Local\Programs\Python\Python311\Lib\concurrent\futures\thread.py", line 58, in run
    result = self.fn(*self.args, **self.kwargs)
             ^^^^^^^^^^^^^^^^^^^^^^^^^^^^^^^^^^
  File "C:\Users\Muhammad Umer\AppData\Local\Programs\Python\Python311\Lib\site-packages\asgiref\sync.py", line 490, in thread_handler
    return func(*args, **kwargs)
           ^^^^^^^^^^^^^^^^^^^^^
  File "D:\Outputs\Django Outputs\scraper\pipelines.py", line 33, in process_item
    location = Location.objects.filter(country_code=item['country']).first()
               ^^^^^^^^^^^^^^^^^^^^^^^^^^^^^^^^^^^^^^^^^^^^^^^^^^^^^^^^^^^^^
  File "C:\Users\Muhammad Umer\AppData\Local\Programs\Python\Python311\Lib\site-packages\django\db\models\query.py", line 1047, in first
    for obj in (self if self.ordered else self.order_by("pk"))[:1]:
  File "C:\Users\Muhammad Umer\AppData\Local\Programs\Python\Python311\Lib\site-packages\django\db\models\query.py", line 394, in __iter__
    self._fetch_all()
  File "C:\Users\Muhammad Umer\AppData\Local\Programs\Python\Python311\Lib\site-packages\django\db\models\query.py", line 1867, in _fetch_all
    self._result_cache = list(self._iterable_class(self))
                         ^^^^^^^^^^^^^^^^^^^^^^^^^^^^^^^^
  File "C:\Users\Muhammad Umer\AppData\Local\Programs\Python\Python311\Lib\site-packages\django\db\models\query.py", line 87, in __iter__
    results = compiler.execute_sql(
              ^^^^^^^^^^^^^^^^^^^^^
  File "C:\Users\Muhammad Umer\AppData\Local\Programs\Python\Python311\Lib\site-packages\django\db\models\sql\compiler.py", line 1396, in execute_sql
    cursor = self.connection.cursor()
             ^^^^^^^^^^^^^^^^^^^^^^^^
  File "C:\Users\Muhammad Umer\AppData\Local\Programs\Python\Python311\Lib\site-packages\django\utils\asyncio.py", line 26, in inner
    return func(*args, **kwargs)
           ^^^^^^^^^^^^^^^^^^^^^
  File "C:\Users\Muhammad Umer\AppData\Local\Programs\Python\Python311\Lib\site-packages\django\db\backends\base\base.py", line 323, in cursor
    return self._cursor()
           ^^^^^^^^^^^^^^
  File "C:\Users\Muhammad Umer\AppData\Local\Programs\Python\Python311\Lib\site-packages\django\db\backends\base\base.py", line 300, in _cursor
    with self.wrap_database_errors:
  File "C:\Users\Muhammad Umer\AppData\Local\Programs\Python\Python311\Lib\site-packages\django\db\utils.py", line 91, in __exit__
    raise dj_exc_value.with_traceback(traceback) from exc_value
  File "C:\Users\Muhammad Umer\AppData\Local\Programs\Python\Python311\Lib\site-packages\django\db\backends\base\base.py", line 301, in _cursor
    return self._prepare_cursor(self.create_cursor(name))
                                ^^^^^^^^^^^^^^^^^^^^^^^^
  File "C:\Users\Muhammad Umer\AppData\Local\Programs\Python\Python311\Lib\site-packages\django\utils\asyncio.py", line 26, in inner
    return func(*args, **kwargs)
           ^^^^^^^^^^^^^^^^^^^^^
  File "C:\Users\Muhammad Umer\AppData\Local\Programs\Python\Python311\Lib\site-packages\django\db\backends\postgresql\base.py", line 269, in create_cursor
    cursor = self.connection.cursor()
             ^^^^^^^^^^^^^^^^^^^^^^^^
django.db.utils.InterfaceError: connection already closed
2023-09-23 18:35:46 [scrapy] ERROR: Error processing {'country': 'DK',
 'keyword': 'iphone 14',
 'position': 10,
 'price': '5.552,99\xa0kr.',
 'product_url': 'https://www.refurbed.dk/p/iphone-14/40928c/?co=dk&utm_cluster=gradeC&utm_content=iphone-14-40928c&utm_group=iphone-14',
 'title': 'iPhone 14 | 128 GB | Dual-SIM | blÃ¥',
 'url': 'refurbed.dk',
 'user_id': 'admin'}
Traceback (most recent call last):
  File "C:\Users\Muhammad Umer\AppData\Local\Programs\Python\Python311\Lib\site-packages\django\db\backends\base\base.py", line 301, in _cursor
    return self._prepare_cursor(self.create_cursor(name))
                                ^^^^^^^^^^^^^^^^^^^^^^^^
  File "C:\Users\Muhammad Umer\AppData\Local\Programs\Python\Python311\Lib\site-packages\django\utils\asyncio.py", line 26, in inner
    return func(*args, **kwargs)
           ^^^^^^^^^^^^^^^^^^^^^
  File "C:\Users\Muhammad Umer\AppData\Local\Programs\Python\Python311\Lib\site-packages\django\db\backends\postgresql\base.py", line 269, in create_cursor
    cursor = self.connection.cursor()
             ^^^^^^^^^^^^^^^^^^^^^^^^
psycopg2.InterfaceError: connection already closed

The above exception was the direct cause of the following exception:

Traceback (most recent call last):
  File "C:\Users\Muhammad Umer\AppData\Local\Programs\Python\Python311\Lib\site-packages\twisted\internet\defer.py", line 1065, in adapt
    extracted = result.result()
                ^^^^^^^^^^^^^^^
  File "C:\Users\Muhammad Umer\AppData\Local\Programs\Python\Python311\Lib\site-packages\asgiref\sync.py", line 448, in __call__
    ret = await asyncio.wait_for(future, timeout=None)
          ^^^^^^^^^^^^^^^^^^^^^^^^^^^^^^^^^^^^^^^^^^^^
  File "C:\Users\Muhammad Umer\AppData\Local\Programs\Python\Python311\Lib\asyncio\tasks.py", line 442, in wait_for
    return await fut
           ^^^^^^^^^
  File "C:\Users\Muhammad Umer\AppData\Local\Programs\Python\Python311\Lib\concurrent\futures\thread.py", line 58, in run
    result = self.fn(*self.args, **self.kwargs)
             ^^^^^^^^^^^^^^^^^^^^^^^^^^^^^^^^^^
  File "C:\Users\Muhammad Umer\AppData\Local\Programs\Python\Python311\Lib\site-packages\asgiref\sync.py", line 490, in thread_handler
    return func(*args, **kwargs)
           ^^^^^^^^^^^^^^^^^^^^^
  File "D:\Outputs\Django Outputs\scraper\pipelines.py", line 33, in process_item
    location = Location.objects.filter(country_code=item['country']).first()
               ^^^^^^^^^^^^^^^^^^^^^^^^^^^^^^^^^^^^^^^^^^^^^^^^^^^^^^^^^^^^^
  File "C:\Users\Muhammad Umer\AppData\Local\Programs\Python\Python311\Lib\site-packages\django\db\models\query.py", line 1047, in first
    for obj in (self if self.ordered else self.order_by("pk"))[:1]:
  File "C:\Users\Muhammad Umer\AppData\Local\Programs\Python\Python311\Lib\site-packages\django\db\models\query.py", line 394, in __iter__
    self._fetch_all()
  File "C:\Users\Muhammad Umer\AppData\Local\Programs\Python\Python311\Lib\site-packages\django\db\models\query.py", line 1867, in _fetch_all
    self._result_cache = list(self._iterable_class(self))
                         ^^^^^^^^^^^^^^^^^^^^^^^^^^^^^^^^
  File "C:\Users\Muhammad Umer\AppData\Local\Programs\Python\Python311\Lib\site-packages\django\db\models\query.py", line 87, in __iter__
    results = compiler.execute_sql(
              ^^^^^^^^^^^^^^^^^^^^^
  File "C:\Users\Muhammad Umer\AppData\Local\Programs\Python\Python311\Lib\site-packages\django\db\models\sql\compiler.py", line 1396, in execute_sql
    cursor = self.connection.cursor()
             ^^^^^^^^^^^^^^^^^^^^^^^^
  File "C:\Users\Muhammad Umer\AppData\Local\Programs\Python\Python311\Lib\site-packages\django\utils\asyncio.py", line 26, in inner
    return func(*args, **kwargs)
           ^^^^^^^^^^^^^^^^^^^^^
  File "C:\Users\Muhammad Umer\AppData\Local\Programs\Python\Python311\Lib\site-packages\django\db\backends\base\base.py", line 323, in cursor
    return self._cursor()
           ^^^^^^^^^^^^^^
  File "C:\Users\Muhammad Umer\AppData\Local\Programs\Python\Python311\Lib\site-packages\django\db\backends\base\base.py", line 300, in _cursor
    with self.wrap_database_errors:
  File "C:\Users\Muhammad Umer\AppData\Local\Programs\Python\Python311\Lib\site-packages\django\db\utils.py", line 91, in __exit__
    raise dj_exc_value.with_traceback(traceback) from exc_value
  File "C:\Users\Muhammad Umer\AppData\Local\Programs\Python\Python311\Lib\site-packages\django\db\backends\base\base.py", line 301, in _cursor
    return self._prepare_cursor(self.create_cursor(name))
                                ^^^^^^^^^^^^^^^^^^^^^^^^
  File "C:\Users\Muhammad Umer\AppData\Local\Programs\Python\Python311\Lib\site-packages\django\utils\asyncio.py", line 26, in inner
    return func(*args, **kwargs)
           ^^^^^^^^^^^^^^^^^^^^^
  File "C:\Users\Muhammad Umer\AppData\Local\Programs\Python\Python311\Lib\site-packages\django\db\backends\postgresql\base.py", line 269, in create_cursor
    cursor = self.connection.cursor()
             ^^^^^^^^^^^^^^^^^^^^^^^^
django.db.utils.InterfaceError: connection already closed
2023-09-23 18:35:46 [scrapy] ERROR: Error processing {'country': 'DK',
 'keyword': 'iphone 14',
 'position': 11,
 'price': '5.496,00\xa0kr.',
 'product_url': 'https://www.telmore.dk/shop/mobiltelefoner/Apple/iphone-14?cid=_semt_terminal_terminal_Shopping_Shopping_u0617',
 'title': 'Apple iPhone 14 128 GB - Midnight. Mindstepris 7.290,00 kr.',
 'url': 'telmore.dk',
 'user_id': 'admin'}
Traceback (most recent call last):
  File "C:\Users\Muhammad Umer\AppData\Local\Programs\Python\Python311\Lib\site-packages\django\db\backends\base\base.py", line 301, in _cursor
    return self._prepare_cursor(self.create_cursor(name))
                                ^^^^^^^^^^^^^^^^^^^^^^^^
  File "C:\Users\Muhammad Umer\AppData\Local\Programs\Python\Python311\Lib\site-packages\django\utils\asyncio.py", line 26, in inner
    return func(*args, **kwargs)
           ^^^^^^^^^^^^^^^^^^^^^
  File "C:\Users\Muhammad Umer\AppData\Local\Programs\Python\Python311\Lib\site-packages\django\db\backends\postgresql\base.py", line 269, in create_cursor
    cursor = self.connection.cursor()
             ^^^^^^^^^^^^^^^^^^^^^^^^
psycopg2.InterfaceError: connection already closed

The above exception was the direct cause of the following exception:

Traceback (most recent call last):
  File "C:\Users\Muhammad Umer\AppData\Local\Programs\Python\Python311\Lib\site-packages\twisted\internet\defer.py", line 1065, in adapt
    extracted = result.result()
                ^^^^^^^^^^^^^^^
  File "C:\Users\Muhammad Umer\AppData\Local\Programs\Python\Python311\Lib\site-packages\asgiref\sync.py", line 448, in __call__
    ret = await asyncio.wait_for(future, timeout=None)
          ^^^^^^^^^^^^^^^^^^^^^^^^^^^^^^^^^^^^^^^^^^^^
  File "C:\Users\Muhammad Umer\AppData\Local\Programs\Python\Python311\Lib\asyncio\tasks.py", line 442, in wait_for
    return await fut
           ^^^^^^^^^
  File "C:\Users\Muhammad Umer\AppData\Local\Programs\Python\Python311\Lib\concurrent\futures\thread.py", line 58, in run
    result = self.fn(*self.args, **self.kwargs)
             ^^^^^^^^^^^^^^^^^^^^^^^^^^^^^^^^^^
  File "C:\Users\Muhammad Umer\AppData\Local\Programs\Python\Python311\Lib\site-packages\asgiref\sync.py", line 490, in thread_handler
    return func(*args, **kwargs)
           ^^^^^^^^^^^^^^^^^^^^^
  File "D:\Outputs\Django Outputs\scraper\pipelines.py", line 33, in process_item
    location = Location.objects.filter(country_code=item['country']).first()
               ^^^^^^^^^^^^^^^^^^^^^^^^^^^^^^^^^^^^^^^^^^^^^^^^^^^^^^^^^^^^^
  File "C:\Users\Muhammad Umer\AppData\Local\Programs\Python\Python311\Lib\site-packages\django\db\models\query.py", line 1047, in first
    for obj in (self if self.ordered else self.order_by("pk"))[:1]:
  File "C:\Users\Muhammad Umer\AppData\Local\Programs\Python\Python311\Lib\site-packages\django\db\models\query.py", line 394, in __iter__
    self._fetch_all()
  File "C:\Users\Muhammad Umer\AppData\Local\Programs\Python\Python311\Lib\site-packages\django\db\models\query.py", line 1867, in _fetch_all
    self._result_cache = list(self._iterable_class(self))
                         ^^^^^^^^^^^^^^^^^^^^^^^^^^^^^^^^
  File "C:\Users\Muhammad Umer\AppData\Local\Programs\Python\Python311\Lib\site-packages\django\db\models\query.py", line 87, in __iter__
    results = compiler.execute_sql(
              ^^^^^^^^^^^^^^^^^^^^^
  File "C:\Users\Muhammad Umer\AppData\Local\Programs\Python\Python311\Lib\site-packages\django\db\models\sql\compiler.py", line 1396, in execute_sql
    cursor = self.connection.cursor()
             ^^^^^^^^^^^^^^^^^^^^^^^^
  File "C:\Users\Muhammad Umer\AppData\Local\Programs\Python\Python311\Lib\site-packages\django\utils\asyncio.py", line 26, in inner
    return func(*args, **kwargs)
           ^^^^^^^^^^^^^^^^^^^^^
  File "C:\Users\Muhammad Umer\AppData\Local\Programs\Python\Python311\Lib\site-packages\django\db\backends\base\base.py", line 323, in cursor
    return self._cursor()
           ^^^^^^^^^^^^^^
  File "C:\Users\Muhammad Umer\AppData\Local\Programs\Python\Python311\Lib\site-packages\django\db\backends\base\base.py", line 300, in _cursor
    with self.wrap_database_errors:
  File "C:\Users\Muhammad Umer\AppData\Local\Programs\Python\Python311\Lib\site-packages\django\db\utils.py", line 91, in __exit__
    raise dj_exc_value.with_traceback(traceback) from exc_value
  File "C:\Users\Muhammad Umer\AppData\Local\Programs\Python\Python311\Lib\site-packages\django\db\backends\base\base.py", line 301, in _cursor
    return self._prepare_cursor(self.create_cursor(name))
                                ^^^^^^^^^^^^^^^^^^^^^^^^
  File "C:\Users\Muhammad Umer\AppData\Local\Programs\Python\Python311\Lib\site-packages\django\utils\asyncio.py", line 26, in inner
    return func(*args, **kwargs)
           ^^^^^^^^^^^^^^^^^^^^^
  File "C:\Users\Muhammad Umer\AppData\Local\Programs\Python\Python311\Lib\site-packages\django\db\backends\postgresql\base.py", line 269, in create_cursor
    cursor = self.connection.cursor()
             ^^^^^^^^^^^^^^^^^^^^^^^^
django.db.utils.InterfaceError: connection already closed
2023-09-23 18:35:46 [scrapy] ERROR: Error processing {'country': 'DK',
 'keyword': 'iphone 14',
 'position': 12,
 'price': '6.666,00\xa0kr.',
 'product_url': 'https://www.power.dk/mobil-og-foto/mobiltelefoner/apple-iphone-14-128-gb-stjerneskaer/p-1803963/',
 'title': 'APPLE IPHONE 14 128 GB STJERNESKÃ†R',
 'url': 'power.dk',
 'user_id': 'admin'}
Traceback (most recent call last):
  File "C:\Users\Muhammad Umer\AppData\Local\Programs\Python\Python311\Lib\site-packages\django\db\backends\base\base.py", line 301, in _cursor
    return self._prepare_cursor(self.create_cursor(name))
                                ^^^^^^^^^^^^^^^^^^^^^^^^
  File "C:\Users\Muhammad Umer\AppData\Local\Programs\Python\Python311\Lib\site-packages\django\utils\asyncio.py", line 26, in inner
    return func(*args, **kwargs)
           ^^^^^^^^^^^^^^^^^^^^^
  File "C:\Users\Muhammad Umer\AppData\Local\Programs\Python\Python311\Lib\site-packages\django\db\backends\postgresql\base.py", line 269, in create_cursor
    cursor = self.connection.cursor()
             ^^^^^^^^^^^^^^^^^^^^^^^^
psycopg2.InterfaceError: connection already closed

The above exception was the direct cause of the following exception:

Traceback (most recent call last):
  File "C:\Users\Muhammad Umer\AppData\Local\Programs\Python\Python311\Lib\site-packages\twisted\internet\defer.py", line 1065, in adapt
    extracted = result.result()
                ^^^^^^^^^^^^^^^
  File "C:\Users\Muhammad Umer\AppData\Local\Programs\Python\Python311\Lib\site-packages\asgiref\sync.py", line 448, in __call__
    ret = await asyncio.wait_for(future, timeout=None)
          ^^^^^^^^^^^^^^^^^^^^^^^^^^^^^^^^^^^^^^^^^^^^
  File "C:\Users\Muhammad Umer\AppData\Local\Programs\Python\Python311\Lib\asyncio\tasks.py", line 442, in wait_for
    return await fut
           ^^^^^^^^^
  File "C:\Users\Muhammad Umer\AppData\Local\Programs\Python\Python311\Lib\concurrent\futures\thread.py", line 58, in run
    result = self.fn(*self.args, **self.kwargs)
             ^^^^^^^^^^^^^^^^^^^^^^^^^^^^^^^^^^
  File "C:\Users\Muhammad Umer\AppData\Local\Programs\Python\Python311\Lib\site-packages\asgiref\sync.py", line 490, in thread_handler
    return func(*args, **kwargs)
           ^^^^^^^^^^^^^^^^^^^^^
  File "D:\Outputs\Django Outputs\scraper\pipelines.py", line 33, in process_item
    location = Location.objects.filter(country_code=item['country']).first()
               ^^^^^^^^^^^^^^^^^^^^^^^^^^^^^^^^^^^^^^^^^^^^^^^^^^^^^^^^^^^^^
  File "C:\Users\Muhammad Umer\AppData\Local\Programs\Python\Python311\Lib\site-packages\django\db\models\query.py", line 1047, in first
    for obj in (self if self.ordered else self.order_by("pk"))[:1]:
  File "C:\Users\Muhammad Umer\AppData\Local\Programs\Python\Python311\Lib\site-packages\django\db\models\query.py", line 394, in __iter__
    self._fetch_all()
  File "C:\Users\Muhammad Umer\AppData\Local\Programs\Python\Python311\Lib\site-packages\django\db\models\query.py", line 1867, in _fetch_all
    self._result_cache = list(self._iterable_class(self))
                         ^^^^^^^^^^^^^^^^^^^^^^^^^^^^^^^^
  File "C:\Users\Muhammad Umer\AppData\Local\Programs\Python\Python311\Lib\site-packages\django\db\models\query.py", line 87, in __iter__
    results = compiler.execute_sql(
              ^^^^^^^^^^^^^^^^^^^^^
  File "C:\Users\Muhammad Umer\AppData\Local\Programs\Python\Python311\Lib\site-packages\django\db\models\sql\compiler.py", line 1396, in execute_sql
    cursor = self.connection.cursor()
             ^^^^^^^^^^^^^^^^^^^^^^^^
  File "C:\Users\Muhammad Umer\AppData\Local\Programs\Python\Python311\Lib\site-packages\django\utils\asyncio.py", line 26, in inner
    return func(*args, **kwargs)
           ^^^^^^^^^^^^^^^^^^^^^
  File "C:\Users\Muhammad Umer\AppData\Local\Programs\Python\Python311\Lib\site-packages\django\db\backends\base\base.py", line 323, in cursor
    return self._cursor()
           ^^^^^^^^^^^^^^
  File "C:\Users\Muhammad Umer\AppData\Local\Programs\Python\Python311\Lib\site-packages\django\db\backends\base\base.py", line 300, in _cursor
    with self.wrap_database_errors:
  File "C:\Users\Muhammad Umer\AppData\Local\Programs\Python\Python311\Lib\site-packages\django\db\utils.py", line 91, in __exit__
    raise dj_exc_value.with_traceback(traceback) from exc_value
  File "C:\Users\Muhammad Umer\AppData\Local\Programs\Python\Python311\Lib\site-packages\django\db\backends\base\base.py", line 301, in _cursor
    return self._prepare_cursor(self.create_cursor(name))
                                ^^^^^^^^^^^^^^^^^^^^^^^^
  File "C:\Users\Muhammad Umer\AppData\Local\Programs\Python\Python311\Lib\site-packages\django\utils\asyncio.py", line 26, in inner
    return func(*args, **kwargs)
           ^^^^^^^^^^^^^^^^^^^^^
  File "C:\Users\Muhammad Umer\AppData\Local\Programs\Python\Python311\Lib\site-packages\django\db\backends\postgresql\base.py", line 269, in create_cursor
    cursor = self.connection.cursor()
             ^^^^^^^^^^^^^^^^^^^^^^^^
django.db.utils.InterfaceError: connection already closed
2023-09-23 18:35:46 [scrapy] ERROR: Error processing {'country': 'DK',
 'keyword': 'iphone 14',
 'position': 13,
 'price': '6.799,00\xa0kr.',
 'product_url': 'https://www.apple.com/dk/shop/go/product/MPVN3?cid=aos-dk-seo-pla',
 'title': 'Apple iPhone 14 128 GB â€“ blÃ¥',
 'url': 'apple.com',
 'user_id': 'admin'}
Traceback (most recent call last):
  File "C:\Users\Muhammad Umer\AppData\Local\Programs\Python\Python311\Lib\site-packages\django\db\backends\base\base.py", line 301, in _cursor
    return self._prepare_cursor(self.create_cursor(name))
                                ^^^^^^^^^^^^^^^^^^^^^^^^
  File "C:\Users\Muhammad Umer\AppData\Local\Programs\Python\Python311\Lib\site-packages\django\utils\asyncio.py", line 26, in inner
    return func(*args, **kwargs)
           ^^^^^^^^^^^^^^^^^^^^^
  File "C:\Users\Muhammad Umer\AppData\Local\Programs\Python\Python311\Lib\site-packages\django\db\backends\postgresql\base.py", line 269, in create_cursor
    cursor = self.connection.cursor()
             ^^^^^^^^^^^^^^^^^^^^^^^^
psycopg2.InterfaceError: connection already closed

The above exception was the direct cause of the following exception:

Traceback (most recent call last):
  File "C:\Users\Muhammad Umer\AppData\Local\Programs\Python\Python311\Lib\site-packages\twisted\internet\defer.py", line 1065, in adapt
    extracted = result.result()
                ^^^^^^^^^^^^^^^
  File "C:\Users\Muhammad Umer\AppData\Local\Programs\Python\Python311\Lib\site-packages\asgiref\sync.py", line 448, in __call__
    ret = await asyncio.wait_for(future, timeout=None)
          ^^^^^^^^^^^^^^^^^^^^^^^^^^^^^^^^^^^^^^^^^^^^
  File "C:\Users\Muhammad Umer\AppData\Local\Programs\Python\Python311\Lib\asyncio\tasks.py", line 442, in wait_for
    return await fut
           ^^^^^^^^^
  File "C:\Users\Muhammad Umer\AppData\Local\Programs\Python\Python311\Lib\concurrent\futures\thread.py", line 58, in run
    result = self.fn(*self.args, **self.kwargs)
             ^^^^^^^^^^^^^^^^^^^^^^^^^^^^^^^^^^
  File "C:\Users\Muhammad Umer\AppData\Local\Programs\Python\Python311\Lib\site-packages\asgiref\sync.py", line 490, in thread_handler
    return func(*args, **kwargs)
           ^^^^^^^^^^^^^^^^^^^^^
  File "D:\Outputs\Django Outputs\scraper\pipelines.py", line 33, in process_item
    location = Location.objects.filter(country_code=item['country']).first()
               ^^^^^^^^^^^^^^^^^^^^^^^^^^^^^^^^^^^^^^^^^^^^^^^^^^^^^^^^^^^^^
  File "C:\Users\Muhammad Umer\AppData\Local\Programs\Python\Python311\Lib\site-packages\django\db\models\query.py", line 1047, in first
    for obj in (self if self.ordered else self.order_by("pk"))[:1]:
  File "C:\Users\Muhammad Umer\AppData\Local\Programs\Python\Python311\Lib\site-packages\django\db\models\query.py", line 394, in __iter__
    self._fetch_all()
  File "C:\Users\Muhammad Umer\AppData\Local\Programs\Python\Python311\Lib\site-packages\django\db\models\query.py", line 1867, in _fetch_all
    self._result_cache = list(self._iterable_class(self))
                         ^^^^^^^^^^^^^^^^^^^^^^^^^^^^^^^^
  File "C:\Users\Muhammad Umer\AppData\Local\Programs\Python\Python311\Lib\site-packages\django\db\models\query.py", line 87, in __iter__
    results = compiler.execute_sql(
              ^^^^^^^^^^^^^^^^^^^^^
  File "C:\Users\Muhammad Umer\AppData\Local\Programs\Python\Python311\Lib\site-packages\django\db\models\sql\compiler.py", line 1396, in execute_sql
    cursor = self.connection.cursor()
             ^^^^^^^^^^^^^^^^^^^^^^^^
  File "C:\Users\Muhammad Umer\AppData\Local\Programs\Python\Python311\Lib\site-packages\django\utils\asyncio.py", line 26, in inner
    return func(*args, **kwargs)
           ^^^^^^^^^^^^^^^^^^^^^
  File "C:\Users\Muhammad Umer\AppData\Local\Programs\Python\Python311\Lib\site-packages\django\db\backends\base\base.py", line 323, in cursor
    return self._cursor()
           ^^^^^^^^^^^^^^
  File "C:\Users\Muhammad Umer\AppData\Local\Programs\Python\Python311\Lib\site-packages\django\db\backends\base\base.py", line 300, in _cursor
    with self.wrap_database_errors:
  File "C:\Users\Muhammad Umer\AppData\Local\Programs\Python\Python311\Lib\site-packages\django\db\utils.py", line 91, in __exit__
    raise dj_exc_value.with_traceback(traceback) from exc_value
  File "C:\Users\Muhammad Umer\AppData\Local\Programs\Python\Python311\Lib\site-packages\django\db\backends\base\base.py", line 301, in _cursor
    return self._prepare_cursor(self.create_cursor(name))
                                ^^^^^^^^^^^^^^^^^^^^^^^^
  File "C:\Users\Muhammad Umer\AppData\Local\Programs\Python\Python311\Lib\site-packages\django\utils\asyncio.py", line 26, in inner
    return func(*args, **kwargs)
           ^^^^^^^^^^^^^^^^^^^^^
  File "C:\Users\Muhammad Umer\AppData\Local\Programs\Python\Python311\Lib\site-packages\django\db\backends\postgresql\base.py", line 269, in create_cursor
    cursor = self.connection.cursor()
             ^^^^^^^^^^^^^^^^^^^^^^^^
django.db.utils.InterfaceError: connection already closed
2023-09-23 18:35:46 [scrapy] ERROR: Error processing {'country': 'DK',
 'keyword': 'iphone 14',
 'position': 14,
 'price': '6.840,00\xa0kr.',
 'product_url': 'https://www.3.dk/shop/mobiler/apple/iphone-15?variantId=4_34939_34980',
 'title': 'iPhone 15 128 GB GB Pink - Fri tale 30 GBmindstepris fra 7800 kr. '
          '(inkl. abonnement). 3Family & 3LikeHome',
 'url': '3.dk',
 'user_id': 'admin'}
Traceback (most recent call last):
  File "C:\Users\Muhammad Umer\AppData\Local\Programs\Python\Python311\Lib\site-packages\django\db\backends\base\base.py", line 301, in _cursor
    return self._prepare_cursor(self.create_cursor(name))
                                ^^^^^^^^^^^^^^^^^^^^^^^^
  File "C:\Users\Muhammad Umer\AppData\Local\Programs\Python\Python311\Lib\site-packages\django\utils\asyncio.py", line 26, in inner
    return func(*args, **kwargs)
           ^^^^^^^^^^^^^^^^^^^^^
  File "C:\Users\Muhammad Umer\AppData\Local\Programs\Python\Python311\Lib\site-packages\django\db\backends\postgresql\base.py", line 269, in create_cursor
    cursor = self.connection.cursor()
             ^^^^^^^^^^^^^^^^^^^^^^^^
psycopg2.InterfaceError: connection already closed

The above exception was the direct cause of the following exception:

Traceback (most recent call last):
  File "C:\Users\Muhammad Umer\AppData\Local\Programs\Python\Python311\Lib\site-packages\twisted\internet\defer.py", line 1065, in adapt
    extracted = result.result()
                ^^^^^^^^^^^^^^^
  File "C:\Users\Muhammad Umer\AppData\Local\Programs\Python\Python311\Lib\site-packages\asgiref\sync.py", line 448, in __call__
    ret = await asyncio.wait_for(future, timeout=None)
          ^^^^^^^^^^^^^^^^^^^^^^^^^^^^^^^^^^^^^^^^^^^^
  File "C:\Users\Muhammad Umer\AppData\Local\Programs\Python\Python311\Lib\asyncio\tasks.py", line 442, in wait_for
    return await fut
           ^^^^^^^^^
  File "C:\Users\Muhammad Umer\AppData\Local\Programs\Python\Python311\Lib\concurrent\futures\thread.py", line 58, in run
    result = self.fn(*self.args, **self.kwargs)
             ^^^^^^^^^^^^^^^^^^^^^^^^^^^^^^^^^^
  File "C:\Users\Muhammad Umer\AppData\Local\Programs\Python\Python311\Lib\site-packages\asgiref\sync.py", line 490, in thread_handler
    return func(*args, **kwargs)
           ^^^^^^^^^^^^^^^^^^^^^
  File "D:\Outputs\Django Outputs\scraper\pipelines.py", line 33, in process_item
    location = Location.objects.filter(country_code=item['country']).first()
               ^^^^^^^^^^^^^^^^^^^^^^^^^^^^^^^^^^^^^^^^^^^^^^^^^^^^^^^^^^^^^
  File "C:\Users\Muhammad Umer\AppData\Local\Programs\Python\Python311\Lib\site-packages\django\db\models\query.py", line 1047, in first
    for obj in (self if self.ordered else self.order_by("pk"))[:1]:
  File "C:\Users\Muhammad Umer\AppData\Local\Programs\Python\Python311\Lib\site-packages\django\db\models\query.py", line 394, in __iter__
    self._fetch_all()
  File "C:\Users\Muhammad Umer\AppData\Local\Programs\Python\Python311\Lib\site-packages\django\db\models\query.py", line 1867, in _fetch_all
    self._result_cache = list(self._iterable_class(self))
                         ^^^^^^^^^^^^^^^^^^^^^^^^^^^^^^^^
  File "C:\Users\Muhammad Umer\AppData\Local\Programs\Python\Python311\Lib\site-packages\django\db\models\query.py", line 87, in __iter__
    results = compiler.execute_sql(
              ^^^^^^^^^^^^^^^^^^^^^
  File "C:\Users\Muhammad Umer\AppData\Local\Programs\Python\Python311\Lib\site-packages\django\db\models\sql\compiler.py", line 1396, in execute_sql
    cursor = self.connection.cursor()
             ^^^^^^^^^^^^^^^^^^^^^^^^
  File "C:\Users\Muhammad Umer\AppData\Local\Programs\Python\Python311\Lib\site-packages\django\utils\asyncio.py", line 26, in inner
    return func(*args, **kwargs)
           ^^^^^^^^^^^^^^^^^^^^^
  File "C:\Users\Muhammad Umer\AppData\Local\Programs\Python\Python311\Lib\site-packages\django\db\backends\base\base.py", line 323, in cursor
    return self._cursor()
           ^^^^^^^^^^^^^^
  File "C:\Users\Muhammad Umer\AppData\Local\Programs\Python\Python311\Lib\site-packages\django\db\backends\base\base.py", line 300, in _cursor
    with self.wrap_database_errors:
  File "C:\Users\Muhammad Umer\AppData\Local\Programs\Python\Python311\Lib\site-packages\django\db\utils.py", line 91, in __exit__
    raise dj_exc_value.with_traceback(traceback) from exc_value
  File "C:\Users\Muhammad Umer\AppData\Local\Programs\Python\Python311\Lib\site-packages\django\db\backends\base\base.py", line 301, in _cursor
    return self._prepare_cursor(self.create_cursor(name))
                                ^^^^^^^^^^^^^^^^^^^^^^^^
  File "C:\Users\Muhammad Umer\AppData\Local\Programs\Python\Python311\Lib\site-packages\django\utils\asyncio.py", line 26, in inner
    return func(*args, **kwargs)
           ^^^^^^^^^^^^^^^^^^^^^
  File "C:\Users\Muhammad Umer\AppData\Local\Programs\Python\Python311\Lib\site-packages\django\db\backends\postgresql\base.py", line 269, in create_cursor
    cursor = self.connection.cursor()
             ^^^^^^^^^^^^^^^^^^^^^^^^
django.db.utils.InterfaceError: connection already closed
2023-09-23 18:35:46 [scrapy] ERROR: Error processing {'country': 'DK',
 'keyword': 'iphone 14',
 'position': 15,
 'price': '7.799,00\xa0kr.',
 'product_url': 'https://www.elgiganten.dk/product/mobil-tablet-smartwatch/mobiltelefon/iphone-15-5g-smartphone-128gb-pink/673000',
 'title': 'iPhone 15 â€“ 5G smartphone 128GB Pink',
 'url': 'elgiganten.dk',
 'user_id': 'admin'}
Traceback (most recent call last):
  File "C:\Users\Muhammad Umer\AppData\Local\Programs\Python\Python311\Lib\site-packages\django\db\backends\base\base.py", line 301, in _cursor
    return self._prepare_cursor(self.create_cursor(name))
                                ^^^^^^^^^^^^^^^^^^^^^^^^
  File "C:\Users\Muhammad Umer\AppData\Local\Programs\Python\Python311\Lib\site-packages\django\utils\asyncio.py", line 26, in inner
    return func(*args, **kwargs)
           ^^^^^^^^^^^^^^^^^^^^^
  File "C:\Users\Muhammad Umer\AppData\Local\Programs\Python\Python311\Lib\site-packages\django\db\backends\postgresql\base.py", line 269, in create_cursor
    cursor = self.connection.cursor()
             ^^^^^^^^^^^^^^^^^^^^^^^^
psycopg2.InterfaceError: connection already closed

The above exception was the direct cause of the following exception:

Traceback (most recent call last):
  File "C:\Users\Muhammad Umer\AppData\Local\Programs\Python\Python311\Lib\site-packages\twisted\internet\defer.py", line 1065, in adapt
    extracted = result.result()
                ^^^^^^^^^^^^^^^
  File "C:\Users\Muhammad Umer\AppData\Local\Programs\Python\Python311\Lib\site-packages\asgiref\sync.py", line 448, in __call__
    ret = await asyncio.wait_for(future, timeout=None)
          ^^^^^^^^^^^^^^^^^^^^^^^^^^^^^^^^^^^^^^^^^^^^
  File "C:\Users\Muhammad Umer\AppData\Local\Programs\Python\Python311\Lib\asyncio\tasks.py", line 442, in wait_for
    return await fut
           ^^^^^^^^^
  File "C:\Users\Muhammad Umer\AppData\Local\Programs\Python\Python311\Lib\concurrent\futures\thread.py", line 58, in run
    result = self.fn(*self.args, **self.kwargs)
             ^^^^^^^^^^^^^^^^^^^^^^^^^^^^^^^^^^
  File "C:\Users\Muhammad Umer\AppData\Local\Programs\Python\Python311\Lib\site-packages\asgiref\sync.py", line 490, in thread_handler
    return func(*args, **kwargs)
           ^^^^^^^^^^^^^^^^^^^^^
  File "D:\Outputs\Django Outputs\scraper\pipelines.py", line 33, in process_item
    location = Location.objects.filter(country_code=item['country']).first()
               ^^^^^^^^^^^^^^^^^^^^^^^^^^^^^^^^^^^^^^^^^^^^^^^^^^^^^^^^^^^^^
  File "C:\Users\Muhammad Umer\AppData\Local\Programs\Python\Python311\Lib\site-packages\django\db\models\query.py", line 1047, in first
    for obj in (self if self.ordered else self.order_by("pk"))[:1]:
  File "C:\Users\Muhammad Umer\AppData\Local\Programs\Python\Python311\Lib\site-packages\django\db\models\query.py", line 394, in __iter__
    self._fetch_all()
  File "C:\Users\Muhammad Umer\AppData\Local\Programs\Python\Python311\Lib\site-packages\django\db\models\query.py", line 1867, in _fetch_all
    self._result_cache = list(self._iterable_class(self))
                         ^^^^^^^^^^^^^^^^^^^^^^^^^^^^^^^^
  File "C:\Users\Muhammad Umer\AppData\Local\Programs\Python\Python311\Lib\site-packages\django\db\models\query.py", line 87, in __iter__
    results = compiler.execute_sql(
              ^^^^^^^^^^^^^^^^^^^^^
  File "C:\Users\Muhammad Umer\AppData\Local\Programs\Python\Python311\Lib\site-packages\django\db\models\sql\compiler.py", line 1396, in execute_sql
    cursor = self.connection.cursor()
             ^^^^^^^^^^^^^^^^^^^^^^^^
  File "C:\Users\Muhammad Umer\AppData\Local\Programs\Python\Python311\Lib\site-packages\django\utils\asyncio.py", line 26, in inner
    return func(*args, **kwargs)
           ^^^^^^^^^^^^^^^^^^^^^
  File "C:\Users\Muhammad Umer\AppData\Local\Programs\Python\Python311\Lib\site-packages\django\db\backends\base\base.py", line 323, in cursor
    return self._cursor()
           ^^^^^^^^^^^^^^
  File "C:\Users\Muhammad Umer\AppData\Local\Programs\Python\Python311\Lib\site-packages\django\db\backends\base\base.py", line 300, in _cursor
    with self.wrap_database_errors:
  File "C:\Users\Muhammad Umer\AppData\Local\Programs\Python\Python311\Lib\site-packages\django\db\utils.py", line 91, in __exit__
    raise dj_exc_value.with_traceback(traceback) from exc_value
  File "C:\Users\Muhammad Umer\AppData\Local\Programs\Python\Python311\Lib\site-packages\django\db\backends\base\base.py", line 301, in _cursor
    return self._prepare_cursor(self.create_cursor(name))
                                ^^^^^^^^^^^^^^^^^^^^^^^^
  File "C:\Users\Muhammad Umer\AppData\Local\Programs\Python\Python311\Lib\site-packages\django\utils\asyncio.py", line 26, in inner
    return func(*args, **kwargs)
           ^^^^^^^^^^^^^^^^^^^^^
  File "C:\Users\Muhammad Umer\AppData\Local\Programs\Python\Python311\Lib\site-packages\django\db\backends\postgresql\base.py", line 269, in create_cursor
    cursor = self.connection.cursor()
             ^^^^^^^^^^^^^^^^^^^^^^^^
django.db.utils.InterfaceError: connection already closed
2023-09-23 18:35:46 [scrapy] ERROR: Error processing {'country': 'DK',
 'keyword': 'iphone 14',
 'position': 16,
 'price': '6.666,00\xa0kr.',
 'product_url': 'https://www.proshop.dk/Mobil/Apple-iPhone-14-5G-128GB-Starlight/3104589?utm_source=google&utm_medium=cpc&utm_campaign=searchengine',
 'title': 'Apple iPhone 14 5G 128GB - Starlight, Mobiltelefon',
 'url': 'proshop.dk',
 'user_id': 'admin'}
Traceback (most recent call last):
  File "C:\Users\Muhammad Umer\AppData\Local\Programs\Python\Python311\Lib\site-packages\django\db\backends\base\base.py", line 301, in _cursor
    return self._prepare_cursor(self.create_cursor(name))
                                ^^^^^^^^^^^^^^^^^^^^^^^^
  File "C:\Users\Muhammad Umer\AppData\Local\Programs\Python\Python311\Lib\site-packages\django\utils\asyncio.py", line 26, in inner
    return func(*args, **kwargs)
           ^^^^^^^^^^^^^^^^^^^^^
  File "C:\Users\Muhammad Umer\AppData\Local\Programs\Python\Python311\Lib\site-packages\django\db\backends\postgresql\base.py", line 269, in create_cursor
    cursor = self.connection.cursor()
             ^^^^^^^^^^^^^^^^^^^^^^^^
psycopg2.InterfaceError: connection already closed

The above exception was the direct cause of the following exception:

Traceback (most recent call last):
  File "C:\Users\Muhammad Umer\AppData\Local\Programs\Python\Python311\Lib\site-packages\twisted\internet\defer.py", line 1065, in adapt
    extracted = result.result()
                ^^^^^^^^^^^^^^^
  File "C:\Users\Muhammad Umer\AppData\Local\Programs\Python\Python311\Lib\site-packages\asgiref\sync.py", line 448, in __call__
    ret = await asyncio.wait_for(future, timeout=None)
          ^^^^^^^^^^^^^^^^^^^^^^^^^^^^^^^^^^^^^^^^^^^^
  File "C:\Users\Muhammad Umer\AppData\Local\Programs\Python\Python311\Lib\asyncio\tasks.py", line 442, in wait_for
    return await fut
           ^^^^^^^^^
  File "C:\Users\Muhammad Umer\AppData\Local\Programs\Python\Python311\Lib\concurrent\futures\thread.py", line 58, in run
    result = self.fn(*self.args, **self.kwargs)
             ^^^^^^^^^^^^^^^^^^^^^^^^^^^^^^^^^^
  File "C:\Users\Muhammad Umer\AppData\Local\Programs\Python\Python311\Lib\site-packages\asgiref\sync.py", line 490, in thread_handler
    return func(*args, **kwargs)
           ^^^^^^^^^^^^^^^^^^^^^
  File "D:\Outputs\Django Outputs\scraper\pipelines.py", line 33, in process_item
    location = Location.objects.filter(country_code=item['country']).first()
               ^^^^^^^^^^^^^^^^^^^^^^^^^^^^^^^^^^^^^^^^^^^^^^^^^^^^^^^^^^^^^
  File "C:\Users\Muhammad Umer\AppData\Local\Programs\Python\Python311\Lib\site-packages\django\db\models\query.py", line 1047, in first
    for obj in (self if self.ordered else self.order_by("pk"))[:1]:
  File "C:\Users\Muhammad Umer\AppData\Local\Programs\Python\Python311\Lib\site-packages\django\db\models\query.py", line 394, in __iter__
    self._fetch_all()
  File "C:\Users\Muhammad Umer\AppData\Local\Programs\Python\Python311\Lib\site-packages\django\db\models\query.py", line 1867, in _fetch_all
    self._result_cache = list(self._iterable_class(self))
                         ^^^^^^^^^^^^^^^^^^^^^^^^^^^^^^^^
  File "C:\Users\Muhammad Umer\AppData\Local\Programs\Python\Python311\Lib\site-packages\django\db\models\query.py", line 87, in __iter__
    results = compiler.execute_sql(
              ^^^^^^^^^^^^^^^^^^^^^
  File "C:\Users\Muhammad Umer\AppData\Local\Programs\Python\Python311\Lib\site-packages\django\db\models\sql\compiler.py", line 1396, in execute_sql
    cursor = self.connection.cursor()
             ^^^^^^^^^^^^^^^^^^^^^^^^
  File "C:\Users\Muhammad Umer\AppData\Local\Programs\Python\Python311\Lib\site-packages\django\utils\asyncio.py", line 26, in inner
    return func(*args, **kwargs)
           ^^^^^^^^^^^^^^^^^^^^^
  File "C:\Users\Muhammad Umer\AppData\Local\Programs\Python\Python311\Lib\site-packages\django\db\backends\base\base.py", line 323, in cursor
    return self._cursor()
           ^^^^^^^^^^^^^^
  File "C:\Users\Muhammad Umer\AppData\Local\Programs\Python\Python311\Lib\site-packages\django\db\backends\base\base.py", line 300, in _cursor
    with self.wrap_database_errors:
  File "C:\Users\Muhammad Umer\AppData\Local\Programs\Python\Python311\Lib\site-packages\django\db\utils.py", line 91, in __exit__
    raise dj_exc_value.with_traceback(traceback) from exc_value
  File "C:\Users\Muhammad Umer\AppData\Local\Programs\Python\Python311\Lib\site-packages\django\db\backends\base\base.py", line 301, in _cursor
    return self._prepare_cursor(self.create_cursor(name))
                                ^^^^^^^^^^^^^^^^^^^^^^^^
  File "C:\Users\Muhammad Umer\AppData\Local\Programs\Python\Python311\Lib\site-packages\django\utils\asyncio.py", line 26, in inner
    return func(*args, **kwargs)
           ^^^^^^^^^^^^^^^^^^^^^
  File "C:\Users\Muhammad Umer\AppData\Local\Programs\Python\Python311\Lib\site-packages\django\db\backends\postgresql\base.py", line 269, in create_cursor
    cursor = self.connection.cursor()
             ^^^^^^^^^^^^^^^^^^^^^^^^
django.db.utils.InterfaceError: connection already closed
2023-09-23 18:35:46 [scrapy] ERROR: Error processing {'country': 'DK',
 'keyword': 'iphone 14',
 'position': 17,
 'price': '5.673,99\xa0kr.',
 'product_url': 'https://www.refurbed.dk/p/iphone-14/40940b/?co=dk&utm_cluster=gradeB&utm_content=iphone-14-40940b&utm_group=iphone-14',
 'title': 'iPhone 14 | 128 GB | Dual-SIM | Midnat',
 'url': 'refurbed.dk',
 'user_id': 'admin'}
Traceback (most recent call last):
  File "C:\Users\Muhammad Umer\AppData\Local\Programs\Python\Python311\Lib\site-packages\django\db\backends\base\base.py", line 301, in _cursor
    return self._prepare_cursor(self.create_cursor(name))
                                ^^^^^^^^^^^^^^^^^^^^^^^^
  File "C:\Users\Muhammad Umer\AppData\Local\Programs\Python\Python311\Lib\site-packages\django\utils\asyncio.py", line 26, in inner
    return func(*args, **kwargs)
           ^^^^^^^^^^^^^^^^^^^^^
  File "C:\Users\Muhammad Umer\AppData\Local\Programs\Python\Python311\Lib\site-packages\django\db\backends\postgresql\base.py", line 269, in create_cursor
    cursor = self.connection.cursor()
             ^^^^^^^^^^^^^^^^^^^^^^^^
psycopg2.InterfaceError: connection already closed

The above exception was the direct cause of the following exception:

Traceback (most recent call last):
  File "C:\Users\Muhammad Umer\AppData\Local\Programs\Python\Python311\Lib\site-packages\twisted\internet\defer.py", line 1065, in adapt
    extracted = result.result()
                ^^^^^^^^^^^^^^^
  File "C:\Users\Muhammad Umer\AppData\Local\Programs\Python\Python311\Lib\site-packages\asgiref\sync.py", line 448, in __call__
    ret = await asyncio.wait_for(future, timeout=None)
          ^^^^^^^^^^^^^^^^^^^^^^^^^^^^^^^^^^^^^^^^^^^^
  File "C:\Users\Muhammad Umer\AppData\Local\Programs\Python\Python311\Lib\asyncio\tasks.py", line 442, in wait_for
    return await fut
           ^^^^^^^^^
  File "C:\Users\Muhammad Umer\AppData\Local\Programs\Python\Python311\Lib\concurrent\futures\thread.py", line 58, in run
    result = self.fn(*self.args, **self.kwargs)
             ^^^^^^^^^^^^^^^^^^^^^^^^^^^^^^^^^^
  File "C:\Users\Muhammad Umer\AppData\Local\Programs\Python\Python311\Lib\site-packages\asgiref\sync.py", line 490, in thread_handler
    return func(*args, **kwargs)
           ^^^^^^^^^^^^^^^^^^^^^
  File "D:\Outputs\Django Outputs\scraper\pipelines.py", line 33, in process_item
    location = Location.objects.filter(country_code=item['country']).first()
               ^^^^^^^^^^^^^^^^^^^^^^^^^^^^^^^^^^^^^^^^^^^^^^^^^^^^^^^^^^^^^
  File "C:\Users\Muhammad Umer\AppData\Local\Programs\Python\Python311\Lib\site-packages\django\db\models\query.py", line 1047, in first
    for obj in (self if self.ordered else self.order_by("pk"))[:1]:
  File "C:\Users\Muhammad Umer\AppData\Local\Programs\Python\Python311\Lib\site-packages\django\db\models\query.py", line 394, in __iter__
    self._fetch_all()
  File "C:\Users\Muhammad Umer\AppData\Local\Programs\Python\Python311\Lib\site-packages\django\db\models\query.py", line 1867, in _fetch_all
    self._result_cache = list(self._iterable_class(self))
                         ^^^^^^^^^^^^^^^^^^^^^^^^^^^^^^^^
  File "C:\Users\Muhammad Umer\AppData\Local\Programs\Python\Python311\Lib\site-packages\django\db\models\query.py", line 87, in __iter__
    results = compiler.execute_sql(
              ^^^^^^^^^^^^^^^^^^^^^
  File "C:\Users\Muhammad Umer\AppData\Local\Programs\Python\Python311\Lib\site-packages\django\db\models\sql\compiler.py", line 1396, in execute_sql
    cursor = self.connection.cursor()
             ^^^^^^^^^^^^^^^^^^^^^^^^
  File "C:\Users\Muhammad Umer\AppData\Local\Programs\Python\Python311\Lib\site-packages\django\utils\asyncio.py", line 26, in inner
    return func(*args, **kwargs)
           ^^^^^^^^^^^^^^^^^^^^^
  File "C:\Users\Muhammad Umer\AppData\Local\Programs\Python\Python311\Lib\site-packages\django\db\backends\base\base.py", line 323, in cursor
    return self._cursor()
           ^^^^^^^^^^^^^^
  File "C:\Users\Muhammad Umer\AppData\Local\Programs\Python\Python311\Lib\site-packages\django\db\backends\base\base.py", line 300, in _cursor
    with self.wrap_database_errors:
  File "C:\Users\Muhammad Umer\AppData\Local\Programs\Python\Python311\Lib\site-packages\django\db\utils.py", line 91, in __exit__
    raise dj_exc_value.with_traceback(traceback) from exc_value
  File "C:\Users\Muhammad Umer\AppData\Local\Programs\Python\Python311\Lib\site-packages\django\db\backends\base\base.py", line 301, in _cursor
    return self._prepare_cursor(self.create_cursor(name))
                                ^^^^^^^^^^^^^^^^^^^^^^^^
  File "C:\Users\Muhammad Umer\AppData\Local\Programs\Python\Python311\Lib\site-packages\django\utils\asyncio.py", line 26, in inner
    return func(*args, **kwargs)
           ^^^^^^^^^^^^^^^^^^^^^
  File "C:\Users\Muhammad Umer\AppData\Local\Programs\Python\Python311\Lib\site-packages\django\db\backends\postgresql\base.py", line 269, in create_cursor
    cursor = self.connection.cursor()
             ^^^^^^^^^^^^^^^^^^^^^^^^
django.db.utils.InterfaceError: connection already closed
2023-09-23 18:35:46 [scrapy] ERROR: Error processing {'country': 'DK',
 'keyword': 'iphone 14',
 'position': 18,
 'price': '6.648,00\xa0kr.',
 'product_url': 'https://www.elgiganten.dk/product/outlet/iphone-14-5g-smartphone-128gb-bla/536427',
 'title': 'iPhone 14 â€“ 5G smartphone 128GB blÃ¥',
 'url': 'elgiganten.dk',
 'user_id': 'admin'}
Traceback (most recent call last):
  File "C:\Users\Muhammad Umer\AppData\Local\Programs\Python\Python311\Lib\site-packages\django\db\backends\base\base.py", line 301, in _cursor
    return self._prepare_cursor(self.create_cursor(name))
                                ^^^^^^^^^^^^^^^^^^^^^^^^
  File "C:\Users\Muhammad Umer\AppData\Local\Programs\Python\Python311\Lib\site-packages\django\utils\asyncio.py", line 26, in inner
    return func(*args, **kwargs)
           ^^^^^^^^^^^^^^^^^^^^^
  File "C:\Users\Muhammad Umer\AppData\Local\Programs\Python\Python311\Lib\site-packages\django\db\backends\postgresql\base.py", line 269, in create_cursor
    cursor = self.connection.cursor()
             ^^^^^^^^^^^^^^^^^^^^^^^^
psycopg2.InterfaceError: connection already closed

The above exception was the direct cause of the following exception:

Traceback (most recent call last):
  File "C:\Users\Muhammad Umer\AppData\Local\Programs\Python\Python311\Lib\site-packages\twisted\internet\defer.py", line 1065, in adapt
    extracted = result.result()
                ^^^^^^^^^^^^^^^
  File "C:\Users\Muhammad Umer\AppData\Local\Programs\Python\Python311\Lib\site-packages\asgiref\sync.py", line 448, in __call__
    ret = await asyncio.wait_for(future, timeout=None)
          ^^^^^^^^^^^^^^^^^^^^^^^^^^^^^^^^^^^^^^^^^^^^
  File "C:\Users\Muhammad Umer\AppData\Local\Programs\Python\Python311\Lib\asyncio\tasks.py", line 442, in wait_for
    return await fut
           ^^^^^^^^^
  File "C:\Users\Muhammad Umer\AppData\Local\Programs\Python\Python311\Lib\concurrent\futures\thread.py", line 58, in run
    result = self.fn(*self.args, **self.kwargs)
             ^^^^^^^^^^^^^^^^^^^^^^^^^^^^^^^^^^
  File "C:\Users\Muhammad Umer\AppData\Local\Programs\Python\Python311\Lib\site-packages\asgiref\sync.py", line 490, in thread_handler
    return func(*args, **kwargs)
           ^^^^^^^^^^^^^^^^^^^^^
  File "D:\Outputs\Django Outputs\scraper\pipelines.py", line 33, in process_item
    location = Location.objects.filter(country_code=item['country']).first()
               ^^^^^^^^^^^^^^^^^^^^^^^^^^^^^^^^^^^^^^^^^^^^^^^^^^^^^^^^^^^^^
  File "C:\Users\Muhammad Umer\AppData\Local\Programs\Python\Python311\Lib\site-packages\django\db\models\query.py", line 1047, in first
    for obj in (self if self.ordered else self.order_by("pk"))[:1]:
  File "C:\Users\Muhammad Umer\AppData\Local\Programs\Python\Python311\Lib\site-packages\django\db\models\query.py", line 394, in __iter__
    self._fetch_all()
  File "C:\Users\Muhammad Umer\AppData\Local\Programs\Python\Python311\Lib\site-packages\django\db\models\query.py", line 1867, in _fetch_all
    self._result_cache = list(self._iterable_class(self))
                         ^^^^^^^^^^^^^^^^^^^^^^^^^^^^^^^^
  File "C:\Users\Muhammad Umer\AppData\Local\Programs\Python\Python311\Lib\site-packages\django\db\models\query.py", line 87, in __iter__
    results = compiler.execute_sql(
              ^^^^^^^^^^^^^^^^^^^^^
  File "C:\Users\Muhammad Umer\AppData\Local\Programs\Python\Python311\Lib\site-packages\django\db\models\sql\compiler.py", line 1396, in execute_sql
    cursor = self.connection.cursor()
             ^^^^^^^^^^^^^^^^^^^^^^^^
  File "C:\Users\Muhammad Umer\AppData\Local\Programs\Python\Python311\Lib\site-packages\django\utils\asyncio.py", line 26, in inner
    return func(*args, **kwargs)
           ^^^^^^^^^^^^^^^^^^^^^
  File "C:\Users\Muhammad Umer\AppData\Local\Programs\Python\Python311\Lib\site-packages\django\db\backends\base\base.py", line 323, in cursor
    return self._cursor()
           ^^^^^^^^^^^^^^
  File "C:\Users\Muhammad Umer\AppData\Local\Programs\Python\Python311\Lib\site-packages\django\db\backends\base\base.py", line 300, in _cursor
    with self.wrap_database_errors:
  File "C:\Users\Muhammad Umer\AppData\Local\Programs\Python\Python311\Lib\site-packages\django\db\utils.py", line 91, in __exit__
    raise dj_exc_value.with_traceback(traceback) from exc_value
  File "C:\Users\Muhammad Umer\AppData\Local\Programs\Python\Python311\Lib\site-packages\django\db\backends\base\base.py", line 301, in _cursor
    return self._prepare_cursor(self.create_cursor(name))
                                ^^^^^^^^^^^^^^^^^^^^^^^^
  File "C:\Users\Muhammad Umer\AppData\Local\Programs\Python\Python311\Lib\site-packages\django\utils\asyncio.py", line 26, in inner
    return func(*args, **kwargs)
           ^^^^^^^^^^^^^^^^^^^^^
  File "C:\Users\Muhammad Umer\AppData\Local\Programs\Python\Python311\Lib\site-packages\django\db\backends\postgresql\base.py", line 269, in create_cursor
    cursor = self.connection.cursor()
             ^^^^^^^^^^^^^^^^^^^^^^^^
django.db.utils.InterfaceError: connection already closed
2023-09-23 18:35:46 [scrapy] ERROR: Error processing {'country': 'DK',
 'keyword': 'iphone 14',
 'position': 19,
 'price': '6.999,00\xa0kr.',
 'product_url': 'https://www.bilka.dk/produkter/iphone-14-128gb-midnight/200162606/',
 'title': 'iPhone 14 128GB - Midnight',
 'url': 'bilka.dk',
 'user_id': 'admin'}
Traceback (most recent call last):
  File "C:\Users\Muhammad Umer\AppData\Local\Programs\Python\Python311\Lib\site-packages\django\db\backends\base\base.py", line 301, in _cursor
    return self._prepare_cursor(self.create_cursor(name))
                                ^^^^^^^^^^^^^^^^^^^^^^^^
  File "C:\Users\Muhammad Umer\AppData\Local\Programs\Python\Python311\Lib\site-packages\django\utils\asyncio.py", line 26, in inner
    return func(*args, **kwargs)
           ^^^^^^^^^^^^^^^^^^^^^
  File "C:\Users\Muhammad Umer\AppData\Local\Programs\Python\Python311\Lib\site-packages\django\db\backends\postgresql\base.py", line 269, in create_cursor
    cursor = self.connection.cursor()
             ^^^^^^^^^^^^^^^^^^^^^^^^
psycopg2.InterfaceError: connection already closed

The above exception was the direct cause of the following exception:

Traceback (most recent call last):
  File "C:\Users\Muhammad Umer\AppData\Local\Programs\Python\Python311\Lib\site-packages\twisted\internet\defer.py", line 1065, in adapt
    extracted = result.result()
                ^^^^^^^^^^^^^^^
  File "C:\Users\Muhammad Umer\AppData\Local\Programs\Python\Python311\Lib\site-packages\asgiref\sync.py", line 448, in __call__
    ret = await asyncio.wait_for(future, timeout=None)
          ^^^^^^^^^^^^^^^^^^^^^^^^^^^^^^^^^^^^^^^^^^^^
  File "C:\Users\Muhammad Umer\AppData\Local\Programs\Python\Python311\Lib\asyncio\tasks.py", line 442, in wait_for
    return await fut
           ^^^^^^^^^
  File "C:\Users\Muhammad Umer\AppData\Local\Programs\Python\Python311\Lib\concurrent\futures\thread.py", line 58, in run
    result = self.fn(*self.args, **self.kwargs)
             ^^^^^^^^^^^^^^^^^^^^^^^^^^^^^^^^^^
  File "C:\Users\Muhammad Umer\AppData\Local\Programs\Python\Python311\Lib\site-packages\asgiref\sync.py", line 490, in thread_handler
    return func(*args, **kwargs)
           ^^^^^^^^^^^^^^^^^^^^^
  File "D:\Outputs\Django Outputs\scraper\pipelines.py", line 33, in process_item
    location = Location.objects.filter(country_code=item['country']).first()
               ^^^^^^^^^^^^^^^^^^^^^^^^^^^^^^^^^^^^^^^^^^^^^^^^^^^^^^^^^^^^^
  File "C:\Users\Muhammad Umer\AppData\Local\Programs\Python\Python311\Lib\site-packages\django\db\models\query.py", line 1047, in first
    for obj in (self if self.ordered else self.order_by("pk"))[:1]:
  File "C:\Users\Muhammad Umer\AppData\Local\Programs\Python\Python311\Lib\site-packages\django\db\models\query.py", line 394, in __iter__
    self._fetch_all()
  File "C:\Users\Muhammad Umer\AppData\Local\Programs\Python\Python311\Lib\site-packages\django\db\models\query.py", line 1867, in _fetch_all
    self._result_cache = list(self._iterable_class(self))
                         ^^^^^^^^^^^^^^^^^^^^^^^^^^^^^^^^
  File "C:\Users\Muhammad Umer\AppData\Local\Programs\Python\Python311\Lib\site-packages\django\db\models\query.py", line 87, in __iter__
    results = compiler.execute_sql(
              ^^^^^^^^^^^^^^^^^^^^^
  File "C:\Users\Muhammad Umer\AppData\Local\Programs\Python\Python311\Lib\site-packages\django\db\models\sql\compiler.py", line 1396, in execute_sql
    cursor = self.connection.cursor()
             ^^^^^^^^^^^^^^^^^^^^^^^^
  File "C:\Users\Muhammad Umer\AppData\Local\Programs\Python\Python311\Lib\site-packages\django\utils\asyncio.py", line 26, in inner
    return func(*args, **kwargs)
           ^^^^^^^^^^^^^^^^^^^^^
  File "C:\Users\Muhammad Umer\AppData\Local\Programs\Python\Python311\Lib\site-packages\django\db\backends\base\base.py", line 323, in cursor
    return self._cursor()
           ^^^^^^^^^^^^^^
  File "C:\Users\Muhammad Umer\AppData\Local\Programs\Python\Python311\Lib\site-packages\django\db\backends\base\base.py", line 300, in _cursor
    with self.wrap_database_errors:
  File "C:\Users\Muhammad Umer\AppData\Local\Programs\Python\Python311\Lib\site-packages\django\db\utils.py", line 91, in __exit__
    raise dj_exc_value.with_traceback(traceback) from exc_value
  File "C:\Users\Muhammad Umer\AppData\Local\Programs\Python\Python311\Lib\site-packages\django\db\backends\base\base.py", line 301, in _cursor
    return self._prepare_cursor(self.create_cursor(name))
                                ^^^^^^^^^^^^^^^^^^^^^^^^
  File "C:\Users\Muhammad Umer\AppData\Local\Programs\Python\Python311\Lib\site-packages\django\utils\asyncio.py", line 26, in inner
    return func(*args, **kwargs)
           ^^^^^^^^^^^^^^^^^^^^^
  File "C:\Users\Muhammad Umer\AppData\Local\Programs\Python\Python311\Lib\site-packages\django\db\backends\postgresql\base.py", line 269, in create_cursor
    cursor = self.connection.cursor()
             ^^^^^^^^^^^^^^^^^^^^^^^^
django.db.utils.InterfaceError: connection already closed
2023-09-23 18:35:46 [scrapy] ERROR: Error processing {'country': 'DK',
 'keyword': 'iphone 14',
 'position': 20,
 'price': '7.651,99\xa0kr.',
 'product_url': 'https://www.refurbed.dk/p/iphone-14-pro/?co=dk&utm_cluster=gradeA&utm_content=iphone-14-pro&utm_group=iphone-14-pro',
 'title': '>> iPhone 14 Pro <<',
 'url': 'refurbed.dk',
 'user_id': 'admin'}
Traceback (most recent call last):
  File "C:\Users\Muhammad Umer\AppData\Local\Programs\Python\Python311\Lib\site-packages\django\db\backends\base\base.py", line 301, in _cursor
    return self._prepare_cursor(self.create_cursor(name))
                                ^^^^^^^^^^^^^^^^^^^^^^^^
  File "C:\Users\Muhammad Umer\AppData\Local\Programs\Python\Python311\Lib\site-packages\django\utils\asyncio.py", line 26, in inner
    return func(*args, **kwargs)
           ^^^^^^^^^^^^^^^^^^^^^
  File "C:\Users\Muhammad Umer\AppData\Local\Programs\Python\Python311\Lib\site-packages\django\db\backends\postgresql\base.py", line 269, in create_cursor
    cursor = self.connection.cursor()
             ^^^^^^^^^^^^^^^^^^^^^^^^
psycopg2.InterfaceError: connection already closed

The above exception was the direct cause of the following exception:

Traceback (most recent call last):
  File "C:\Users\Muhammad Umer\AppData\Local\Programs\Python\Python311\Lib\site-packages\twisted\internet\defer.py", line 1065, in adapt
    extracted = result.result()
                ^^^^^^^^^^^^^^^
  File "C:\Users\Muhammad Umer\AppData\Local\Programs\Python\Python311\Lib\site-packages\asgiref\sync.py", line 448, in __call__
    ret = await asyncio.wait_for(future, timeout=None)
          ^^^^^^^^^^^^^^^^^^^^^^^^^^^^^^^^^^^^^^^^^^^^
  File "C:\Users\Muhammad Umer\AppData\Local\Programs\Python\Python311\Lib\asyncio\tasks.py", line 442, in wait_for
    return await fut
           ^^^^^^^^^
  File "C:\Users\Muhammad Umer\AppData\Local\Programs\Python\Python311\Lib\concurrent\futures\thread.py", line 58, in run
    result = self.fn(*self.args, **self.kwargs)
             ^^^^^^^^^^^^^^^^^^^^^^^^^^^^^^^^^^
  File "C:\Users\Muhammad Umer\AppData\Local\Programs\Python\Python311\Lib\site-packages\asgiref\sync.py", line 490, in thread_handler
    return func(*args, **kwargs)
           ^^^^^^^^^^^^^^^^^^^^^
  File "D:\Outputs\Django Outputs\scraper\pipelines.py", line 33, in process_item
    location = Location.objects.filter(country_code=item['country']).first()
               ^^^^^^^^^^^^^^^^^^^^^^^^^^^^^^^^^^^^^^^^^^^^^^^^^^^^^^^^^^^^^
  File "C:\Users\Muhammad Umer\AppData\Local\Programs\Python\Python311\Lib\site-packages\django\db\models\query.py", line 1047, in first
    for obj in (self if self.ordered else self.order_by("pk"))[:1]:
  File "C:\Users\Muhammad Umer\AppData\Local\Programs\Python\Python311\Lib\site-packages\django\db\models\query.py", line 394, in __iter__
    self._fetch_all()
  File "C:\Users\Muhammad Umer\AppData\Local\Programs\Python\Python311\Lib\site-packages\django\db\models\query.py", line 1867, in _fetch_all
    self._result_cache = list(self._iterable_class(self))
                         ^^^^^^^^^^^^^^^^^^^^^^^^^^^^^^^^
  File "C:\Users\Muhammad Umer\AppData\Local\Programs\Python\Python311\Lib\site-packages\django\db\models\query.py", line 87, in __iter__
    results = compiler.execute_sql(
              ^^^^^^^^^^^^^^^^^^^^^
  File "C:\Users\Muhammad Umer\AppData\Local\Programs\Python\Python311\Lib\site-packages\django\db\models\sql\compiler.py", line 1396, in execute_sql
    cursor = self.connection.cursor()
             ^^^^^^^^^^^^^^^^^^^^^^^^
  File "C:\Users\Muhammad Umer\AppData\Local\Programs\Python\Python311\Lib\site-packages\django\utils\asyncio.py", line 26, in inner
    return func(*args, **kwargs)
           ^^^^^^^^^^^^^^^^^^^^^
  File "C:\Users\Muhammad Umer\AppData\Local\Programs\Python\Python311\Lib\site-packages\django\db\backends\base\base.py", line 323, in cursor
    return self._cursor()
           ^^^^^^^^^^^^^^
  File "C:\Users\Muhammad Umer\AppData\Local\Programs\Python\Python311\Lib\site-packages\django\db\backends\base\base.py", line 300, in _cursor
    with self.wrap_database_errors:
  File "C:\Users\Muhammad Umer\AppData\Local\Programs\Python\Python311\Lib\site-packages\django\db\utils.py", line 91, in __exit__
    raise dj_exc_value.with_traceback(traceback) from exc_value
  File "C:\Users\Muhammad Umer\AppData\Local\Programs\Python\Python311\Lib\site-packages\django\db\backends\base\base.py", line 301, in _cursor
    return self._prepare_cursor(self.create_cursor(name))
                                ^^^^^^^^^^^^^^^^^^^^^^^^
  File "C:\Users\Muhammad Umer\AppData\Local\Programs\Python\Python311\Lib\site-packages\django\utils\asyncio.py", line 26, in inner
    return func(*args, **kwargs)
           ^^^^^^^^^^^^^^^^^^^^^
  File "C:\Users\Muhammad Umer\AppData\Local\Programs\Python\Python311\Lib\site-packages\django\db\backends\postgresql\base.py", line 269, in create_cursor
    cursor = self.connection.cursor()
             ^^^^^^^^^^^^^^^^^^^^^^^^
django.db.utils.InterfaceError: connection already closed
2023-09-23 18:35:46 [scrapy] ERROR: Error processing {'country': 'DK',
 'keyword': 'iphone 14',
 'position': 21,
 'price': '6.840,00\xa0kr.',
 'product_url': 'https://www.3.dk/shop/mobiler/apple/iphone-15?variantId=4_34939_34979',
 'title': 'iPhone 15 128 GB GB Black - Fri tale 30 GBmindstepris fra 7800 kr. '
          '(inkl. abonnement). 3Family & 3LikeHome',
 'url': '3.dk',
 'user_id': 'admin'}
Traceback (most recent call last):
  File "C:\Users\Muhammad Umer\AppData\Local\Programs\Python\Python311\Lib\site-packages\django\db\backends\base\base.py", line 301, in _cursor
    return self._prepare_cursor(self.create_cursor(name))
                                ^^^^^^^^^^^^^^^^^^^^^^^^
  File "C:\Users\Muhammad Umer\AppData\Local\Programs\Python\Python311\Lib\site-packages\django\utils\asyncio.py", line 26, in inner
    return func(*args, **kwargs)
           ^^^^^^^^^^^^^^^^^^^^^
  File "C:\Users\Muhammad Umer\AppData\Local\Programs\Python\Python311\Lib\site-packages\django\db\backends\postgresql\base.py", line 269, in create_cursor
    cursor = self.connection.cursor()
             ^^^^^^^^^^^^^^^^^^^^^^^^
psycopg2.InterfaceError: connection already closed

The above exception was the direct cause of the following exception:

Traceback (most recent call last):
  File "C:\Users\Muhammad Umer\AppData\Local\Programs\Python\Python311\Lib\site-packages\twisted\internet\defer.py", line 1065, in adapt
    extracted = result.result()
                ^^^^^^^^^^^^^^^
  File "C:\Users\Muhammad Umer\AppData\Local\Programs\Python\Python311\Lib\site-packages\asgiref\sync.py", line 448, in __call__
    ret = await asyncio.wait_for(future, timeout=None)
          ^^^^^^^^^^^^^^^^^^^^^^^^^^^^^^^^^^^^^^^^^^^^
  File "C:\Users\Muhammad Umer\AppData\Local\Programs\Python\Python311\Lib\asyncio\tasks.py", line 442, in wait_for
    return await fut
           ^^^^^^^^^
  File "C:\Users\Muhammad Umer\AppData\Local\Programs\Python\Python311\Lib\concurrent\futures\thread.py", line 58, in run
    result = self.fn(*self.args, **self.kwargs)
             ^^^^^^^^^^^^^^^^^^^^^^^^^^^^^^^^^^
  File "C:\Users\Muhammad Umer\AppData\Local\Programs\Python\Python311\Lib\site-packages\asgiref\sync.py", line 490, in thread_handler
    return func(*args, **kwargs)
           ^^^^^^^^^^^^^^^^^^^^^
  File "D:\Outputs\Django Outputs\scraper\pipelines.py", line 33, in process_item
    location = Location.objects.filter(country_code=item['country']).first()
               ^^^^^^^^^^^^^^^^^^^^^^^^^^^^^^^^^^^^^^^^^^^^^^^^^^^^^^^^^^^^^
  File "C:\Users\Muhammad Umer\AppData\Local\Programs\Python\Python311\Lib\site-packages\django\db\models\query.py", line 1047, in first
    for obj in (self if self.ordered else self.order_by("pk"))[:1]:
  File "C:\Users\Muhammad Umer\AppData\Local\Programs\Python\Python311\Lib\site-packages\django\db\models\query.py", line 394, in __iter__
    self._fetch_all()
  File "C:\Users\Muhammad Umer\AppData\Local\Programs\Python\Python311\Lib\site-packages\django\db\models\query.py", line 1867, in _fetch_all
    self._result_cache = list(self._iterable_class(self))
                         ^^^^^^^^^^^^^^^^^^^^^^^^^^^^^^^^
  File "C:\Users\Muhammad Umer\AppData\Local\Programs\Python\Python311\Lib\site-packages\django\db\models\query.py", line 87, in __iter__
    results = compiler.execute_sql(
              ^^^^^^^^^^^^^^^^^^^^^
  File "C:\Users\Muhammad Umer\AppData\Local\Programs\Python\Python311\Lib\site-packages\django\db\models\sql\compiler.py", line 1396, in execute_sql
    cursor = self.connection.cursor()
             ^^^^^^^^^^^^^^^^^^^^^^^^
  File "C:\Users\Muhammad Umer\AppData\Local\Programs\Python\Python311\Lib\site-packages\django\utils\asyncio.py", line 26, in inner
    return func(*args, **kwargs)
           ^^^^^^^^^^^^^^^^^^^^^
  File "C:\Users\Muhammad Umer\AppData\Local\Programs\Python\Python311\Lib\site-packages\django\db\backends\base\base.py", line 323, in cursor
    return self._cursor()
           ^^^^^^^^^^^^^^
  File "C:\Users\Muhammad Umer\AppData\Local\Programs\Python\Python311\Lib\site-packages\django\db\backends\base\base.py", line 300, in _cursor
    with self.wrap_database_errors:
  File "C:\Users\Muhammad Umer\AppData\Local\Programs\Python\Python311\Lib\site-packages\django\db\utils.py", line 91, in __exit__
    raise dj_exc_value.with_traceback(traceback) from exc_value
  File "C:\Users\Muhammad Umer\AppData\Local\Programs\Python\Python311\Lib\site-packages\django\db\backends\base\base.py", line 301, in _cursor
    return self._prepare_cursor(self.create_cursor(name))
                                ^^^^^^^^^^^^^^^^^^^^^^^^
  File "C:\Users\Muhammad Umer\AppData\Local\Programs\Python\Python311\Lib\site-packages\django\utils\asyncio.py", line 26, in inner
    return func(*args, **kwargs)
           ^^^^^^^^^^^^^^^^^^^^^
  File "C:\Users\Muhammad Umer\AppData\Local\Programs\Python\Python311\Lib\site-packages\django\db\backends\postgresql\base.py", line 269, in create_cursor
    cursor = self.connection.cursor()
             ^^^^^^^^^^^^^^^^^^^^^^^^
django.db.utils.InterfaceError: connection already closed
2023-09-23 18:35:46 [scrapy] ERROR: Error processing {'country': 'DK',
 'keyword': 'iphone 14',
 'position': 22,
 'price': '7.799,00\xa0kr.',
 'product_url': 'https://www.elgiganten.dk/product/mobil-tablet-smartwatch/mobiltelefon/iphone-15-5g-smartphone-128gb-sort/673005',
 'title': 'iPhone 15 â€“ 5G smartphone 128GB Sort',
 'url': 'elgiganten.dk',
 'user_id': 'admin'}
Traceback (most recent call last):
  File "C:\Users\Muhammad Umer\AppData\Local\Programs\Python\Python311\Lib\site-packages\django\db\backends\base\base.py", line 301, in _cursor
    return self._prepare_cursor(self.create_cursor(name))
                                ^^^^^^^^^^^^^^^^^^^^^^^^
  File "C:\Users\Muhammad Umer\AppData\Local\Programs\Python\Python311\Lib\site-packages\django\utils\asyncio.py", line 26, in inner
    return func(*args, **kwargs)
           ^^^^^^^^^^^^^^^^^^^^^
  File "C:\Users\Muhammad Umer\AppData\Local\Programs\Python\Python311\Lib\site-packages\django\db\backends\postgresql\base.py", line 269, in create_cursor
    cursor = self.connection.cursor()
             ^^^^^^^^^^^^^^^^^^^^^^^^
psycopg2.InterfaceError: connection already closed

The above exception was the direct cause of the following exception:

Traceback (most recent call last):
  File "C:\Users\Muhammad Umer\AppData\Local\Programs\Python\Python311\Lib\site-packages\twisted\internet\defer.py", line 1065, in adapt
    extracted = result.result()
                ^^^^^^^^^^^^^^^
  File "C:\Users\Muhammad Umer\AppData\Local\Programs\Python\Python311\Lib\site-packages\asgiref\sync.py", line 448, in __call__
    ret = await asyncio.wait_for(future, timeout=None)
          ^^^^^^^^^^^^^^^^^^^^^^^^^^^^^^^^^^^^^^^^^^^^
  File "C:\Users\Muhammad Umer\AppData\Local\Programs\Python\Python311\Lib\asyncio\tasks.py", line 442, in wait_for
    return await fut
           ^^^^^^^^^
  File "C:\Users\Muhammad Umer\AppData\Local\Programs\Python\Python311\Lib\concurrent\futures\thread.py", line 58, in run
    result = self.fn(*self.args, **self.kwargs)
             ^^^^^^^^^^^^^^^^^^^^^^^^^^^^^^^^^^
  File "C:\Users\Muhammad Umer\AppData\Local\Programs\Python\Python311\Lib\site-packages\asgiref\sync.py", line 490, in thread_handler
    return func(*args, **kwargs)
           ^^^^^^^^^^^^^^^^^^^^^
  File "D:\Outputs\Django Outputs\scraper\pipelines.py", line 33, in process_item
    location = Location.objects.filter(country_code=item['country']).first()
               ^^^^^^^^^^^^^^^^^^^^^^^^^^^^^^^^^^^^^^^^^^^^^^^^^^^^^^^^^^^^^
  File "C:\Users\Muhammad Umer\AppData\Local\Programs\Python\Python311\Lib\site-packages\django\db\models\query.py", line 1047, in first
    for obj in (self if self.ordered else self.order_by("pk"))[:1]:
  File "C:\Users\Muhammad Umer\AppData\Local\Programs\Python\Python311\Lib\site-packages\django\db\models\query.py", line 394, in __iter__
    self._fetch_all()
  File "C:\Users\Muhammad Umer\AppData\Local\Programs\Python\Python311\Lib\site-packages\django\db\models\query.py", line 1867, in _fetch_all
    self._result_cache = list(self._iterable_class(self))
                         ^^^^^^^^^^^^^^^^^^^^^^^^^^^^^^^^
  File "C:\Users\Muhammad Umer\AppData\Local\Programs\Python\Python311\Lib\site-packages\django\db\models\query.py", line 87, in __iter__
    results = compiler.execute_sql(
              ^^^^^^^^^^^^^^^^^^^^^
  File "C:\Users\Muhammad Umer\AppData\Local\Programs\Python\Python311\Lib\site-packages\django\db\models\sql\compiler.py", line 1396, in execute_sql
    cursor = self.connection.cursor()
             ^^^^^^^^^^^^^^^^^^^^^^^^
  File "C:\Users\Muhammad Umer\AppData\Local\Programs\Python\Python311\Lib\site-packages\django\utils\asyncio.py", line 26, in inner
    return func(*args, **kwargs)
           ^^^^^^^^^^^^^^^^^^^^^
  File "C:\Users\Muhammad Umer\AppData\Local\Programs\Python\Python311\Lib\site-packages\django\db\backends\base\base.py", line 323, in cursor
    return self._cursor()
           ^^^^^^^^^^^^^^
  File "C:\Users\Muhammad Umer\AppData\Local\Programs\Python\Python311\Lib\site-packages\django\db\backends\base\base.py", line 300, in _cursor
    with self.wrap_database_errors:
  File "C:\Users\Muhammad Umer\AppData\Local\Programs\Python\Python311\Lib\site-packages\django\db\utils.py", line 91, in __exit__
    raise dj_exc_value.with_traceback(traceback) from exc_value
  File "C:\Users\Muhammad Umer\AppData\Local\Programs\Python\Python311\Lib\site-packages\django\db\backends\base\base.py", line 301, in _cursor
    return self._prepare_cursor(self.create_cursor(name))
                                ^^^^^^^^^^^^^^^^^^^^^^^^
  File "C:\Users\Muhammad Umer\AppData\Local\Programs\Python\Python311\Lib\site-packages\django\utils\asyncio.py", line 26, in inner
    return func(*args, **kwargs)
           ^^^^^^^^^^^^^^^^^^^^^
  File "C:\Users\Muhammad Umer\AppData\Local\Programs\Python\Python311\Lib\site-packages\django\db\backends\postgresql\base.py", line 269, in create_cursor
    cursor = self.connection.cursor()
             ^^^^^^^^^^^^^^^^^^^^^^^^
django.db.utils.InterfaceError: connection already closed
2023-09-23 18:35:46 [scrapy] ERROR: Error processing {'country': 'DK',
 'keyword': 'iphone 14',
 'position': 23,
 'price': '5.496,00\xa0kr.',
 'product_url': 'https://www.telmore.dk/shop/mobiltelefoner/Apple/iphone-14?cid=_semt_terminal_terminal_Shopping_Shopping_u0617',
 'title': 'Apple iPhone 14 128 GB - Product Red. Mindstepris 7.290,00 kr.',
 'url': 'telmore.dk',
 'user_id': 'admin'}
Traceback (most recent call last):
  File "C:\Users\Muhammad Umer\AppData\Local\Programs\Python\Python311\Lib\site-packages\django\db\backends\base\base.py", line 301, in _cursor
    return self._prepare_cursor(self.create_cursor(name))
                                ^^^^^^^^^^^^^^^^^^^^^^^^
  File "C:\Users\Muhammad Umer\AppData\Local\Programs\Python\Python311\Lib\site-packages\django\utils\asyncio.py", line 26, in inner
    return func(*args, **kwargs)
           ^^^^^^^^^^^^^^^^^^^^^
  File "C:\Users\Muhammad Umer\AppData\Local\Programs\Python\Python311\Lib\site-packages\django\db\backends\postgresql\base.py", line 269, in create_cursor
    cursor = self.connection.cursor()
             ^^^^^^^^^^^^^^^^^^^^^^^^
psycopg2.InterfaceError: connection already closed

The above exception was the direct cause of the following exception:

Traceback (most recent call last):
  File "C:\Users\Muhammad Umer\AppData\Local\Programs\Python\Python311\Lib\site-packages\twisted\internet\defer.py", line 1065, in adapt
    extracted = result.result()
                ^^^^^^^^^^^^^^^
  File "C:\Users\Muhammad Umer\AppData\Local\Programs\Python\Python311\Lib\site-packages\asgiref\sync.py", line 448, in __call__
    ret = await asyncio.wait_for(future, timeout=None)
          ^^^^^^^^^^^^^^^^^^^^^^^^^^^^^^^^^^^^^^^^^^^^
  File "C:\Users\Muhammad Umer\AppData\Local\Programs\Python\Python311\Lib\asyncio\tasks.py", line 442, in wait_for
    return await fut
           ^^^^^^^^^
  File "C:\Users\Muhammad Umer\AppData\Local\Programs\Python\Python311\Lib\concurrent\futures\thread.py", line 58, in run
    result = self.fn(*self.args, **self.kwargs)
             ^^^^^^^^^^^^^^^^^^^^^^^^^^^^^^^^^^
  File "C:\Users\Muhammad Umer\AppData\Local\Programs\Python\Python311\Lib\site-packages\asgiref\sync.py", line 490, in thread_handler
    return func(*args, **kwargs)
           ^^^^^^^^^^^^^^^^^^^^^
  File "D:\Outputs\Django Outputs\scraper\pipelines.py", line 33, in process_item
    location = Location.objects.filter(country_code=item['country']).first()
               ^^^^^^^^^^^^^^^^^^^^^^^^^^^^^^^^^^^^^^^^^^^^^^^^^^^^^^^^^^^^^
  File "C:\Users\Muhammad Umer\AppData\Local\Programs\Python\Python311\Lib\site-packages\django\db\models\query.py", line 1047, in first
    for obj in (self if self.ordered else self.order_by("pk"))[:1]:
  File "C:\Users\Muhammad Umer\AppData\Local\Programs\Python\Python311\Lib\site-packages\django\db\models\query.py", line 394, in __iter__
    self._fetch_all()
  File "C:\Users\Muhammad Umer\AppData\Local\Programs\Python\Python311\Lib\site-packages\django\db\models\query.py", line 1867, in _fetch_all
    self._result_cache = list(self._iterable_class(self))
                         ^^^^^^^^^^^^^^^^^^^^^^^^^^^^^^^^
  File "C:\Users\Muhammad Umer\AppData\Local\Programs\Python\Python311\Lib\site-packages\django\db\models\query.py", line 87, in __iter__
    results = compiler.execute_sql(
              ^^^^^^^^^^^^^^^^^^^^^
  File "C:\Users\Muhammad Umer\AppData\Local\Programs\Python\Python311\Lib\site-packages\django\db\models\sql\compiler.py", line 1396, in execute_sql
    cursor = self.connection.cursor()
             ^^^^^^^^^^^^^^^^^^^^^^^^
  File "C:\Users\Muhammad Umer\AppData\Local\Programs\Python\Python311\Lib\site-packages\django\utils\asyncio.py", line 26, in inner
    return func(*args, **kwargs)
           ^^^^^^^^^^^^^^^^^^^^^
  File "C:\Users\Muhammad Umer\AppData\Local\Programs\Python\Python311\Lib\site-packages\django\db\backends\base\base.py", line 323, in cursor
    return self._cursor()
           ^^^^^^^^^^^^^^
  File "C:\Users\Muhammad Umer\AppData\Local\Programs\Python\Python311\Lib\site-packages\django\db\backends\base\base.py", line 300, in _cursor
    with self.wrap_database_errors:
  File "C:\Users\Muhammad Umer\AppData\Local\Programs\Python\Python311\Lib\site-packages\django\db\utils.py", line 91, in __exit__
    raise dj_exc_value.with_traceback(traceback) from exc_value
  File "C:\Users\Muhammad Umer\AppData\Local\Programs\Python\Python311\Lib\site-packages\django\db\backends\base\base.py", line 301, in _cursor
    return self._prepare_cursor(self.create_cursor(name))
                                ^^^^^^^^^^^^^^^^^^^^^^^^
  File "C:\Users\Muhammad Umer\AppData\Local\Programs\Python\Python311\Lib\site-packages\django\utils\asyncio.py", line 26, in inner
    return func(*args, **kwargs)
           ^^^^^^^^^^^^^^^^^^^^^
  File "C:\Users\Muhammad Umer\AppData\Local\Programs\Python\Python311\Lib\site-packages\django\db\backends\postgresql\base.py", line 269, in create_cursor
    cursor = self.connection.cursor()
             ^^^^^^^^^^^^^^^^^^^^^^^^
django.db.utils.InterfaceError: connection already closed
2023-09-23 18:35:46 [scrapy] ERROR: Error processing {'country': 'DK',
 'keyword': 'iphone 14',
 'position': 24,
 'price': '6.467,00\xa0kr.',
 'product_url': 'http://www.computersalg.dk/i/9226184/apple-iphone-14-5g-smartphone-dual-sim-intern-hukommelse-128-gb-oled-sk%C3%A6rm-6-1-2532-x-1170-pixels-2x-bagkameraer-12-mp-12-mp?utm_source=googlefeed&utm_medium=5065-it-elektronik-telefoni-gps-mobiltelefoner&utm_campaign=apple&utm_content=24',
 'title': 'Apple Iphone 14 - 5G Smartphone - Dual-Sim / Intern Hukommelse 128 '
          'Gb - Oled-SkÃ¦rm - 6.1" - 2532 X 1170 Pixels - 2X Bagkameraer 12 Mp, '
          '12 Mp - Front',
 'url': 'computersalg.dk',
 'user_id': 'admin'}
Traceback (most recent call last):
  File "C:\Users\Muhammad Umer\AppData\Local\Programs\Python\Python311\Lib\site-packages\django\db\backends\base\base.py", line 301, in _cursor
    return self._prepare_cursor(self.create_cursor(name))
                                ^^^^^^^^^^^^^^^^^^^^^^^^
  File "C:\Users\Muhammad Umer\AppData\Local\Programs\Python\Python311\Lib\site-packages\django\utils\asyncio.py", line 26, in inner
    return func(*args, **kwargs)
           ^^^^^^^^^^^^^^^^^^^^^
  File "C:\Users\Muhammad Umer\AppData\Local\Programs\Python\Python311\Lib\site-packages\django\db\backends\postgresql\base.py", line 269, in create_cursor
    cursor = self.connection.cursor()
             ^^^^^^^^^^^^^^^^^^^^^^^^
psycopg2.InterfaceError: connection already closed

The above exception was the direct cause of the following exception:

Traceback (most recent call last):
  File "C:\Users\Muhammad Umer\AppData\Local\Programs\Python\Python311\Lib\site-packages\twisted\internet\defer.py", line 1065, in adapt
    extracted = result.result()
                ^^^^^^^^^^^^^^^
  File "C:\Users\Muhammad Umer\AppData\Local\Programs\Python\Python311\Lib\site-packages\asgiref\sync.py", line 448, in __call__
    ret = await asyncio.wait_for(future, timeout=None)
          ^^^^^^^^^^^^^^^^^^^^^^^^^^^^^^^^^^^^^^^^^^^^
  File "C:\Users\Muhammad Umer\AppData\Local\Programs\Python\Python311\Lib\asyncio\tasks.py", line 442, in wait_for
    return await fut
           ^^^^^^^^^
  File "C:\Users\Muhammad Umer\AppData\Local\Programs\Python\Python311\Lib\concurrent\futures\thread.py", line 58, in run
    result = self.fn(*self.args, **self.kwargs)
             ^^^^^^^^^^^^^^^^^^^^^^^^^^^^^^^^^^
  File "C:\Users\Muhammad Umer\AppData\Local\Programs\Python\Python311\Lib\site-packages\asgiref\sync.py", line 490, in thread_handler
    return func(*args, **kwargs)
           ^^^^^^^^^^^^^^^^^^^^^
  File "D:\Outputs\Django Outputs\scraper\pipelines.py", line 33, in process_item
    location = Location.objects.filter(country_code=item['country']).first()
               ^^^^^^^^^^^^^^^^^^^^^^^^^^^^^^^^^^^^^^^^^^^^^^^^^^^^^^^^^^^^^
  File "C:\Users\Muhammad Umer\AppData\Local\Programs\Python\Python311\Lib\site-packages\django\db\models\query.py", line 1047, in first
    for obj in (self if self.ordered else self.order_by("pk"))[:1]:
  File "C:\Users\Muhammad Umer\AppData\Local\Programs\Python\Python311\Lib\site-packages\django\db\models\query.py", line 394, in __iter__
    self._fetch_all()
  File "C:\Users\Muhammad Umer\AppData\Local\Programs\Python\Python311\Lib\site-packages\django\db\models\query.py", line 1867, in _fetch_all
    self._result_cache = list(self._iterable_class(self))
                         ^^^^^^^^^^^^^^^^^^^^^^^^^^^^^^^^
  File "C:\Users\Muhammad Umer\AppData\Local\Programs\Python\Python311\Lib\site-packages\django\db\models\query.py", line 87, in __iter__
    results = compiler.execute_sql(
              ^^^^^^^^^^^^^^^^^^^^^
  File "C:\Users\Muhammad Umer\AppData\Local\Programs\Python\Python311\Lib\site-packages\django\db\models\sql\compiler.py", line 1396, in execute_sql
    cursor = self.connection.cursor()
             ^^^^^^^^^^^^^^^^^^^^^^^^
  File "C:\Users\Muhammad Umer\AppData\Local\Programs\Python\Python311\Lib\site-packages\django\utils\asyncio.py", line 26, in inner
    return func(*args, **kwargs)
           ^^^^^^^^^^^^^^^^^^^^^
  File "C:\Users\Muhammad Umer\AppData\Local\Programs\Python\Python311\Lib\site-packages\django\db\backends\base\base.py", line 323, in cursor
    return self._cursor()
           ^^^^^^^^^^^^^^
  File "C:\Users\Muhammad Umer\AppData\Local\Programs\Python\Python311\Lib\site-packages\django\db\backends\base\base.py", line 300, in _cursor
    with self.wrap_database_errors:
  File "C:\Users\Muhammad Umer\AppData\Local\Programs\Python\Python311\Lib\site-packages\django\db\utils.py", line 91, in __exit__
    raise dj_exc_value.with_traceback(traceback) from exc_value
  File "C:\Users\Muhammad Umer\AppData\Local\Programs\Python\Python311\Lib\site-packages\django\db\backends\base\base.py", line 301, in _cursor
    return self._prepare_cursor(self.create_cursor(name))
                                ^^^^^^^^^^^^^^^^^^^^^^^^
  File "C:\Users\Muhammad Umer\AppData\Local\Programs\Python\Python311\Lib\site-packages\django\utils\asyncio.py", line 26, in inner
    return func(*args, **kwargs)
           ^^^^^^^^^^^^^^^^^^^^^
  File "C:\Users\Muhammad Umer\AppData\Local\Programs\Python\Python311\Lib\site-packages\django\db\backends\postgresql\base.py", line 269, in create_cursor
    cursor = self.connection.cursor()
             ^^^^^^^^^^^^^^^^^^^^^^^^
django.db.utils.InterfaceError: connection already closed
2023-09-23 18:35:46 [scrapy] ERROR: Error processing {'country': 'DK',
 'keyword': 'iphone 14',
 'position': 25,
 'price': '4.310,99\xa0kr.',
 'product_url': 'https://www.refurbed.dk/p/iphone-13/14156c/?co=dk&utm_cluster=gradeC&utm_content=iphone-13-14156c&utm_group=iphone-13',
 'title': 'iPhone 13 | 128 GB | Dual-SIM | pink',
 'url': 'refurbed.dk',
 'user_id': 'admin'}
Traceback (most recent call last):
  File "C:\Users\Muhammad Umer\AppData\Local\Programs\Python\Python311\Lib\site-packages\django\db\backends\base\base.py", line 301, in _cursor
    return self._prepare_cursor(self.create_cursor(name))
                                ^^^^^^^^^^^^^^^^^^^^^^^^
  File "C:\Users\Muhammad Umer\AppData\Local\Programs\Python\Python311\Lib\site-packages\django\utils\asyncio.py", line 26, in inner
    return func(*args, **kwargs)
           ^^^^^^^^^^^^^^^^^^^^^
  File "C:\Users\Muhammad Umer\AppData\Local\Programs\Python\Python311\Lib\site-packages\django\db\backends\postgresql\base.py", line 269, in create_cursor
    cursor = self.connection.cursor()
             ^^^^^^^^^^^^^^^^^^^^^^^^
psycopg2.InterfaceError: connection already closed

The above exception was the direct cause of the following exception:

Traceback (most recent call last):
  File "C:\Users\Muhammad Umer\AppData\Local\Programs\Python\Python311\Lib\site-packages\twisted\internet\defer.py", line 1065, in adapt
    extracted = result.result()
                ^^^^^^^^^^^^^^^
  File "C:\Users\Muhammad Umer\AppData\Local\Programs\Python\Python311\Lib\site-packages\asgiref\sync.py", line 448, in __call__
    ret = await asyncio.wait_for(future, timeout=None)
          ^^^^^^^^^^^^^^^^^^^^^^^^^^^^^^^^^^^^^^^^^^^^
  File "C:\Users\Muhammad Umer\AppData\Local\Programs\Python\Python311\Lib\asyncio\tasks.py", line 442, in wait_for
    return await fut
           ^^^^^^^^^
  File "C:\Users\Muhammad Umer\AppData\Local\Programs\Python\Python311\Lib\concurrent\futures\thread.py", line 58, in run
    result = self.fn(*self.args, **self.kwargs)
             ^^^^^^^^^^^^^^^^^^^^^^^^^^^^^^^^^^
  File "C:\Users\Muhammad Umer\AppData\Local\Programs\Python\Python311\Lib\site-packages\asgiref\sync.py", line 490, in thread_handler
    return func(*args, **kwargs)
           ^^^^^^^^^^^^^^^^^^^^^
  File "D:\Outputs\Django Outputs\scraper\pipelines.py", line 33, in process_item
    location = Location.objects.filter(country_code=item['country']).first()
               ^^^^^^^^^^^^^^^^^^^^^^^^^^^^^^^^^^^^^^^^^^^^^^^^^^^^^^^^^^^^^
  File "C:\Users\Muhammad Umer\AppData\Local\Programs\Python\Python311\Lib\site-packages\django\db\models\query.py", line 1047, in first
    for obj in (self if self.ordered else self.order_by("pk"))[:1]:
  File "C:\Users\Muhammad Umer\AppData\Local\Programs\Python\Python311\Lib\site-packages\django\db\models\query.py", line 394, in __iter__
    self._fetch_all()
  File "C:\Users\Muhammad Umer\AppData\Local\Programs\Python\Python311\Lib\site-packages\django\db\models\query.py", line 1867, in _fetch_all
    self._result_cache = list(self._iterable_class(self))
                         ^^^^^^^^^^^^^^^^^^^^^^^^^^^^^^^^
  File "C:\Users\Muhammad Umer\AppData\Local\Programs\Python\Python311\Lib\site-packages\django\db\models\query.py", line 87, in __iter__
    results = compiler.execute_sql(
              ^^^^^^^^^^^^^^^^^^^^^
  File "C:\Users\Muhammad Umer\AppData\Local\Programs\Python\Python311\Lib\site-packages\django\db\models\sql\compiler.py", line 1396, in execute_sql
    cursor = self.connection.cursor()
             ^^^^^^^^^^^^^^^^^^^^^^^^
  File "C:\Users\Muhammad Umer\AppData\Local\Programs\Python\Python311\Lib\site-packages\django\utils\asyncio.py", line 26, in inner
    return func(*args, **kwargs)
           ^^^^^^^^^^^^^^^^^^^^^
  File "C:\Users\Muhammad Umer\AppData\Local\Programs\Python\Python311\Lib\site-packages\django\db\backends\base\base.py", line 323, in cursor
    return self._cursor()
           ^^^^^^^^^^^^^^
  File "C:\Users\Muhammad Umer\AppData\Local\Programs\Python\Python311\Lib\site-packages\django\db\backends\base\base.py", line 300, in _cursor
    with self.wrap_database_errors:
  File "C:\Users\Muhammad Umer\AppData\Local\Programs\Python\Python311\Lib\site-packages\django\db\utils.py", line 91, in __exit__
    raise dj_exc_value.with_traceback(traceback) from exc_value
  File "C:\Users\Muhammad Umer\AppData\Local\Programs\Python\Python311\Lib\site-packages\django\db\backends\base\base.py", line 301, in _cursor
    return self._prepare_cursor(self.create_cursor(name))
                                ^^^^^^^^^^^^^^^^^^^^^^^^
  File "C:\Users\Muhammad Umer\AppData\Local\Programs\Python\Python311\Lib\site-packages\django\utils\asyncio.py", line 26, in inner
    return func(*args, **kwargs)
           ^^^^^^^^^^^^^^^^^^^^^
  File "C:\Users\Muhammad Umer\AppData\Local\Programs\Python\Python311\Lib\site-packages\django\db\backends\postgresql\base.py", line 269, in create_cursor
    cursor = self.connection.cursor()
             ^^^^^^^^^^^^^^^^^^^^^^^^
django.db.utils.InterfaceError: connection already closed
2023-09-23 18:35:46 [scrapy] ERROR: Error processing {'country': 'DK',
 'keyword': 'iphone 14',
 'position': 26,
 'price': '6.666,00\xa0kr.',
 'product_url': 'https://www.proshop.dk/Mobil/Apple-iPhone-14-5G-128GB-Purple/3104591?utm_source=google&utm_medium=cpc&utm_campaign=searchengine',
 'title': 'Apple iPhone 14 5G 128GB - Purple, Mobiltelefon',
 'url': 'proshop.dk',
 'user_id': 'admin'}
Traceback (most recent call last):
  File "C:\Users\Muhammad Umer\AppData\Local\Programs\Python\Python311\Lib\site-packages\django\db\backends\base\base.py", line 301, in _cursor
    return self._prepare_cursor(self.create_cursor(name))
                                ^^^^^^^^^^^^^^^^^^^^^^^^
  File "C:\Users\Muhammad Umer\AppData\Local\Programs\Python\Python311\Lib\site-packages\django\utils\asyncio.py", line 26, in inner
    return func(*args, **kwargs)
           ^^^^^^^^^^^^^^^^^^^^^
  File "C:\Users\Muhammad Umer\AppData\Local\Programs\Python\Python311\Lib\site-packages\django\db\backends\postgresql\base.py", line 269, in create_cursor
    cursor = self.connection.cursor()
             ^^^^^^^^^^^^^^^^^^^^^^^^
psycopg2.InterfaceError: connection already closed

The above exception was the direct cause of the following exception:

Traceback (most recent call last):
  File "C:\Users\Muhammad Umer\AppData\Local\Programs\Python\Python311\Lib\site-packages\twisted\internet\defer.py", line 1065, in adapt
    extracted = result.result()
                ^^^^^^^^^^^^^^^
  File "C:\Users\Muhammad Umer\AppData\Local\Programs\Python\Python311\Lib\site-packages\asgiref\sync.py", line 448, in __call__
    ret = await asyncio.wait_for(future, timeout=None)
          ^^^^^^^^^^^^^^^^^^^^^^^^^^^^^^^^^^^^^^^^^^^^
  File "C:\Users\Muhammad Umer\AppData\Local\Programs\Python\Python311\Lib\asyncio\tasks.py", line 442, in wait_for
    return await fut
           ^^^^^^^^^
  File "C:\Users\Muhammad Umer\AppData\Local\Programs\Python\Python311\Lib\concurrent\futures\thread.py", line 58, in run
    result = self.fn(*self.args, **self.kwargs)
             ^^^^^^^^^^^^^^^^^^^^^^^^^^^^^^^^^^
  File "C:\Users\Muhammad Umer\AppData\Local\Programs\Python\Python311\Lib\site-packages\asgiref\sync.py", line 490, in thread_handler
    return func(*args, **kwargs)
           ^^^^^^^^^^^^^^^^^^^^^
  File "D:\Outputs\Django Outputs\scraper\pipelines.py", line 33, in process_item
    location = Location.objects.filter(country_code=item['country']).first()
               ^^^^^^^^^^^^^^^^^^^^^^^^^^^^^^^^^^^^^^^^^^^^^^^^^^^^^^^^^^^^^
  File "C:\Users\Muhammad Umer\AppData\Local\Programs\Python\Python311\Lib\site-packages\django\db\models\query.py", line 1047, in first
    for obj in (self if self.ordered else self.order_by("pk"))[:1]:
  File "C:\Users\Muhammad Umer\AppData\Local\Programs\Python\Python311\Lib\site-packages\django\db\models\query.py", line 394, in __iter__
    self._fetch_all()
  File "C:\Users\Muhammad Umer\AppData\Local\Programs\Python\Python311\Lib\site-packages\django\db\models\query.py", line 1867, in _fetch_all
    self._result_cache = list(self._iterable_class(self))
                         ^^^^^^^^^^^^^^^^^^^^^^^^^^^^^^^^
  File "C:\Users\Muhammad Umer\AppData\Local\Programs\Python\Python311\Lib\site-packages\django\db\models\query.py", line 87, in __iter__
    results = compiler.execute_sql(
              ^^^^^^^^^^^^^^^^^^^^^
  File "C:\Users\Muhammad Umer\AppData\Local\Programs\Python\Python311\Lib\site-packages\django\db\models\sql\compiler.py", line 1396, in execute_sql
    cursor = self.connection.cursor()
             ^^^^^^^^^^^^^^^^^^^^^^^^
  File "C:\Users\Muhammad Umer\AppData\Local\Programs\Python\Python311\Lib\site-packages\django\utils\asyncio.py", line 26, in inner
    return func(*args, **kwargs)
           ^^^^^^^^^^^^^^^^^^^^^
  File "C:\Users\Muhammad Umer\AppData\Local\Programs\Python\Python311\Lib\site-packages\django\db\backends\base\base.py", line 323, in cursor
    return self._cursor()
           ^^^^^^^^^^^^^^
  File "C:\Users\Muhammad Umer\AppData\Local\Programs\Python\Python311\Lib\site-packages\django\db\backends\base\base.py", line 300, in _cursor
    with self.wrap_database_errors:
  File "C:\Users\Muhammad Umer\AppData\Local\Programs\Python\Python311\Lib\site-packages\django\db\utils.py", line 91, in __exit__
    raise dj_exc_value.with_traceback(traceback) from exc_value
  File "C:\Users\Muhammad Umer\AppData\Local\Programs\Python\Python311\Lib\site-packages\django\db\backends\base\base.py", line 301, in _cursor
    return self._prepare_cursor(self.create_cursor(name))
                                ^^^^^^^^^^^^^^^^^^^^^^^^
  File "C:\Users\Muhammad Umer\AppData\Local\Programs\Python\Python311\Lib\site-packages\django\utils\asyncio.py", line 26, in inner
    return func(*args, **kwargs)
           ^^^^^^^^^^^^^^^^^^^^^
  File "C:\Users\Muhammad Umer\AppData\Local\Programs\Python\Python311\Lib\site-packages\django\db\backends\postgresql\base.py", line 269, in create_cursor
    cursor = self.connection.cursor()
             ^^^^^^^^^^^^^^^^^^^^^^^^
django.db.utils.InterfaceError: connection already closed
2023-09-23 18:35:46 [scrapy] ERROR: Error processing {'country': 'DK',
 'keyword': 'iphone 14',
 'position': 27,
 'price': '7.200,00\xa0kr.',
 'product_url': 'https://www.3.dk/shop/mobiler/apple/iphone-14?variantId=4_16870_16922',
 'title': 'iPhone 14 128 GB GB Purple - Fri tale 30 GBmindstepris fra 8160 kr. '
          '(inkl. abonnement). 3Family & 3LikeHome',
 'url': '3.dk',
 'user_id': 'admin'}
Traceback (most recent call last):
  File "C:\Users\Muhammad Umer\AppData\Local\Programs\Python\Python311\Lib\site-packages\django\db\backends\base\base.py", line 301, in _cursor
    return self._prepare_cursor(self.create_cursor(name))
                                ^^^^^^^^^^^^^^^^^^^^^^^^
  File "C:\Users\Muhammad Umer\AppData\Local\Programs\Python\Python311\Lib\site-packages\django\utils\asyncio.py", line 26, in inner
    return func(*args, **kwargs)
           ^^^^^^^^^^^^^^^^^^^^^
  File "C:\Users\Muhammad Umer\AppData\Local\Programs\Python\Python311\Lib\site-packages\django\db\backends\postgresql\base.py", line 269, in create_cursor
    cursor = self.connection.cursor()
             ^^^^^^^^^^^^^^^^^^^^^^^^
psycopg2.InterfaceError: connection already closed

The above exception was the direct cause of the following exception:

Traceback (most recent call last):
  File "C:\Users\Muhammad Umer\AppData\Local\Programs\Python\Python311\Lib\site-packages\twisted\internet\defer.py", line 1065, in adapt
    extracted = result.result()
                ^^^^^^^^^^^^^^^
  File "C:\Users\Muhammad Umer\AppData\Local\Programs\Python\Python311\Lib\site-packages\asgiref\sync.py", line 448, in __call__
    ret = await asyncio.wait_for(future, timeout=None)
          ^^^^^^^^^^^^^^^^^^^^^^^^^^^^^^^^^^^^^^^^^^^^
  File "C:\Users\Muhammad Umer\AppData\Local\Programs\Python\Python311\Lib\asyncio\tasks.py", line 442, in wait_for
    return await fut
           ^^^^^^^^^
  File "C:\Users\Muhammad Umer\AppData\Local\Programs\Python\Python311\Lib\concurrent\futures\thread.py", line 58, in run
    result = self.fn(*self.args, **self.kwargs)
             ^^^^^^^^^^^^^^^^^^^^^^^^^^^^^^^^^^
  File "C:\Users\Muhammad Umer\AppData\Local\Programs\Python\Python311\Lib\site-packages\asgiref\sync.py", line 490, in thread_handler
    return func(*args, **kwargs)
           ^^^^^^^^^^^^^^^^^^^^^
  File "D:\Outputs\Django Outputs\scraper\pipelines.py", line 33, in process_item
    location = Location.objects.filter(country_code=item['country']).first()
               ^^^^^^^^^^^^^^^^^^^^^^^^^^^^^^^^^^^^^^^^^^^^^^^^^^^^^^^^^^^^^
  File "C:\Users\Muhammad Umer\AppData\Local\Programs\Python\Python311\Lib\site-packages\django\db\models\query.py", line 1047, in first
    for obj in (self if self.ordered else self.order_by("pk"))[:1]:
  File "C:\Users\Muhammad Umer\AppData\Local\Programs\Python\Python311\Lib\site-packages\django\db\models\query.py", line 394, in __iter__
    self._fetch_all()
  File "C:\Users\Muhammad Umer\AppData\Local\Programs\Python\Python311\Lib\site-packages\django\db\models\query.py", line 1867, in _fetch_all
    self._result_cache = list(self._iterable_class(self))
                         ^^^^^^^^^^^^^^^^^^^^^^^^^^^^^^^^
  File "C:\Users\Muhammad Umer\AppData\Local\Programs\Python\Python311\Lib\site-packages\django\db\models\query.py", line 87, in __iter__
    results = compiler.execute_sql(
              ^^^^^^^^^^^^^^^^^^^^^
  File "C:\Users\Muhammad Umer\AppData\Local\Programs\Python\Python311\Lib\site-packages\django\db\models\sql\compiler.py", line 1396, in execute_sql
    cursor = self.connection.cursor()
             ^^^^^^^^^^^^^^^^^^^^^^^^
  File "C:\Users\Muhammad Umer\AppData\Local\Programs\Python\Python311\Lib\site-packages\django\utils\asyncio.py", line 26, in inner
    return func(*args, **kwargs)
           ^^^^^^^^^^^^^^^^^^^^^
  File "C:\Users\Muhammad Umer\AppData\Local\Programs\Python\Python311\Lib\site-packages\django\db\backends\base\base.py", line 323, in cursor
    return self._cursor()
           ^^^^^^^^^^^^^^
  File "C:\Users\Muhammad Umer\AppData\Local\Programs\Python\Python311\Lib\site-packages\django\db\backends\base\base.py", line 300, in _cursor
    with self.wrap_database_errors:
  File "C:\Users\Muhammad Umer\AppData\Local\Programs\Python\Python311\Lib\site-packages\django\db\utils.py", line 91, in __exit__
    raise dj_exc_value.with_traceback(traceback) from exc_value
  File "C:\Users\Muhammad Umer\AppData\Local\Programs\Python\Python311\Lib\site-packages\django\db\backends\base\base.py", line 301, in _cursor
    return self._prepare_cursor(self.create_cursor(name))
                                ^^^^^^^^^^^^^^^^^^^^^^^^
  File "C:\Users\Muhammad Umer\AppData\Local\Programs\Python\Python311\Lib\site-packages\django\utils\asyncio.py", line 26, in inner
    return func(*args, **kwargs)
           ^^^^^^^^^^^^^^^^^^^^^
  File "C:\Users\Muhammad Umer\AppData\Local\Programs\Python\Python311\Lib\site-packages\django\db\backends\postgresql\base.py", line 269, in create_cursor
    cursor = self.connection.cursor()
             ^^^^^^^^^^^^^^^^^^^^^^^^
django.db.utils.InterfaceError: connection already closed
2023-09-23 18:35:46 [scrapy] ERROR: Error processing {'country': 'DK',
 'keyword': 'iphone 14',
 'position': 28,
 'price': '5.281,00\xa0kr.',
 'product_url': 'https://yousee.dk/mobil/mobiltelefoner/apple/iphone-14/1471/mobil_80/kontant/',
 'title': 'Apple iPhone 14 128 GB StjerneskÃ¦r med abonnementsaftale. '
          'Mindstepris 6.595,00 kr.',
 'url': 'yousee.dk',
 'user_id': 'admin'}
Traceback (most recent call last):
  File "C:\Users\Muhammad Umer\AppData\Local\Programs\Python\Python311\Lib\site-packages\django\db\backends\base\base.py", line 301, in _cursor
    return self._prepare_cursor(self.create_cursor(name))
                                ^^^^^^^^^^^^^^^^^^^^^^^^
  File "C:\Users\Muhammad Umer\AppData\Local\Programs\Python\Python311\Lib\site-packages\django\utils\asyncio.py", line 26, in inner
    return func(*args, **kwargs)
           ^^^^^^^^^^^^^^^^^^^^^
  File "C:\Users\Muhammad Umer\AppData\Local\Programs\Python\Python311\Lib\site-packages\django\db\backends\postgresql\base.py", line 269, in create_cursor
    cursor = self.connection.cursor()
             ^^^^^^^^^^^^^^^^^^^^^^^^
psycopg2.InterfaceError: connection already closed

The above exception was the direct cause of the following exception:

Traceback (most recent call last):
  File "C:\Users\Muhammad Umer\AppData\Local\Programs\Python\Python311\Lib\site-packages\twisted\internet\defer.py", line 1065, in adapt
    extracted = result.result()
                ^^^^^^^^^^^^^^^
  File "C:\Users\Muhammad Umer\AppData\Local\Programs\Python\Python311\Lib\site-packages\asgiref\sync.py", line 448, in __call__
    ret = await asyncio.wait_for(future, timeout=None)
          ^^^^^^^^^^^^^^^^^^^^^^^^^^^^^^^^^^^^^^^^^^^^
  File "C:\Users\Muhammad Umer\AppData\Local\Programs\Python\Python311\Lib\asyncio\tasks.py", line 442, in wait_for
    return await fut
           ^^^^^^^^^
  File "C:\Users\Muhammad Umer\AppData\Local\Programs\Python\Python311\Lib\concurrent\futures\thread.py", line 58, in run
    result = self.fn(*self.args, **self.kwargs)
             ^^^^^^^^^^^^^^^^^^^^^^^^^^^^^^^^^^
  File "C:\Users\Muhammad Umer\AppData\Local\Programs\Python\Python311\Lib\site-packages\asgiref\sync.py", line 490, in thread_handler
    return func(*args, **kwargs)
           ^^^^^^^^^^^^^^^^^^^^^
  File "D:\Outputs\Django Outputs\scraper\pipelines.py", line 33, in process_item
    location = Location.objects.filter(country_code=item['country']).first()
               ^^^^^^^^^^^^^^^^^^^^^^^^^^^^^^^^^^^^^^^^^^^^^^^^^^^^^^^^^^^^^
  File "C:\Users\Muhammad Umer\AppData\Local\Programs\Python\Python311\Lib\site-packages\django\db\models\query.py", line 1047, in first
    for obj in (self if self.ordered else self.order_by("pk"))[:1]:
  File "C:\Users\Muhammad Umer\AppData\Local\Programs\Python\Python311\Lib\site-packages\django\db\models\query.py", line 394, in __iter__
    self._fetch_all()
  File "C:\Users\Muhammad Umer\AppData\Local\Programs\Python\Python311\Lib\site-packages\django\db\models\query.py", line 1867, in _fetch_all
    self._result_cache = list(self._iterable_class(self))
                         ^^^^^^^^^^^^^^^^^^^^^^^^^^^^^^^^
  File "C:\Users\Muhammad Umer\AppData\Local\Programs\Python\Python311\Lib\site-packages\django\db\models\query.py", line 87, in __iter__
    results = compiler.execute_sql(
              ^^^^^^^^^^^^^^^^^^^^^
  File "C:\Users\Muhammad Umer\AppData\Local\Programs\Python\Python311\Lib\site-packages\django\db\models\sql\compiler.py", line 1396, in execute_sql
    cursor = self.connection.cursor()
             ^^^^^^^^^^^^^^^^^^^^^^^^
  File "C:\Users\Muhammad Umer\AppData\Local\Programs\Python\Python311\Lib\site-packages\django\utils\asyncio.py", line 26, in inner
    return func(*args, **kwargs)
           ^^^^^^^^^^^^^^^^^^^^^
  File "C:\Users\Muhammad Umer\AppData\Local\Programs\Python\Python311\Lib\site-packages\django\db\backends\base\base.py", line 323, in cursor
    return self._cursor()
           ^^^^^^^^^^^^^^
  File "C:\Users\Muhammad Umer\AppData\Local\Programs\Python\Python311\Lib\site-packages\django\db\backends\base\base.py", line 300, in _cursor
    with self.wrap_database_errors:
  File "C:\Users\Muhammad Umer\AppData\Local\Programs\Python\Python311\Lib\site-packages\django\db\utils.py", line 91, in __exit__
    raise dj_exc_value.with_traceback(traceback) from exc_value
  File "C:\Users\Muhammad Umer\AppData\Local\Programs\Python\Python311\Lib\site-packages\django\db\backends\base\base.py", line 301, in _cursor
    return self._prepare_cursor(self.create_cursor(name))
                                ^^^^^^^^^^^^^^^^^^^^^^^^
  File "C:\Users\Muhammad Umer\AppData\Local\Programs\Python\Python311\Lib\site-packages\django\utils\asyncio.py", line 26, in inner
    return func(*args, **kwargs)
           ^^^^^^^^^^^^^^^^^^^^^
  File "C:\Users\Muhammad Umer\AppData\Local\Programs\Python\Python311\Lib\site-packages\django\db\backends\postgresql\base.py", line 269, in create_cursor
    cursor = self.connection.cursor()
             ^^^^^^^^^^^^^^^^^^^^^^^^
django.db.utils.InterfaceError: connection already closed
2023-09-23 18:35:46 [scrapy] ERROR: Error processing {'country': 'DK',
 'keyword': 'iphone 14',
 'position': 29,
 'price': '5.579,00\xa0kr.',
 'product_url': 'https://swappie.com/dk/iphone/iphone-14/iphone-14-128gb-lilla-16/',
 'title': 'iPhone 14 128GB Lilla Apple',
 'url': 'swappie.com',
 'user_id': 'admin'}
Traceback (most recent call last):
  File "C:\Users\Muhammad Umer\AppData\Local\Programs\Python\Python311\Lib\site-packages\django\db\backends\base\base.py", line 301, in _cursor
    return self._prepare_cursor(self.create_cursor(name))
                                ^^^^^^^^^^^^^^^^^^^^^^^^
  File "C:\Users\Muhammad Umer\AppData\Local\Programs\Python\Python311\Lib\site-packages\django\utils\asyncio.py", line 26, in inner
    return func(*args, **kwargs)
           ^^^^^^^^^^^^^^^^^^^^^
  File "C:\Users\Muhammad Umer\AppData\Local\Programs\Python\Python311\Lib\site-packages\django\db\backends\postgresql\base.py", line 269, in create_cursor
    cursor = self.connection.cursor()
             ^^^^^^^^^^^^^^^^^^^^^^^^
psycopg2.InterfaceError: connection already closed

The above exception was the direct cause of the following exception:

Traceback (most recent call last):
  File "C:\Users\Muhammad Umer\AppData\Local\Programs\Python\Python311\Lib\site-packages\twisted\internet\defer.py", line 1065, in adapt
    extracted = result.result()
                ^^^^^^^^^^^^^^^
  File "C:\Users\Muhammad Umer\AppData\Local\Programs\Python\Python311\Lib\site-packages\asgiref\sync.py", line 448, in __call__
    ret = await asyncio.wait_for(future, timeout=None)
          ^^^^^^^^^^^^^^^^^^^^^^^^^^^^^^^^^^^^^^^^^^^^
  File "C:\Users\Muhammad Umer\AppData\Local\Programs\Python\Python311\Lib\asyncio\tasks.py", line 442, in wait_for
    return await fut
           ^^^^^^^^^
  File "C:\Users\Muhammad Umer\AppData\Local\Programs\Python\Python311\Lib\concurrent\futures\thread.py", line 58, in run
    result = self.fn(*self.args, **self.kwargs)
             ^^^^^^^^^^^^^^^^^^^^^^^^^^^^^^^^^^
  File "C:\Users\Muhammad Umer\AppData\Local\Programs\Python\Python311\Lib\site-packages\asgiref\sync.py", line 490, in thread_handler
    return func(*args, **kwargs)
           ^^^^^^^^^^^^^^^^^^^^^
  File "D:\Outputs\Django Outputs\scraper\pipelines.py", line 33, in process_item
    location = Location.objects.filter(country_code=item['country']).first()
               ^^^^^^^^^^^^^^^^^^^^^^^^^^^^^^^^^^^^^^^^^^^^^^^^^^^^^^^^^^^^^
  File "C:\Users\Muhammad Umer\AppData\Local\Programs\Python\Python311\Lib\site-packages\django\db\models\query.py", line 1047, in first
    for obj in (self if self.ordered else self.order_by("pk"))[:1]:
  File "C:\Users\Muhammad Umer\AppData\Local\Programs\Python\Python311\Lib\site-packages\django\db\models\query.py", line 394, in __iter__
    self._fetch_all()
  File "C:\Users\Muhammad Umer\AppData\Local\Programs\Python\Python311\Lib\site-packages\django\db\models\query.py", line 1867, in _fetch_all
    self._result_cache = list(self._iterable_class(self))
                         ^^^^^^^^^^^^^^^^^^^^^^^^^^^^^^^^
  File "C:\Users\Muhammad Umer\AppData\Local\Programs\Python\Python311\Lib\site-packages\django\db\models\query.py", line 87, in __iter__
    results = compiler.execute_sql(
              ^^^^^^^^^^^^^^^^^^^^^
  File "C:\Users\Muhammad Umer\AppData\Local\Programs\Python\Python311\Lib\site-packages\django\db\models\sql\compiler.py", line 1396, in execute_sql
    cursor = self.connection.cursor()
             ^^^^^^^^^^^^^^^^^^^^^^^^
  File "C:\Users\Muhammad Umer\AppData\Local\Programs\Python\Python311\Lib\site-packages\django\utils\asyncio.py", line 26, in inner
    return func(*args, **kwargs)
           ^^^^^^^^^^^^^^^^^^^^^
  File "C:\Users\Muhammad Umer\AppData\Local\Programs\Python\Python311\Lib\site-packages\django\db\backends\base\base.py", line 323, in cursor
    return self._cursor()
           ^^^^^^^^^^^^^^
  File "C:\Users\Muhammad Umer\AppData\Local\Programs\Python\Python311\Lib\site-packages\django\db\backends\base\base.py", line 300, in _cursor
    with self.wrap_database_errors:
  File "C:\Users\Muhammad Umer\AppData\Local\Programs\Python\Python311\Lib\site-packages\django\db\utils.py", line 91, in __exit__
    raise dj_exc_value.with_traceback(traceback) from exc_value
  File "C:\Users\Muhammad Umer\AppData\Local\Programs\Python\Python311\Lib\site-packages\django\db\backends\base\base.py", line 301, in _cursor
    return self._prepare_cursor(self.create_cursor(name))
                                ^^^^^^^^^^^^^^^^^^^^^^^^
  File "C:\Users\Muhammad Umer\AppData\Local\Programs\Python\Python311\Lib\site-packages\django\utils\asyncio.py", line 26, in inner
    return func(*args, **kwargs)
           ^^^^^^^^^^^^^^^^^^^^^
  File "C:\Users\Muhammad Umer\AppData\Local\Programs\Python\Python311\Lib\site-packages\django\db\backends\postgresql\base.py", line 269, in create_cursor
    cursor = self.connection.cursor()
             ^^^^^^^^^^^^^^^^^^^^^^^^
django.db.utils.InterfaceError: connection already closed
2023-09-23 18:35:46 [scrapy] ERROR: Error processing {'country': 'DK',
 'keyword': 'iphone 14',
 'position': 30,
 'price': None,
 'product_url': None,
 'title': None,
 'url': '',
 'user_id': 'admin'}
Traceback (most recent call last):
  File "C:\Users\Muhammad Umer\AppData\Local\Programs\Python\Python311\Lib\site-packages\django\db\backends\base\base.py", line 301, in _cursor
    return self._prepare_cursor(self.create_cursor(name))
                                ^^^^^^^^^^^^^^^^^^^^^^^^
  File "C:\Users\Muhammad Umer\AppData\Local\Programs\Python\Python311\Lib\site-packages\django\utils\asyncio.py", line 26, in inner
    return func(*args, **kwargs)
           ^^^^^^^^^^^^^^^^^^^^^
  File "C:\Users\Muhammad Umer\AppData\Local\Programs\Python\Python311\Lib\site-packages\django\db\backends\postgresql\base.py", line 269, in create_cursor
    cursor = self.connection.cursor()
             ^^^^^^^^^^^^^^^^^^^^^^^^
psycopg2.InterfaceError: connection already closed

The above exception was the direct cause of the following exception:

Traceback (most recent call last):
  File "C:\Users\Muhammad Umer\AppData\Local\Programs\Python\Python311\Lib\site-packages\twisted\internet\defer.py", line 1065, in adapt
    extracted = result.result()
                ^^^^^^^^^^^^^^^
  File "C:\Users\Muhammad Umer\AppData\Local\Programs\Python\Python311\Lib\site-packages\asgiref\sync.py", line 448, in __call__
    ret = await asyncio.wait_for(future, timeout=None)
          ^^^^^^^^^^^^^^^^^^^^^^^^^^^^^^^^^^^^^^^^^^^^
  File "C:\Users\Muhammad Umer\AppData\Local\Programs\Python\Python311\Lib\asyncio\tasks.py", line 442, in wait_for
    return await fut
           ^^^^^^^^^
  File "C:\Users\Muhammad Umer\AppData\Local\Programs\Python\Python311\Lib\concurrent\futures\thread.py", line 58, in run
    result = self.fn(*self.args, **self.kwargs)
             ^^^^^^^^^^^^^^^^^^^^^^^^^^^^^^^^^^
  File "C:\Users\Muhammad Umer\AppData\Local\Programs\Python\Python311\Lib\site-packages\asgiref\sync.py", line 490, in thread_handler
    return func(*args, **kwargs)
           ^^^^^^^^^^^^^^^^^^^^^
  File "D:\Outputs\Django Outputs\scraper\pipelines.py", line 33, in process_item
    location = Location.objects.filter(country_code=item['country']).first()
               ^^^^^^^^^^^^^^^^^^^^^^^^^^^^^^^^^^^^^^^^^^^^^^^^^^^^^^^^^^^^^
  File "C:\Users\Muhammad Umer\AppData\Local\Programs\Python\Python311\Lib\site-packages\django\db\models\query.py", line 1047, in first
    for obj in (self if self.ordered else self.order_by("pk"))[:1]:
  File "C:\Users\Muhammad Umer\AppData\Local\Programs\Python\Python311\Lib\site-packages\django\db\models\query.py", line 394, in __iter__
    self._fetch_all()
  File "C:\Users\Muhammad Umer\AppData\Local\Programs\Python\Python311\Lib\site-packages\django\db\models\query.py", line 1867, in _fetch_all
    self._result_cache = list(self._iterable_class(self))
                         ^^^^^^^^^^^^^^^^^^^^^^^^^^^^^^^^
  File "C:\Users\Muhammad Umer\AppData\Local\Programs\Python\Python311\Lib\site-packages\django\db\models\query.py", line 87, in __iter__
    results = compiler.execute_sql(
              ^^^^^^^^^^^^^^^^^^^^^
  File "C:\Users\Muhammad Umer\AppData\Local\Programs\Python\Python311\Lib\site-packages\django\db\models\sql\compiler.py", line 1396, in execute_sql
    cursor = self.connection.cursor()
             ^^^^^^^^^^^^^^^^^^^^^^^^
  File "C:\Users\Muhammad Umer\AppData\Local\Programs\Python\Python311\Lib\site-packages\django\utils\asyncio.py", line 26, in inner
    return func(*args, **kwargs)
           ^^^^^^^^^^^^^^^^^^^^^
  File "C:\Users\Muhammad Umer\AppData\Local\Programs\Python\Python311\Lib\site-packages\django\db\backends\base\base.py", line 323, in cursor
    return self._cursor()
           ^^^^^^^^^^^^^^
  File "C:\Users\Muhammad Umer\AppData\Local\Programs\Python\Python311\Lib\site-packages\django\db\backends\base\base.py", line 300, in _cursor
    with self.wrap_database_errors:
  File "C:\Users\Muhammad Umer\AppData\Local\Programs\Python\Python311\Lib\site-packages\django\db\utils.py", line 91, in __exit__
    raise dj_exc_value.with_traceback(traceback) from exc_value
  File "C:\Users\Muhammad Umer\AppData\Local\Programs\Python\Python311\Lib\site-packages\django\db\backends\base\base.py", line 301, in _cursor
    return self._prepare_cursor(self.create_cursor(name))
                                ^^^^^^^^^^^^^^^^^^^^^^^^
  File "C:\Users\Muhammad Umer\AppData\Local\Programs\Python\Python311\Lib\site-packages\django\utils\asyncio.py", line 26, in inner
    return func(*args, **kwargs)
           ^^^^^^^^^^^^^^^^^^^^^
  File "C:\Users\Muhammad Umer\AppData\Local\Programs\Python\Python311\Lib\site-packages\django\db\backends\postgresql\base.py", line 269, in create_cursor
    cursor = self.connection.cursor()
             ^^^^^^^^^^^^^^^^^^^^^^^^
django.db.utils.InterfaceError: connection already closed
2023-09-23 18:35:46 [scrapy] INFO: Closing spider (finished)
2023-09-23 18:35:46 [scrapy] INFO: Dumping Scrapy stats:
{'downloader/request_bytes': 422,
 'downloader/request_count': 1,
 'downloader/request_method_count/GET': 1,
 'downloader/response_bytes': 260721,
 'downloader/response_count': 1,
 'downloader/response_status_count/200': 1,
 'elapsed_time_seconds': 6.482886,
 'finish_reason': 'finished',
 'finish_time': datetime.datetime(2023, 9, 23, 13, 35, 46, 911287),
 'httpcompression/response_bytes': 1027082,
 'httpcompression/response_count': 1,
 'log_count/DEBUG': 1,
 'log_count/ERROR': 30,
 'log_count/INFO': 8,
 'response_received_count': 1,
 'scheduler/dequeued': 1,
 'scheduler/dequeued/memory': 1,
 'scheduler/enqueued': 1,
 'scheduler/enqueued/memory': 1,
 'start_time': datetime.datetime(2023, 9, 23, 13, 35, 40, 428401)}
2023-09-23 18:35:46 [scrapy] INFO: Spider closed (finished)
